Workbook

Sheet Version_Control
A1: VERSION CONTROL — FlowCast
A3: Version | B3: Date | C3: Author | D3: Change | E3: Status
A4: v001-v004 | B4: 2026-09-05 | C4: Claude for Senthil/KP | D4: Lineage: marketplace master (868 entries) -> portfolio plan (12 products) -> wave-1 (RetainKit/ShiftDesk/EngageOS, v005) -> this product selected for wave-3 | E4: Released
A5: v007 | B5: 2026-09-05 19:50 | C5: Claude for Senthil/KP | D5: Full product workbook for FlowCast on Xero App Store: spec, screen inventory, 100+ story backlog, live sprint board, 18-month financial model (editable assumptions), GTM execution tasks, platform launch checklist, metric targets, risk register | E5: Released
A6: v008 | B6: 2026-09-10 22:01 | C6: Claude for Senthil/KP | D6: Sprint_Tracker_Log + Traceability_Matrix sheets added; D13 100% coverage gate applied (ST-085 amended); S1 foundation + code-completable S2-S8 stories built in TypeScript with 11 Jest suites / 120 tests at 100% stmts/branches/funcs/lines; Full_Backlog statuses updated (58 Done, 4 pending-live, 2 in progress); portfolio D15 note logged | E6: Released
A7: v009 | B7: 2026-09-10 22:20 | C7: Claude for Senthil/KP | D7: UI surfaces (5 React screens + MetricsPanel) with Xero deep links; ST-003 rule builder; notifications w/ per-type mute; pause toggles; portal rules; per-feature metrics/trends; CI workflow (ST-086). 13 suites / 148 tests at 100% coverage incl. components; statuses now 74 Done / 5 pending-live / 21 backlog | E7: Released
A8: v010 | B8: 2026-09-10 22:27 | C8: Claude for Senthil/KP | D8: Reliability + a11y code (latency budgets, degradation comms, jest-axe WCAG pass), demo-data mode, scenario/portal notification events; 12 content artifacts (15 help articles, chat SLA, video script, listing copy A/B, asset specs, pricing, trust page, dry-run gap report, 3 runbooks). 14 suites/155 tests at 100%. Dry-run found webhook build gap -> v011 | E8: Released
A9: v011 | B9: 2026-09-10 22:51 | C9: Claude for Senthil/KP | D9: Content webhooks built (dry-run gap #4): signature verify, fast-ack idempotent queue, retry/dead-letter/heal, payment->cancel-nudges mapping; bank-txn 15-min polling (platform has no such webhook). Launch_Checklist statuses updated honestly. 15 suites / 170 tests at 100%. Sandbox work exhausted — remaining items need Senthil | E9: Released
A10: v012 | B10: 2026-09-10 22:56 | C10: Claude for Senthil/KP | D10: Per-tenant 60/min rate limiter; 20-client + 12-month QA drills executed (found+fixed batch-isolation anomaly blind spot via detectWithHistory); k6 load harness (5x); blue/green deploy workflow; HTTP wiring layer. 16 suites / 182 tests at 100%. Backlog down to 4 (all require live infra/humans) | E10: Released
A11: v013 | B11: 2026-09-10 23:03 | C11: Claude for Senthil/KP | D11: Live-sweep readiness: typed config loader + .env.example, 30-min dev-org setup guide, 12-step scripted verification sweep. Portfolio action board issued as separate workbook. 17 suites / 186 tests at 100% | E11: Released
A12: v014 | B12: 2026-09-11 11:09 | C12: Claude for Senthil/KP | D12: Cold-review pass 1: 5 defects found + fixed with regression tests (F-001 unbounded webhook idempotency ledger -> FIFO 10k; F-002 signed-but-malformed payload crashed fast-ack -> guarded parse; F-003 rate-limiter idle tenants never evicted -> prune(); F-004 duplicate anomaly repeated per txn with 3+ matches -> deduped; F-005 nudgesPerMonth had no cycle-scoped counter/reset -> UsageCycle built). ST-066 encryption at rest built (AES-256-GCM envelope, SecretsVault boundary, token sealing, TLS assertion, self-verifying evidence drill). Security evidence pack (sandbox half of ST-068) + REVIEW_PACK.md for external second reviewer. 18 suites / 207 tests at 100% zero pragmas; tsc clean. Review_Findings sheet added for Senthil dispositions | E12: Released
A13: v015 | B13: 2026-09-11 12:47 | C13: Claude for Senthil/KP | D13: Cold-review pass 2 (the 10 modules pass 1 did not deep-read): 4 defects found + fixed with regressions — F-006 nudge planner re-sent the same tier daily (no sent-history) -> SentHistory, tier fires once, test-mode not recorded, failed sends retried; F-007 purgeExpired flagged accounts but never deleted the record -> record deleted (data deletion honoured), purged status removed; F-008 non-finite platform dates silently dropped items from the forecast -> validated with clear errors, plus traffic light now judged on displayed rounded balance; F-009 monthly scenario cost omitted its 4th occurrence inside the 13-week horizon (week 13) -> 4 occurrences, optimism bias removed. 2 observations logged without fix (no backoff jitter; unlimited half-open breaker probes). 2 pre-existing assertions updated (one encoded F-009). 19 suites / 219 tests at 100% zero pragmas; tsc clean. Cold review COMPLETE across all 27 modules | E13: Released
A14: v016 | B14: 2026-09-11 15:27 | C14: Claude for Senthil/KP | D14: CODE-PHASE-COMPLETION WAVE (sibling-validated TeleField/VoiceBridge pattern): ST-081 built-in chat + 4-business-hour SLA engine (business-hours math skips weekends/out-of-hours; queue sorts tightest deadline; chat-vendor decision now OPTIONAL — D-F6); ST-099 listing SEO iteration engine sandbox half (promote/keyword/demote rules with 100-impression thin-data floor; live half needs post-launch search-term data); ST-100 10-slot design-partner tracker (stale-nudge at 7 days; honest exit math separates reviews from G-02 paying strangers); ST-080 ranked help-center search over the 15 launch articles (manifest test-gated against docs/help); ST-095 pricing plan-matrix generated from billing.ts single source + DRIFT GATE test binding the published page to the enforced constants. 20 suites / 243 tests at 100% zero pragmas; tsc clean. FLOWCAST CODE PHASE COMPLETE — backlog zero, no further code sprints planned | E14: Released
... A31: v033 | B31: 2026-09-13 18:48 | C31: Claude for Senthil/KP | D31: ASYNC-OWNERSHIP GATE (sixth, and the last derived from a shipped defect) + REVIEW PLAYBOOK. A real defect found first: the worker tick called drainOnce with no catch, and drainOnce RETHROWS after re-queuing (F4-04) — so every store or sink failure produced an unhandled rejection that the degradation counter never saw and /ready never showed. The process guards stopped it being fatal, but it was invisible. Both that and the SIGTERM shutdown call now have owners; shutdown failures are reported with credentials redacted. Sixth gate: a promise started and not awaited must have an owner (safely(), or an explicit .catch). Only resilience.ts is exempt — it IS the owner of last resort and cannot wrap itself. Proved against the exact CHAOS-1 shape; all five provable gates now print PROVED. REVIEW PLAYBOOK written (gates/REVIEW_PLAYBOOK.md): the eight review passes in the order that proved productive — cold review by module, external verification sweep, artifact-gap audit, integration audit, review-the-previous-session, environment assumptions, artifact pairing, outsider-first document review — plus the rules learned the hard way and how to run them on another product. ~40 defects were found in code that was already at 100% coverage with zero backlog; the gates catch recurrence, the passes find what nobody has thought of yet. 36 suites / 500 tests at 100% zero pragmas; six gates in CI. Recommendation recorded: this is a natural stopping point for sandbox work | E31: Released
A32: v034 | D32: PLANNED: opens on live evidence (dev org + DATABASE_URL) or dispositions — no further sandbox sprints recommended | E32: Planned
A33: v034 | B33: 2026-09-13 22:47 | C33: Claude for Senthil/KP | D33: External review response, sprint E5 (code v0.28.0, tracker v022). 15 findings FC-R001..R015 from the first independent non-author review triaged into three waves. Wave 1 executed: IANA time zones with DST, shared cross-instance Xero rate budget, jittered backoff, bounded half-open probes, leader fencing token, SBOM + drift gate, evidence manifest, security headers, threat model, 20/100/500-client scale drills, DSAR end-to-end. FC-R002 closed as a DOCUMENTATION defect — the dry-run had claimed webhooks uncoded since before v011. 40 suites / 595 tests at 100% zero pragmas; 7 gates proved. New Enhancement_Backlog sheet keeps the 399-point baseline frozen. Story position unchanged at 77 Done. | E33: Released
A34: v035 | B34: 2026-09-13 23:03 | C34: Claude for Senthil/KP | D34: Cross-product defect-class sweep, sprint E5b (code v0.29.0, tracker v023). Wave 2 deliberately not started — it is gated on DEC-F16. PORT-04 executed instead: RetainKit external-review questions asked of FlowCast. Four findings, two critical, both deploy-configuration rather than logic and both invisible to a 100% suite and eight prior review passes: production booted with no database (silently reinstating GAP-F3, ENV-1 and E5-05 at once) and with no encryption key (failing at the first merchant install, with the key absent from .env.example). Shutdown given a deadline; requests given timeouts. Two further classes verified absent rather than assumed. 40 suites / 608 tests at 100%; 8 gates proved. Story position unchanged at 77 Done. | E34: Released
A35: v036 | B35: 2026-09-20 10:14 | C35: Claude for Senthil/KP | D35: Perplexity V001 response, sprint E6 / Wave P1 (code v0.30.0, tracker v024). Second independent review found 3 BLOCKER code defects on the live path (PPX-01 no production data path for the forecast; PPX-02 supplier bills mixed into receivables; PPX-03 billing rail on the deprecated XASS channel) + 7 more. P1-1..P1-7 executed (96 pts, enhancement pool); P1-8 logged from four new boot-composition findings (E6-F3..F6); P2/P3/P4 logged. Per Senthil 10:17: nothing deleted, no story re-statused, billing rail untouched (PPX-D4). Enhancement_Backlog, Risk_Register, Senthil_Handover, Launch_Checklist, Financial_Model note and Sprint_Tracker_Log extended. | E35: Released

Sheet ReadMe_Scope
A1: FlowCast — 13-week cash forecast, scenario planning, invoice-chasing nudges for SMB owners and their accountants
A3: PLATFORM: Xero App Store | CATEGORY: Cash Flow Forecasting
A4: PROBLEM: Float/Fathom serve accountants; owner-facing simple forecasting still underserved at low price points
A5: DIFFERENTIATION: Plain-language forecast, WhatsApp/email nudge integration, accountant multi-client view
A6: ICP: SMBs 1-50 staff on Xero + their accountants/bookkeepers (multi-client)
A8: HOW TO USE: Full_Backlog is the single source of truth (edit Status column during execution). Sprint_Board recalculates points per sprint automatically. Financial_Model assumptions (yellow) are editable — the 18-month build recalculates. Launch_Checklist is the platform-specific gate before submission. All costs/timelines are market-standard estimates; verify platform terms (fees/review rules) during S0.
A10: STACK ASSUMPTION (market standard): TypeScript/Node or platform-mandated runtime, React frontends, Postgres, hosted on AWS/GCP/platform FaaS as required, GitHub Actions CI, PostHog + Sentry telemetry, Intercom-class support.

Sheet Senthil_Handover
A1: FLOWCAST — EVERYTHING BLOCKED ON SENTHIL (as of 13 Sep 2026 12:03, workbook v026) — v036 (20 Sep 10:14): items 16–21 added from Perplexity V001; item 4 is STALE (XASS deprecated — see 18)
A2: Ordered by leverage: external lead times first (they queue while you do everything else), then same-day unlocks, then decisions, then post-launch.
A4: # | B4: Item | C4: Why it is blocked on you | D4: What it unlocks | E4: Effort | F4: Lead time | G4: Type
A5: 1 | B5: Xero dev org + app registration | C5: Needs your Xero account; scopes, webhook key and redirect URI come from it. ALSO NOW: a Postgres DATABASE_URL — since v027 tenant state is durable, and without the database the app falls back to memory (visible as durableStore:false on /health) | D5: THE big one: the 12-step live sweep, which flips 16 code-complete stories to Done. Step 1 is now npm ci && npm run build && npm run migrate && npm start | E5: ~30 min | F5: Same day | G5: External access
A6: 2 | B6: Pen-test vendor engagement | C6: Vendor selection and budget are yours; it is the external half of ST-068 | D6: Security evidence pack completion → Xero App Partner certification (LC-5) | E6: Email + scoping | F6: 2-4 weeks | G6: External vendor
A7: 3 | B7: External second reviewer (REVIEW_PACK.md) | C7: Same-AI review is not independent; ST-097 stays In progress until a human or different AI signs off | D7: Submission dry-run credibility; independent check on ~30 findings I both made and fixed | E7: 2-3 hrs of their time | F7: Days | G7: External person
A8: 4 | B8: Xero App Store partner application | C8: Your company details and bank/tax info | D8: In-store subscription billing (ST-059); sweep step 9 test purchase. NOTE: App Store Subscriptions confirmed for UK/AU/NZ; re-check current region list at onboarding | E8: ~1 hr | F8: 1-3 weeks | G8: External queue
A9: 5 | B9: F-001..F-009, INT-F1..F5, VER-001..003, F3-01..04, F4-01..04, HOLE-1/2 dispositions | C9: ~30 findings in the Review_Findings sheet are all fixed but marked Pending your disposition — you may disagree with a fix or want one reverted | D9: Closes the review record; anything you reject, I change | E9: ~45 min reading | F9: — | G9: Decision
A10: 6 | B10: OBS-001 / OBS-002 dispositions | C10: Logged no-fix deliberately: no backoff jitter (retry herds) and unlimited half-open breaker probes. Both are judgement calls on launch traffic | D10: Either accept as-is for launch or I build them | E10: ~10 min | F10: — | G10: Decision
A11: 7 | B11: Listing copy A/B pick | C11: Two full drafts exist (listing-copy-A.md, listing-copy-B.md); the choice is positioning, which is yours | D11: ST-093; listing submission | E11: ~20 min | F11: — | G11: Decision
A12: 8 | B12: D-F6 chat vendor ratification | C12: The built-in chat + 4-business-hour SLA engine works, so a vendor is OPTIONAL — a later transport swap, not a launch blocker | D12: Formally closes ST-081 | E12: ~5 min | F12: — | G12: Decision
A13: 9 | B13: D15 portfolio sequencing | C13: Open since 10 Sep across all products: parallel builds vs strict WIN order | D13: Affects whether FlowCast launches before the rank-1..11 products | E13: — | F13: — | G13: Decision
A14: 10 | B14: Screenshot/video capture | C14: Needs the app running against a real org with real data — i.e. item 1 first | D14: ST-094; listing assets | E14: ~2 hrs | F14: After item 1 | G14: Post-dev-org
A15: 11 | B15: Design-partner outreach | C15: The 10-slot tracker with honest exit math is built and empty; sending the emails is yours | D15: ST-100; the G-02 gate needs 10 PAYING strangers — reviews do not count | E15: ~1 hr | F15: Weeks | G15: Post-launch
A16: 12 | B16: Port the gate pack to other products | C16: gates/README.md + npm run prove:gates are ready; which products get them is a portfolio call | D16: Would catch the same defect classes in the other 10 builds — but competes with getting this one live | E16: ~1 hr each | F16: — | G16: Decision
A18: Nothing on this list is codeable in the sandbox. FlowCast code is 29 suites / 395 tests at 100% coverage, zero pragmas, three proved gates in CI, and boots end to end (npm start → /health → signed webhook).
A20: UPDATED 13 Sep 2026 22:47 after the external review. Items 1-4 are unchanged and still the critical path; the two decisions below now sit above them for sequencing because they cost minutes and unblock sprints.
A22: # | B22: Item | C22: Why it is blocked on you | D22: What it unlocks | E22: Effort | F22: Lead time | G22: Type
A23: 0a | B23: DEC-F16 — the positioning wedge | C23: The external review says generic Xero cash-flow forecasting is crowded (Xero ships 30/90/180-day by plan; Syft, Fathom, Spotlight, Futrli, Float are established). Its recommendation: narrow to a 13-week cash control and collections copilot for practices, and sell the closed loop. Only you can take this. | D23: All of Wave 2 — 84 points across forecast accuracy, collections, practice depth and enterprise tenancy. Nothing there should be built before it. | E23: ~30 min reading | F23: — | G23: Decision
A24: 0b | B24: DEC-F17 — does a non-author AI review close ST-097? | C24: The review pack says a same-author review is not independent. A different model has now reviewed it. Whether that is sufficient, or a human is still required, is a standard you set. | D24: ST-097 here and on eight sibling products; submission dry-run row 11. | E24: ~10 min | F24: — | G24: Decision
A25: 5b | B25: 8 new Review_Findings dispositions (E5-xx, OBS-005, DEAD-2) | C25: Fixed and regression-pinned, but the record is only closed when you accept or reject each. | D25: Closes the E5 review record. | E25: ~15 min reading | F25: — | G25: Decision
A26: 13 | B26: Signing key + custody decision | C26: No key is held, so release provenance cannot be claimed however much we build. FC-R015 stays half open until this exists. | D26: Signed artifacts; the provenance half of G01. | E26: ~1 hr + a decision | F26: — | G26: External / decision
A28: ADDED 23:03 — sandbox-codeable work arising from both reviews is now exhausted. Everything below this line needs a decision or a live environment; further sitting time on FlowCast has declining marginal value until one of them moves.
A30: 14 | B30: PORT-04 — which products get the E5b fixes | C30: The fail-closed boot check and the shutdown deadline apply to every product with a Postgres store and a blue/green deploy. Both critical findings survived a 100% suite and eight review passes here, so they are very likely live in the siblings. | D30: Closes the same two classes across the portfolio before they are found in production. | E30: ~30 min each | F30: — | G30: Decision
A31: 15 | B31: 6 new Review_Findings dispositions (E5b-01..04, CLEARED-1/2) | C31: Fixed and pinned; the record closes when you accept or reject. | D31: Closes the E5b review record. | E31: ~10 min | F31: — | G31: Decision
A32: 16 | B32: PPX-D2 — unblock Wave P2 (closed-loop spine) from DEC-F16 | C32: Reverses a standing sequencing decision. The reviewer argues the spine is valuable under every positioning and that DEC-F16 cannot be judged against a forecast that does not run — it runs now (P1-2). | D32: 84 points of sandbox-buildable product depth (P2-1..P2-4). | E32: ~15 min | F32: — | G32: Decision
A33: 17 | B33: PPX-D3 — reprice from $25 to the £45–£99 band | C33: Pricing is founder territory. Reviewer: $25 does not clear cost at any volume the plan reaches; the category prices 2–8× higher for narrower jobs. | D33: P4-1 model rebuild; listing/pricing copy; the accountant channel becoming affordable. | E33: ~30 min | F33: — | G33: Decision
A34: 18 | B34: PPX-D4 — retire the xero_marketplace rail (Stripe-only) | C34: You said on 20 Sep: delete nothing this sprint. The rail is recorded as CONTRADICTED (PA-11) and the build will demand a re-verification by ~19 Dec. Item 4 above (App Store partner application for in-store billing) is stale: XASS is deprecated; the partner application is still needed for the listing and the referral fee, not for billing. | D34: Removes dead logic; unblocks P4-1; corrects LC-6, ST-059 and the financial model's fee line. | E34: ~10 min to decide | F34: — | G34: Decision
A35: 19 | B35: PPX-D5 — PORT-05: audit the nine siblings for the PPX-01 and PPX-03 shapes | C35: Portfolio call. Both classes survived a 100% suite, eight gates and two reviews here. dataPathGate and platformDriftGate are portable as written. | D35: Prevents the same two blockers surfacing in each sibling's first external review. | E35: ~1 sitting per product | F35: — | G35: Decision
A36: 20 | B36: PPX-D6 — DEC-F17 revisited: does a non-author AI review close ST-097? | C36: Two independent AI reviews have now found blockers the author's passes did not; the reviewer's recommendation is "necessary, not yet sufficient — human before submission, not before building". | D36: ST-097 status; the same story on eight siblings. | E36: ~10 min | F36: — | G36: Decision
A37: 21 | B37: P1-8 boot composition — approve the sprint before 31 Oct 2026 | C37: The method-level gate found the durable store, webhook worker and uninstall path have no production driver (E6-F3..F5). Their KNOWN_GAPS expire 31 Oct; after that the suite is red until wired. Sandbox-codeable; needs your go. | D37: A restart that keeps every tenant; drained webhooks; uninstall actually removing tokens. | E37: "go ahead" | F37: — | G37: Decision
A38: 22 | B38: E6-F2 — pick an email/notification transport | C38: No transport exists in src. Nudges, dunning emails, trial expiry and anomaly alerts have logic and no delivery; boot reports this rather than faking it. | D38: The nudge feature actually reaching a customer. | E38: Vendor pick | F38: Days | G38: Decision

Sheet Product_Spec
A1: PRODUCT SPEC
A3: Module (feature) | B3: Scope in MVP | C3: Out of scope (v1) | D3: Non-functional requirements
A4: 13-week forecast engine | B4: 13-week forecast engine: end-to-end happy path + edge cases + permissions | C4: Advanced automation, AI beyond listed, multi-language beyond launch set | D4: p95 <500ms API / <2s UI loads
A5: Scenario sliders | B5: Scenario sliders: end-to-end happy path + edge cases + permissions | C5: Advanced automation, AI beyond listed, multi-language beyond launch set | D5: 99.5% monthly uptime
A6: Invoice chase nudges | B6: Invoice chase nudges: end-to-end happy path + edge cases + permissions | C6: Advanced automation, AI beyond listed, multi-language beyond launch set | D6: WCAG AA
A7: Accountant portal | B7: Accountant portal: end-to-end happy path + edge cases + permissions | C7: Advanced automation, AI beyond listed, multi-language beyond launch set | D7: SOC2-track controls
A8: Bank-feed anomaly alerts | B8: Bank-feed anomaly alerts: end-to-end happy path + edge cases + permissions | C8: Advanced automation, AI beyond listed, multi-language beyond launch set | D8: Rate-limit safe (backoff+queue)
A10: Persona | B10: Jobs-to-be-done
A11: SMB owner | B11: Anxiety about cash; wants traffic-light simplicity
A12: Accountant partner | B12: Advisory revenue tool across client base
A13: Bookkeeper | B13: Data hygiene; bank-feed exceptions

Sheet Screens_Wireframes
A1: SCREEN INVENTORY (attach Figma links in col E during S0)
A3: # | B3: Screen | C3: Purpose | D3: Key elements | E3: Wireframe link
A4: 1 | B4: Onboarding / first-run | C4: Reach aha in <1 day | D4: Checklist, sample data toggle, connect steps
A5: 2 | B5: Home dashboard | C5: Daily habit surface | D5: KPI cards, activity feed, alerts
A6: 3 | B6: 13-week forecast engine workspace | C6: Core value surface | D6: List+detail, bulk actions, status chips
A7: 4 | B7: Scenario sliders builder | C7: Configure second pillar | D7: Rule builder, preview, test mode
A8: 5 | B8: Invoice chase nudges view | C8: Differentiator surface | D8: Timeline/visual, export
A9: 6 | B9: Settings & team | C9: Roles, notifications, data | D9: Role matrix, API keys, danger zone
A10: 7 | B10: Billing | C10: Plan/trial/invoices | D10: Plan cards, usage meter, invoices
A11: 8 | B11: Analytics | C11: Prove ROI | D11: Funnel, cohort, export
A12: 9 | B12: Help & support | C12: Deflect + assist | D12: Search, chat, status

Sheet Enhancement_Backlog
A1: ENHANCEMENT BACKLOG — work arising from the external review, on its OWN point pool.
A2: D-F7 (to ratify): the 399-point / 100-story baseline in Full_Backlog stays FROZEN. Enhancement work never moves the 77-Done position. The reviewer called our code completeness "misleadingly high"; letting a correctness release inflate apparent delivery would prove the point. Sibling precedent: RetainKit.
A4: ID | B4: Wave | C4: Theme | D4: Scope | E4: Points | F4: Status | G4: Closes | H4: Gate / evidence
A5: E5-01 | B5: 1 | C5: Reproducible build + evidence | D5: Clean reproduction of the suite from the supplied package; EVIDENCE_MANIFEST.json with per-file SHA-256 and a rollup; verify command wired into CI. | E5: 5 | F5: Done-in-code | G5: FC-R005 (repro half), G01 | H5: npm run verify:evidence; tests/supplyChainGate.test.ts
A6: E5-02 | B6: 1 | C6: Supply chain | D6: CycloneDX 1.5 SBOM from the lockfile with a drift gate; npm audit on shipped dependencies; secret-shape scanner; security headers on every response incl. 404/500. | E6: 8 | F6: Done-in-code | G6: FC-R015, FC-R006 | H6: tests/supplyChainGate.test.ts; proved in prove-gates
A7: E5-03 | B7: 1 | C7: Threat model | D7: STRIDE model over 5 trust boundaries with a module scope table and an explicit "Not defended, deliberately" list of six gaps; SECURITY_POLICY.md. | E7: 5 | F7: Done-in-code | G7: FC-R006 | H7: tests/docFreshnessGate.test.ts now covers THREAT_MODEL.md
A8: E5-04 | B8: 1 | C8: Time zones + DST | D8: IANA zones resolved per instant via Node 22 ICU; DST matrices for Europe/London, Australia/Sydney, Pacific/Auckland; fixed-offset fallback preserved. | E8: 8 | F8: Done | G8: FC-R008, OBS-003 | H8: tests/timezoneDst.test.ts — 21 regressions
A9: E5-05 | B9: 1 | C9: Distributed reliability | D9: Shared cross-instance Xero org budget in Postgres; full-jitter backoff; bounded half-open probes; monotonic leader fencing token read per scheduler tick. | E9: 13 | F9: Done-in-code | G9: FC-R007, OBS-001/002/004 | H9: tests/distributedReliability.test.ts — 30 regressions
A10: E5-06 | B10: 1 | C10: Scale drills | D10: Deterministic non-uniform practice generator; forecast + portal at 20/100/500 clients over 24 months with p95 budgets and a per-row cost check. | E10: 8 | F10: Done-in-code | G10: FC-R010 (compute half), FC-R014 (scale half) | H10: tests/practiceScaleAndPrivacy.test.ts
A11: E5-07 | B11: 1 | C11: Privacy end-to-end | D11: DSAR export/delete E2E incl. the cross-tenant negative and idempotent re-deletion; retention schedule coherence pinned; help article bound to the code. | E11: 5 | F11: Done-in-code | G11: FC-R009 (sandbox half) | H11: tests/practiceScaleAndPrivacy.test.ts
A12: E5-08 | B12: 1 | C12: Stale-claim gate | D12: Dry-run document rewritten with its history; sixth gate fails the build when a published document claims a gap about a module that exists. | E12: 5 | F12: Done | G12: FC-R002 | H12: tests/supplyChainGate.test.ts; proved by restoring the original sentence
A13: E6-01 | B13: 2 | C13: Forecast accuracy | D13: Forecast-vs-actual ledger, backtesting, confidence bands, payment-behaviour calibration, seasonality, red-week explanation. | E13: 21 | F13: BLOCKED — DEC-F16 | G13: FC-R012 | H13: —
A14: E6-02 | B14: 2 | C14: Collections copilot | D14: Cash-impact ranked debtors, owner/task assignment, channel rules, promise-to-pay and dispute state, recovered-cash attribution. | E14: 21 | F14: BLOCKED — DEC-F16 | G14: FC-R013, FC-R004 | H14: —
A15: E6-03 | B15: 2 | C15: Practice OS depth | D15: Portfolio heatmap, bulk triage, delegation, client notes, branded exports, advisory workflow. | E15: 21 | F15: BLOCKED — DEC-F16 | G15: FC-R014 | H15: —
A16: E6-04 | B16: 2 | C16: Enterprise tenancy + admin | D16: Org/user lifecycle, SSO/OIDC abstraction, fine-grained RBAC beyond three roles, audit export, approval-gated support impersonation, tamper-evident audit log. | E16: 21 | F16: BLOCKED — DEC-F16 | G16: FC-R009, G10 | H16: —
... A42: P4-2 | B42: P4 | C42: Positioning and listing | D42: Listing copy around recovered cash; comparison pages vs native Xero, Float, Chaser; Fluidly precedent + Syft acquisition in the risk register (done: R-F18/R-F19); pricing page rebuilt. | E42: 11 | F42: OPEN — DEC-F16 / PPX-D3 | G42: FC-R004, DEC-F16 | H42: —
A44: TOTALS | D44: Delivered (Wave 1 + E5b + P1) / total enhancement pool | E44: =SUMIFS(E5:E42,B5:B42,"1")+SUMIFS(E5:E42,B5:B42,"P1",F5:F42,"Done*")&" of "&SUM(E5:E42)
A46: Wave 1 is complete. Wave 2 cannot start until DEC-F16 (the positioning wedge) is decided — building depth first would be building the wrong depth. Wave 3 cannot start at all without Senthil. — v036 (20 Sep): Wave P1 (P1-1..P1-7) delivered per the Perplexity plan; P1-8 open with a 31 Oct 2026 gate expiry; P2 needs PPX-D2; P3 not started; P4 needs PPX-D3/D4/DEC-F16. The earlier E6-01..E6-04 rows are KEPT and cross-referenced (D-F8) — P1-7 delivers the ledger half of E6-01; P2-2/P2-4/P3-3 supersede E6-02/E6-03/E6-04. Reviewer's honest remaining distance: ~425 points against the 399-point baseline.

Sheet Full_Backlog
A1: FULL BACKLOG | H1: As-built verification (13 Sep 12:03)
A3: ID | B3: Epic | C3: Story | D3: Points | E3: Priority | F3: Sprint | G3: Status
A4: ST-001 | B4: F1 | C4: As a SMB owner, I can set up 13-week forecast engine with sensible defaults in one screen | D4: 5 | E4: P0 | F4: S2 | G4: Done
A5: ST-002 | B5: F1 | C5: As a SMB owner, the 13-week forecast engine happy path completes without documentation | D5: 8 | E5: P0 | F5: S2 | G5: Done
A6: ST-003 | B6: F1 | C6: As a Accountant partner, I can customise 13-week forecast engine rules/conditions for my workflow | D6: 5 | E6: P1 | F6: S2 | G6: Done
A7: ST-004 | B7: F1 | C7: As a user, 13-week forecast engine shows clear errors and retry paths on platform API failures | D7: 3 | E7: P0 | F7: S2 | G7: Done
A8: ST-005 | B8: F1 | C8: As a Bookkeeper, 13-week forecast engine works on the web app with Xero deep links + accountant portal surface end-to-end | D8: 5 | E8: P0 | F8: S3 | G8: Done
A9: ST-006 | B9: F1 | C9: As a Accountant partner, I can see 13-week forecast engine performance metrics and trends | D9: 3 | E9: P1 | F9: S3 | G9: Done
A10: ST-007 | B10: F1 | C10: As a user, 13-week forecast engine respects role permissions and audit logging | D10: 3 | E10: P1 | F10: S3 | G10: Done
A11: ST-008 | B11: F1 | C11: As a SMB owner, I can pause/disable 13-week forecast engine without data loss | D11: 2 | E11: P2 | F11: S3 | G11: Done
A12: ST-009 | B12: F1 | C12: As a Accountant partner, I can import/migrate existing data into 13-week forecast engine (CSV + competitor importer) | D12: 5 | E12: P1 | F12: S3 | G12: Done
A13: ST-010 | B13: F1 | C13: As a user, I get notifications (in-app + email) for key 13-week forecast engine events with per-type mute | D13: 3 | E13: P2 | F13: S3 | G13: Done
A14: ST-011 | B14: F2 | C14: As a SMB owner, I can set up Scenario sliders with sensible defaults in one screen | D14: 5 | E14: P0 | F14: S3 | G14: Done
A15: ST-012 | B15: F2 | C15: As a SMB owner, the Scenario sliders happy path completes without documentation | D15: 8 | E15: P0 | F15: S3 | G15: Done
... A24: ST-021 | B24: F3 | C24: As a SMB owner, I can set up Invoice chase nudges with sensible defaults in one screen | D24: 5 | E24: P0 | F24: S5 | G24: Done
A25: ST-022 | B25: F3 | C25: As a SMB owner, the Invoice chase nudges happy path completes without documentation | D25: 8 | E25: P0 | F25: S5 | G25: Done | H25: Marked Done at build, but planNudges had NO driver until v020 (GAP-F2) — the daily cycle never ran. True as built since v020
A26: ST-023 | B26: F3 | C26: As a Accountant partner, I can customise Invoice chase nudges rules/conditions for my workflow | D26: 5 | E26: P1 | F26: S5 | G26: Done
A27: ST-024 | B27: F3 | C27: As a user, Invoice chase nudges shows clear errors and retry paths on platform API failures | D27: 3 | E27: P0 | F27: S5 | G27: Done | H27: Retry existed at build; the send path only ran from v020 (GAP-F2), once-per-tier from v015 (F-006). True as built since v020
A28: ST-025 | B28: F3 | C28: As a Bookkeeper, Invoice chase nudges works on the web app with Xero deep links + accountant portal surface end-to-end | D28: 5 | E28: P0 | F28: S5 | G28: Done
A29: ST-026 | B29: F3 | C29: As a Accountant partner, I can see Invoice chase nudges performance metrics and trends | D29: 3 | E29: P1 | F29: S5 | G29: Done
A30: ST-027 | B30: F3 | C30: As a user, Invoice chase nudges respects role permissions and audit logging | D30: 3 | E30: P1 | F30: S5 | G30: Done
A31: ST-028 | B31: F3 | C31: As a SMB owner, I can pause/disable Invoice chase nudges without data loss | D31: 2 | E31: P2 | F31: S5 | G31: Done
A32: ST-029 | B32: F3 | C32: As a Accountant partner, I can import/migrate existing data into Invoice chase nudges (CSV + competitor importer) | D32: 5 | E32: P1 | F32: S5 | G32: Done
A33: ST-030 | B33: F3 | C33: As a user, I get notifications (in-app + email) for key Invoice chase nudges events with per-type mute | D33: 3 | E33: P2 | F33: S5 | G33: Done
A34: ST-031 | B34: F4 | C34: As a SMB owner, I can set up Accountant portal with sensible defaults in one screen | D34: 5 | E34: P0 | F34: S6 | G34: Done
A35: ST-032 | B35: F4 | C35: As a SMB owner, the Accountant portal happy path completes without documentation | D35: 8 | E35: P0 | F35: S6 | G35: Done
A36: ST-033 | B36: F4 | C36: As a Accountant partner, I can customise Accountant portal rules/conditions for my workflow | D36: 5 | E36: P1 | F36: S6 | G36: Done
A37: ST-034 | B37: F4 | C37: As a user, Accountant portal shows clear errors and retry paths on platform API failures | D37: 3 | E37: P0 | F37: S6 | G37: Done
A38: ST-035 | B38: F4 | C38: As a Bookkeeper, Accountant portal works on the web app with Xero deep links + accountant portal surface end-to-end | D38: 5 | E38: P0 | F38: S6 | G38: Done
A39: ST-036 | B39: F4 | C39: As a Accountant partner, I can see Accountant portal performance metrics and trends | D39: 3 | E39: P1 | F39: S6 | G39: Done
... A43: ST-040 | B43: F4 | C43: As a user, I get notifications (in-app + email) for key Accountant portal events with per-type mute | D43: 3 | E43: P2 | F43: S6 | G43: Done
A44: ST-041 | B44: F5 | C44: As a SMB owner, I can set up Bank-feed anomaly alerts with sensible defaults in one screen | D44: 5 | E44: P0 | F44: S8 | G44: Done | H44: Detection existed at build; polling — the ENTIRE mechanism under D-F4 — only ran from v020 (GAP-F2), per-tenant from v022 (F4-01). True as built since v022
A45: ST-042 | B45: F5 | C45: As a SMB owner, the Bank-feed anomaly alerts happy path completes without documentation | D45: 8 | E45: P0 | F45: S8 | G45: Done | H45: Happy path could not complete before v020 (no poll driver) and ran for only ONE org until v022 (F4-01). True as built since v022
A46: ST-043 | B46: F5 | C46: As a Accountant partner, I can customise Bank-feed anomaly alerts rules/conditions for my workflow | D46: 5 | E46: P1 | F46: S8 | G46: Done
A47: ST-044 | B47: F5 | C47: As a user, Bank-feed anomaly alerts shows clear errors and retry paths on platform API failures | D47: 3 | E47: P0 | F47: S8 | G47: Done | H47: Error/retry paths unreachable before the poll ran (v020); breaker protection verified v021. True as built since v021
A48: ST-045 | B48: F5 | C48: As a Bookkeeper, Bank-feed anomaly alerts works on the web app with Xero deep links + accountant portal surface end-to-end | D48: 5 | E48: P0 | F48: S8 | G48: Done
A49: ST-046 | B49: F5 | C49: As a Accountant partner, I can see Bank-feed anomaly alerts performance metrics and trends | D49: 3 | E49: P1 | F49: S8 | G49: Done
A50: ST-047 | B50: F5 | C50: As a user, Bank-feed anomaly alerts respects role permissions and audit logging | D50: 3 | E50: P1 | F50: S8 | G50: Done
A51: ST-048 | B51: F5 | C51: As a SMB owner, I can pause/disable Bank-feed anomaly alerts without data loss | D51: 2 | E51: P2 | F51: S8 | G51: Done
A52: ST-049 | B52: F5 | C52: As a Accountant partner, I can import/migrate existing data into Bank-feed anomaly alerts (CSV + competitor importer) | D52: 5 | E52: P1 | F52: S8 | G52: Done
...

Sheet Sprint_Board
A1: SPRINT BOARD — live counts from Full_Backlog
A3: Sprint | B3: Focus | C3: Stories | D3: Points | E3: Done | F3: Exit criteria
A4: S0 | B4: Discovery & Design (2 wks) | C4: =COUNTIF(Full_Backlog!F4:F103,"S0") | D4: =SUMIF(Full_Backlog!F4:F103,"S0",Full_Backlog!D4:D103) | E4: =COUNTIFS(Full_Backlog!F4:F103,"S0",Full_Backlog!G4:G103,"Done") | F4: PRD signed off; prototype tested with 5 target users
A5: S1 | B5: Foundation (2 wks) | C5: =COUNTIF(Full_Backlog!F4:F103,"S1") | D5: =SUMIF(Full_Backlog!F4:F103,"S1",Full_Backlog!D4:D103) | E5: =COUNTIFS(Full_Backlog!F4:F103,"S1",Full_Backlog!G4:G103,"Done") | F5: App installs cleanly in dev store/org; telemetry firing
A6: S2 | B6: Core feature 13-week forecast engine - part 1 | C6: =COUNTIF(Full_Backlog!F4:F103,"S2") | D6: =SUMIF(Full_Backlog!F4:F103,"S2",Full_Backlog!D4:D103) | E6: =COUNTIFS(Full_Backlog!F4:F103,"S2",Full_Backlog!G4:G103,"Done") | F6: 13-week forecast engine happy path demoable
A7: S3 | B7: Core feature 13-week forecast engine - part 2 + Scenario sliders start | C7: =COUNTIF(Full_Backlog!F4:F103,"S3") | D7: =SUMIF(Full_Backlog!F4:F103,"S3",Full_Backlog!D4:D103) | E7: =COUNTIFS(Full_Backlog!F4:F103,"S3",Full_Backlog!G4:G103,"Done") | F7: 13-week forecast engine complete with tests; Scenario sliders skeleton
A8: S4 | B8: Core feature Scenario sliders | C8: =COUNTIF(Full_Backlog!F4:F103,"S4") | D8: =SUMIF(Full_Backlog!F4:F103,"S4",Full_Backlog!D4:D103) | E8: =COUNTIFS(Full_Backlog!F4:F103,"S4",Full_Backlog!G4:G103,"Done") | F8: MVP loop usable end-to-end internally
A9: S5 | B9: Feature Invoice chase nudges + alpha hardening | C9: =COUNTIF(Full_Backlog!F4:F103,"S5") | D9: =SUMIF(Full_Backlog!F4:F103,"S5",Full_Backlog!D4:D103) | E9: =COUNTIFS(Full_Backlog!F4:F103,"S5",Full_Backlog!G4:G103,"Done") | F9: Internal alpha: team dogfoods daily
A10: S6 | B10: Billing + Accountant portal | C10: =COUNTIF(Full_Backlog!F4:F103,"S6") | D10: =SUMIF(Full_Backlog!F4:F103,"S6",Full_Backlog!D4:D103) | E10: =COUNTIFS(Full_Backlog!F4:F103,"S6",Full_Backlog!G4:G103,"Done") | F10: Can charge a test customer; upgrade/downgrade paths work
A11: S7 | B11: Private beta (design partners) | C11: =COUNTIF(Full_Backlog!F4:F103,"S7") | D11: =SUMIF(Full_Backlog!F4:F103,"S7",Full_Backlog!D4:D103) | E11: =COUNTIFS(Full_Backlog!F4:F103,"S7",Full_Backlog!G4:G103,"Done") | F11: 3+ partners active weekly; NPS pulse >30
A12: S8 | B12: Beta iteration + Bank-feed anomaly alerts | C12: =COUNTIF(Full_Backlog!F4:F103,"S8") | D12: =SUMIF(Full_Backlog!F4:F103,"S8",Full_Backlog!D4:D103) | E12: =COUNTIFS(Full_Backlog!F4:F103,"S8",Full_Backlog!G4:G103,"Done") | F12: Retention of beta cohort week-over-week >60%
A13: S9 | B13: Marketplace review prep | C13: =COUNTIF(Full_Backlog!F4:F103,"S9") | D13: =SUMIF(Full_Backlog!F4:F103,"S9",Full_Backlog!D4:D103) | E13: =COUNTIFS(Full_Backlog!F4:F103,"S9",Full_Backlog!G4:G103,"Done") | F13: Review submission accepted into queue
A14: S10 | B14: Review remediation + docs | C14: =COUNTIF(Full_Backlog!F4:F103,"S10") | D14: =SUMIF(Full_Backlog!F4:F103,"S10",Full_Backlog!D4:D103) | E14: =COUNTIFS(Full_Backlog!F4:F103,"S10",Full_Backlog!G4:G103,"Done") | F14: Marketplace approval obtained (or final remediation cycle)
A15: S11 | B15: Launch | C15: =COUNTIF(Full_Backlog!F4:F103,"S11") | D15: =SUMIF(Full_Backlog!F4:F103,"S11",Full_Backlog!D4:D103) | E15: =COUNTIFS(Full_Backlog!F4:F103,"S11",Full_Backlog!G4:G103,"Done") | F15: First 10 installs; first 3 reviews; activation >40%
A16: S12 | B16: Iterate & scale decision | C16: =COUNTIF(Full_Backlog!F4:F103,"S12") | D16: =SUMIF(Full_Backlog!F4:F103,"S12",Full_Backlog!D4:D103) | E16: =COUNTIFS(Full_Backlog!F4:F103,"S12",Full_Backlog!G4:G103,"Done") | F16: Growth model doc with CAC/LTV first estimates
B17: TOTAL | C17: =SUM(C4:C16) | D17: =SUM(D4:D16)
B18: Velocity check: points/sprint S2-S8 should sit within 30-45 for a 4-6 person team; rebalance Sprint column in backlog if a sprint exceeds capacity.

Sheet Financial_Model
A1: 18-MONTH FINANCIAL MODEL — Xero: accountant-channel PLG (edit yellow assumptions)
A3: Assumption | B3: Value
A4: Trials/mo (month 1) | B4: 50
A5: Monthly growth of that | B5: 0.12
A6: Trial->paid % | B6: 0.14
A7: ARPU $/mo | B7: 25
A8: Monthly churn | B8: 0.04
A9: Marketplace fee | B9: 0.15
A10: Team cost month 1 (India-lean $) | B10: 14000
A11: Cost growth/mo | B11: 0.03
A12: Fee note: 15% via Xero in-store subscriptions (external billing where permitted)
A14: Line | B14: M1 | C14: M2 | D14: M3 | E14: M4 | F14: M5 | G14: M6 | H14: M7 | I14: M8 | J14: M9 | K14: M10 | L14: M11 | M14: M12 | N14: M13 | O14: M14 | P14: M15 | Q14: M16 | R14: M17 | S14: M18
A15: Leads/installs | B15: =$B$4 | C15: =B15*(1+$B$5) | D15: =C15*(1+$B$5) | E15: =D15*(1+$B$5) | F15: =E15*(1+$B$5) | G15: =F15*(1+$B$5) | H15: =G15*(1+$B$5) | I15: =H15*(1+$B$5) | J15: =I15*(1+$B$5) | ... S15: =R15*(1+$B$5)
A16: New paying | B16: =ROUND(B15*$B$6,1) | C16: =ROUND(C15*$B$6,1) | D16: =ROUND(D15*$B$6,1) | E16: =ROUND(E15*$B$6,1) | F16: =ROUND(F15*$B$6,1) | G16: =ROUND(G15*$B$6,1) | H16: =ROUND(H15*$B$6,1) | I16: =ROUND(I15*$B$6,1) | ... S16: =ROUND(S15*$B$6,1)
A17: Paying accounts | B17: =B16 | C17: =ROUND(B17*(1-$B$8)+C16,1) | D17: =ROUND(C17*(1-$B$8)+D16,1) | E17: =ROUND(D17*(1-$B$8)+E16,1) | F17: =ROUND(E17*(1-$B$8)+F16,1) | G17: =ROUND(F17*(1-$B$8)+G16,1) | H17: =ROUND(G17*(1-$B$8)+H16,1) | I17: =ROUND(H17*(1-$B$8)+I16,1) | J17: =ROUND(I17*(1-$B$8)+J16,1) | ... S17: =ROUND(R17*(1-$B$8)+S16,1)
A18: MRR (net of fee) | B18: =ROUND(B17*$B$7*(1-$B$9),0) | C18: =ROUND(C17*$B$7*(1-$B$9),0) | D18: =ROUND(D17*$B$7*(1-$B$9),0) | E18: =ROUND(E17*$B$7*(1-$B$9),0) | F18: =ROUND(F17*$B$7*(1-$B$9),0) | G18: =ROUND(G17*$B$7*(1-$B$9),0) | H18: =ROUND(H17*$B$7*(1-$B$9),0) | I18: =ROUND(I17*$B$7*(1-$B$9),0) | ... S18: =ROUND(S17*$B$7*(1-$B$9),0)
A19: Team cost | B19: =$B$10 | C19: =ROUND(B19*(1+$B$11),0) | D19: =ROUND(C19*(1+$B$11),0) | E19: =ROUND(D19*(1+$B$11),0) | F19: =ROUND(E19*(1+$B$11),0) | G19: =ROUND(F19*(1+$B$11),0) | H19: =ROUND(G19*(1+$B$11),0) | I19: =ROUND(H19*(1+$B$11),0) | J19: =ROUND(I19*(1+$B$11),0) | ... S19: =ROUND(R19*(1+$B$11),0)
A20: Net cash/mo | B20: =B18-B19 | C20: =C18-C19 | D20: =D18-D19 | E20: =E18-E19 | F20: =F18-F19 | G20: =G18-G19 | H20: =H18-H19 | I20: =I18-I19 | ... S20: =S18-S19
A21: Cumulative | B21: =B20 | C21: =B21+C20 | D21: =C21+D20 | E21: =D21+E20 | F21: =E21+F20 | G21: =F21+G20 | H21: =G21+H20 | I21: =H21+I20 | J21: =I21+J20 | ... S21: =R21+S20
A23: Reading: churn applies before adds; MRR nets the marketplace fee; costs use India-lean base from Team_Roles_Budget (v004). Breakeven = first month Net cash ≥ 0. This is a planning model, not a forecast — replace assumptions with S7-S8 beta actuals.
A25: v036 NOTE (20 Sep 2026, Perplexity V001 PPX-03/PPX-10 — model deliberately NOT changed by instruction): (a) the 15% "marketplace fee" is now a Xero REFERRAL fee — 15% of agreed ARPU per user who clicks "Get this app", connects, and stays 65 days; it does NOT apply to self-sourced customers, and a connections/API-usage tier cost is missing; (b) on these assumptions the reviewer computes ~659 accounts to cover M1 cost, 315 reached by M18, −$281k cumulative, ~23+ months to breakeven, ~$86 ARPU needed. Rebuild = P4-1, decision = PPX-D3.

Sheet GTM_Execution
A1: GTM EXECUTION TASKS
A3: Phase | B3: Task | C3: Owner (role) | D3: Target sprint
A4: Pre-launch | B4: Positioning doc + message house (problem/promise/proof) | C4: Founder | D4: S7
A5: Pre-launch | B5: Listing SEO: keyword study in marketplace search + title/intro drafts | C5: Growth | D5: S8
A6: Pre-launch | B6: 10 design-partner mini case snippets with metric proof | C6: Founder | D6: S8
A7: Pre-launch | B7: 5 comparison/alternative pages drafted | C7: Growth | D7: S9
A8: Pre-launch | B8: Screenshots (5) + 2-min demo video produced | C8: Design | D8: S9
A9: Launch | B9: Listing live + launch post + video published | C9: Growth | D9: S11
A10: Launch | B10: Founder outreach: 100 named ICP accounts, 3-touch sequence | C10: Founder | D10: S11
A11: Launch | B11: Community value-posts (3 relevant communities) | C11: Founder | D11: S11
A12: Launch | B12: Review-generation program on (in-app ask post-aha) | C12: Eng | D12: S11
A13: Post-launch | B13: Weekly SEO/how-to content cadence starts | C13: Growth | D13: S12
A14: Post-launch | B14: Marketplace paid placement pilot (where offered) | C14: Growth | D14: S12
... A16: Post-launch | B16: G2/Capterra profiles + first 10 reviews | C16: Growth | D16: S12+

Sheet Launch_Checklist
A1: PLATFORM LAUNCH CHECKLIST — Xero App Store
A3: # | B3: Item | C3: Status
A4: 1 | B4: Xero developer account + app partner program application | C4: BLOCKED — needs Senthil: dev account + partner application
A5: 2 | B5: OAuth2 + tenant handling for multi-org accountants tested | C5: Code-complete — pending live dev-org test
A6: 3 | B6: API rate limits (60/min per tenant) queue + backoff verified | C6: Code-complete: proactive 60/min per-tenant limiter (v012) + reactive backoff/breaker — pending live verification
A7: 4 | B7: Webhooks (invoices, payments, bank transactions) resilience tested | C7: Code-complete — webhooks (INVOICE/CONTACT/SUBSCRIPTION) + bank-txn polling built v011; pending live wiring. NOTE: platform has no bank-txn webhook — polling every 15 min is the documented substitute
A8: 5 | B8: App partner certification: API best practice + security questionnaire + brand review | C8: Trust page drafted; SECURITY_EVIDENCE.md pack compiled v014 (auth, encryption-at-rest AES-256-GCM + vault, webhook HMAC, rate limiting, data lifecycle, 100% gate); questionnaire answerable from pack + brand review pending live artefacts
A9: 6 | B9: In-store subscription configuration + test purchase | C9: Rail logic coded; store config + test purchase pending dev org
A10: 7 | B10: Accountant multi-client portal tested with 20-client dataset | C10: DONE at logic level: 20-client dataset drill passed (risk-first sort + rules at scale); live UI pass pending
A11: 8 | B11: Bank-feed anomaly logic QA on 12 months of demo data | C11: DONE at logic level: 12-month dataset QA passed — found + fixed batch-isolation blind spot (detectWithHistory); live-feed QA pending
A12: 9 | B12: Listing: accountant-channel messaging + partner directory entry | C12: Listing copy A/B drafted (B = accountant channel) — Senthil review pending
A13: 10 | B13: UK/AU/NZ tax-locale display verified (GST/VAT labels) | C13: GST/VAT fields coded + tested; UI locale pass pending deployed UI
A14: 3 (update v036) | B14: API rate limits — restated after PPX-04/05 | C14: Code-complete: TIERED daily budget (1,000 Starter default / 5,000 Core via XERO_API_TIER), Retry-After honoured, remaining-call headers reconciled, 5-concurrent semaphore, app-wide 10,000/min — platformLimitsGate proved. Live verification of the actual tier pending dev org.
A15: 6 (update v036) | B15: In-store subscription configuration — restated after PPX-03 | C15: STALE: Xero App Store Subscriptions deprecated (March 2026). Rail logic left in code by instruction (PPX-D4); Stripe-only migration logged as P4-1. Partner application still required for the listing/referral fee.
A16: 11 | B16: Forecast production data path proven live (PPX-01) | C16: Code-complete in sandbox (P1-2, dataPathGate proved). Live proof = live-sweep step with a real org: /api/forecast returns a 13-week forecast whose opening balance matches the Xero bank summary.
A17: 12 | B17: Platform assumptions re-verified within budget (PPX-03) | C17: docs/platform-assumptions.json — 11 entries verified 20 Sep 2026; CI fails on age-out (~19 Dec 2026).

Sheet Metrics_Targets
A1: METRIC TARGETS (first 12 months post-launch)
A3: Metric | B3: M1 | C3: M3 | D3: M6 | E3: M12 | F3: Notes
A4: Installs/signups cumulative | B4: varies | C4: 3x M1 | D4: 8x M1 | E4: 20x M1 | F4: Drive via listing SEO + outbound
A5: Activation % (24h) | B5: 30% | C5: 40% | D5: 45% | E5: 50% | F5: Onboarding iterations S12+
A6: Trial→paid % | B6: baseline | C6: +2pts | D6: +4pts | E6: +6pts | F6: Pricing test at S12
A7: Rating | B7: 4.5+ | C7: 4.6+ | D7: 4.7+ | E7: 4.7+ | F7: Review program + support speed
A8: MRR | B8: first $ | C8: 3x | D8: 8x | E8: 20x | F8: Model sheet has the math
A9: Logo churn/mo | B9: <5% | C9: <4% | D9: <3% | E9: <3% | F9: Health-score saves

Sheet Risk_Register
A1: PRODUCT RISK REGISTER
A3: Risk | B3: Impact | C3: Likelihood | D3: Mitigation
A4: Xero native short-term cash flow improves | B4: High | C4: Medium | D4: Scenario depth + accountant multi-client portal moat
A5: Accountant channel slow to activate | B5: Medium | C5: High | D5: Partner program with rev share; 10 pilot firms by S8
A6: Float/Fathom price moves | B6: Medium | C6: Medium | D6: Owner-facing simplicity positioning; annual bundles
A7: Positioning: generic Xero cash-flow forecasting is a crowded category and the platform itself now ships 30/90/180-day horizons (external review FC-R004) | B7: High | C7: High | D7: Hold Wave 2 until DEC-F16. Reviewer's proposed wedge: 13-week cash control and collections copilot for practices, sold as a closed loop rather than a dashboard.
A8: Internal review has a ceiling — an outside reader found three defect classes in one pass, one of them in a document we had all read | B8: High | C8: Medium | D8: Sixth gate closes the specific decay mode mechanically. DEC-F17 sets the standing rule for independent review.
A9: Scale evidence is in-process compute only and could be quoted as production performance | B9: Medium | C9: Medium | D9: Stated in the module header, the dry-run doc, the tracker and the enhancement backlog. PERF-1 already re-baselined budgets once for this confusion.
A10: Both critical findings in sprint E5b were deploy-configuration rather than logic, and both survived a 100% suite and eight review passes. The other nine products share the author and the patterns (R-F13). | B10: High | C10: High | D10: Port the fail-closed boot check and the shutdown deadline first — they are the two most transferable fixes. Which products and when is Senthil's call.
A11: Fluidly precedent — a well-funded Xero cash-flow forecasting app with the same ICP was acquired by OakNorth (2021) and shut to accountants; reported as a write-off (Perplexity V001 §4; R-F18) | B11: High | C11: Medium | D11: Positioning, not code: the closed loop forecast-shortfall → chase → recovered cash (PPX-D2 / P2). Do not launch as a generic forecaster.
A12: Platform absorption — Xero acquired Syft Analytics (~$70m) and ships native 7–180-day projections; the middle of the category is a platform-absorption zone (R-F19) | B12: High | C12: High | D12: Raises the first risk on this register from Medium to High likelihood. Same mitigation as above.
A13: Unit economics do not close at $25 ARPU — reviewer's recomputation on this workbook's own assumptions: ~23+ months to breakeven, −$281k cumulative to M18, ~$86 ARPU needed (PPX-10; R-F20) | B13: High | C13: High | D13: PPX-D3: reprice to the £45–£99 band the category actually pays; rebuild the model in P4-1. Model untouched this sprint by instruction.
A14: Boot composition incomplete — the durable store, webhook worker and uninstall path have no production driver (E6-F3..F5; R-F14..R-F16). A restart still loses every tenant. | B14: High | C14: High | D14: P1-8. KNOWN_GAPS expire 31 Oct 2026 so the build itself forces the work.
... A16: Platform assumptions decay silently — PPX-03 went six months stale while every document checked out against the code | B16: High | C16: Medium | D16: docs/platform-assumptions.json + platformDriftGate (P1-6): CI fails when an assumption ages past its budget. Next forced re-verification ~19 Dec 2026.

Sheet Sprint_Tracker_Log
A1: SPRINT TRACKER LOG — FlowCast (created v008 per directive, 10 Sep 2026 22:01)
A3: Date/Time | B3: Sprint | C3: Action | D3: Stories touched | E3: Evidence | F3: Decision ref
A4: 2026-09-05 19:50 | B4: S0 | C4: v007 full product workbook released (spec, backlog, board, model) | D4: — | E4: v007 Version_Control | F4: —
A5: 2026-09-10 22:01 | B5: — | C5: v008 opened: Sprint_Tracker_Log + Traceability_Matrix sheets added per directive | D5: — | E5: This file | F5: Directive 10 Sep 22:01
A6: 2026-09-10 22:01 | B6: — | C6: D13 applied to FlowCast: 100% automation coverage gate on all code; ST-085 amended | D6: ST-085 | E6: jest.config.js coverageThreshold=100 | F6: D13
A7: 2026-09-10 22:01 | B7: S1 | C7: Foundation built: OAuth install/uninstall/reinstall, token rotation, source attribution, role matrix + audit log. Xero OAuth client mocked | D7: ST-051..ST-056 | E7: src/installFlow.ts, src/permissions.ts + tests | F7: —
A8: 2026-09-10 22:01 | B8: S2-S3 | C8: 13-week forecast engine: bucketing, traffic lights, validation errors, pause-without-loss; scenario sliders: levers, validation, preview | D8: ST-001..ST-004, ST-007..ST-009, ST-011..ST-014, ST-017, ST-019 | E8: src/forecastEngine.ts, src/scenarioSliders.ts + tests | F8: —
A9: 2026-09-10 22:01 | B9: S5 | C9: Invoice chase nudges: rule ladder, planning, test mode, retry-on-failure, per-type mute | D9: ST-021..ST-024, ST-027..ST-030 | E9: src/invoiceNudges.ts + tests | F9: —
A10: 2026-09-10 22:01 | B10: S6 | C10: Accountant portal + shared CSV importer; billing: trial, proration, rail selection, dunning, limits, GST/VAT invoices, cancellation | D10: ST-031/032/034/037/039, ST-057..ST-063 | E10: src/accountantPortal.ts, src/billing.ts + tests | F10: —
A11: 2026-09-10 22:01 | B11: S8 | C11: Bank-feed anomaly alerts; compliance: scope audit, retention, export/delete, backoff + circuit breaker; full telemetry suite; onboarding surfaces | D11: ST-041..ST-049, ST-064..ST-077 (code subset), ST-078/079/082/084 | E11: src/anomalyAlerts.ts, src/compliance.ts, src/telemetry.ts, src/onboarding.ts + tests | F11: —
A12: 2026-09-10 22:01 | B12: — | C12: TEST RUN: 11 suites, 120 tests, 100% statements/branches/functions/lines; gate enforced at 100 — build fails below | D12: All Done stories | E12: npx jest --coverage output; coverage/coverage-summary.json | F12: D13
A13: 2026-09-10 22:01 | B13: — | C13: Statuses written to Full_Backlog; Sprint_Board Done counts recalc from formulas. 58 Done, 4 code-complete-pending-live, 2 in progress, 36 backlog | D13: All | E13: Full_Backlog col G | F13: —
A14: 2026-09-10 22:01 | B14: — | C14: PORTFOLIO NOTE: FlowCast (rank 12) is a third open build while RevRescue rank-1 gate unmet; sequencing decision D15 remains open with Senthil | D14: — | E14: marketplace portfolio record | F14: D15 (open)
... A93: 2026-09-20 10:14 | B93: E6 | C93: Perplexity V001 response, Wave P1. 10 findings (3 BLOCKER) verified against source and closed in code where sandbox-closable: P1-1..P1-7. Boot found never to start the scheduler or build the API client (E6-F1) — fixed. Method-level gate found 4 further boot-composition clusters (E6-F3..F6) → P1-8 with 31 Oct gate expiry. 6 new gates, 15 mutations proved. Nothing deleted; no re-statusing; billing rail untouched. | D93: None — enhancement pool (P1-1..P1-8) | E93: tracker v024 External_Review_PPX; code v0.30.0; 49 suites / 719 tests at 100% | F93: PPX-D1, PPX-D4 (Senthil 10:17); PPX-D2/D3/D5/D6 open; D-F8

Sheet Traceability_Matrix
A1: TRACEABILITY MATRIX — story → code → automated test → coverage (v008 build, 10 Sep 2026)
A2: Coverage source: jest --coverage, gate = 100% statements/branches/functions/lines (D13). All Xero platform calls mocked in tests; "pending live" = logic complete, live platform verification outstanding.
A4: ID | B4: Epic | C4: Status (v008) | D4: Code file(s) | E4: Automated test file(s) | F4: Coverage | G4: Evidence / notes
A5: ST-001 | B5: F1 | C5: Done | D5: src/forecastEngine.ts | E5: tests/forecastEngine.test.ts | F5: 100% | G5: defaultInput one-screen setup
A6: ST-002 | B6: F1 | C6: Done | D6: src/forecastEngine.ts | E6: tests/forecastEngine.test.ts | F6: 100% | G6: computeForecast happy path, 13-week bucketing
A7: ST-003 | B7: F1 | C7: Done | D7: src/forecastRules.ts | E7: tests/rulesNotificationsMetrics.test.ts | F7: 100% | G7: Rule builder complete: min_balance / amber_floor / week_drop_pct over week ranges; supersedes amber-floor-only v008 state
A8: ST-004 | B8: F1 | C8: Done | D8: src/forecastEngine.ts; src/compliance.ts | E8: tests/forecastEngine.test.ts; tests/compliance.test.ts | F8: 100% | G8: validate() named errors; callWithProtection retry
A9: ST-005 | B9: F1 | C9: Done | D9: src/ui/ForecastScreens.tsx | E9: tests/ui/screens.test.tsx | F9: 100% | G9: ForecastScreen: 13-week table, rule violations, Xero receivables deep link, empty state
A10: ST-006 | B10: F1 | C10: Done | D10: src/featureMetrics.ts; src/ui/MetricsPanel.tsx | E10: tests/rulesNotificationsMetrics.test.ts; tests/ui/screens.test.tsx | F10: 100% | G10: weeklySeries + trend + MetricsPanel surface
A11: ST-007 | B11: F1 | C11: Done | D11: src/permissions.ts | E11: tests/permissions.test.ts | F11: 100% | G11: authorize + AuditLog on forecast actions
A12: ST-008 | B12: F1 | C12: Done | D12: src/forecastEngine.ts | E12: tests/forecastEngine.test.ts | F12: 100% | G12: setEnabled preserves lastInput
A13: ST-009 | B13: F1 | C13: Done | D13: src/accountantPortal.ts | E13: tests/accountantPortal.test.ts | F13: 100% | G13: importCsv shared migration importer
A14: ST-010 | B14: F1 | C14: Done | D14: src/notifications.ts | E14: tests/rulesNotificationsMetrics.test.ts | F14: 100% | G14: dispatch in-app+email, per-type mute, daily digest (forecast event types)
A15: ST-011 | B15: F2 | C15: Done | D15: src/scenarioSliders.ts | E15: tests/scenarioSliders.test.ts | F15: 100% | G15: baselineScenario defaults
... A104: ST-100 | B104: EL | C104: Code-complete — pending live | D104: v016 | E104: src/launchOps.ts (PartnerTracker) | F104: — | G104: 10 slots, 7-day stale-nudge, exit math separating reviews from G-02 paying strangers; outreach = Senthil
A106: Summary (v010): 77 Done · 8 Code-complete — pending live · 7 Drafted — pending publish/review · 2 In progress · 6 Backlog (live-infra: ST-066/068/088/092; post-launch: ST-099/100). Test evidence: 14 suites / 155 tests / 100-100-100-100 incl. jest-axe WCAG pass; tsc clean.
A108: WBH-001 | B108: EQ+ | C108: Code-complete — pending live | D108: src/webhooks.ts | E108: tests/webhooks.test.ts | F108: 100% | G108: Dry-run gap #4 closed in code: HMAC-SHA256 signature verify (constant-time, intent-to-receive), fast-ack + idempotent queue with retry/dead-letter/redelivery-heal, invoice/contact/subscription action mapping (payment cancels nudges), bank-txn polling behind shared circuit breaker (no platform webhook exists — 15-min poll documented). Live wiring pending dev org. Unnumbered: added post-baseline from dry-run, outside ST-001..100 board counts by design
A109: WBH-002 | B109: EQ+ | C109: Done (code) | D109: src/rateLimiter.ts | E109: tests/rateLimitQaHttp.test.ts | F109: 100% | G109: Checklist #3 hardening: proactive per-tenant 60/min sliding-window limiter + paced execution (complements reactive backoff/breaker); live verification pending
A110: WBH-003 | B110: EQ+ | C110: Done (code) | D110: src/server.ts | E110: tests/rateLimitQaHttp.test.ts | F110: 100% | G110: HTTP wiring layer: routed fast-ack webhook endpoint (raw-body signature contract) + /health with release + queue depth; net binding is 5 lines at deploy
A111: QA-007 | B111: EQ+ | C111: Done (logic drill) | D111: src/qaDatasets.ts (twentyClientBook) | E111: tests/rateLimitQaHttp.test.ts | F111: 100% | G111: Checklist #7: 20-client book drill — risk-first sort + portal rules at scale verified
A112: QA-008 | B112: EQ+ | C112: Done (logic drill) | D112: src/qaDatasets.ts (twelveMonthFeed); src/anomalyAlerts.ts (detectWithHistory) | E112: tests/rateLimitQaHttp.test.ts | F112: 100% | G112: Checklist #8: 12-month drill caught a REAL defect — isolated small-batch scans hide lone outliers (self-inflated sigma). Fixed: production scans batch against trailing history; all 3 planted faults caught, false positives <= 2
A113: CFG-001 | B113: EQ+ | C113: Done (code) | D113: src/config.ts; .env.example | E113: tests/config.test.ts | F113: 100% | G113: Typed config loader: all live credentials named + validated at boot (missing keys listed at once; https redirect enforced; Stripe key required only outside UK/AU/NZ). Live-sweep readiness
