Workbook

Sheet Daily Tracker
A1: Sl: No: | B1: Noted Date | C1: Noted Time | D1: Noted Day | E1: Category | F1: Task Details | G1: Priority | H1: Actual Start Day | I1: Actual Start Date | J1: Actual Start Time | K1: Actual End Day | L1: Actual End Date | M1: Actual End Time | N1: Status | O1: Remarks / Notes | P1: Next Action | Q1: Follow-up Date
A2: 1 | B2: 46213 | C2: 0.58333333 | D2: =VLOOKUP( WEEKDAY(B2) ,Lookup!$A$2:$B$8,2,FALSE) -> Friday | E2: Hiring | F2: Menaga and Jaya Sudha whatsapp msg preparation | G2: High | H2: =VLOOKUP( WEEKDAY(I2) ,Lookup!$A$2:$B$8,2,FALSE) -> Friday | I2: 46213 | J2: 0.59722222 | K2: =VLOOKUP( WEEKDAY(L2) ,Lookup!$A$2:$B$8,2,FALSE) -> Friday | L2: 46213 | M2: 0.61111111 | N2: Completed partially | O2: Msg Shared in group | P2: After the approval need to share directly | Q2: 46214
A3: =A2+1 -> 2 | B3: 46213 | C3: 0.58333333 | D3: =VLOOKUP( WEEKDAY(B3) ,Lookup!$A$2:$B$8,2,FALSE) -> Friday | E3: Documentation | F3: Create a master sheet and Put together all the links | G3: High | H3: =VLOOKUP( WEEKDAY(I3) ,Lookup!$A$2:$B$8,2,FALSE) -> Friday | I3: 46213 | K3: =VLOOKUP( WEEKDAY(L3) ,Lookup!$A$2:$B$8,2,FALSE) -> Friday | L3: 46213
A4: =A3+1 -> 3 | B4: 46213 | C4: 0.45833333 | D4: =VLOOKUP( WEEKDAY(B4) ,Lookup!$A$2:$B$8,2,FALSE) -> Friday | E4: Company Registration | F4: Talk to Renu Chennai | G4: High | H4: =VLOOKUP( WEEKDAY(I4) ,Lookup!$A$2:$B$8,2,FALSE) -> Friday | I4: 46213 | J4: 0.66666667 | K4: =VLOOKUP( WEEKDAY(L4) ,Lookup!$A$2:$B$8,2,FALSE) -> Friday | L4: 46213 | O4: She is Refering her Auditor cum Auditor friend as she handles only GST | Q4: 46214
A5: =A4+1 -> 4 | B5: 46214 | D5: =VLOOKUP( WEEKDAY(B5) ,Lookup!$A$2:$B$8,2,FALSE) -> Saturday | E5: Web Site Design | F5: Cute Pay Website Design, Need to check the UI and Speak to them | H5: =VLOOKUP( WEEKDAY(I5) ,Lookup!$A$2:$B$8,2,FALSE) -> Friday | I5: 46213 | K5: =VLOOKUP( WEEKDAY(L5) ,Lookup!$A$2:$B$8,2,FALSE) -> Friday | L5: 46213
A6: =A5+1 -> 5 | B6: 46214 | D6: =VLOOKUP( WEEKDAY(B6) ,Lookup!$A$2:$B$8,2,FALSE) -> Saturday | E6: Web Site Design | F6: Jacob for branding ans suggestion for UI from Cute Pay | H6: =VLOOKUP( WEEKDAY(I6) ,Lookup!$A$2:$B$8,2,FALSE) -> Friday | I6: 46213 | K6: =VLOOKUP( WEEKDAY(L6) ,Lookup!$A$2:$B$8,2,FALSE) -> Friday | L6: 46213
A7: =A6+1 -> 6 | B7: 46214 | C7: 0.45833333 | D7: =VLOOKUP( WEEKDAY(B7) ,Lookup!$A$2:$B$8,2,FALSE) -> Saturday | E7: Company Registration | F7: Renu Akka ask friend number and speak to auditor | H7: =VLOOKUP( WEEKDAY(I7) ,Lookup!$A$2:$B$8,2,FALSE) -> Saturday | I7: 46214 | J7: 0.45833333 | K7: =VLOOKUP( WEEKDAY(L7) ,Lookup!$A$2:$B$8,2,FALSE) -> Saturday
A8: =A7+1 -> 7 | B8: 46214 | C8: 0.45833333 | D8: =VLOOKUP( WEEKDAY(B8) ,Lookup!$A$2:$B$8,2,FALSE) -> Saturday | E8: Company Registration | F8: Auditir Bala Murugan previously Registered Auditort | H8: =VLOOKUP( WEEKDAY(I8) ,Lookup!$A$2:$B$8,2,FALSE) -> Saturday | I8: 46214 | J8: 0.46875 | K8: =VLOOKUP( WEEKDAY(L8) ,Lookup!$A$2:$B$8,2,FALSE) -> Saturday | L8: 46214 | M8: 0.47916667 | N8: COmpleted | O8: Actual to Move to Jageedeswari akka, as we wan to support womens | P8: NIl
A9: =A8+1 -> 8 | B9: 46215 | D9: =VLOOKUP( WEEKDAY(B9) ,Lookup!$A$2:$B$8,2,FALSE) -> Sunday | E9: Interview | F9: jayashree Interview for Customer Support | G9: High | H9: =VLOOKUP( WEEKDAY(I9) ,Lookup!$A$2:$B$8,2,FALSE) -> Friday | I9: 46213 | J9: 0.59722222 | K9: =VLOOKUP( WEEKDAY(L9) ,Lookup!$A$2:$B$8,2,FALSE) -> Sunday | L9: 46215 | M9: 0.61458333 | N9: COmpleted | O9: Suitable for Customer Support Executive
A10: =A9+1 -> 9 | B10: 46215 | C10: 0.58333333 | D10: =VLOOKUP( WEEKDAY(B10) ,Lookup!$A$2:$B$8,2,FALSE) -> Sunday | E10: Learnings | F10: Public Speaking class Completde | G10: Medium | H10: =VLOOKUP( WEEKDAY(I10) ,Lookup!$A$2:$B$8,2,FALSE) -> Sunday | I10: 46215 | J10: 0.45833333 | K10: =VLOOKUP( WEEKDAY(L10) ,Lookup!$A$2:$B$8,2,FALSE) -> Sunday | L10: 46215 | M10: 0.58333333
A11: =A10+1 -> 10 | B11: 46215 | C11: 0.45833333 | D11: =VLOOKUP( WEEKDAY(B11) ,Lookup!$A$2:$B$8,2,FALSE) -> Sunday | E11: Interview | F11: Recuritments Preparations | H11: =VLOOKUP( WEEKDAY(I11) ,Lookup!$A$2:$B$8,2,FALSE) -> Sunday | I11: 46215 | J11: 0.58333333 | K11: =VLOOKUP( WEEKDAY(L11) ,Lookup!$A$2:$B$8,2,FALSE) -> Sunday | L11: 46215 | M11: 0.60069444 | N11: Completed
A12: =A11+1 -> 11 | B12: 46215 | C12: 0.45833333 | D12: =VLOOKUP( WEEKDAY(B12) ,Lookup!$A$2:$B$8,2,FALSE) -> Sunday | E12: Interview | F12: Swetha | H12: =VLOOKUP( WEEKDAY(I12) ,Lookup!$A$2:$B$8,2,FALSE) -> Sunday | I12: 46215 | J12: 0.6875 | K12: =VLOOKUP( WEEKDAY(L12) ,Lookup!$A$2:$B$8,2,FALSE) -> Sunday | L12: 46215
A13: =A12+1 -> 12 | B13: 46215 | C13: 0.45833333 | D13: =VLOOKUP( WEEKDAY(B13) ,Lookup!$A$2:$B$8,2,FALSE) -> Sunday | E13: Interview | F13: Subu lakshmi | H13: =VLOOKUP( WEEKDAY(I13) ,Lookup!$A$2:$B$8,2,FALSE) -> Sunday | I13: 46215 | K13: =VLOOKUP( WEEKDAY(L13) ,Lookup!$A$2:$B$8,2,FALSE) -> Sunday | L13: 46215
A14: =A13+1 -> 13 | B14: 46215 | C14: 0.45833333 | D14: =VLOOKUP( WEEKDAY(B14) ,Lookup!$A$2:$B$8,2,FALSE) -> Sunday | F14: Google | H14: =VLOOKUP( WEEKDAY(I14) ,Lookup!$A$2:$B$8,2,FALSE) -> Sunday | I14: 46215 | K14: =VLOOKUP( WEEKDAY(L14) ,Lookup!$A$2:$B$8,2,FALSE) -> Sunday | L14: 46215
A15: =A14+1 -> 14 | B15: 46216 | C15: 0.45833333 | D15: =VLOOKUP( WEEKDAY(B15) ,Lookup!$A$2:$B$8,2,FALSE) -> Monday | E15: Interview | F15: Swetha | H15: =VLOOKUP( WEEKDAY(I15) ,Lookup!$A$2:$B$8,2,FALSE) -> Monday | I15: 46216 | J15: 0.47916667 | K15: =VLOOKUP( WEEKDAY(L15) ,Lookup!$A$2:$B$8,2,FALSE) -> Monday | L15: 46216
A16: =A15+1 -> 15 | B16: 46216 | C16: 0.45833333 | D16: =VLOOKUP( WEEKDAY(B16) ,Lookup!$A$2:$B$8,2,FALSE) -> Monday | E16: Learning | F16: BPO training | H16: =VLOOKUP( WEEKDAY(I16) ,Lookup!$A$2:$B$8,2,FALSE) -> Monday | I16: 46216 | J16: 0.5 | K16: =VLOOKUP( WEEKDAY(L16) ,Lookup!$A$2:$B$8,2,FALSE) -> Monday | L16: 46216
A17: =A16+1 -> 16 | B17: 46216 | C17: 0.4375 | D17: =VLOOKUP( WEEKDAY(B17) ,Lookup!$A$2:$B$8,2,FALSE) -> Monday | E17: Documentation | F17: Informed Princy to document the Call recording software absorvation and Hostel in tambaram | H17: =VLOOKUP( WEEKDAY(I17) ,Lookup!$A$2:$B$8,2,FALSE) -> Monday | I17: 46216 | K17: =VLOOKUP( WEEKDAY(L17) ,Lookup!$A$2:$B$8,2,FALSE) -> Monday | L17: 46216
A18: =A17+1 -> 17 | B18: 46216 | C18: 0.4375 | D18: =VLOOKUP( WEEKDAY(B18) ,Lookup!$A$2:$B$8,2,FALSE) -> Monday | E18: Website | F18: Cute Pay check the status of teh website, logo and company profile | H18: =VLOOKUP( WEEKDAY(I18) ,Lookup!$A$2:$B$8,2,FALSE) -> Monday | I18: 46216 | K18: =VLOOKUP( WEEKDAY(L18) ,Lookup!$A$2:$B$8,2,FALSE) -> Monday | L18: 46216
A19: =A18+1 -> 18 | B19: 46216 | C19: 0.60416667 | D19: =VLOOKUP( WEEKDAY(B19) ,Lookup!$A$2:$B$8,2,FALSE) -> Monday | E19: Training Session | F19: Jaya Shree, Swetha, Subu lakshmi, Princy shedule not confirmed, Muthulakshmi will check the recording | H19: =VLOOKUP( WEEKDAY(I19) ,Lookup!$A$2:$B$8,2,FALSE) -> Monday | I19: 46216 | J19: 0.79166667 | K19: =VLOOKUP( WEEKDAY(L19) ,Lookup!$A$2:$B$8,2,FALSE) -> Monday | L19: 46216
A20: =A19+1 -> 19 | B20: 46217 | C20: 0.41666667 | D20: =VLOOKUP( WEEKDAY(B20) ,Lookup!$A$2:$B$8,2,FALSE) -> Tuesday | E20: training Session | F20: Training Record check | H20: =VLOOKUP( WEEKDAY(I20) ,Lookup!$A$2:$B$8,2,FALSE) -> Tuesday | I20: 46217 | K20: =VLOOKUP( WEEKDAY(L20) ,Lookup!$A$2:$B$8,2,FALSE) -> Tuesday | L20: 46217
A21: =A20+1 -> 20 | B21: 46218 | C21: 0.4375 | D21: =VLOOKUP( WEEKDAY(B21) ,Lookup!$A$2:$B$8,2,FALSE) -> Wednesday | E21: Website | F21: Need to share abous Us, Service and other details | H21: =VLOOKUP( WEEKDAY(I21) ,Lookup!$A$2:$B$8,2,FALSE) -> Wednesday | I21: 46218 | K21: =VLOOKUP( WEEKDAY(L21) ,Lookup!$A$2:$B$8,2,FALSE) -> Wednesday | L21: 46218
A22: =A21+1 -> 21 | B22: 46218 | C22: 0.4375 | D22: =VLOOKUP( WEEKDAY(B22) ,Lookup!$A$2:$B$8,2,FALSE) -> Wednesday | E22: Training Session | H22: =VLOOKUP( WEEKDAY(I22) ,Lookup!$A$2:$B$8,2,FALSE) -> Wednesday | I22: 46218 | K22: =VLOOKUP( WEEKDAY(L22) ,Lookup!$A$2:$B$8,2,FALSE) -> Wednesday | L22: 46218
A23: =A22+1 -> 22 | B23: 46218 | C23: 0.4375 | D23: =VLOOKUP( WEEKDAY(B23) ,Lookup!$A$2:$B$8,2,FALSE) -> Wednesday | E23: website | F23: Create Instagram Page, face book page, linkedin page and twitter | H23: =VLOOKUP( WEEKDAY(I23) ,Lookup!$A$2:$B$8,2,FALSE) -> Wednesday | I23: 46218 | K23: =VLOOKUP( WEEKDAY(L23) ,Lookup!$A$2:$B$8,2,FALSE) -> Wednesday | L23: 46218
A24: =A23+1 -> 23 | B24: 46219 | C24: 0.51388889 | D24: =VLOOKUP( WEEKDAY(B24) ,Lookup!$A$2:$B$8,2,FALSE) -> Thursday | F24: Today send another set of datas | H24: =VLOOKUP( WEEKDAY(I24) ,Lookup!$A$2:$B$8,2,FALSE) -> Thursday | I24: 46219 | K24: =VLOOKUP( WEEKDAY(L24) ,Lookup!$A$2:$B$8,2,FALSE) -> Thursday | L24: 46219
A25: =A24+1 -> 24 | B25: 46220 | D25: =VLOOKUP( WEEKDAY(B25) ,Lookup!$A$2:$B$8,2,FALSE) -> Friday | E25: chithirai Event | F25: Chennai travel | H25: =VLOOKUP( WEEKDAY(I25) ,Lookup!$A$2:$B$8,2,FALSE) -> Friday | I25: 46220 | K25: =VLOOKUP( WEEKDAY(L25) ,Lookup!$A$2:$B$8,2,FALSE) -> Friday | L25: 46220
A26: =A25+1 -> 25 | B26: 46221 | D26: =VLOOKUP( WEEKDAY(B26) ,Lookup!$A$2:$B$8,2,FALSE) -> Saturday | E26: chithirai Event | F26: chithirai Event | H26: =VLOOKUP( WEEKDAY(I26) ,Lookup!$A$2:$B$8,2,FALSE) -> Saturday | I26: 46221 | K26: =VLOOKUP( WEEKDAY(L26) ,Lookup!$A$2:$B$8,2,FALSE) -> Saturday | L26: 46221
A27: =A26+1 -> 26 | B27: 46222 | D27: =VLOOKUP( WEEKDAY(B27) ,Lookup!$A$2:$B$8,2,FALSE) -> Sunday | E27: chithirai Event | F27: Return to Tirunelveli from Chennai | H27: =VLOOKUP( WEEKDAY(I27) ,Lookup!$A$2:$B$8,2,FALSE) -> Sunday | I27: 46222 | K27: =VLOOKUP( WEEKDAY(L27) ,Lookup!$A$2:$B$8,2,FALSE) -> Sunday | L27: 46222
A28: =A27+1 -> 27 | B28: 46223 | C28: 0.41666667 | D28: =VLOOKUP( WEEKDAY(B28) ,Lookup!$A$2:$B$8,2,FALSE) -> Monday | E28: Asset purchase | F28: laptop Collect | G28: High | H28: =VLOOKUP( WEEKDAY(I28) ,Lookup!$A$2:$B$8,2,FALSE) -> Monday | I28: 46223 | K28: =VLOOKUP( WEEKDAY(L28) ,Lookup!$A$2:$B$8,2,FALSE) -> Monday | L28: 46223 | M28: 10:5
A29: =A28+1 -> 28 | B29: 46223 | C29: 0.41666667 | D29: =VLOOKUP( WEEKDAY(B29) ,Lookup!$A$2:$B$8,2,FALSE) -> Monday | E29: Client Followup | F29: Send a reminder whatsapp msg to i met at chithirai event | H29: =VLOOKUP( WEEKDAY(I29) ,Lookup!$A$2:$B$8,2,FALSE) -> Monday | I29: 46223 | K29: =VLOOKUP( WEEKDAY(L29) ,Lookup!$A$2:$B$8,2,FALSE) -> Monday | L29: 46223 | O29: whatsapp msg
A30: =A29+1 -> 29 | B30: 46223 | C30: 0.41666667 | D30: =VLOOKUP( WEEKDAY(B30) ,Lookup!$A$2:$B$8,2,FALSE) -> Monday | E30: Asset purchase | F30: Laptop Setup | H30: =VLOOKUP( WEEKDAY(I30) ,Lookup!$A$2:$B$8,2,FALSE) -> Monday | I30: 46223 | J30: 0.47916667 | K30: =VLOOKUP( WEEKDAY(L30) ,Lookup!$A$2:$B$8,2,FALSE) -> Monday | L30: 46223 | M30: 0.53472222 | N30: completed
A31: =A30+1 -> 30 | B31: 46223 | C31: 0.41666667 | D31: =VLOOKUP( WEEKDAY(B31) ,Lookup!$A$2:$B$8,2,FALSE) -> Monday | E31: Software Analysis | F31: TeleCMI Purchase | H31: =VLOOKUP( WEEKDAY(I31) ,Lookup!$A$2:$B$8,2,FALSE) -> Monday | I31: 46223 | K31: =VLOOKUP( WEEKDAY(L31) ,Lookup!$A$2:$B$8,2,FALSE) -> Monday | L31: 46223
A32: =A31+1 -> 31 | B32: 46223 | C32: 0.41666667 | D32: =VLOOKUP( WEEKDAY(B32) ,Lookup!$A$2:$B$8,2,FALSE) -> Monday | E32: Software Analysis | F32: Other call recording Software need to check | H32: =VLOOKUP( WEEKDAY(I32) ,Lookup!$A$2:$B$8,2,FALSE) -> Monday | I32: 46223 | K32: =VLOOKUP( WEEKDAY(L32) ,Lookup!$A$2:$B$8,2,FALSE) -> Monday | L32: 46223
A33: =A32+1 -> 32 | B33: 46223 | C33: 0.41666667 | D33: =VLOOKUP( WEEKDAY(B33) ,Lookup!$A$2:$B$8,2,FALSE) -> Monday | E33: Software Analysis | F33: CRM Software need to check | H33: =VLOOKUP( WEEKDAY(I33) ,Lookup!$A$2:$B$8,2,FALSE) -> Monday | I33: 46223 | K33: =VLOOKUP( WEEKDAY(L33) ,Lookup!$A$2:$B$8,2,FALSE) -> Monday | L33: 46223
A34: =A33+1 -> 33 | B34: 46223 | C34: 0.41666667 | D34: =VLOOKUP( WEEKDAY(B34) ,Lookup!$A$2:$B$8,2,FALSE) -> Monday | E34: Software Analysis | F34: Vsanth Ticket management, Chennai Event demo need to check | H34: =VLOOKUP( WEEKDAY(I34) ,Lookup!$A$2:$B$8,2,FALSE) -> Monday | I34: 46223 | K34: =VLOOKUP( WEEKDAY(L34) ,Lookup!$A$2:$B$8,2,FALSE) -> Monday | L34: 46223
A35: =A34+1 -> 34 | B35: 46223 | C35: 0.41666667 | D35: =VLOOKUP( WEEKDAY(B35) ,Lookup!$A$2:$B$8,2,FALSE) -> Monday | E35: Hiring | F35: Selvi 9years experience candidate need to interview | H35: =VLOOKUP( WEEKDAY(I35) ,Lookup!$A$2:$B$8,2,FALSE) -> Monday | I35: 46223 | K35: =VLOOKUP( WEEKDAY(L35) ,Lookup!$A$2:$B$8,2,FALSE) -> Monday | L35: 46223
A36: =A35+1 -> 35 | B36: 46223 | C36: 0.41666667 | D36: =VLOOKUP( WEEKDAY(B36) ,Lookup!$A$2:$B$8,2,FALSE) -> Monday | E36: Hiring | F36: Employees Schedule Confirmation | H36: =VLOOKUP( WEEKDAY(I36) ,Lookup!$A$2:$B$8,2,FALSE) -> Monday | I36: 46223 | J36: 0.54861111 | K36: =VLOOKUP( WEEKDAY(L36) ,Lookup!$A$2:$B$8,2,FALSE) -> Monday | L36: 46223 | M36: 0.55972222 | N36: completed | O36: Whatsa app
A37: =A36+1 -> 36 | B37: 46223 | C37: 0.41666667 | D37: =VLOOKUP( WEEKDAY(B37) ,Lookup!$A$2:$B$8,2,FALSE) -> Monday | E37: Training (Incoming Call) | F37: Rajiv Taljeras team | H37: =VLOOKUP( WEEKDAY(I37) ,Lookup!$A$2:$B$8,2,FALSE) -> Monday | I37: 46223 | J37: 0.46527778 | K37: =VLOOKUP( WEEKDAY(L37) ,Lookup!$A$2:$B$8,2,FALSE) -> Monday | L37: 46223 | M37: 0.47222222 | N37: Completed
A38: =A37+1 -> 37 | B38: 46223 | D38: =VLOOKUP( WEEKDAY(B38) ,Lookup!$A$2:$B$8,2,FALSE) -> Monday | E38: friendly call (Incoming call) | F38: Falmora Ragi chennai event participants | H38: =VLOOKUP( WEEKDAY(I38) ,Lookup!$A$2:$B$8,2,FALSE) -> Monday | I38: 46223 | J38: 0.57291667 | K38: =VLOOKUP( WEEKDAY(L38) ,Lookup!$A$2:$B$8,2,FALSE) -> Monday | L38: 46223 | M38: 0.57986111 | N38: Completed
A39: =A38+1 -> 38 | B39: 46223 | C39: 0.59027778 | D39: =VLOOKUP( WEEKDAY(B39) ,Lookup!$A$2:$B$8,2,FALSE) -> Monday | F39: Call center pricing analysis | H39: =VLOOKUP( WEEKDAY(I39) ,Lookup!$A$2:$B$8,2,FALSE) -> Monday | I39: 46223 | J39: 0.6 | K39: =VLOOKUP( WEEKDAY(L39) ,Lookup!$A$2:$B$8,2,FALSE) -> Monday | L39: 46223
A40: =A39+1 -> 39 | B40: 46223 | C40: 0.63541667 | D40: =VLOOKUP( WEEKDAY(B40) ,Lookup!$A$2:$B$8,2,FALSE) -> Monday | E40: Mentoring Session | F40: Senthil Anna call regarding client pricing and general discussion | H40: =VLOOKUP( WEEKDAY(I40) ,Lookup!$A$2:$B$8,2,FALSE) -> Monday | I40: 46223 | J40: 0.63541667 | K40: =VLOOKUP( WEEKDAY(L40) ,Lookup!$A$2:$B$8,2,FALSE) -> Monday | L40: 46223 | M40: 0.82986111 | N40: Completed
...

Sheet Over All Planner
A1: Sl. No. | B1: Noted Start Date | C1: Noted Start Time | D1: Noted Time Spend | E1: Noted End Date | F1: Noted End Time | G1: Day | H1: Category | I1: Task / Activity | J1: Priority | K1: PlanStart Date | L1: PlanStart Time | M1: PlanEnd Date | N1: PlanEnd Time | O1: Status | P1: Remarks / Notes | Q1: Next Action | R1: Follow-up Date
A2: 1 | B2: 46223 | C2: 0.41666667 | G2: Monday | H2: Software Analysis | I2: TeleCMI Purchase | K2: 46224 | M2: 46224 | P2: Need to Purchase 2 agents, and check all the features
A3: 2 | B3: 46223 | C3: 0.41666667 | G3: Monday | H3: Software Analysis | I3: Other call recording Software need to check
A4: 3 | B4: 46223 | C4: 0.41666667 | G4: Monday | H4: Software Analysis | I4: CRM Software need to check
A5: 4 | B5: 46223 | C5: 0.41666667 | G5: Monday | H5: Software Analysis | I5: Vsanth Ticket management, Chennai Event demo need to check
A6: 5 | B6: 46223 | C6: 0.78819444 | E6: 46223 | F6: 0.79166667 | G6: Monday | H6: Hiring | I6: Selvi 9years experience candidate need to prepare for Interview, Google sheet, Folder, Timing confirmation | K6: 46224 | L6: 0 | M6: 46224 | N6: 0.017361111
A7: 6 | B7: 46223 | C7: 0.41666667 | G7: Monday | H7: Hiring | I7: Selvi 9years experience candidate need to interview | K7: 46224 | L7: 0.020833333 | M7: 46224 | N7: 0.54166667 | P7: Need to check the availability time
A8: 7 | B8: 46223 | C8: 0.41666667 | G8: Monday | H8: Training (Incoming Call) | I8: Rajiv Taljeras team | O8: Future Planning
A9: 8 | B9: 46223 | C9: 0.41666667 | G9: Monday | H9: Pricing | I9: Pricing fro Client need to work out
A10: 9 | B10: 46223 | C10: 0.60902778 | G10: Monday | H10: Documentation | I10: Company mail Id
A11: 10 | B11: 46223 | C11: 0.62847222 | G11: Monday | H11: Mentoring | I11: Bhuvana Annie call preparation
A12: 11 | B12: 46223 | C12: 0.75694444 | G12: Monday | H12: Accounts | I12: Chithirai Events Expense need to be corrected details in the pending
A13: 12 | B13: 46223 | C13: 0.77430556 | G13: Monday | H13: Accounts | I13: Need to check how a gmail is placed in desktop | J13: Low
A14: 13 | B14: 46223 | C14: 0.77430556 | G14: Monday | H14: Accounts | I14: Main Accounts update form july 10th 2026
A15: 14 | B15: 46223 | C15: 0.89583333 | D15: 2 MInutes | E15: 46223 | F15: 0.89585648 | G15: Monday | H15: Transcript | I15: Sarvam Ai: Chithirai Chennai Event Transcription | J15: Medium | K15: 46223 | L15: 0.88194444 | M15: 46223 | N15: 0.44444444 | O15: Completed | P15: Initially started with Perplexity, But perplexity record stopped unexpectedly, so again download the file and convert to MP3 file using online free converter and upload the document | Q15: Nil | R15: Nil
A16: 15 | B16: 46223 | C16: 0.94791667 | D16: 2 MInutes | E16: 46223 | F16: 0.94930556 | G16: Monday | I16: Organise File and Folders in Laptop (Book Mark)
A17: 16 | B17: 46223 | C17: 0.95138889 | D17: 2 MInutes | E17: 46223 | F17: 0.95277778 | G17: Monday | I17: Move all the Palm Era group to Archieve
A18: 17 | B18: 46223 | C18: 0.96527778 | D18: 2 MInutes | E18: 46223 | F18: 0.96736111 | G18: Monday | H18: Scheduling | I18: Need to talk to all the telecallers, Pesi romba nal achu, enna pannittu irukanga, avanga current situation ennan kekanum
A19: 18 | B19: 46224 | C19: 0.42361111 | D19: 2 Minutes | E19: 46224 | F19: 0.425 | G19: Tuesday | H19: Marketing | I19: Personal Branding | J19: Medium | K19: 46224 | L19: 0.425
A20: 19 | B20: 46224 | C20: 0.42708333 | D20: 2 Minutes | E20: 46224 | F20: 0.43055556 | G20: Tuesday | H20: Marketing | I20: Social Media Marketing: Instagram, Facebook and Linkedin | J20: Medium | K20: 46224 | L20: 0.43055556
A21: 20 | B21: 46224 | C21: 0.43055556 | D21: 2 Minutes | E21: 46224 | F21: 0.43402778 | G21: Tuesday | H21: Technical | I21: Need to Check while sharing the screen the google meet disconnects, yesterday call with bhuvana annies the issue occurs 2 times | J21: High | K21: 46224 | L21: 0.43402778
A22: 21 | B22: 46224 | C22: 0.44097222 | D22: 2 Minutes | E22: 46224 | F22: 0.46111111 | G22: Tuesday | H22: Technical | I22: Subha BPO training class need to Plan | J22: Medium | K22: 46224 | L22: 0.46111111
A23: 22 | B23: 46224 | C23: 0.78125 | D23: 2 Minutes | E23: 46224 | F23: 0.78263889 | G23: Tuesday | H23: Documentation | I23: Auditor Kitta pesanum , Before that prepare set of question | J23: High | K23: 46226 | L23: 0.41666667 | M23: 46226 | N23: 0.42708333 | O23: https://docs.google.com/spreadsheets/d/1BX1arbiV9XQvbCuUtAJIHWUkeA-NH-pXHAf1W1kwv68/edit?usp=sharing
A24: 23 | B24: 46224 | C24: 0.78263889 | D24: 2 Minutes | E24: 46224 | F24: 0.78402778 | G24: Tuesday | H24: Documentation | I24: Chatgptla Whatsapp Notes pottu analyse pannanum | J24: High | K24: 46224 | L24: 0.78402778
A25: 24 | B25: 46224 | C25: 0.78402778 | D25: 2 Minutes | E25: 46224 | F25: 0.78541667 | G25: Tuesday | H25: Research | I25: Check Previous sheet for Pricing and resources | J25: High | K25: 46224 | L25: 0.78541667
A26: 25 | B26: 46224 | C26: 0.94444444 | D26: 2 Minutes | E26: 46224 | F26: 0.94583333 | G26: Tuesday | H26: Research | I26: Compare BNI, JCI, Rotary, and other association | J26: Medium | K26: 46224 | L26: 0.94583333
A27: 26 | B27: 46224 | C27: 0.94444444 | D27: 2 Minutes | E27: 46224 | F27: 0.94583333 | G27: Tuesday | H27: Research | I27: Analyse the website for price calculation https://www.magellan-solutions.com/blog/calculate-cost-per-call/ | J27: High | K27: 46224 | L27: 0.94583333
A28: 27 | B28: 46224 | C28: 0.94444444 | D28: 2 Minutes | E28: 46224 | F28: 0.94583333 | G28: Tuesday | H28: Research | I28: Target Audience List | J28: High | K28: 46224 | L28: 0.94583333
A29: 28 | B29: 46224 | C29: 0.95138889 | D29: 1 MInutes | E29: 46224 | F29: 0.95277778 | G29: Tuesday | H29: Research | I29: Set of Questions for Client Requirement Checking | J29: Medium | K29: 46224 | L29: 0.95277778
A30: 29 | B30: 46225 | C30: 0.86458333 | D30: 1 MInutes | E30: 46225 | F30: 0.86597222 | G30: Wednesday | H30: Research | I30: Check all the previous Chithirai Follow up calls | J30: High | K30: 46225 | L30: 0.86597222 | M30: 46225 | N30: 0.875
A31: 30 | B31: 46225 | C31: 0.86597222 | D31: 1 MInutes | E31: 46225 | F31: 0.86736111 | G31: Wednesday | H31: Research | I31: Prepare subha previous work experience | J31: High | K31: 46225 | L31: 0.875 | M31: 46225 | N31: 0.89583333
A32: 31 | B32: 46225 | C32: 0.86736111 | D32: 1 MInutes | E32: 46225 | F32: 0.86944444 | G32: Wednesday | H32: Research | I32: Services Subha worked on her experience | J32: High | K32: 46225 | L32: 0.89583333 | M32: 46225 | N32: 0.90277778
A33: 32 | B33: 46225 | C33: 0.86944444 | D33: 1 MInutes | E33: 46225 | F33: 0.87083333 | G33: Wednesday | H33: Research | I33: Industries where BPO can give service | J33: High | K33: 46225 | L33: 0.90277778 | M33: 46225 | N33: 0.91666667
A34: 33 | B34: 46225 | C34: 0.91666667 | E34: 46225 | F34: 0.91805556 | G34: Wednesday | H34: Pricing | I34: Cost calculation for Starter, standard, premium | K34: 46225 | L34: 0.91666667 | M34: 46225 | N34: 0.96180556
A35: 34 | B35: 46226 | C35: 0.40625 | E35: 46226 | F35: 0.40694444 | G35: Thursday | H35: Client | I35: Sales Proposal
A36: 35 | B36: 46226 | C36: 0.40694444 | E36: 46226 | F36: 0.40763889 | G36: Thursday | H36: Marketing | I36: Digital Marketing
A37: 36 | B37: 46226 | C37: 0.40763889 | E37: 46226 | F37: 0.40833333 | G37: Thursday | H37: Marketing | I37: Website followup and finalise
A38: 37 | B38: 46226 | C38: 0.9375 | E38: 46226 | F38: 0.93888889 | G38: Thursday | H38: Finance | I38: HDFC Bank Direct visit | K38: 46227 | L38: 0.38541667 | M38: 46227 | N38: 0.42708333
A39: 38 | B39: 46226 | C39: 0.93888889 | E39: 46226 | F39: 0.94027778 | G39: Thursday | H39: Asset : Post Paid Sim Purchase | I39: Airtel Office -> Post Paid Sim to get fancy number to display in website and marketing activities post
A40: 39 | B40: 46226 | C40: 0.94027778 | E40: 46226 | F40: 0.94166667 | G40: Thursday | H40: Hiring : Appointment | I40: Tead lead Selvi Requirt, Monthly Salary will be 18000 initially, after 3 months the salary will be revised
...

Sheet Daily Planner
A1: Sl: No: | B1: Date | C1: Time | D1: Day | E1: Category | F1: Details | G1: Priority | H1: Planned Start Date | I1: Planned Start Time | J1: Planned End Date | K1: Planned End Time | L1: Status | M1: Remarks / Notes | N1: Next Action | O1: Follow-up Date
A2: 1 | B2: 46224 | C2: 0.41666667 | D2: =VLOOKUP( WEEKDAY(B2) ,Lookup!$A$2:$B$8,2,FALSE) -> Tuesday | E2: Hiring | F2: Selvi 9years experience candidate need to prepare for Interview, Google sheet, Folder, Timing confirmation | G2: High | H2: 46224 | I2: 0.4375 | J2: 46224 | K2: 0.45833333
A3: 2 | B3: 46224 | C3: 0.41666667 | D3: =VLOOKUP( WEEKDAY(B3) ,Lookup!$A$2:$B$8,2,FALSE) -> Tuesday | E3: Hiring | F3: Selvi 9years experience candidate need to interview | G3: High | H3: 46224 | I3: 0.45833333 | J3: 46224 | K3: 0.47916667
A4: 3 | B4: 46224 | C4: 0.41666667 | D4: =VLOOKUP( WEEKDAY(B4) ,Lookup!$A$2:$B$8,2,FALSE) -> Tuesday | E4: Scheduling | F4: Need to talk to all the telecallers, Pesi romba nal achu, enna pannittu irukanga, avanga current situation ennan kekanum | G4: High | H4: 46224 | I4: 0.47916667 | J4: 46224 | K4: 0.58333333
A5: 4 | B5: 46224 | C5: 0.41666667 | D5: =VLOOKUP( WEEKDAY(B5) ,Lookup!$A$2:$B$8,2,FALSE) -> Tuesday | E5: Documentation | F5: Organise File and Folders in Laptop (Book Mark) | G5: High | H5: 46224 | I5: 0.58333333 | J5: 46224 | K5: 0.60416667
A6: 5 | B6: 46224 | C6: 0.41666667 | D6: =VLOOKUP( WEEKDAY(B6) ,Lookup!$A$2:$B$8,2,FALSE) -> Tuesday | E6: Documentation | F6: Move all the Palm Era group to Archieve | G6: Medium | H6: 46224 | I6: 2.30Pm | J6: 46224 | K6: 0.625
A7: 6 | B7: 46224 | C7: 0.41666667 | D7: =VLOOKUP( WEEKDAY(B7) ,Lookup!$A$2:$B$8,2,FALSE) -> Tuesday | E7: Mentoring | F7: Bhuvana Annie call preparation | G7: High | H7: 46224 | I7: 0.625 | J7: 46224 | K7: 0.66666667
A8: 7 | B8: 46224 | C8: 0.47569444 | D8: =VLOOKUP( WEEKDAY(B8) ,Lookup!$A$2:$B$8,2,FALSE) -> Tuesday | E8: BPO training | F8: BPO training daily class | G8: Medium | H8: 46224 | I8: 0.66666667 | J8: 46224 | K8: 0.70833333 | M8: Pradeep in travel, so call training moved to tomorrow
A9: 8 | B9: 46224 | C9: 0.41666667 | D9: =VLOOKUP( WEEKDAY(B9) ,Lookup!$A$2:$B$8,2,FALSE) -> Tuesday | E9: Pricing | F9: Pricing fro Client need to work out | G9: High | H9: 46224 | I9: 0.70833333 | J9: 46224 | K9: 0.75
A10: 9 | B10: 46225 | C10: 0.41666667 | D10: =VLOOKUP( WEEKDAY(B10) ,Lookup!$A$2:$B$8,2,FALSE) -> Wednesday | E10: Research | F10: Analyse the website for price calculation https://www.magellan-solutions.com/blog/calculate-cost-per-call/ | G10: High | H10: 46225 | I10: 0.41666667 | J10: 46225 | K10: 0.45833333
A11: 10 | B11: 46225 | C11: 0.41666667 | D11: =VLOOKUP( WEEKDAY(B11) ,Lookup!$A$2:$B$8,2,FALSE) -> Wednesday | E11: Reserach | F11: Prepare Set of Questions for Auditor for Name change, pricing, and what are all the things a company will face | G11: High | H11: 46225 | I11: 0.45833333 | J11: 22-Ju;-2026 | K11: 0.47916667
A12: 11 | B12: 46225 | C12: 0.41666667 | D12: =VLOOKUP( WEEKDAY(B12) ,Lookup!$A$2:$B$8,2,FALSE) -> Wednesday | E12: Research | F12: Talk to Auditor Jagadeswari, Allan Cowork space, Santhi (Chithirai Chennai Participants) | G12: High | H12: 46225 | I12: 0.47916667 | J12: 46225 | K12: 0.010416667
A13: 12 | B13: 46225 | C13: 0.41666667 | D13: =VLOOKUP( WEEKDAY(B13) ,Lookup!$A$2:$B$8,2,FALSE) -> Wednesday | E13: Hiring | F13: Requirt selvi telecalling tomorrow, Assign Market research for call recording tools | G13: Medium | H13: 46225 | I13: 0.51041667 | J13: 46225 | K13: 0.54166667
A14: 13 | B14: 46225 | C14: 0.41666667 | D14: =VLOOKUP( WEEKDAY(B14) ,Lookup!$A$2:$B$8,2,FALSE) -> Wednesday | E14: Training | F14: Subha BPO Training class | G14: Medium | H14: 46225 | I14: 0.54166667 | J14: 46225 | K14: 0.58333333
A15: 14 | B15: 46225 | C15: 0.41666667 | D15: =VLOOKUP( WEEKDAY(B15) ,Lookup!$A$2:$B$8,2,FALSE) -> Wednesday | E15: Schedule | F15: Call with Telecallers, take Individual call, and check there available time and challeges if any | G15: High | H15: 46225 | I15: 0.58333333 | J15: 46225 | K15: 0.66666667
A16: 15 | B16: 46225 | C16: 0.41666667 | D16: =VLOOKUP( WEEKDAY(B16) ,Lookup!$A$2:$B$8,2,FALSE) -> Wednesday | E16: Documentation | F16: Organise File and Folders in Laptop (Book Mark) | G16: High | H16: 46225 | I16: 0.66666667 | J16: 46225 | K16: 0.70833333
A17: 16 | B17: 46225 | C17: 0.41666667 | D17: =VLOOKUP( WEEKDAY(B17) ,Lookup!$A$2:$B$8,2,FALSE) -> Wednesday | E17: Mentoring | F17: Bhuvana Annie call preparation | G17: High | H17: 46225 | I17: 0.70833333 | J17: 46225 | K17: 0.75
A18: 17 | B18: 46225 | C18: 0.41666667 | D18: =VLOOKUP( WEEKDAY(B18) ,Lookup!$A$2:$B$8,2,FALSE) -> Wednesday | E18: Documentation | F18: Chithirai participants list update in sheet | G18: Medium | H18: 46225 | I18: 0.75 | J18: 46225 | K18: 0.77083333
A19: 18 | B19: 46225 | C19: 0.42708333 | D19: =VLOOKUP( WEEKDAY(B19) ,Lookup!$A$2:$B$8,2,FALSE) -> Wednesday | E19: Accounts | F19: Main Accounts Sheet Update | G19: High | H19: 46225 | I19: 0.43055556 | J19: 46225 | K19: 0.45833333 | L19: Completed
A20: 19 | B20: 46226 | C20: 0.41666667 | D20: =VLOOKUP( WEEKDAY(B20) ,Lookup!$A$2:$B$8,2,FALSE) -> Thursday | E20: Reserach | F20: Prepare Set of Questions for Auditor for Name change, pricing, and what are all the things a company will face | G20: High | H20: 46226 | I20: 0.39583333 | J20: 46226 | K20: 0.41666667
A21: 20 | B21: 46226 | C21: 0.41666667 | D21: =VLOOKUP( WEEKDAY(B21) ,Lookup!$A$2:$B$8,2,FALSE) -> Thursday | E21: Research | F21: Talk to Auditor Jagadeswari, Allan Cowork space, Santhi (Chithirai Chennai Participants) | G21: High | H21: 46226 | I21: 0.41666667 | J21: 46226 | K21: 0.42708333 | L21: Completed | M21: https://docs.google.com/spreadsheets/d/1BX1arbiV9XQvbCuUtAJIHWUkeA-NH-pXHAf1W1kwv68/edit?usp=sharing
A22: 21 | B22: 46226 | C22: 0.41666667 | D22: =VLOOKUP( WEEKDAY(B22) ,Lookup!$A$2:$B$8,2,FALSE) -> Thursday | E22: Scheduling | F22: Call with Telecallers, take Individual call, and check there available time and challeges if any | G22: High | H22: 46226 | I22: 0.42708333 | J22: 46226 | K22: 0
A23: 22 | B23: 46226 | C23: 0.41666667 | D23: =VLOOKUP( WEEKDAY(B23) ,Lookup!$A$2:$B$8,2,FALSE) -> Thursday | E23: Research | F23: Chithirai participants list update in sheet | G23: High | H23: 46226 | I23: 0 | J23: 46226 | K23: 0.54166667
A24: 23 | B24: 46226 | C24: 0.41666667 | D24: =VLOOKUP( WEEKDAY(B24) ,Lookup!$A$2:$B$8,2,FALSE) -> Thursday | E24: Research | F24: Call Recording software finalise tomorrow | G24: High | H24: 46226 | I24: 0.54166667 | J24: 46226 | K24: 0.58333333
A25: 24 | B25: 46226 | C25: 0.41666667 | D25: =VLOOKUP( WEEKDAY(B25) ,Lookup!$A$2:$B$8,2,FALSE) -> Thursday | E25: Cibil Score | F25: Kathika , Mathan Anna Friend Need to check for Bajaj Finance closing and Credit Card | G25: High | H25: 46226 | I25: 0.58333333 | J25: 46226 | K25: 0.59375 | L25: Completed
A26: 25 | B26: 46226 | C26: 0.41666667 | D26: =VLOOKUP( WEEKDAY(B26) ,Lookup!$A$2:$B$8,2,FALSE) -> Thursday | E26: Social Media Manager | F26: Manimegai Social Media Manager Need to talk regarding Linkedin, Facebook and Instagram | G26: High | H26: 46226 | I26: 0.59375 | J26: 46226 | K26: 0.625
A27: 26 | B27: 46226 | C27: 0.41666667 | D27: =VLOOKUP( WEEKDAY(B27) ,Lookup!$A$2:$B$8,2,FALSE) -> Thursday | E27: BPO training | F27: BPO training daily class | G27: Medium | H27: 46226 | I27: 0.625 | J27: 46226 | K27: 0.66666667
A28: 27 | B28: 46227 | C28: 0.38541667 | D28: =VLOOKUP( WEEKDAY(B28) ,Lookup!$A$2:$B$8,2,FALSE) -> Friday | E28: Finance | F28: HDFC Bank Direct visit | H28: 46227 | I28: 0.38541667 | J28: 46227 | K28: 0.42708333 | L28: Completed
A29: 28 | B29: 46227 | C29: 0.38541667 | D29: =VLOOKUP( WEEKDAY(B29) ,Lookup!$A$2:$B$8,2,FALSE) -> Friday | E29: Asset : Post Paid Sim Purchase | F29: Airtel Office -> Post Paid Sim to get fancy number to display in website and marketing activities post | H29: 46227 | I29: 0.42708333 | J29: 46227 | K29: 0.45833333
A30: 29 | B30: 46227 | C30: 0.38541667 | D30: =VLOOKUP( WEEKDAY(B30) ,Lookup!$A$2:$B$8,2,FALSE) -> Friday | E30: Hiring : Appointment | F30: Tead lead Selvi Requirt, Monthly Salary will be 18000 initially, after 3 months the salary will be revised | H30: 46227 | I30: 0.45833333 | J30: 46227 | K30: 0.47916667
A31: 30 | B31: 46227 | C31: 0.38541667 | D31: =VLOOKUP( WEEKDAY(B31) ,Lookup!$A$2:$B$8,2,FALSE) -> Friday | E31: Software : Purchase | F31: My operator to be finalised tomorrow | H31: 46227 | I31: 0.47916667 | J31: 46227 | K31: 0
A32: 31 | B32: 46227 | C32: 0.38541667 | D32: =VLOOKUP( WEEKDAY(B32) ,Lookup!$A$2:$B$8,2,FALSE) -> Friday | E32: Marketing | F32: Website content to be finalised tomorrow | H32: 46227 | I32: 0 | J32: 46227 | K32: 0.58333333
A33: 32 | B33: 46227 | C33: 0.38541667 | D33: =VLOOKUP( WEEKDAY(B33) ,Lookup!$A$2:$B$8,2,FALSE) -> Friday | E33: Registration | F33: Auditor call about registration and other prepared questions | H33: 46227 | I33: 0.58333333 | J33: 46227 | K33: 0.60416667 | L33: Completed
A34: 33 | B34: 46227 | C34: 0.38541667 | D34: =VLOOKUP( WEEKDAY(B34) ,Lookup!$A$2:$B$8,2,FALSE) -> Friday | E34: Mentoring | F34: Bhuvana Annie Call Preparation Industry and the services, | H34: 46227 | I34: 0.60416667 | J34: 46227 | K34: 0.6875
A35: 34 | B35: 46227 | C35: 0.38541667 | D35: =VLOOKUP( WEEKDAY(B35) ,Lookup!$A$2:$B$8,2,FALSE) -> Friday | E35: Scheduling | F35: Call with Telecallers, take Individual call, and check there available time and challeges if any | H35: 46227 | I35: 0.6875 | J35: 46227 | K35: 0.77083333
A36: 35 | B36: 46227 | C36: 0.38541667 | D36: =VLOOKUP( WEEKDAY(B36) ,Lookup!$A$2:$B$8,2,FALSE) -> Friday | E36: Mentoring | F36: Bhuvana Annie Call Preparation Industry and the services, | H36: 46227 | I36: 0.77083333 | J36: 46227 | K36: 0.79166667
A37: 36 | B37: 46227 | C37: 0.38541667 | D37: =VLOOKUP( WEEKDAY(B37) ,Lookup!$A$2:$B$8,2,FALSE) -> Friday | E37: Mentoring | F37: Bhuvana Annie call | H37: 46227 | I37: 0.79166667 | J37: 46227 | K37: 0.8125
A38: 37 | B38: 46227 | C38: 0.38541667 | D38: =VLOOKUP( WEEKDAY(B38) ,Lookup!$A$2:$B$8,2,FALSE) -> Friday | E38: Documentation | F38: Rental Agreement for Spaco Co work space | H38: 46227 | I38: 0.76041667 | J38: 46227 | K38: 0.76388889
A39: 38 | B39: 46228 | C39: 0.38541667 | D39: =VLOOKUP( WEEKDAY(B39) ,Lookup!$A$2:$B$8,2,FALSE) -> Saturday | E39: Hiring | F39: Hire Selvi Tomorrow | H39: 46228 | I39: 0.91666667 | J39: 46228 | K39: 0.9375
A40: 39 | B40: 46228 | C40: 0.38541667 | D40: =VLOOKUP( WEEKDAY(B40) ,Lookup!$A$2:$B$8,2,FALSE) -> Saturday | E40: Training | F40: Check Bounvoice again, and start training with bounvoice tomorrow before that speak to the employees | H40: 46228 | I40: 0.9375 | J40: 46228 | K40: 0.5
...

Sheet Index

Sheet Time Sheet
A1: Date | B1: Name | C1: From Home to Office | D1: CO Work Space Check In | E1: CO Work Space Check Out | F1: From Office to Home | G1: Home Work Start time | H1: Home Work End time
A2: 46224 | B2: Thilaga Subha S | C2: 0.40694444 | D2: 0.42083333 | E2: 0.80694444 | F2: 0.83333333 | G2: 0.86458333 | H2: 0.96875
A3: 46225 | B3: Thilaga Subha S | C3: 0.40625 | D3: 0.42638889 | E3: 0.81597222 | F3: 0.82986111 | G3: 0.86458333 | H3: 0.96527778
A4: 46226 | B4: Thilaga Subha S | C4: NIL | D4: NIL | E4: NIl | F4: Nil | G4: 0.38541667 | H4: 0.95138889
A5: 46227 | B5: Thilaga Subha S | C5: 0.39583333 | D5: 0.47222222 | E5: 0.825 | F5: 0.84375 | G5: 0.91666667 | H5: 0.9375
A6: 46228 | B6: Thilaga Subha S | C6: 0.38194444 | D6: 0.40277778 | E6: 0.70833333 | F6: 0.73611111 | G6: 0.75 | H6: 0.88888889
A7: 46229 | B7: Thilaga Subha S | C7: NIL | D7: NIL | E7: NIL | F7: NIL | G7: 0.39583333 | H7: 0
A8: 46229 | B8: Thilaga Subha S | C8: NIL | D8: NIL | E8: NIL | F8: NIL | G8: 0.57291667 | H8: 0.625
A9: 46229 | B9: Thilaga Subha S | C9: NIL | D9: NIL | E9: NIL | F9: NIL | G9: 0.75 | H9: 0.89583333
A10: 46229 | B10: Thilaga Subha S | C10: NIL | D10: NIL | E10: NIL | F10: NIL | G10: 0.94791667 | H10: 0.59375
A11: 46230 | B11: Thilaga Subha S | C11: 0.92013889 | D11: 0.93472222 | E11: 0.72986111 | F11: 0.73472222 | G11: 0.75694444 | H11: 0.925
A12: 46231 | B12: Thilaga Subha S | C12: 10:20 Pm (ISM Data Technology Tenkasi) | D12: 11:40 (ISM Data technology) | E12: 12:50 PM(ISM Data Technology) | F12: 2:20:00 PM(Reached Home) | G12: 0.70833333 | H12: 0.013888889
A13: 46232 | B13: Thilaga Subha S | C13: 0.40625 | D13: 0.41944444 | E13: 0.83333333 | F13: 0.86458333 | G13: 0.88888889 | H13: 0.99305556
A14: 46233 | B14: Thilaga Subha S | C14: 0.39444444 | D14: 0.48958333 | E14: 0.80555556 | F14: 0.81944444
A15: 46234 | B15: Thilaga Subha S | C15: 0.39236111 | D15: 0.40972222 | E15: 0.77430556 | F15: 0.79166667 | G15: 0.79166667 | H15: 0.89583333
A16: 46235 | B16: Thilaga Subha S | C16: 7:20:00 AM (Madurai Women professional Meet) | F16: 6.50 PM | G16: 0.79166667 | H16: 0.90277778
A17: 46236 | B17: Thilaga Subha S | G17: 0.45138889 | H17: 0.90972222
A18: 46237 | B18: Thilaga Subha S | C18: 0.42708333 | D18: 0.44444444 | E18: 0.77083333 | F18: 0.79166667 | G18: 0.79166667 | H18: 0.95833333
A19: 46238 | B19: Thilaga Subha S | C19: 0.38888889 | D19: 0.41319444 | E19: 0.75 | F19: 0.78472222 | G19: 0.92708333 | H19: 0.95833333
A20: 46239 | B20: Thilaga Subha S | C20: 0.35416667 | D20: 0.37152778

Sheet Lookup
A2: 1 | B2: Sunday
A3: =A2+1 -> 2 | B3: Monday
A4: =A3+1 -> 3 | B4: Tuesday
A5: =A4+1 -> 4 | B5: Wednesday
A6: =A5+1 -> 5 | B6: Thursday
A7: =A6+1 -> 6 | B7: Friday
A8: =A7+1 -> 7 | B8: Saturday
