Workbook

Sheet Version_Control
A1: VERSION CONTROL — MeetSync Sprint Tracker & Traceability
A2: File naming: claude_v<NNN>_<proper file name>_YYYYMMDD_HHMI.xlsx. Companion: v008 product workbook = backlog source of truth; v009 of that workbook stays planned for full as-built re-baseline.
A3: Version | B3: Date/Time | C3: Author | D3: Change Description | E3: Status
A4: v001 | B4: 2026-09-11 08:42 | C4: Claude for Senthil/KP | D4: THIS FILE — Standalone live execution tracker for MeetSync (Zoom App Marketplace), extracted to the TeleField-v001 file pattern per Senthil's 08:42 instruction; supersedes nothing — mirrors and will carry forward the tracker sheets embedded in the v008 product workbook. Contains: Sprint_Tracker_Log E001-E011, Decisions (D13/D15 + D-M1..M3), full 100-story Traceability_Matrix from v008 Full_Backlog (399 pts, rollup formula-verified: 74 Done-in-code / 292 pts / 73.2%), Sprint_Status_Rollup S1-S12, S9_Prep_Board, RAID_Carryover, Gate_Checklist. Build state carried in: S1-S8 executed under D13 — 18 Jest suites / 139 tests, 100% stmts/branches/funcs/lines, zero pragmas. Code: claude_v008_meetsync_s1_s8_code_20260910_2258.zip. | E4: Released
A5: v002 | B5: 2026-09-11 08:47 | C5: Claude for Senthil/KP | D5: THIS FILE — S9 CODEABLE SCOPE EXECUTED on 08:47 continue: ST-069 delete-my-data self-serve SHIPPED (owner-only POST /orgs/:id/delete-my-data, explicit DELETE confirmation, immediate token wipe, purge due at next sweep — retention window bypassed; allow/deny audit-logged per ST-067; accelerates purge on already-uninstalled accounts preserving original uninstall facts). ST-091 degradation made observable in code: ZoomClient.platformHealth() ok/degraded/probing surfaced on /orgs/:id/status — breaker-open shows 'degraded' without erroring; live chaos drill still owed. D13 gate re-verified: 19 Jest suites / 149 tests, 100% stmts/branches/funcs/lines, ZERO pragmas. Rollup now 75 Done-in-code / 297 pts / 74.4%. Docs updated (DATA_FLOW ST-069 shipped; README v0.9.0). Code: claude_v009_meetsync_s9_code_20260911_0847.zip. E012 logged. | E5: Released
A6: v003 | B6: 2026-09-11 13:32 | C6: Claude for Senthil/KP | D6: THIS FILE — S10 CODEABLE SCOPE EXECUTED on 13:32 continue: ST-080 help center SHIPPED (15 launch articles covering install->troubleshooting + ranked keyword search title>keyword>body with deterministic tie-break; /help/articles, /help/articles/:id, /help/search — same source for hosted site and in-app panel). ST-084 status page SHIPPED (public /status JSON + /status.html, component health incl. ST-091 platformHealth, uptime; incident comms template docs/INCIDENT_COMMS.md). ST-095 pricing endpoint /pricing served from the SAME PLANS object billing enforces (matrix+FAQ draft docs/PRICING_PAGE.md). ST-083 code side: demo-data mode POST /orgs/:id/demo-mode (admin+) seeds realistic workspace — notes session, extracted actions, completed sandbox writebacks; 2-min video remains live. ST-096 trust page drafted (docs/TRUST_PAGE.md incl. subprocessors). D13 gate: 20 suites / 160 tests, 100x4, zero pragmas. Rollup 77 Done-in-code / 304 pts / 76.2%. Code: claude_v010_meetsync_s10_code_20260911_1332.zip. E013 + S10_Board added. | E6: Released
A7: v004 | B7: 2026-09-11 15:26 | C7: Claude for Senthil/KP | D7: THIS FILE — CODEABLE RUNWAY CLOSED on 15:26 continue: ST-098 launch-day runbook FINALIZED v1.0 (monitoring table over shipped surfaces /healthz /status funnel errorSpike; <2-min blue/green rollback with the safety properties that make it lossless — webhook replay-guard/dedupe, queued writebacks; Zoom-outage DON'T-rollback path; comms tree + T-1d..T+7d launch sequence) -> Done-in-code. ST-099 groundwork built, story kept HONESTLY in Backlog (it is a post-launch iteration from real data): help-search terms now captured, normalized, ranked at /analytics/search-terms so iteration 1 has data on day 1. D13 gate: 20 suites / 162 tests, 100x4, zero pragmas. Rollup 78 Done-in-code / 307 pts / 76.9%. NEW Senthil_Handover sheet consolidates every remaining item by decision/live/human with what-Claude-needs-back. Code: claude_v011_meetsync_s11_code_20260911_1526.zip. E014 logged. All codeable MeetSync scope is now exhausted. | E7: Released
A8: v005 | B8: 2026-09-11 22:09 | C8: Claude for Senthil/KP | D8: THIS FILE — WEB SURFACE BUILT on 22:09 continue. Correction to E014's 'runway closed': the five surface stories (ST-005/015/025/035/045) read 'in-meeting panel + WEB DASHBOARD surface' — the dashboard half and the panel UI were codeable all along with the Zoom Apps SDK behind a boundary interface; only the live SDK handshake needs the dev app. Built: React web/ layer — NotesPanel (timestamped entries, chip cycling, degraded-mode banner wired to ST-091 platformHealth), ActionsPanel (rule preview in test mode), CrmPanel (mappings, queue, terminal-failure retry visibility), DealRiskPanel (score bands + sensitivity), IndicSettings (pack toggles), App shell serving in-meeting panel AND web dashboard from one codebase via ZoomSdk boundary (MockZoomSdk in tests), typed Api client w/ ApiError. RTL suite added under the SAME gate: 21 suites / 171 tests, 100% x4 across src/ AND web/, zero pragmas. Evidence upgraded on all five surface rows — remaining gap is ONLY the live dev-app handshake (Handover #2). Code: claude_v012_meetsync_web_surface_code_20260911_2209.zip. E015 logged. | E8: Released
A9: v006 | B9: 2026-09-13 09:52 | C9: Claude for Senthil/KP | D9: THIS FILE — ADVERSARIAL COLD REVIEW passes 1+2 executed on 11 Sep 22:32 / 13 Sep 09:52 'do them all properly' / 'continue'. First cold review of MeetSync; all 20 src modules plus the web surface read line by line against the sibling defect classes. 21 defects fixed with pinned regressions (M-F01..M-F21, new Review_Findings sheet), 3 observations logged no-fix for Senthil's disposition. Code v013 released: 22 suites / 225 tests at 100% statements/branches/functions/lines, zero istanbul pragmas, tsc clean. Story position deliberately UNCHANGED (78 Done / 22 remaining) — this is a correctness release, no story flips. | E9: Released
A10: v007 | B10: 2026-09-13 10:01 | C10: Claude for Senthil/KP | D10: THIS FILE — product workbook AS-BUILT RE-BASELINE released as claude_v009_meetsync_zoom_product_workbook_20260913_1001.xlsx, closing Senthil_Handover #11. Full_Backlog statuses and a new evidence column synced from this tracker's Traceability_Matrix; Sprint_Board Done formula corrected to count Done-in-code (it counted exact 'Done' only, so it had been reading zero for eight days); Product_Spec, Screens_Wireframes, Launch_Checklist, Risk_Register and Metrics_Targets rewritten from what v013 actually does. No story states changed in this tracker — the workbook was brought to the tracker, not the other way round. | E10: Released
A11: v008 | B11: 2026-09-13 10:25 | C11: Claude for Senthil/KP | D11: THIS FILE — EXTERNAL VERIFICATION SWEEP against live Zoom platform documentation, MeetSync's first. 7 findings in a new Verification_Sweep sheet, 4 of them LIVE-BLOCKING and invisible to a suite at 100% coverage, because every test asserted our own wrong shape back to us. Code v014 released (claude_v014_meetsync_verification_sweep_code_20260913_1025.zip): 22 suites / 239 tests at 100% statements/branches/functions/lines, zero pragmas, tsc clean. Story position UNCHANGED (78 Done / 307 of 399 pts) — correctness release. Same sibling pattern as VoiceBridge VER-V01/V02 and TestPulse's runtime/API sweep: the defects a cold review cannot reach are the ones where the code is internally consistent and externally wrong. | E11: Released
A12: v009 | B12: 2026-09-13 10:36 | C12: Claude for Senthil/KP | D12: THIS FILE — two artifact claims closed in code. (1) WCAG AA, asserted as an NFR since 5 Sep and never audited on MeetSync: web/a11y.test.tsx now audits all five panels and the shell in every render state, inside the 100% gate. axe found zero violations even on its full ruleset; a manual read of the same markup found four real failures it cannot see, all fixed (see A11Y_Audit sheet). (2) Trial-to-paid, MRR, ARPU and logo churn had targets and no computation: Billing.revenueMetrics + operator-gated /analytics/revenue close it. Code v015 released (claude_v015_meetsync_a11y_metrics_code_20260913_1036.zip): 23 suites / 253 tests at 100% four ways, zero pragmas, tsc clean. Story position UNCHANGED (78 Done / 307 of 399) — neither item is a story, both are claims the artifacts were already making. | E12: Released
A13: v010 | B13: 2026-09-13 10:43 | C13: Claude for Senthil/KP | D13: THIS FILE — OBS-M3 CLOSED (partially, and the partially is the important word). The Store interface is now async with a real PostgresStore beside InMemoryStore, both held to one contract suite that runs every case twice against both implementations and is NOT skipped when no database is present. Verified against a live PostgreSQL 16 in this session, not written blind — an unverified SQL adapter would have repeated exactly the VER-M01 mistake this project has now made three times across products. CI provisions postgres:16 and Node was lifted 20 to 22 (Node 20 EOL Apr 2026). Code v016: 23 suites / 281 tests at 100% four ways, zero pragmas, tsc clean. Story position UNCHANGED (78 Done / 307 of 399). docs/PERSISTENCE.md states plainly what is still process-local — billing, tenant state, CRM queue, RBAC audit — and that MeetSync therefore still cannot run more than one instance. | E13: Released
A14: v011 | B14: 2026-09-13 10:56 | C14: Claude for Senthil/KP | D14: THIS FILE — SECOND DURABLE SLICE: subscriptions. Billing now sits behind a SubscriptionStore with the same two-implementation, one-contract arrangement as the account store, verified against live PostgreSQL 16. This was the recommended next slice because losing it did not merely lose history — a restart reverted every account to no_subscription, un-gating every paid feature and reporting MRR as zero. Code v017: 23 suites / 301 tests at 100% four ways, zero pragmas, tsc clean. Story position UNCHANGED (78 Done / 307 of 399). Entitlement and billing are no longer among the things two instances would disagree about; the single-instance constraint itself stands until tenant state, the CRM queue and the RBAC audit log follow. | E14: Released
... A43: v040 | B43: 2026-09-20 12:29 | C43: Claude for Senthil/KP | D43: THIS FILE — first external review absorbed. Perplexity Review V001 (16 Sep) raised PR-01…PR-14 and a S13–S20 plan of 51 stories / 248 pts. Code v045 closes S13 in full (ST-101…108) and S14 in code (ST-109…115) plus ST-141; 712 tests, 100x4, zero pragmas, three standing gates (capability→caller, route→client, document→code). All 51 new stories are in Traceability_Matrix with honest status; PR rows in Review_Findings; PD-01…PD-06 in Decisions; S13_S20_Board added; rollup extended to S20; handover items 36–43 added. Nothing removed from any sheet. | E43: Released
A44: v041 | D44: PLANNED: opens on any of PD-01/PD-02/PD-03 (pricing, intelligence vs rules engine, SMB vs enterprise) — they gate S15–S18 — or on the Zoom dev app (Handover #2), whose hold (PD-05) lifts now that S13 is closed. | E44: Planned

Sheet Sprint_Tracker_Log
A1: SPRINT TRACKER LOG — every execution event, newest last
A2: Pattern: TeleField v001 tracker. Refs = decisions/stories. Append only.
A3: ID | B3: Date/Time | C3: Sprint | D3: What happened | E3: Refs | F3: State changes | G3: Blockers | H3: Next
A4: E001 | B4: 2026-09-10 22:58 | C4: — | D4: MEETSYNC BUILD OPENED — Senthil 22:58 instruction: continue per sprint from v007 workbook, tracker + traceability to TeleField-v001 pattern, complete development with 100% automation testing. D13 (100% coverage; discovery parked, dev proceeds) applied per 20:45 portfolio-wide direction. D15 sequencing (nine concurrent builds incl. this) remains Senthil's open decision; logged per R7. | E4: D13,D15,R7 | F4: MeetSync S1 opened | G4: None | H4: S1–S8 build
A5: E002 | B5: 2026-09-10 22:58 | C5: S1 | D5: S1 FOUNDATION BUILT (TypeScript/Node/Express per v007 stack): config w/ region us|in|eu + validation; typed Store layer (in-memory, Postgres adapter point — R-M4); zoomAuth (ST-051 exchange, ST-055 rotation-persisting refresh); zoomClient 429/5xx backoff+jitter + circuit breaker w/ half-open (ST-070) + auto-refresh-once on 401 no-loop; webhooks x-zm-signature HMAC + endpoint.url_validation challenge + timestamp replay guard + dedupe ledger; lifecycle install w/ ST-056 attribution, ST-052 uninstall token WIPE + retention-scheduled purge + sweep; express /healthz /oauth/callback /webhooks/zoom /orgs/:id/status; GitHub Actions CI w/ 100%x4 threshold. | E5: ST-051,ST-052,ST-055,ST-056 | F5: 4 S1 stories Done-in-code (13 pts) | G5: Live Zoom dev app = Senthil (LC-1) | H5: E003
A6: E003 | B6: 2026-09-10 22:58 | C6: S2 | D6: S2 DONE-IN-CODE: Live notes panel core (ST-001..004) — sessions, timestamped entries, status chips, close; typed retryable errors w/ backoff hint + error metrics. ST-053 re-install restores archived account within retention (original attribution preserved). ST-054 owner/admin/member RBAC matrix enforced at API via role header; allow+deny audit-logged. | E6: ST-001..004,ST-053,ST-054 | F6: 6 stories (29 pts) Done-in-code | G6: None | H6: E004
A7: E004 | B7: 2026-09-10 22:58 | C7: S3 | D7: S3 DONE-IN-CODE: notes metrics/permissions/pause/import/notifications (ST-006..010) via FeatureEngine — shared F1–F5 engine: one-screen defaults setup, rule customisation, pause WITHOUT data loss (asserted), competitor-CSV import w/ row-level validation, per-type notification mute, day-trend metrics. Action-item extraction started: base+custom rules, speaker-owner + due-day attribution, preview/test mode (ST-011..014). ST-085 coverage gate SUPERSEDED by D13: threshold set to 100x4, not 70. ST-005 (real Zoom panel surface) code-complete pending live. | E7: ST-005..014,ST-085 | F7: 10 Done-in-code, ST-005 pending live | G7: Zoom panel surface = LC-1 | H7: E005
A8: E005 | B8: 2026-09-10 22:58 | C8: S4 | D8: S4 DONE-IN-CODE: extraction metrics/permissions/pause/import/notifications (ST-016..020). ST-071 activation funnel (install->setup->aha->habit) + /analytics/funnel dashboard; ST-072 error tracking w/ release tags + windowed spike alert. ST-086 E2E smoke suite (install->setup->import->billing->onboarding-aha->deauth-wipe) wired into CI and deploy gate. ST-015 pending live surface. MVP loop usable end-to-end in tests — S4 exit met in-code. | E8: ST-015..020,ST-071,ST-072,ST-086 | F8: 8 Done-in-code, 1 pending live | G8: None | H8: E006
A9: E006 | B9: 2026-09-10 22:58 | C9: S5 | D9: S5 DONE-IN-CODE: CRM field writeback — CrmAdapter interface + HubSpot/Salesforce/Zoho sandbox adapters (LC-6 class), field-level mapping w/ overwrite=false respecting existing CRM values, retrying writeback queue (transient-fail recovery + terminal fail audit + error metric), idempotent re-drain (ST-021..024, 026..030). Onboarding: 4-step first-run checklist to aha <1 day + teaching empty states (ST-078, ST-079). ST-025 pending live. | E9: ST-021..030,ST-078,ST-079 | F9: 11 Done-in-code, 1 pending live | G9: Live CRM sandboxes for LC-6 = Senthil | H9: E007
A10: E007 | B10: 2026-09-10 22:58 | C10: S6 | D10: S6 DONE-IN-CODE: Deal-risk signals — competitor/pricing/sentiment detectors + no-next-step inference, sensitivity-weighted (low/med/high w/ fallback), 0–100 capped score (ST-031..034, 036..040). Billing: 14-day no-card trial w/ countdown banner (ST-057), mid-cycle proration up+down (ST-058), marketplace-vs-Stripe routing (ST-059 — live marketplace verification pending). S6 exit (charge test customer, up/downgrade) met in-code. | E10: ST-031..040,ST-057..059 | F10: 12 Done-in-code, ST-035+059 pending live | G10: Marketplace billing verification = LC-10 | H10: E008
A11: E008 | B11: 2026-09-10 22:58 | C11: S7 | D11: S7 CODEABLE SCOPE DONE-IN-CODE: dunning 7-day grace + 3 emails + read-only (ST-060), plan-limit prompts 80/100% (ST-061), GST/VAT invoices (ST-062), cancellation save-offer + exit survey (ST-063), least-privilege scope map doc (ST-064). Sprint exit (3+ design partners weekly, NPS>30) needs humans — S7 sprint stays open on beta evidence. | E11: ST-060..064 | F11: 5 stories Done-in-code | G11: Design partners = Senthil | H11: E009
A12: E009 | B12: 2026-09-10 22:58 | C12: S8 | D12: S8 DONE-IN-CODE: Indic language pack — Devanagari/Tamil script detection, pack-scoped segmentation w/ clear not-enabled errors, Levenshtein WER benchmark harness for LC-7 (ST-041..044, 046..050). Security: data-flow+retention doc ST-065, admin audit ST-067, backoff+breaker ST-070. Analytics suite ST-073..077 (heatmap, weekly email, health score, CSV export, configurable thresholds). ST-087 p95 budgets + k6 thresholds. ST-082 post-aha review ask (S11 story, shipped early). Pending live: ST-045 surface, ST-088 5x load run (harness written), ST-092 blue/green (workflow written). ST-066 vault/encryption = live infra. | E12: ST-041..050,ST-065..077,ST-082,ST-087..092 | F12: 18 Done-in-code, 3 pending live | G12: Staging infra = Senthil | H12: E010
A13: E010 | B13: 2026-09-10 22:58 | C13: — | D13: D13 TEST GATE MET — 18 Jest suites / 139 automated tests (unit + supertest API integration + E2E smoke; negative paths: bad/short/stale signatures, replay, malformed JSON, OAuth 400/502/500, refresh-loop guard, breaker open/half-open, ragged CSV, seat limits, dunning day-by-day). Coverage 100% statements / 100% branches / 100% functions / 100% lines, ZERO istanbul-ignore pragmas; jest coverageThreshold 100x4 fails any future commit below. Rollup 74/100 stories Done-in-code (292/399 pts). Drafted: listing copy A/B (ST-093), runbook (ST-098). Next sprint S9 (review prep) — mostly live/human items. | E13: D13 | F13: Evidence in Traceability col K | G13: S9 items need Senthil (see RAID) | H13: v009
A14: E011 | B14: 2026-09-11 08:42 | C14: — | D14: TRACKER EXTRACTED TO STANDALONE FILE — Senthil 08:42: create sprint tracker + traceability for MeetSync as a separate document to the TeleField-v001 file pattern (23:48 feedback: v008 embedded the sheets in the product workbook instead of releasing a companion file). This file is now the live tracker; the v008 product workbook remains backlog source of truth; v009 re-baseline of the product workbook stays planned. House style aligned to template (navy title bar, light-blue header rows). | E14: D15 | F14: Tracker lives here from E012 on | G14: None | H14: S9 on "continue"
... A100: E097 | B100: 2026-09-20 12:29 | C100: Handover | D100: WHAT CHANGED FOR SENTHIL. Three P1s are decisions, not credentials: PD-01 (price), PD-02 (build vs rules engine), PD-06 (demand tests). The Zoom dev app (Handover #2) is the right first move again because the PD-05 hold lifts with S13 closed. Two new deployment values (MEETSYNC_MAIL_*, MEETSYNC_CORS_ORIGINS). S15–S17 (110 pts) cannot be sequenced until PD-02; S18 (26 pts) until PD-01. Nothing in this sitting made the product demand-tested: 0 installs is still 0 installs. | E100: Senthil_Handover #36–43, Decisions PD-01…06 | F100: No story impact — planning | G100: PD-01, PD-02, PD-06 | H100: v041 on a PD decision or the Zoom app

Sheet Decisions
A1: DECISIONS (tracker scope)
A2: Portfolio decisions D13/D15 restated for this product; product-local decisions D-M*.
A3: ID | B3: Decision | C3: Rationale | D3: Decided by | E3: Status
A4: D13 | B4: (Portfolio-wide) Discovery interviews parked; dev proceeds with 100% automation test coverage on all code. | C4: Senthil 10 Sep 20:45; applied to MeetSync per 22:58 instruction. | D4: Senthil | E4: LOCKED
A5: D15 | B5: MeetSync (wave-3, Zoom) build opened 10 Sep 22:58 while rank-1 gate unmet; nine concurrent builds now exist. MODE TO RATIFY: (a) parallel builds — supersedes serial rule, or (b) order swap. | C5: R7/R1-class rules require logging any re-ordering; this entry is the log for MeetSync. | D5: Senthil (mode ratification pending) | E5: OPEN — pick (a) or (b)
A6: D-M1 | B6: Stack = TypeScript/Node/Express per v007 ReadMe stack assumption; persistence behind typed Store interface with in-memory impl (no Postgres in sandbox), Postgres adapter at deploy. | C6: Follows workbook; matches accepted precedent across the eight sibling builds. | D6: Claude — flagged | E6: OPEN for ratification
A7: D-M2 | B7: ST-085 (>=70% coverage gate) superseded: gate enforced at 100% x4 with zero pragmas. | C7: D13 supersedes the workbook's pre-D13 quality bar. | D7: Senthil (via D13) | E7: LOCKED
A8: D-M3 | B8: Zoom webhook contract implemented to published pattern (x-zm-signature v0 HMAC + endpoint.url_validation challenge); real payload shapes verified at first live dev-app event. | C8: Verification isolated in src/webhooks.ts — a format change is one-module (R-M5). | D8: Claude — flagged | E8: OPEN — verify at LC-1
A9: PD-01 | B9: Pricing model and number (PR-05, ST-136). Code bills per seat; the pricing page reads as flat — 50x apart at Team. Recommendation on file: per-seat, $12–$18/seat/month, 5-seat minimum. | C9: HubSpot listing rules require the listed price to match the website; the claim gate (test/claims.test.ts) refuses PRICING_PAGE.md without its DECISION PENDING banner until resolved. | D9: Senthil | E9: OPEN — blocks S18 and the listing
A10: PD-02 | B10: Build the intelligence (S15+S16, 71 pts) or reposition as a deterministic rules engine (PR-02). | C10: There is no model, ASR or NLP in the product; the listing copy is HELD (docs/LISTING_COPY.md banner) until this is decided. A rules engine is a real, smaller business; the model path brings eval discipline, cost caps and a trust surface (ST-116…128). | D10: Senthil | E10: OPEN — gates 71 of 248 pts
A11: PD-03 | B11: Enterprise-first or SMB-first (S19). | C11: SMB-first: launch after S18, S19 demand-driven, SOC 2 clock starts on a named deal. Enterprise-first: S19 blocks launch, SOC 2 Type II $35K–$120K over 6–18 months starts now. Recommendation: SMB-first. | D11: Senthil | E11: OPEN — decides whether S19 blocks S20
A12: PD-04 | B12: Keep or cut F4 deal risk (PR-11, ST-124). | C12: 13 English keywords, no evidence span or confidence, cannot fire on Hindi/Tamil. Rebuild inside ST-117 evidence-bearing extraction, or remove from product and pricing table. It is currently a Team-tier differentiator. | D12: Senthil | E12: OPEN — scope of S15/S16 and the pricing matrix
A13: PD-05 | B13: Hold Zoom Marketplace app creation until S13 closes (PR-01, Handover #2). | C13: Installing a takeover-vulnerable app against a real Zoom account converted a fixable defect into a live incident. S13 is CLOSED in code at v045 (ST-101…108, pinned by test/s13.test.ts), so the hold LIFTS: Handover #2 is the right first move again. | D13: Senthil (hold recommended by Claude; lifted by v045) | E13: RESOLVED BY v045 — hold lifted
A14: PD-06 | B14: Run the three demand tests before more feature code (review §4.6): RevOps field test n=5; Hinglish head-to-head n=10 calls; willingness-to-switch n=10 teams. | C14: Each has a kill signal. Any one failing changes the plan. Days, not sprints; none is codeable. | D14: Senthil | E14: OPEN — validates or invalidates the wedge

Sheet S9_Prep_Board
A1: S9 BOARD — Marketplace review prep — exit: review submission accepted into queue
A2: Backlog stories in S9 + live items carried from S1–S8. Edit Status/Notes (yellow).
A3: ID | B3: Item | C3: Story ref | D3: Points | E3: Owner | F3: Status | G3: Notes / Evidence
A4: S9-01 | B4: Zoom dev app created, scopes per docs/SECURITY_SCOPES.md; live install of S1 code | C4: ST-051 live | D4: 3 | E4: Senthil + Claude | F4: To do | G4: LC-1. Evidence: install screenshot + account id + telemetry row.
A5: S9-02 | B5: Verify real webhook payload shapes vs D-M3 assumption | C5: — | D5: 1 | E5: Senthil + Claude | F5: To do | G5: First live event through src/webhooks.ts; adjust one module if format differs (R-M5).
A6: S9-03 | B6: CRM writeback live runs vs HubSpot/SFDC/Zoho sandboxes | C6: LC-6 | D6: 3 | E6: Senthil + Claude | F6: To do | G6: Adapters coded+tested; needs sandbox credentials.
A7: S9-04 | B7: Delete-my-data self-serve endpoint on retention sweep path | C7: ST-069 | D7: 5 | E7: Claude | F7: Done-in-code | G7: Shipped 08:47 — see Traceability ST-069 / tracker E012. Evidence: s9.test.ts.
A8: S9-05 | B8: Pen-test / platform security evidence archived | C8: ST-068 | D8: 5 | E8: Senthil | F8: To do | G8: LC-2 pack: TDD doc, data-flow (done), pen-test summary.
A9: S9-06 | B9: WCAG AA pass on primary flows | C9: ST-089 | D9: 3 | E9: Senthil + Claude | F9: To do | G9: Needs rendered UI on live surface.
A10: S9-07 | B10: Backup+restore drill; chaos test (platform outage degrades gracefully) | C10: ST-090,ST-091 | D10: 5 | E10: Senthil + Claude | F10: To do | G10: Breaker + typed errors coded; platformHealth surface added (ST-091 code side done); drills need staging.
A11: S9-08 | B11: k6 5x load run + blue/green live verification | C11: ST-088,ST-092 | D11: 3 | E11: Senthil + Claude | F11: To do | G11: Harness + workflow shipped in repo; needs staging slots.
A12: S9-09 | B12: Listing copy variant pick (A/B drafted) + 5 screenshots + 2-min video | C12: ST-093,ST-094 | D12: 5 | E12: Senthil | F12: To do | G12: Copy in docs/LISTING_COPY.md; assets need live UI.
A13: S9-10 | B13: Encryption-at-rest/vault verification on deploy infra | C13: ST-066 | D13: 2 | E13: Senthil + Claude | F13: To do | G13: Config/secrets validation coded; vault = infra.

Sheet Traceability_Matrix
A1: TRACEABILITY MATRIX — 151 stories: module -> epic -> story -> screen -> verification -> status (ST-001…100 from v008 workbook; ST-101…151 from Perplexity Review V001, added v040)
A2: Source: v008 product workbook Full_Backlog (single source of truth). Done rows carry code/test evidence per D13. Status: Done-in-code / Code-complete (pending live) / Drafted / Backlog. | L2: Added v016 per Handover #20 and BROUGHT CURRENT at v032 (13 Sep 20:36). It had been eleven sittings stale: every "column L moves on your next pass" note went unactioned, so the column described the product as it was at 11:32 while the code moved to v038.
A3: Story ID | B3: Epic | C3: Module / feature | D3: Story | E3: Points | F3: Priority | G3: Sprint | H3: Primary screen | I3: Verification | J3: Status | K3: Evidence | L3: Customer-reachable (v021) | M3: Reached by / what is missing
A4: ST-001 | B4: F1 | C4: Live notes panel | D4: As a Sales leader, I can set up Live notes panel with sensible defaults in one screen | E4: 5 | F4: P0 | G4: S2 | H4: SCR-3 Live notes workspace | I4: E2E test + demo | J4: Done-in-code | K4: FeatureEngine.setupWithDefaults one-screen + overrides; API test. | L4: REACHABLE | M4: POST /features/:key/setup
A5: ST-002 | B5: F1 | C5: Live notes panel | D5: As a Sales leader, the Live notes panel happy path completes without documentation | E5: 8 | F5: P0 | G5: S2 | H5: SCR-3 Live notes workspace | I5: E2E test + demo | J5: Done-in-code | K5: Core happy path: notes.ts sessions/entries/chips. Module suite + E2E smoke. | L5: REACHABLE | M5: feature route: notes session+entries / actions extract / crm writeback / deal-risk analyse / indic segment
A6: ST-003 | B6: F1 | C6: Live notes panel | D6: As a CS lead, I can customise Live notes panel rules/conditions for my workflow | E6: 5 | F6: P1 | G6: S2 | H6: SCR-3 Live notes workspace | I6: Integration test + manual QA | J6: Done-in-code | K6: addRule customisation + role guard; notes.ts sessions/entries/chips rule tests. | L6: REACHABLE | M6: POST /features/:key/rules (and POST /features/actions/rules for extraction verbs)
A7: ST-004 | B7: F1 | C7: Live notes panel | D7: As a user, Live notes panel shows clear errors and retry paths on platform API failures | E7: 3 | F7: P0 | G7: S2 | H7: SCR-3 Live notes workspace | I7: E2E test + demo | J7: Done-in-code | K7: Typed error paths w/ retry hints (403/409/422/500 mapped); error metric recorded. | L7: REACHABLE | M7: shared error mapper on every feature route: 403/409/422/503 with retry hints
A8: ST-005 | B8: F1 | C8: Live notes panel | D8: As a IT admin, Live notes panel works on the Zoom App in-meeting panel + web dashboard surface end-to-end | E8: 5 | F8: P0 | G8: S3 | H8: SCR-3 Live notes workspace | I8: E2E test + demo | J8: Code-complete (pending live) | K8: UI BUILT+TESTED: web/NotesPanel.tsx in App shell serving in-meeting panel AND web dashboard from one codebase; Zoom Apps SDK behind ZoomSdk boundary (MockZoomSdk in RTL tests, 100x4). Domain logic done since S1-S8. ONLY the live dev-app SDK handshake remains (Handover #2). | L8: PENDING LIVE | M8: needs the Zoom dev app; panel components exist and are RTL-tested (Handover #2)
A9: ST-006 | B9: F1 | C9: Live notes panel | D9: As a CS lead, I can see Live notes panel performance metrics and trends | E9: 3 | F9: P1 | G9: S3 | H9: SCR-3 Live notes workspace | I9: Integration test + manual QA | J9: Done-in-code | K9: engine.metrics events/errors/errorRate + sorted day trend; /features/:key/metrics. | L9: REACHABLE | M9: GET /features/:key/metrics
A10: ST-007 | B10: F1 | C10: Live notes panel | D10: As a user, Live notes panel respects role permissions and audit logging | E10: 3 | F10: P1 | G10: S3 | H10: SCR-3 Live notes workspace | I10: Integration test + manual QA | J10: Done-in-code | K10: RBAC matrix enforced + audit rows (allow and deny). | L10: REACHABLE | M10: RBAC enforced on every route; audit readable at GET /orgs/:id/audit-log
A11: ST-008 | B11: F1 | C11: Live notes panel | D11: As a Sales leader, I can pause/disable Live notes panel without data loss | E11: 2 | F11: P2 | G11: S3 | H11: SCR-3 Live notes workspace | I11: Manual QA | J11: Done-in-code | K11: setEnabled pause keeps records (asserted); resume restores. | L11: REACHABLE | M11: POST /features/:key/pause — data retention on pause is tested
A12: ST-009 | B12: F1 | C12: Live notes panel | D12: As a CS lead, I can import/migrate existing data into Live notes panel (CSV + competitor importer) | E12: 5 | F12: P1 | G12: S3 | H12: SCR-3 Live notes workspace | I12: Integration test + manual QA | J12: Done-in-code | K12: importCsv competitor-format, header/ragged-row validation w/ row numbers. | L12: REACHABLE | M12: POST /features/:key/import (RFC-4180)
A13: ST-010 | B13: F1 | C13: Live notes panel | D13: As a user, I get notifications (in-app + email) for key Live notes panel events with per-type mute | E13: 3 | F13: P2 | G13: S3 | H13: SCR-3 Live notes workspace | I13: Manual QA | J13: Done-in-code | K13: notify in-app+email; per-type mute/unmute. | L13: PARTIAL | M13: in-app half reachable (GET /features/:key/notifications, POST /mute). v021 stopped notify() recording an email row it had never sent; the email half still has no sender
A14: ST-011 | B14: F2 | C14: Action-item extraction | D14: As a Sales leader, I can set up Action-item extraction with sensible defaults in one screen | E14: 5 | F14: P0 | G14: S3 | H14: SCR-4 Extraction builder | I14: E2E test + demo | J14: Done-in-code | K14: FeatureEngine.setupWithDefaults one-screen + overrides; API test. | L14: REACHABLE | M14: POST /features/:key/setup
A15: ST-012 | B15: F2 | C15: Action-item extraction | D15: As a Sales leader, the Action-item extraction happy path completes without documentation | E15: 8 | F15: P0 | G15: S3 | H15: SCR-4 Extraction builder | I15: E2E test + demo | J15: Done-in-code | K15: Core happy path: actions.ts rules+preview mode. Module suite + E2E smoke. | L15: REACHABLE | M15: feature route: notes session+entries / actions extract / crm writeback / deal-risk analyse / indic segment
... A68: ST-065 | B68: E6 | C68: Security & compliance | D68: Data-flow diagram + retention policy published | E68: 3 | F68: P0 | G68: S8 | H68: SCR-6 Settings & team | I68: E2E test + demo | J68: Done-in-code | K68: docs/DATA_FLOW.md — flow + retention/purge/restore, region config. | L68: REACHABLE | M68: docs/DATA_FLOW.md — purge scope and scheduling both corrected (M-F03, GAP-2)
A69: ST-066 | B69: E6 | C69: Security & compliance | D69: Encryption at rest + in transit verified; secrets in vault | E69: 5 | F69: P0 | G69: S8 | H69: SCR-6 Settings & team | I69: E2E test + demo | J69: Backlog | L69: REACHABLE | M69: v031: AES-256-GCM at rest, key outside the database, rotation via MEETSYNC_TOKEN_KEY_PREVIOUS
A70: ST-067 | B70: E6 | C70: Security & compliance | D70: Audit log for admin-sensitive actions | E70: 5 | F70: P1 | G70: S8 | H70: SCR-6 Settings & team | I70: Integration test + manual QA | J70: Done-in-code | K70: Rbac.authorize writes audit rows for admin-sensitive actions incl. denials. | L70: REACHABLE | M70: GET /orgs/:id/audit-log, gated by audit.read — the read path did not exist before v020
A71: ST-068 | B71: E6 | C71: Security & compliance | D71: Pen-test (or platform-required evidence) completed and archived | E71: 8 | F71: P0 | G71: S9 | H71: SCR-6 Settings & team | I71: E2E test + demo | J71: Backlog | L71: NOT REACHABLE | M71: backlog: needs a pen-test vendor (Handover)
A72: ST-069 | B72: E6 | C72: Security & compliance | D72: Data export + delete-my-data self-serve | E72: 5 | F72: P0 | G72: S9 | H72: SCR-6 Settings & team | I72: E2E test + demo | J72: Done-in-code | K72: POST /orgs/:id/delete-my-data — owner-only via RBAC (deny audit-logged), confirm=DELETE guard (422), immediate token wipe, deletionScheduledAt=now so next retentionSweep purges (no 30-day wait); preserves original uninstall facts when already uninstalled. lifecycle.ts deleteMyData + s9.test.ts (8 tests). | L72: REACHABLE | M72: v028 added GET /orgs/:id/export, audit-logged and excluding credentials; delete-my-data already shipped
A73: ST-070 | B73: E6 | C73: Security & compliance | D73: Rate-limit backoff + circuit breaker on platform APIs | E73: 5 | F73: P0 | G73: S8 | H73: SCR-6 Settings & team | I73: E2E test + demo | J73: Done-in-code | K73: src/zoomClient.ts exp backoff + jitter on 429/5xx, circuit breaker w/ half-open probe; 8 tests. | L73: REACHABLE | M73: v029: ZoomClient.download carries the transcript fetch through the shared backoff and breaker
A74: ST-071 | B74: E7 | C74: Telemetry & analytics | D74: Activation funnel events (install->setup->aha->habit) in one dashboard | E74: 5 | F74: P0 | G74: S4 | H74: SCR-8 Analytics | I74: E2E test + demo | J74: Done-in-code | K74: Telemetry funnel install->setup->aha->habit; /analytics/funnel; aha wired from onboarding. | L74: REACHABLE | M74: GET /analytics/funnel (operator token)
A75: ST-072 | B75: E7 | C75: Telemetry & analytics | D75: Error tracking with release tagging; alert on error-rate spike | E75: 3 | F75: P0 | G75: S4 | H75: SCR-8 Analytics | I75: E2E test + demo | J75: Done-in-code | K75: trackError with release tag; errorSpike windowed alert vs configurable threshold. | L75: REACHABLE | M75: v040: alerts are POSTed to an operator-supplied https webhook (MEETSYNC_ALERT_WEBHOOK). At most once, fire-and-forget, not a paging system — limits documented. Alert bodies carry no tenant identity (OpsAlert invariant, pinned by test in v041). Without a URL they remain readable at /analytics/ops
A76: ST-073 | B76: E7 | C76: Telemetry & analytics | D76: Feature-usage heatmap for roadmap decisions | E76: 3 | F76: P2 | G76: S8 | H76: SCR-8 Analytics | I76: Manual QA | J76: Done-in-code | K76: heatmap() hits sorted desc. | L76: REACHABLE | M76: v027: every feature route feeds the heatmap; readable at GET /analytics/ops
A77: ST-074 | B77: E7 | C77: Telemetry & analytics | D77: Weekly automated metrics email to team | E77: 2 | F77: P2 | G77: S8 | H77: SCR-8 Analytics | I77: Manual QA | J77: Done-in-code | K77: weeklyEmail(): funnel + top features + 7d errors; empty-state covered. | L77: PARTIAL | M77: the weekly digest is computed and readable at GET /analytics/ops. The story says EMAIL and no mail sender exists, so the automated part is not done
A78: ST-075 | B78: E7 | C78: Telemetry & analytics | D78: Health score computed per account (usage+billing+support) | E78: 5 | F78: P1 | G78: S8 | H78: SCR-8 Analytics | I78: Integration test + manual QA | J78: Done-in-code | K78: healthScore usage+billing+support blend, capped/floored; 3 boundary tests. | L78: REACHABLE | M78: v042/v043: computed per account from MEASURED inputs — active days from recorded activity, billing from the entitlement. Open tickets have no data source and are excluded; a pre-trial account has no billing signal yet and is excluded from at-risk. maxScore states which components counted. GET /orgs/:id/health, GET /analytics/at-risk
A79: ST-076 | B79: E7 | C79: Telemetry & analytics | D79: Metrics export to CSV/warehouse for founder analysis | E79: 3 | F79: P2 | G79: S8 | H79: SCR-8 Analytics | I79: Manual QA | J79: Done-in-code | K79: /analytics/export.csv one row per account with stage flags. | L79: REACHABLE | M79: GET /analytics/export.csv (operator token), RFC-4180 quoted
A80: ST-077 | B80: E7 | C80: Telemetry & analytics | D80: Alert thresholds configurable (activation drop, error spike, churn signal) | E80: 3 | F80: P2 | G80: S8 | H80: SCR-8 Analytics | I80: Manual QA | J80: Done-in-code | K80: setThresholds partial-merge; churnAlert respects configured score. | L80: REACHABLE | M80: v027: POST /analytics/thresholds, validated
A81: ST-078 | B81: E8 | C81: Onboarding & support | D81: First-run checklist reaches aha-moment in <1 day | E81: 5 | F81: P0 | G81: S5 | H81: SCR-1 / SCR-9 Help | I81: E2E test + demo | J81: Done-in-code | K81: Onboarding 4-step checklist -> aha; withinDay <=24h asserted both sides. | L81: REACHABLE | M81: POST /onboarding/:id/start and /complete; aha feeds the funnel
A82: ST-079 | B82: E8 | C82: Onboarding & support | D82: Empty states teach next action on every screen | E82: 3 | F82: P1 | G82: S5 | H82: SCR-1 / SCR-9 Help | I82: Integration test + manual QA | J82: Done-in-code | K82: EMPTY_STATES teach next action on 5 screens + fallback. | L82: REACHABLE | M82: v022: one source in src/emptyStates.ts, imported by the API and all five panels; tests assert the constant
A83: ST-080 | B83: E8 | C83: Onboarding & support | D83: Help center with 15 launch articles + search | E83: 5 | F83: P1 | G83: S10 | H83: SCR-1 / SCR-9 Help | I83: Integration test + manual QA | J83: Done-in-code | K83: 15 launch articles (getting-started -> troubleshooting) + ranked keyword search (title 3 / keyword 2 / body 1, deterministic tie-break) at /help/*; same content source for hosted help site and in-app panel. helpcenter.ts + s10.test.ts. Hosting/publish at go-live. | L83: REACHABLE | M83: GET /help/articles, /help/articles/:id, /help/search
A84: ST-081 | B84: E8 | C84: Onboarding & support | D84: In-app chat with <4 business-hr first response | E84: 3 | F84: P0 | G84: S10 | H84: SCR-1 / SCR-9 Help | I84: E2E test + demo | J84: Backlog | L84: NOT REACHABLE | M84: backlog: no chat vendor decision
A85: ST-082 | B85: E8 | C85: Onboarding & support | D85: In-app review ask after aha-moment (marketplace rating engine) | E85: 3 | F85: P1 | G85: S11 | H85: SCR-1 / SCR-9 Help | I85: Integration test + manual QA | J85: Done-in-code | K85: maybeAskReview: only after aha, exactly once; wired into /onboarding complete. | L85: REACHABLE | M85: reviewAsk returned by POST /onboarding/:id/complete, once, after aha
A86: ST-083 | B86: E8 | C86: Onboarding & support | D86: Demo video (2 min) + interactive sandbox/demo data mode | E86: 5 | F86: P1 | G86: S10 | H86: SCR-1 / SCR-9 Help | I86: Integration test + manual QA | J86: Code-complete (pending live) | K86: Interactive demo/sandbox HALF SHIPPED: POST /orgs/:id/demo-mode (admin+) seeds notes session, 2 extracted actions, 2 completed sandbox writebacks (demo.ts). 2-min video = live recording (Senthil). | L86: PARTIAL | M86: demo-data mode is reachable at POST /orgs/:id/demo-mode and seeds an isolated demo- workspace; the 2-minute video is not captured
A87: ST-084 | B87: E8 | C87: Onboarding & support | D87: Status page + incident comms template | E87: 2 | F87: P2 | G87: S10 | H87: SCR-1 / SCR-9 Help | I87: Manual QA | J87: Done-in-code | K87: Public /status (JSON) + /status.html: api + zoomPlatform component health (breaker-driven ok/degraded/probing), uptime; incident comms template docs/INCIDENT_COMMS.md. statuspage.ts + tests. | L87: REACHABLE | M87: GET /status and /status.html, public by design
A88: ST-085 | B88: EQ | C88: Quality engineering | D88: Unit+integration test coverage gate ≥70% on core modules | E88: 5 | F88: P0 | G88: S3 | H88: — | I88: E2E test + demo | J88: Done-in-code | K88: SUPERSEDED by D13: gate is 100%x4 (jest coverageThreshold), not >=70%. 18 suites/139 tests, zero pragmas. | L88: REACHABLE | M88: CI runs the 100/100/100/100 gate on every push
A89: ST-086 | B89: EQ | C89: Quality engineering | D89: E2E smoke suite runs on every deploy | E89: 5 | F89: P0 | G89: S4 | H89: — | I89: E2E test + demo | J89: Done-in-code | K89: E2E smoke in app.test.ts runs in CI + deploy workflow before slot swap. | L89: REACHABLE | M89: E2E smoke in the API suite; CI provisions postgres:16
A90: ST-087 | B90: EQ | C90: Quality engineering | D90: p95 latency budgets defined and monitored per surface | E90: 3 | F90: P0 | G90: S8 | H90: — | I90: E2E test + demo | J90: Done-in-code | K90: docs/PERF_BUDGETS.md + k6 thresholds p95<500ms. | L90: REACHABLE | M90: v037/v038: p95 per route pattern against the published budgets, breach alert in the digest. Server handling time only — the 2s UI budget is still unmeasured
A91: ST-088 | B91: EQ | C91: Quality engineering | D91: Load test at 5x expected launch traffic | E91: 5 | F91: P1 | G91: S8 | H91: — | I91: Integration test + manual QA | J91: Code-complete (pending live) | K91: load/k6-smoke.js 5x-launch scenario written; live run needs staging infra (Senthil). | L91: PENDING LIVE | M91: k6 harness exists; never run against a deployment
A92: ST-089 | B92: EQ | C92: Quality engineering | D92: Accessibility WCAG AA pass on primary flows | E92: 3 | F92: P1 | G92: S9 | H92: — | I92: Integration test + manual QA | J92: Backlog | L92: PARTIAL | M92: automated WCAG AA checks pass on every build (v015); contrast, focus, zoom and real screen-reader behaviour need a manual pass
...

Sheet Sprint_Status_Rollup
A1: SPRINT STATUS ROLLUP — live formulas over Traceability_Matrix
A2: Do not edit computed cells. 'Done' counts Done-in-code + Done. Exit criteria from product workbook (S1–S12) and Perplexity Review V001 §7 (S13–S20). Ranges cover rows 4–154 of Traceability_Matrix (v040).
A3: Sprint | B3: Focus | C3: Stories | D3: Points | E3: Done | F3: Done points | G3: % points done | H3: RAG (manual) | I3: Exit criteria
A4: S1 | B4: Foundation (2 wks) | C4: =COUNTIF(Traceability_Matrix!$G$4:$G$154,"S1") | D4: =SUMIF(Traceability_Matrix!$G$4:$G$154,"S1",Traceability_Matrix!$E$4:$E$154) | E4: =COUNTIFS(Traceability_Matrix!$G$4:$G$154,"S1",Traceability_Matrix!$J$4:$J$154,"Done-in-code")+COUNTIFS(Traceability_Matrix!$G$4:$G$154,"S1",Traceability_Matrix!$J$4:$J$154,"Done") | F4: =SUMIFS(Traceability_Matrix!$E$4:$E$154,Traceability_Matrix!$G$4:$G$154,"S1",Traceability_Matrix!$J$4:$J$154,"Done-in-code")+SUMIFS(Traceability_Matrix!$E$4:$E$154,Traceability_Matrix!$G$4:$G$154,"S1",Traceability_Matrix!$J$4:$J$154,"Done") | G4: =IFERROR((SUMIFS(Traceability_Matrix!$E$4:$E$154,Traceability_Matrix!$G$4:$G$154,"S1",Traceability_Matrix!$J$4:$J$154,"Done-in-code")+SUMIFS(Traceability_Matrix!$E$4:$E$154,Traceability_Matrix!$G$4:$G$154,"S1",Traceability_Matrix!$J$4:$J$154,"Done"))/SUMIF(Traceability_Matrix!$G$4:$G$154,"S1",Traceability_Matrix!$E$4:$E$154),0) | H4: GREEN — 4/4 done-in-code; live install pending (LC-1) | I4: App installs cleanly in dev store/org; telemetry firing
A5: S2 | B5: Live notes panel pt 1 | C5: =COUNTIF(Traceability_Matrix!$G$4:$G$154,"S2") | D5: =SUMIF(Traceability_Matrix!$G$4:$G$154,"S2",Traceability_Matrix!$E$4:$E$154) | E5: =COUNTIFS(Traceability_Matrix!$G$4:$G$154,"S2",Traceability_Matrix!$J$4:$J$154,"Done-in-code")+COUNTIFS(Traceability_Matrix!$G$4:$G$154,"S2",Traceability_Matrix!$J$4:$J$154,"Done") | F5: =SUMIFS(Traceability_Matrix!$E$4:$E$154,Traceability_Matrix!$G$4:$G$154,"S2",Traceability_Matrix!$J$4:$J$154,"Done-in-code")+SUMIFS(Traceability_Matrix!$E$4:$E$154,Traceability_Matrix!$G$4:$G$154,"S2",Traceability_Matrix!$J$4:$J$154,"Done") | G5: =IFERROR((SUMIFS(Traceability_Matrix!$E$4:$E$154,Traceability_Matrix!$G$4:$G$154,"S2",Traceability_Matrix!$J$4:$J$154,"Done-in-code")+SUMIFS(Traceability_Matrix!$E$4:$E$154,Traceability_Matrix!$G$4:$G$154,"S2",Traceability_Matrix!$J$4:$J$154,"Done"))/SUMIF(Traceability_Matrix!$G$4:$G$154,"S2",Traceability_Matrix!$E$4:$E$154),0) | H5: GREEN — all done-in-code | I5: Live notes panel happy path demoable
A6: S3 | B6: Notes pt 2 + Extraction start | C6: =COUNTIF(Traceability_Matrix!$G$4:$G$154,"S3") | D6: =SUMIF(Traceability_Matrix!$G$4:$G$154,"S3",Traceability_Matrix!$E$4:$E$154) | E6: =COUNTIFS(Traceability_Matrix!$G$4:$G$154,"S3",Traceability_Matrix!$J$4:$J$154,"Done-in-code")+COUNTIFS(Traceability_Matrix!$G$4:$G$154,"S3",Traceability_Matrix!$J$4:$J$154,"Done") | F6: =SUMIFS(Traceability_Matrix!$E$4:$E$154,Traceability_Matrix!$G$4:$G$154,"S3",Traceability_Matrix!$J$4:$J$154,"Done-in-code")+SUMIFS(Traceability_Matrix!$E$4:$E$154,Traceability_Matrix!$G$4:$G$154,"S3",Traceability_Matrix!$J$4:$J$154,"Done") | G6: =IFERROR((SUMIFS(Traceability_Matrix!$E$4:$E$154,Traceability_Matrix!$G$4:$G$154,"S3",Traceability_Matrix!$J$4:$J$154,"Done-in-code")+SUMIFS(Traceability_Matrix!$E$4:$E$154,Traceability_Matrix!$G$4:$G$154,"S3",Traceability_Matrix!$J$4:$J$154,"Done"))/SUMIF(Traceability_Matrix!$G$4:$G$154,"S3",Traceability_Matrix!$E$4:$E$154),0) | H6: GREEN — surface story pending live | I6: Notes complete with tests; extraction skeleton
A7: S4 | B7: Action-item extraction | C7: =COUNTIF(Traceability_Matrix!$G$4:$G$154,"S4") | D7: =SUMIF(Traceability_Matrix!$G$4:$G$154,"S4",Traceability_Matrix!$E$4:$E$154) | E7: =COUNTIFS(Traceability_Matrix!$G$4:$G$154,"S4",Traceability_Matrix!$J$4:$J$154,"Done-in-code")+COUNTIFS(Traceability_Matrix!$G$4:$G$154,"S4",Traceability_Matrix!$J$4:$J$154,"Done") | F7: =SUMIFS(Traceability_Matrix!$E$4:$E$154,Traceability_Matrix!$G$4:$G$154,"S4",Traceability_Matrix!$J$4:$J$154,"Done-in-code")+SUMIFS(Traceability_Matrix!$E$4:$E$154,Traceability_Matrix!$G$4:$G$154,"S4",Traceability_Matrix!$J$4:$J$154,"Done") | G7: =IFERROR((SUMIFS(Traceability_Matrix!$E$4:$E$154,Traceability_Matrix!$G$4:$G$154,"S4",Traceability_Matrix!$J$4:$J$154,"Done-in-code")+SUMIFS(Traceability_Matrix!$E$4:$E$154,Traceability_Matrix!$G$4:$G$154,"S4",Traceability_Matrix!$J$4:$J$154,"Done"))/SUMIF(Traceability_Matrix!$G$4:$G$154,"S4",Traceability_Matrix!$E$4:$E$154),0) | H7: GREEN — exit met in-code | I7: MVP loop usable end-to-end internally
A8: S5 | B8: CRM writeback + alpha hardening | C8: =COUNTIF(Traceability_Matrix!$G$4:$G$154,"S5") | D8: =SUMIF(Traceability_Matrix!$G$4:$G$154,"S5",Traceability_Matrix!$E$4:$E$154) | E8: =COUNTIFS(Traceability_Matrix!$G$4:$G$154,"S5",Traceability_Matrix!$J$4:$J$154,"Done-in-code")+COUNTIFS(Traceability_Matrix!$G$4:$G$154,"S5",Traceability_Matrix!$J$4:$J$154,"Done") | F8: =SUMIFS(Traceability_Matrix!$E$4:$E$154,Traceability_Matrix!$G$4:$G$154,"S5",Traceability_Matrix!$J$4:$J$154,"Done-in-code")+SUMIFS(Traceability_Matrix!$E$4:$E$154,Traceability_Matrix!$G$4:$G$154,"S5",Traceability_Matrix!$J$4:$J$154,"Done") | G8: =IFERROR((SUMIFS(Traceability_Matrix!$E$4:$E$154,Traceability_Matrix!$G$4:$G$154,"S5",Traceability_Matrix!$J$4:$J$154,"Done-in-code")+SUMIFS(Traceability_Matrix!$E$4:$E$154,Traceability_Matrix!$G$4:$G$154,"S5",Traceability_Matrix!$J$4:$J$154,"Done"))/SUMIF(Traceability_Matrix!$G$4:$G$154,"S5",Traceability_Matrix!$E$4:$E$154),0) | H8: GREEN — live CRM sandboxes pending | I8: Internal alpha: team dogfoods daily
A9: S6 | B9: Billing + Deal-risk signals | C9: =COUNTIF(Traceability_Matrix!$G$4:$G$154,"S6") | D9: =SUMIF(Traceability_Matrix!$G$4:$G$154,"S6",Traceability_Matrix!$E$4:$E$154) | E9: =COUNTIFS(Traceability_Matrix!$G$4:$G$154,"S6",Traceability_Matrix!$J$4:$J$154,"Done-in-code")+COUNTIFS(Traceability_Matrix!$G$4:$G$154,"S6",Traceability_Matrix!$J$4:$J$154,"Done") | F9: =SUMIFS(Traceability_Matrix!$E$4:$E$154,Traceability_Matrix!$G$4:$G$154,"S6",Traceability_Matrix!$J$4:$J$154,"Done-in-code")+SUMIFS(Traceability_Matrix!$E$4:$E$154,Traceability_Matrix!$G$4:$G$154,"S6",Traceability_Matrix!$J$4:$J$154,"Done") | G9: =IFERROR((SUMIFS(Traceability_Matrix!$E$4:$E$154,Traceability_Matrix!$G$4:$G$154,"S6",Traceability_Matrix!$J$4:$J$154,"Done-in-code")+SUMIFS(Traceability_Matrix!$E$4:$E$154,Traceability_Matrix!$G$4:$G$154,"S6",Traceability_Matrix!$J$4:$J$154,"Done"))/SUMIF(Traceability_Matrix!$G$4:$G$154,"S6",Traceability_Matrix!$E$4:$E$154),0) | H9: GREEN — marketplace billing verification pending | I9: Can charge a test customer; up/downgrade paths work
A10: S7 | B10: Private beta (design partners) | C10: =COUNTIF(Traceability_Matrix!$G$4:$G$154,"S7") | D10: =SUMIF(Traceability_Matrix!$G$4:$G$154,"S7",Traceability_Matrix!$E$4:$E$154) | E10: =COUNTIFS(Traceability_Matrix!$G$4:$G$154,"S7",Traceability_Matrix!$J$4:$J$154,"Done-in-code")+COUNTIFS(Traceability_Matrix!$G$4:$G$154,"S7",Traceability_Matrix!$J$4:$J$154,"Done") | F10: =SUMIFS(Traceability_Matrix!$E$4:$E$154,Traceability_Matrix!$G$4:$G$154,"S7",Traceability_Matrix!$J$4:$J$154,"Done-in-code")+SUMIFS(Traceability_Matrix!$E$4:$E$154,Traceability_Matrix!$G$4:$G$154,"S7",Traceability_Matrix!$J$4:$J$154,"Done") | G10: =IFERROR((SUMIFS(Traceability_Matrix!$E$4:$E$154,Traceability_Matrix!$G$4:$G$154,"S7",Traceability_Matrix!$J$4:$J$154,"Done-in-code")+SUMIFS(Traceability_Matrix!$E$4:$E$154,Traceability_Matrix!$G$4:$G$154,"S7",Traceability_Matrix!$J$4:$J$154,"Done"))/SUMIF(Traceability_Matrix!$G$4:$G$154,"S7",Traceability_Matrix!$E$4:$E$154),0) | H10: AMBER — code done; beta humans pending | I10: 3+ partners active weekly; NPS pulse >30
A11: S8 | B11: Beta iteration + Indic pack | C11: =COUNTIF(Traceability_Matrix!$G$4:$G$154,"S8") | D11: =SUMIF(Traceability_Matrix!$G$4:$G$154,"S8",Traceability_Matrix!$E$4:$E$154) | E11: =COUNTIFS(Traceability_Matrix!$G$4:$G$154,"S8",Traceability_Matrix!$J$4:$J$154,"Done-in-code")+COUNTIFS(Traceability_Matrix!$G$4:$G$154,"S8",Traceability_Matrix!$J$4:$J$154,"Done") | F11: =SUMIFS(Traceability_Matrix!$E$4:$E$154,Traceability_Matrix!$G$4:$G$154,"S8",Traceability_Matrix!$J$4:$J$154,"Done-in-code")+SUMIFS(Traceability_Matrix!$E$4:$E$154,Traceability_Matrix!$G$4:$G$154,"S8",Traceability_Matrix!$J$4:$J$154,"Done") | G11: =IFERROR((SUMIFS(Traceability_Matrix!$E$4:$E$154,Traceability_Matrix!$G$4:$G$154,"S8",Traceability_Matrix!$J$4:$J$154,"Done-in-code")+SUMIFS(Traceability_Matrix!$E$4:$E$154,Traceability_Matrix!$G$4:$G$154,"S8",Traceability_Matrix!$J$4:$J$154,"Done"))/SUMIF(Traceability_Matrix!$G$4:$G$154,"S8",Traceability_Matrix!$E$4:$E$154),0) | H11: AMBER — code done; live load/deploy/infra pending | I11: Beta cohort WoW retention >60%
A12: S9 | B12: Marketplace review prep | C12: =COUNTIF(Traceability_Matrix!$G$4:$G$154,"S9") | D12: =SUMIF(Traceability_Matrix!$G$4:$G$154,"S9",Traceability_Matrix!$E$4:$E$154) | E12: =COUNTIFS(Traceability_Matrix!$G$4:$G$154,"S9",Traceability_Matrix!$J$4:$J$154,"Done-in-code")+COUNTIFS(Traceability_Matrix!$G$4:$G$154,"S9",Traceability_Matrix!$J$4:$J$154,"Done") | F12: =SUMIFS(Traceability_Matrix!$E$4:$E$154,Traceability_Matrix!$G$4:$G$154,"S9",Traceability_Matrix!$J$4:$J$154,"Done-in-code")+SUMIFS(Traceability_Matrix!$E$4:$E$154,Traceability_Matrix!$G$4:$G$154,"S9",Traceability_Matrix!$J$4:$J$154,"Done") | G12: =IFERROR((SUMIFS(Traceability_Matrix!$E$4:$E$154,Traceability_Matrix!$G$4:$G$154,"S9",Traceability_Matrix!$J$4:$J$154,"Done-in-code")+SUMIFS(Traceability_Matrix!$E$4:$E$154,Traceability_Matrix!$G$4:$G$154,"S9",Traceability_Matrix!$J$4:$J$154,"Done"))/SUMIF(Traceability_Matrix!$G$4:$G$154,"S9",Traceability_Matrix!$E$4:$E$154),0) | I12: Review submission accepted into queue
A13: S10 | B13: Review remediation + docs | C13: =COUNTIF(Traceability_Matrix!$G$4:$G$154,"S10") | D13: =SUMIF(Traceability_Matrix!$G$4:$G$154,"S10",Traceability_Matrix!$E$4:$E$154) | E13: =COUNTIFS(Traceability_Matrix!$G$4:$G$154,"S10",Traceability_Matrix!$J$4:$J$154,"Done-in-code")+COUNTIFS(Traceability_Matrix!$G$4:$G$154,"S10",Traceability_Matrix!$J$4:$J$154,"Done") | F13: =SUMIFS(Traceability_Matrix!$E$4:$E$154,Traceability_Matrix!$G$4:$G$154,"S10",Traceability_Matrix!$J$4:$J$154,"Done-in-code")+SUMIFS(Traceability_Matrix!$E$4:$E$154,Traceability_Matrix!$G$4:$G$154,"S10",Traceability_Matrix!$J$4:$J$154,"Done") | G13: =IFERROR((SUMIFS(Traceability_Matrix!$E$4:$E$154,Traceability_Matrix!$G$4:$G$154,"S10",Traceability_Matrix!$J$4:$J$154,"Done-in-code")+SUMIFS(Traceability_Matrix!$E$4:$E$154,Traceability_Matrix!$G$4:$G$154,"S10",Traceability_Matrix!$J$4:$J$154,"Done"))/SUMIF(Traceability_Matrix!$G$4:$G$154,"S10",Traceability_Matrix!$E$4:$E$154),0) | I13: Marketplace approval obtained
A14: S11 | B14: Launch | C14: =COUNTIF(Traceability_Matrix!$G$4:$G$154,"S11") | D14: =SUMIF(Traceability_Matrix!$G$4:$G$154,"S11",Traceability_Matrix!$E$4:$E$154) | E14: =COUNTIFS(Traceability_Matrix!$G$4:$G$154,"S11",Traceability_Matrix!$J$4:$J$154,"Done-in-code")+COUNTIFS(Traceability_Matrix!$G$4:$G$154,"S11",Traceability_Matrix!$J$4:$J$154,"Done") | F14: =SUMIFS(Traceability_Matrix!$E$4:$E$154,Traceability_Matrix!$G$4:$G$154,"S11",Traceability_Matrix!$J$4:$J$154,"Done-in-code")+SUMIFS(Traceability_Matrix!$E$4:$E$154,Traceability_Matrix!$G$4:$G$154,"S11",Traceability_Matrix!$J$4:$J$154,"Done") | G14: =IFERROR((SUMIFS(Traceability_Matrix!$E$4:$E$154,Traceability_Matrix!$G$4:$G$154,"S11",Traceability_Matrix!$J$4:$J$154,"Done-in-code")+SUMIFS(Traceability_Matrix!$E$4:$E$154,Traceability_Matrix!$G$4:$G$154,"S11",Traceability_Matrix!$J$4:$J$154,"Done"))/SUMIF(Traceability_Matrix!$G$4:$G$154,"S11",Traceability_Matrix!$E$4:$E$154),0) | I14: First 10 installs; first 3 reviews; activation >40%
A15: S12 | B15: Iterate & scale decision | C15: =COUNTIF(Traceability_Matrix!$G$4:$G$154,"S12") | D15: =SUMIF(Traceability_Matrix!$G$4:$G$154,"S12",Traceability_Matrix!$E$4:$E$154) | E15: =COUNTIFS(Traceability_Matrix!$G$4:$G$154,"S12",Traceability_Matrix!$J$4:$J$154,"Done-in-code")+COUNTIFS(Traceability_Matrix!$G$4:$G$154,"S12",Traceability_Matrix!$J$4:$J$154,"Done") | F15: =SUMIFS(Traceability_Matrix!$E$4:$E$154,Traceability_Matrix!$G$4:$G$154,"S12",Traceability_Matrix!$J$4:$J$154,"Done-in-code")+SUMIFS(Traceability_Matrix!$E$4:$E$154,Traceability_Matrix!$G$4:$G$154,"S12",Traceability_Matrix!$J$4:$J$154,"Done") | G15: =IFERROR((SUMIFS(Traceability_Matrix!$E$4:$E$154,Traceability_Matrix!$G$4:$G$154,"S12",Traceability_Matrix!$J$4:$J$154,"Done-in-code")+SUMIFS(Traceability_Matrix!$E$4:$E$154,Traceability_Matrix!$G$4:$G$154,"S12",Traceability_Matrix!$J$4:$J$154,"Done"))/SUMIF(Traceability_Matrix!$G$4:$G$154,"S12",Traceability_Matrix!$E$4:$E$154),0) | I15: Growth model doc with CAC/LTV first estimates
A16: S13 | B16: Trust & tenancy hardening (BLOCKING) | C16: =COUNTIF(Traceability_Matrix!$G$4:$G$154,"S13") | D16: =SUMIF(Traceability_Matrix!$G$4:$G$154,"S13",Traceability_Matrix!$E$4:$E$154) | E16: =COUNTIFS(Traceability_Matrix!$G$4:$G$154,"S13",Traceability_Matrix!$J$4:$J$154,"Done-in-code")+COUNTIFS(Traceability_Matrix!$G$4:$G$154,"S13",Traceability_Matrix!$J$4:$J$154,"Done") | F16: =SUMIFS(Traceability_Matrix!$E$4:$E$154,Traceability_Matrix!$G$4:$G$154,"S13",Traceability_Matrix!$J$4:$J$154,"Done-in-code")+SUMIFS(Traceability_Matrix!$E$4:$E$154,Traceability_Matrix!$G$4:$G$154,"S13",Traceability_Matrix!$J$4:$J$154,"Done") | G16: =IFERROR((SUMIFS(Traceability_Matrix!$E$4:$E$154,Traceability_Matrix!$G$4:$G$154,"S13",Traceability_Matrix!$J$4:$J$154,"Done-in-code")+SUMIFS(Traceability_Matrix!$E$4:$E$154,Traceability_Matrix!$G$4:$G$154,"S13",Traceability_Matrix!$J$4:$J$154,"Done"))/SUMIF(Traceability_Matrix!$G$4:$G$154,"S13",Traceability_Matrix!$E$4:$E$154),0) | H16: GREEN — 8/8 done-in-code at v045; PR-01/06/07/08/10 pinned | I16: Caller cannot install onto a workspace it does not own; every trust-page claim maps to code
A17: S14 | B17: Close the product loop | C17: =COUNTIF(Traceability_Matrix!$G$4:$G$154,"S14") | D17: =SUMIF(Traceability_Matrix!$G$4:$G$154,"S14",Traceability_Matrix!$E$4:$E$154) | E17: =COUNTIFS(Traceability_Matrix!$G$4:$G$154,"S14",Traceability_Matrix!$J$4:$J$154,"Done-in-code")+COUNTIFS(Traceability_Matrix!$G$4:$G$154,"S14",Traceability_Matrix!$J$4:$J$154,"Done") | F17: =SUMIFS(Traceability_Matrix!$E$4:$E$154,Traceability_Matrix!$G$4:$G$154,"S14",Traceability_Matrix!$J$4:$J$154,"Done-in-code")+SUMIFS(Traceability_Matrix!$E$4:$E$154,Traceability_Matrix!$G$4:$G$154,"S14",Traceability_Matrix!$J$4:$J$154,"Done") | G17: =IFERROR((SUMIFS(Traceability_Matrix!$E$4:$E$154,Traceability_Matrix!$G$4:$G$154,"S14",Traceability_Matrix!$J$4:$J$154,"Done-in-code")+SUMIFS(Traceability_Matrix!$E$4:$E$154,Traceability_Matrix!$G$4:$G$154,"S14",Traceability_Matrix!$J$4:$J$154,"Done"))/SUMIF(Traceability_Matrix!$G$4:$G$154,"S14",Traceability_Matrix!$E$4:$E$154),0) | H17: GREEN — 7/7 done-in-code; live webhook half pending S9-01; mail transport config = Senthil | I17: Signed webhook → extract → staged → panel renders from API → approve → CRM audit row
A18: S15 | B18: Real intelligence + evaluation | C18: =COUNTIF(Traceability_Matrix!$G$4:$G$154,"S15") | D18: =SUMIF(Traceability_Matrix!$G$4:$G$154,"S15",Traceability_Matrix!$E$4:$E$154) | E18: =COUNTIFS(Traceability_Matrix!$G$4:$G$154,"S15",Traceability_Matrix!$J$4:$J$154,"Done-in-code")+COUNTIFS(Traceability_Matrix!$G$4:$G$154,"S15",Traceability_Matrix!$J$4:$J$154,"Done") | F18: =SUMIFS(Traceability_Matrix!$E$4:$E$154,Traceability_Matrix!$G$4:$G$154,"S15",Traceability_Matrix!$J$4:$J$154,"Done-in-code")+SUMIFS(Traceability_Matrix!$E$4:$E$154,Traceability_Matrix!$G$4:$G$154,"S15",Traceability_Matrix!$J$4:$J$154,"Done") | G18: =IFERROR((SUMIFS(Traceability_Matrix!$E$4:$E$154,Traceability_Matrix!$G$4:$G$154,"S15",Traceability_Matrix!$J$4:$J$154,"Done-in-code")+SUMIFS(Traceability_Matrix!$E$4:$E$154,Traceability_Matrix!$G$4:$G$154,"S15",Traceability_Matrix!$J$4:$J$154,"Done"))/SUMIF(Traceability_Matrix!$G$4:$G$154,"S15",Traceability_Matrix!$E$4:$E$154),0) | H18: RED — 0/8; gated by PD-02 | I18: Golden set ≥100 with per-field P/R, CI floor, cost cap, no-model fallback
A19: S16 | B19: Indic wedge, proven | C19: =COUNTIF(Traceability_Matrix!$G$4:$G$154,"S16") | D19: =SUMIF(Traceability_Matrix!$G$4:$G$154,"S16",Traceability_Matrix!$E$4:$E$154) | E19: =COUNTIFS(Traceability_Matrix!$G$4:$G$154,"S16",Traceability_Matrix!$J$4:$J$154,"Done-in-code")+COUNTIFS(Traceability_Matrix!$G$4:$G$154,"S16",Traceability_Matrix!$J$4:$J$154,"Done") | F19: =SUMIFS(Traceability_Matrix!$E$4:$E$154,Traceability_Matrix!$G$4:$G$154,"S16",Traceability_Matrix!$J$4:$J$154,"Done-in-code")+SUMIFS(Traceability_Matrix!$E$4:$E$154,Traceability_Matrix!$G$4:$G$154,"S16",Traceability_Matrix!$J$4:$J$154,"Done") | G19: =IFERROR((SUMIFS(Traceability_Matrix!$E$4:$E$154,Traceability_Matrix!$G$4:$G$154,"S16",Traceability_Matrix!$J$4:$J$154,"Done-in-code")+SUMIFS(Traceability_Matrix!$E$4:$E$154,Traceability_Matrix!$G$4:$G$154,"S16",Traceability_Matrix!$J$4:$J$154,"Done"))/SUMIF(Traceability_Matrix!$G$4:$G$154,"S16",Traceability_Matrix!$E$4:$E$154),0) | H19: RED — 0/5; gated by PD-02/PD-04 + corpus | I19: Published WER + field accuracy vs Zoom on ≥50 real calls
