Workbook

Sheet 00_Cover
A1: MeetSync — Version Detail & Manual Test Specification
A3: Product | B3: MeetSync — in-meeting notes, action extraction and CRM auto-sync for the Zoom App Marketplace
A4: Portfolio reference | B4: 003-MoPr12-meetsync_zoom (portfolio rank: wave 3)
A5: Document | B5: claude_V001_MoPr12-meetsync_zoom_versiondetail_manualtest
A6: Document version | B6: V001 — first issue
A7: Date / time issued | B7: 2026-09-20 12:29 BST
A8: Author | B8: Claude for Senthil/KP
A9: Owner / approver | B9: Senthil (KP)
A10: Describes code version | B10: MeetSync v0.45.0 (released 2026-09-20 12:29)
A11: Companion artefacts | B11: claude_v040_meetsync_sprint_tracker_traceability_20260920_1229.xlsx (sprint tracker & traceability) claude_V001_MoPr12-meetsync_zoom_product_status_map_20260920_1229.html / .pdf / .png (pictorial status map) claude_v045_meetsync_external_review_s13_s14_20260920_1229.zip (source)
A12: Status | B12: Released
A13: Classification | B13: Internal — build, release and test evidence
A14: Retention | B14: Keep for the life of the product; superseded versions retained for audit
... A19: HEADLINE STATE | B19: 38 code releases. 712 automated tests at 100% statements, branches, functions and lines with zero coverage pragmas. Three standing build gates. Zero live installs, zero paying customers, zero real CRM writes.

Sheet 01_Document_Control
A1: DOCUMENT CONTROL — revision history of THIS document
A2: HOW TO USE THIS SHEET — This sheet versions the document, not the product. The product versions are in 05_Version_Detail. Add a row for every reissue; never overwrite a released row.
A3: Doc version | B3: Date / time | C3: Author | D3: Change description | E3: Reviewed by | F3: Status
A4: V001 | B4: 2026-09-20 12:29 | C4: Claude for Senthil/KP | D4: First issue. Covers MeetSync code v0.08.0 to v0.45.0 (38 releases), nine pending releases with their blockers, ordered execution steps per release, and 177 manual test cases across 19 areas with positive and negative coverage. Sources: README.md version paragraphs authored at each release, sprint tracker v040 (Version_Control, Sprint_Tracker_Log, Review_Findings), docs/PERSISTENCE.md, and Perplexity Review V001 of 16 Sep 2026. | E4: Pending — Senthil | F4: Released
A5: V002 | D5: PLANNED: reissue after the first live Zoom install, when the PENDING LIVE test cases (TC-INS-001, TC-WHK-005, TC-UI-001, TC-UI-006 and the rest) can be executed for the first time and their Actual result columns filled in. | F5: Planned

Sheet 02_Context_Scope
A1: CONTEXT AND SCOPE
A2: HOW TO USE THIS SHEET — Read this before anything else. It states what the product is, what this document covers, what it deliberately does not cover, and where every fact in it came from.
A3: # | B3: Section | C3: Content
A4: 1 | B4: The product | C4: MeetSync is a Zoom App Marketplace application for sales teams. A meeting ends; Zoom produces a transcript; MeetSync reads it, extracts the commitments and risk signals, and writes agreed fields into the customer's CRM — under per-field rules the customer sets, with a human review step, a queue that survives a crash, and an audit row for every write. Built in TypeScript on Node and Express with a React panel that serves both the Zoom in-meeting surface and a web dashboard from one codebase.
A5: 2 | B5: The wedge | C5: Notes and action items are now free inside Zoom itself. The defensible part of MeetSync is not transcription — it is governed CRM writeback (per-field overwrite policy, dry-run, review step, durable queue, audit trail) and, if it is ever built, measurably better handling of Hindi, Tamil and Hinglish sales calls. That is the argument the 16 Sep external review made and it is accepted here.
A6: 3 | B6: Scope of this document | C6: Every MeetSync CODE release from v0.08.0 to v0.45.0: what was done, why, in what order, with what evidence. Every PENDING release with the specific thing blocking it. A manual test specification of 177 cases, positive and negative, executable by hand.
A7: 4 | B7: Out of scope | C7: Sprint and story management (see the sprint tracker v040: Traceability_Matrix, Sprint_Status_Rollup, S13_S20_Board). Commercial and market analysis (see Perplexity Review V001 sections 4 and 8). Automated test implementation (see the repository test/ directory). Infrastructure and deployment topology (see docs/RUNBOOK.md).
A8: 5 | B8: Relationship to automation | C8: 712 automated tests already run on every build at a 100% threshold across statements, branches, functions and lines. The manual cases here exist for what automation cannot reach: behaviour against the real Zoom platform, a real CRM tenant, a real browser inside the Zoom client, a real screen reader, and colour contrast — none of which jsdom or a sandbox adapter can judge. Where an automated test pins the same behaviour it is named, so a manual failure can be checked against it.
A9: 6 | B9: Test environment assumed | C9: A deployed MeetSync instance with PostgreSQL 16, the required secrets set, and — for the cases marked PENDING LIVE — a Zoom Marketplace application installed on a real Zoom account. Cases that need a second Zoom account, a CRM sandbox or a controllable Zoom double say so in their preconditions.
A10: 7 | B10: Sources | C10: README.md version paragraphs, written at the time of each release. Sprint tracker v040: Version_Control (41 rows), Sprint_Tracker_Log (E001–E097), Review_Findings (M-F, VER-M, OBS-M, SR, PR). docs/PERSISTENCE.md, docs/RUNBOOK.md, docs/THREAT_MODEL.md, docs/DATA_FLOW.md. Perplexity Review V001, 16 Sep 2026. The source archive claude_v045_meetsync_external_review_s13_s14.
A11: 8 | B11: A note on honesty | C11: Several test cases in 08_Test_Cases are marked EXPECTED TO FIND NOTHING — TC-ACT-004, TC-RSK-003, TC-RSK-004, TC-IND-004, TC-BIL-011. They document gaps deliberately, so that the absence is repeatable and visible rather than discovered by a customer. Do not raise them as defects; they are evidence for the decisions in 06_Pending_Versions.

Sheet 03_How_To_Use
A1: HOW TO USE THIS WORKBOOK — sheet by sheet
A2: HOW TO USE THIS SHEET — Every sheet also carries its own one-line instruction in row 2. Yellow cells are the ones a tester fills in; everything else is a record and should not be edited in place.
A3: Sheet | B3: What it holds | C3: Who uses it | D3: How to use it
A4: 00_Cover | B4: Identity of the document and the headline state of the product. | C4: Everyone | D4: Read first. Check you have the right document version and the right code version.
A5: 01_Document_Control | B5: Revision history of this workbook. | C5: Author, auditor | D5: Add a row on every reissue. Never overwrite a released row.
A6: 02_Context_Scope | B6: What the product is, what is covered, what is not, and every source. | C6: Everyone | D6: Read before drawing conclusions from any other sheet.
A7: 03_How_To_Use | B7: This sheet. | C7: Everyone | D7: Navigation.
A8: 04_Glossary | B8: Every prefix and abbreviation used across the artefacts. | C8: New readers | D8: Look up ST-, PR-, M-F, LC-, PD-, SR-, GAP- and the gate names.
A9: 05_Version_Detail | B9: Each of the 38 released code versions: what was done, why it was done, what it closed, the gate result. | C9: Senthil, auditor | D9: Read top to bottom for the arc, or filter the Type column to see just the review-driven releases. The Why column is the one that matters — every release has a trigger.
A10: 06_Pending_Versions | B10: Nine pending releases, each with the specific thing blocking it and who owns that thing. | C10: Senthil | D10: This is the decision sheet. Four of the nine are blocked on a decision only you can make; one is blocked on credentials; the rest queue behind those.
A11: 07_Version_Steps | B11: The ordered steps executed within each release. | C11: Auditor, engineer | D11: Filter by Version to reconstruct a release. Steps are in execution order with the artefact each produced.
A12: 08_Test_Cases | B12: 177 manual test cases with preconditions, numbered steps and expected results. | C12: Tester | D12: Filter by Priority for a risk-based pass, or by Area for a feature pass, or by Version to regression-test one release. Fill the yellow columns: Actual result, Status, Tester, Date, Defect ref. Do not edit the white columns.
A13: 09_Test_Summary | B13: Live counts by area, type, priority and execution status. | C13: Test lead | D13: Do not edit — every cell is a formula over 08_Test_Cases. It updates as the tester fills in the Status column.
A14: 10_Traceability | B14: Requirement or finding, to the version that addressed it, to the test cases that cover it. | C14: Auditor, reviewer | D14: Use to answer "how do we know X works?" — read across from the reference to the test case ids.
... A16: 12_Sign_Off | B16: Approval of this document and of the test pass. | C16: Senthil | D16: Sign the rows that apply. An unsigned test pass is not a test pass.

Sheet 04_Glossary
A1: GLOSSARY AND ABBREVIATIONS
A2: HOW TO USE THIS SHEET — Every prefix used in this workbook and in the sprint tracker. If a reference appears anywhere and is not here, it is an error — say so.
A3: Term | B3: Meaning
A4: ST-nnn | B4: Story id. ST-001 to ST-100 come from the v007 product workbook backlog; ST-101 to ST-151 were added by Perplexity Review V001.
A5: M-Fnn | B5: Finding from the v0.13.0 adversarial cold review (21 findings across two passes over all 20 modules).
A6: VER-Mnn | B6: Finding from the v0.14.0 external verification sweep — code checked against Zoom's published documentation rather than against itself.
A7: OBS-Mn | B7: Observation raised during the cold review that needed a decision rather than a fix.
A8: GAP-n | B8: Finding from asking what calls what, rather than from reading modules. GAP-3 is the big one: 78 stories marked done for code a customer could not invoke.
A9: SR-nn | B9: Self-review finding — a defect found in the previous sitting's own work by the standing review step introduced at v0.32.0.
A10: A11Y-nn | B10: Accessibility finding, including four that axe passed and a human did not.
A11: PR-nn | B11: Finding from Perplexity Review V001, the first review conducted from outside the repository (16 Sep 2026). PR-01 to PR-14.
A12: PD-nn | B12: Decision owed by Senthil, raised by Perplexity Review V001. PD-01 to PD-06.
A13: LC-n | B13: Launch checklist item from the product workbook.
A14: G-nn | B14: Portfolio completion gate. G-02 — ten paying installs from strangers — is the one that matters.
... A24: PENDING LIVE | B24: A test case that cannot be executed until a real Zoom Marketplace app exists and a real account installs it.

Sheet 05_Version_Detail
A1: VERSION DETAIL — every released code version: what was done and why
A2: HOW TO USE THIS SHEET — One row per released code version, oldest first. The "Why it was done" column carries the trigger — no release here was undertaken because it seemed like a good idea. Filter Type to isolate the review-driven releases.
A3: Code version | B3: Released | C3: Type | D3: Headline | E3: What was done | F3: Why it was done (the trigger) | G3: Findings / stories closed | H3: Gate result | I3: Status
A4: v0.08.0 | B4: 2026-09-10 22:58 | C4: Build | D4: S1–S8 foundation through Indic pack — the whole feature set, built | E4: TypeScript/Node/Express foundation: config with region validation; typed Store layer; Zoom OAuth exchange and rotation-persisting refresh; ZoomClient with 429/5xx backoff, jitter and a circuit breaker; webhook verification (x-zm-signature HMAC + endpoint.url_validation challenge + replay guard + dedupe); install/uninstall lifecycle with token wipe and retention schedule; RBAC owner/admin/member matrix with audit log; the shared feature engine powering F1–F5; live notes, action extraction, CRM adapters with a retrying queue, deal-risk scoring, the Indic WER harness; billing with trial, plans, proration, dunning and seat limits; telemetry funnel; onboarding checklist; CSV import. | F4: Senthil opened the build at 22:58 on 10 Sep with the instruction to execute per sprint from the v007 product workbook with 100% automation coverage. D13 (discovery parked, dev proceeds at 100% coverage) applied portfolio-wide. | G4: S1–S8 · 74 stories | H4: 18 suites / 139 tests · 100x4 | I4: Superseded
A5: v0.09.0 | B5: 2026-09-11 08:47 | C5: Build | D5: S9 codeable scope — self-serve deletion and observable degradation | E5: ST-069 delete-my-data shipped: owner-only POST /orgs/:id/delete-my-data with explicit DELETE confirmation, immediate token wipe and a purge due at the next sweep rather than after the retention window; allow and deny both audit-logged. ST-091 made platform degradation observable: ZoomClient.platformHealth() reports ok/degraded/probing and /orgs/:id/status surfaces it, so a breaker-open state shows as degraded instead of erroring. | F5: S9 was the next sprint and two of its stories could be executed without a live Zoom app. A published deletion policy that a customer cannot invoke is a policy in name only. | G5: ST-069, ST-091 | H5: 19 suites / 149 tests · 100x4 | I5: Superseded
A6: v0.10.0 | B6: 2026-09-11 13:32 | C6: Build | D6: S10 codeable scope — help centre, status page, pricing, demo mode | E6: ST-080 help centre: 15 launch articles from install to troubleshooting with ranked keyword search (title > keyword > body, deterministic tie-break) served from the same source as the hosted site. ST-084 public status page as JSON and HTML with component health and uptime, plus an incident comms template. ST-095 pricing endpoint served from the same PLANS object the billing engine enforces, so the published matrix cannot drift from what is charged. ST-083 demo-data mode: an admin seeds an isolated demo workspace with a notes session, extracted actions and completed sandbox writebacks. | F6: Same reason as v0.09.0 — take the S10 stories that need no live platform. Pricing was bound to PLANS deliberately: a pricing page that is a separate document is a pricing page that will disagree with the invoice. | G6: ST-080, ST-083 (code half), ST-084, ST-095, ST-096 (draft) | H6: 20 suites / 160 tests · 100x4 | I6: Superseded
A7: v0.11.0 | B7: 2026-09-11 15:26 | C7: Build | D7: Codeable runway closed — launch runbook and SEO groundwork | E7: ST-098 launch-day runbook finalised at v1.0 over the surfaces that actually ship: monitoring table, rollback under two minutes, comms tree. ST-099 groundwork: help-search terms are captured and exposed at /analytics/search-terms so post-launch listing SEO has real data rather than guesses. | F7: Everything remaining in S9–S12 needed either a live Zoom app, a deployment, or a human. This release drew that line explicitly rather than inventing work that looked like progress. | G7: ST-098, ST-099 (groundwork) | H7: 20 suites / 162 tests · 100x4 | I7: Superseded
A8: v0.12.0 | B8: 2026-09-11 22:09 | C8: Build | D8: Web surface — one React codebase for the panel and the dashboard | E8: Five panel components (Notes, Action items, CRM sync, Deal risk, Languages) plus the shell, serving both the Zoom in-meeting panel and the web dashboard from one codebase; Zoom Apps SDK behind a ZoomSdk boundary with a MockZoomSdk for tests; a typed Api client; RTL suite at the same 100x4 gate. | F8: The backlog carried five surface stories (ST-005/015/025/035/045) that had no UI at all. Building them against a mocked SDK was the only way to execute them without a Marketplace app. | G8: ST-005, ST-015, ST-025, ST-035, ST-045 | H8: 21 suites / 171 tests · 100x4 | I8: Superseded
A9: v0.13.0 | B9: 2026-09-13 09:52 | C9: Review fix | D9: Adversarial cold review — 21 defects, four of them blocking | E9: v013 cold review (passes 1+2, all 20 modules): 21 defects fixed with pinned regressions. Headlines — identity is an HMAC-signed session minted server-side, never the caller's own `x-role` header (src/auth.ts); tenant state is allocated per account (src/tenancy.ts) instead of one process-wide engine; deletion clears every registered holder of the account's data, not just its row; the billing entitlement the trial and dunning engines maintain is now actually enforced on mutating routes; operator analytics require MEETSYNC_OPERATOR_TOKEN; every in-memory ledger is FIFO-capped (src/ledger.ts). See the tracker's Review_Findings sheet for the full list and the three observations left open for disposition. | F9: A deliberate adversarial review of all 20 modules, run because the build had been fast and nothing had yet challenged it. It found that identity was taken from a request header the browser sets, that tenant state was one process-wide singleton, and that an account could stop paying and keep writing. | G9: M-F01 … M-F21 | H9: 22 suites / 225 tests · 100x4 | I9: Superseded
A10: v0.14.0 | B10: 2026-09-13 10:25 | C10: Review fix | D10: External verification sweep — the Zoom contract was wrong in four places | E10: v014 external verification sweep (against live Zoom platform docs, 13 Sep): 7 findings, 4 of them live-blocking and invisible to the test suite because the tests asserted our own wrong shape back to us. The OAuth token endpoint authenticates the client with an HTTP Basic header, not client_id/client_secret in the body, and requires redirect_uri on the code exchange — both install and refresh would have been rejected on the first live call. The Zoom Apps SDK boundary was built around an API that does not exist: config() was never called, getMeetingContext() does not return account/role/user, and running context is a separate call. Scope map corrected from classic to granular scopes (a newly created app cannot select the classic names at all). | F10: Every prior test asserted MeetSync's own shape back to itself. This sweep checked the code against Zoom's published documentation instead, and found that the OAuth exchange, the refresh, the SDK boundary and the scope list would all have failed on the first live call. | G10: VER-M01 … VER-M07 | H10: 22 suites / 239 tests · 100x4 | I10: Superseded
A11: v0.15.0 | B11: 2026-09-13 10:36 | C11: Review fix | D11: Two claims the artefacts made that the code did not back | E11: v015 closes two claims the artifacts made that the code did not back. (1) WCAG AA has been asserted as an NFR since 5 Sep and had never been audited on this product; web/a11y.test.tsx now audits every panel and the shell against wcag2a/2aa/21a/21aa on each render state. axe reported zero violations even on its full ruleset — and reading the markup still found four real failures it structurally cannot see, the worst being a status button whose aria-label REPLACED the visible state text, so the one thing the control existed to convey was hidden from assistive tech. Colour contrast cannot be judged under jsdom and remains an open manual check. (2) Trial-to-paid, MRR, ARPU and logo churn had targets set against them and nothing computing them; Billing.revenueMetrics and /analytics/revenue (operator-gated) close that. | F11: The product spec had asserted WCAG AA since 5 Sep with no audit ever run, and the revenue targets in Metrics_Targets had nothing computing them. Both were claims, not features. | G11: ST-089 (partial), ST-076, A11Y-01…04 | H11: 23 suites / 253 tests · 100x4 | I11: Superseded
A12: v0.16.0 | B12: 2026-09-13 10:43 | C12: Hardening | D12: Durability, slice one — the account row reaches PostgreSQL | E12: v016 closes OBS-M3, the largest gap between the artifacts and the code: the Store interface is now async with a real PostgresStore alongside InMemoryStore, both held to one shared contract suite that runs every case twice and is NOT skipped when a database is absent. CI provisions postgres:16. | F12: OBS-M3: every guarantee the product published — token wipe on uninstall, the retention purge, delete-my-data, the billing entitlement — was true only until the process restarted. | G12: OBS-M3 (partial) | H12: 23 suites / 281 tests · 100x4 | I12: Superseded
A13: v0.17.0 | B13: 2026-09-13 10:56 | C13: Hardening | D13: Durability, slice two — subscriptions | E13: v017 and v018 add the second and third durable slices: subscriptions and the RBAC audit log, each behind the same two-implementation contract. Read docs/PERSISTENCE.md before describing MeetSync as durable — tenant feature state and the CRM writeback queue are still process-local, which also means the app cannot yet run more than one instance. | F13: A restart reverted every account to no_subscription, which un-gated every paid feature and zeroed the revenue metrics — the one piece of lost state that silently falsifies a business number rather than merely losing history. | G13: OBS-M3 (partial) | H13: 23 suites / 301 tests · 100x4 | I13: Superseded
A14: v0.18.0 | B14: 2026-09-13 11:03 | C14: Hardening | D14: Durability, slice three — the RBAC audit log | E14: The audit log moved behind an AuditStore with in-memory and PostgreSQL implementations run through one contract suite. The data.delete rows are retained through a purge as proof of erasure while everything else for that account goes. | F14: The audit log holds the proof that a deletion actually happened. An erasure record that evaporates on restart is worse than no record at all, because its absence is indistinguishable from the deletion never having been performed. | G14: OBS-M3 (partial), ST-067 | H14: 23 suites / 316 tests · 100x4 | I14: Superseded
... A41: v0.45.0 | B41: 2026-09-20 12:29 | C41: External-review response | D41: S13 closed in full, S14 closed in code — the first review from outside the repository | E41: v045 is the response to the first review that did not come from inside this repository. The 16 Sep external review (Perplexity, `perplexity_review_V001`) read the code and then checked what the artefacts around it claimed, and found fourteen things (PR-01 … PR-14), three of them CRITICAL. Its diagnosis of the review programme was fair: every pass from v013 to v044 asked "is this module correct?" or "what calls this?", questions answerable from inside the repository, and the findings clustered exactly where those questions cannot reach. This release closes sprint S13 (trust and tenancy) in full and S14 (the product loop) in code, and takes the process lesson as a standing gate rather than a paragraph. The one that matters most: PR-01. `/oauth/start` took the workspace id from the caller's query string and the callback installed whatever Zoom login completed OAuth onto that id, minting an owner session for it. The signature on `state` proved the server issued the state; it could not prove the caller owned the account, and every test asserted the account it supplied came back — the suite asserted the vulnerability as intended behaviour, the VER-M01 shape again. Tenant identity now comes from Zoom's `GET /users/me` with the token Zoom just issued; the query string is an attribution hint that is refused with a 403 and an audit row when it disagrees, and `installAccount` re-checks the invariant so the store is the last place the class can be stopped. The rule is written down in `docs/THREAT_MODEL.md` as the first standing rule. The session also names a real Zoom user and role now (PR-08) rather than `owner@<accountId>`, which means the audit log answers "who". Sessions live sixty minutes, carry a `jti`, and can be revoked one at a time or per workspace; they arrive in an HttpOnly cookie rather than a URL fragment (PR-10). Uninstall and delete-my-data end every session. Security headers with a CSP that admits the Zoom client as frame ancestor, an explicit CORS allowlist, a 256 KB body limit and token-bucket rate limits per IP, per account and for the operator surface are all dependency-free and exercised by the suite. The operator routes sit on their own router with a credential that rotates in place. The purge-target list — which had drifted into two, with the explicit erasure path the weaker one (PR-06) — is one factory with a test asserting the two paths match. `/trust` is served from `src/claims.ts` and `docs/TRUST_PAGE.md` is checked against it in `test/claims.test.ts` (PR-07): PostHog, Sentry and Stripe are gone from the page because nothing sends them data, the four granular scopes are named, and residency is stated as a label until ST-145 makes it a boundary. The product loop closes. The React panels used to hold local state and call nothing (PR-03); the typed client now covers every route and each panel reads and writes through it, with optimistic updates that roll back on refusal, and the RTL suite drives a fake server rather than hand-passed props. A second reachability gate (`tools/reachability/routes.ts`) fails the build when a route in `app.ts` has no client method and no reasoned exemption — GAP-3 made permanent on the other side of the boundary. Ingestion no longer stops at "derived" (PR-04): when a CRM is connected and mapped, a meeting's fields are staged for review (on by default) and an Approve on the new review screen enqueues exactly one job, however many times Zoom redelivers; with review off they queue on ingest. Notes and insights are durable (PR-13) behind the same two-implementation contract suite as every other store — which caught a real divergence on its first run: the in-memory revocation store let a second revoke shorten a deny row's expiry, and the SQL one did not. There is a mail transport behind a `Sender` seam (ST-115); an `email` notification row is written only after the transport says yes, and when none is configured the outcome is recorded as `no_sender` rather than faked. The funnel has an `activated` stage — first approved CRM writeback — and trial conversion is cohorted by trial-start week (PR-14). What v045 does not do, said plainly: there is still no model, no ASR and no live CRM OAuth (PR-02 and S15–S17 await the decisions in the tracker's Decisions sheet); the pricing page carries a DECISION PENDING banner rather than a resolution (PR-05); residency, SSO, SOC 2 and a penetration test are listed under "Not yet" on the trust page because that is where they are. | F41: On 16 Sep an external reviewer read the code and then checked the claims made around it, raising 14 findings including a cross-tenant account takeover in the install flow. The reviewer's diagnosis of the programme was accepted: every pass from v0.13.0 to v0.44.0 asked questions answerable from inside the repository, and the findings clustered exactly where those questions cannot reach. The answer was two more standing gates, not more self-review. | G41: PR-01, PR-03, PR-04, PR-06, PR-07, PR-08, PR-10, PR-13, PR-14, SR-09 · ST-101…115, ST-141 | H41: 40 suites / 712 tests · 100x4 | I41: CURRENT
A43: 38 released versions. v0.01.0 to v0.07.0 in the shared artefact counter were product-workbook and planning documents, not code; the first code release was v0.08.0.

Sheet 06_Pending_Versions
A1: PENDING VERSIONS — what is not done, and the exact reason
A2: HOW TO USE THIS SHEET — THE DECISION SHEET. Every row names one specific thing that must happen before that release can start, and who owns it. Four of the nine are blocked on a decision only Senthil can make.
A3: Planned version | B3: Triggered by | C3: Scope | D3: Why it is pending — the reason in full | E3: Blocked on (owner) | F3: What it unblocks | G3: Earliest start
A4: v0.46.0 | B4: On Zoom dev app | C4: S14 live verification — install once against a real Zoom account and verify the webhook half of the product loop end to end | D4: Nothing in S14 has ever run against Zoom. The code is complete and pinned by 712 tests, but no Zoom account has installed this app, so the webhook signature format, the transcript download token and the SDK handshake are all verified against documentation rather than against the platform. The PD-05 hold that kept this release back has LIFTED now that S13 is closed — installing a takeover-vulnerable app was the reason to wait, and that reason is gone. | E4: Senthil — Handover #2 (Zoom Marketplace dev app: client id, client secret, webhook secret) | F4: Converts ST-101/102/103/111/113/114 from Done-in-code to verified; unblocks 7 pending-live stories; the panel stops being RTL-tested-only | G4: Immediately on credentials
A5: v0.47.0 | B5: On PD-01 | C5: ST-136 — resolve the pricing model and make the served matrix, the pricing page, the listing and the website agree | D5: The code bills per seat and the pricing page reads as flat monthly prices — a 50x disagreement at the Team tier (PR-05). This is a decision, not a build: one line of arithmetic follows from it. The page currently carries a DECISION PENDING banner that the claim gate enforces, so neither reading can be published by accident. HubSpot listing rules require the listed price to match the website, so this also gates the second marketplace. | E5: Senthil — decision PD-01 (per-seat or flat, and the number; recommendation on file is per-seat $12–$18/seat/month with a 5-seat minimum) | F5: S18 entirely; the HubSpot listing; the banner comes off the pricing page | G5: Same day as the decision
A6: v0.48.0 | B6: On PD-02 | C6: S15 — the intelligence layer: model provider abstraction, structured extraction with evidence spans, CRM-field summaries, an evaluation harness with a CI floor, injection guards, PII redaction, cost caps and a model transparency surface (ST-116…123, 42 pts) | D6: There is no model, no ASR and no NLP anywhere in the product; extraction is a five-phrase substring matcher (PR-02). Building this is not a small change — it brings a provider dependency, a per-meeting cost, an evaluation discipline, a prompt-injection threat surface and a new set of trust-page claims. The alternative is to reposition MeetSync as a deterministic rules engine, which is a legitimate and honest product with a different pitch, a different price and a much smaller scope. Until that choice is made, building either way is a guess. | E6: Senthil — decision PD-02 (build the intelligence, or reposition as a rules engine) | F6: 42 points directly, and it gates S16 (a further 29); determines the listing copy and the price | G6: On the decision
A7: v0.49.0 | B7: On PD-02 + corpus | C7: S16 — the Indic wedge: language-aware signal detection, Indic ASR provider integration, Hinglish code-switch handling, a published WER and field-accuracy benchmark, and a localised surface (ST-124…128, 29 pts) | D7: Two things are missing and only one of them is a decision. The first is PD-02 — without a model path there is nothing to put an ASR in front of. The second is a corpus: the benchmark that would make this claim defensible needs at least fifty real Indian-language sales calls with consent to use them, and no such corpus exists. This is the most defensible claim MeetSync could make and the least built part of it; the WER ruler has been in the code since S8 with nothing to measure. | E7: Senthil — PD-02, plus a consented corpus of real Hindi/Tamil/Hinglish sales calls | F7: The listing's central claim; the only part of the wedge Zoom's free bundle does not already cover | G7: On the decision and the corpus
A8: v0.50.0 | B8: On CRM credentials | C8: S17 — live CRM depth: authorization-code OAuth for HubSpot, Salesforce and Zoho, object and field discovery, a mapping UI with dry-run and diff, association and multi-object writeback, a failure surface with replay, and the HubSpot marketplace listing (ST-129…135, 39 pts) | D8: This is the only major pending release blocked purely on access rather than on a decision. Three sandbox adapters exist and have been exercised; zero live OAuth flows exist and no real CRM has ever received a write from MeetSync. Everything downstream — field discovery, type validation, picklist checks, provider rate-limit compliance, the 95% API success rate HubSpot certification requires — needs a real tenant to build against. The HubSpot marketplace is itself a second, slower approval path (3 active installs to list, 60 unaffiliated to certify, six months listed before certification). | E8: Senthil — Handover #3 (HubSpot / Salesforce / Zoho sandbox accounts or OAuth sessions) | F8: LC-6; the actual commercial wedge; the second distribution channel | G8: On credentials
A9: v0.51.0 | B9: After v0.47.0 | C9: S18 remainder — payment processor, Zoom Marketplace billing route, seat detection from measured usage, and the plan-to-feature entitlement matrix (ST-137…140, 24 pts) | D9: Ordered after the pricing decision because the processor integration encodes the pricing model. Dunning has had a sender seam since v0.45.0 but nothing to report a failure; invoices remain a document about money that never moved. Seats are still self-declared in the request body, which is why the tracker no longer claims per-seat detection is live (PR-12). The measured input exists — telemetry records distinct active days per account since v0.42.0 — only the derivation does not. | E9: Senthil — PD-01 first, then a payment processor account | F9: G-02 (paying installs); LC-10; retires two reachability allowlist exceptions | G9: After v0.47.0
A10: v0.52.0 | B10: On PD-03 | C10: S19 — enterprise readiness: SSO and SCIM, an admin console, backups with PITR and stated RPO/RTO, enforced data residency, the compliance programme and a third-party penetration test (ST-142…147, 32 pts) | D10: Mostly programme work rather than code. SOC 2 Type II is a funded exercise — roughly $35K–$120K over six to eighteen months with a minimum three-month observation window — not a sprint, and starting the clock is a commercial decision. Residency is currently a label that v0.45.0 stopped claiming rather than started enforcing. The honest recommendation is SMB-first: launch after S18 and treat S19 as demand-driven, pulling SSO and the admin console forward only when a named deal requires them. | E10: Senthil — decision PD-03 (SMB-first or enterprise-first) | F10: Enterprise deals only; it should not block an SMB launch | G10: On the decision; runs in parallel with S20 if SMB-first
A11: v0.53.0 | B11: After all of the above | C11: S20 — launch and proof: Zoom Marketplace submission, the listing asset pack, a manual accessibility pass on the live UI, and the first paying installs (ST-148…151, 12 pts) | D11: The smallest release and the only one that produces the evidence that matters. Every other pending item feeds it. The listing copy cannot be written until PD-02 resolves what the product actually is; the demo video is recorded on the ST-114 review screen, which needs a live install; the accessibility pass needs a rendered surface inside the Zoom client, which jsdom cannot simulate. The gate is ten paying installs from strangers, and no amount of further code moves it. | E11: Senthil — everything above, then outreach | F11: G-01, G-02, G-03, G-04 — the completion gate | G11: Last
A12: — | B12: Unscheduled | C12: PD-06 demand tests — five RevOps pricing conversations, a ten-call Hinglish head-to-head against Zoom's own summary, and ten Zoom-paying teams on willingness to switch | D12: Not a code release, and listed here because it should happen before several of the ones above. Each test has a falsifiable kill signal, each costs days rather than sprints, and any one of them failing should change the plan rather than the schedule. Running S15 through S17 — 110 points — before knowing whether anyone will pay for governed CRM writeback is the expensive way to find out. | E12: Senthil — PD-06 | F12: Validates or invalidates the wedge before the S15–S17 spend | G12: Now — it blocks nothing and informs everything

Sheet 07_Version_Steps
A1: VERSION STEPS — the ordered execution of each release
A2: HOW TO USE THIS SHEET — Filter by Version to reconstruct exactly what was done in a release and in what order. Phase tells you whether a step was analysis, a change, a test, a gate or documentation.
A3: Code version | B3: Step | C3: Phase | D3: What was done | E3: Artefact / evidence
A4: v0.08.0 | B4: 1 | C4: Plan | D4: Read the v007 product workbook Full_Backlog and sequence S1–S8 under D13 (100% coverage, discovery parked). | E4: 100-story backlog mapped to sprints
A5: v0.08.0 | B5: 2 | C5: Build | D5: Foundation: config with region and secret validation, typed Store interface, Zoom OAuth exchange and rotation-safe refresh. | E5: src/config.ts, src/store.ts, src/zoomAuth.ts
A6: v0.08.0 | B6: 3 | C6: Build | D6: Platform resilience: ZoomClient backoff with jitter, circuit breaker with half-open probe, auto-refresh-once on 401. | E6: src/zoomClient.ts
A7: v0.08.0 | B7: 4 | C7: Build | D7: Webhook verification: HMAC x-zm-signature, url_validation challenge, replay guard, dedupe ledger. | E7: src/webhooks.ts
A8: v0.08.0 | B8: 5 | C8: Build | D8: Feature engine and F1–F5: notes, action extraction, CRM adapters and queue, deal risk, Indic WER harness. | E8: src/features.ts and five feature modules
A9: v0.08.0 | B9: 6 | C9: Build | D9: Commercial and platform: billing with trial/plans/proration/dunning, RBAC matrix with audit log, telemetry funnel, onboarding. | E9: src/billing.ts, src/rbac.ts, src/telemetry.ts, src/onboarding.ts
A10: v0.08.0 | B10: 7 | C10: Gate | D10: Run the suite at the D13 threshold. | E10: 18 suites / 139 tests / 100x4 / zero pragmas
A11: v0.09.0 | B11: 1 | C11: Analyse | D11: Identify the defect or scope for v0.09.0 and record it as ST-069, ST-091. | E11: Tracker Review_Findings / Traceability row
A12: v0.09.0 | B12: 2 | C12: Build | D12: Implement the change described in the Version_Detail row for v0.09.0. | E12: src/ change set
A13: v0.09.0 | B13: 3 | C13: Pin | D13: Write a named regression test that fails before the change and passes after it. | E13: test/ suite
A14: v0.09.0 | B14: 4 | C14: Gate | D14: Run the full suite at the D13 threshold; refuse the release below 100% on any of the four measures. | E14: 19 suites / 149 tests · 100x4
A15: v0.09.0 | B15: 5 | C15: Document | D15: Add the version paragraph to README.md in the established voice and update any affected document in docs/. | E15: README.md + docs/
... A213: v0.45.0 | B213: 19 | C213: Correction | D213: During the documentation pass, found the README title still reading v0.44.0 against package.json 0.45.0 — the same claim-drift class. Fixed and gated rather than merely corrected. | E213: test/claims.test.ts README version gate

Sheet 08_Test_Cases
A1: MANUAL TEST CASES — 177 cases, positive and negative
A2: HOW TO USE THIS SHEET — Execute top to bottom, or filter: Priority=P0 for a risk-based pass, Area for a feature pass, Version to regression-test one release. Fill ONLY the yellow columns (Actual result, Status, Tester, Date, Defect ref). Steps are numbered and run in order. Five cases are marked EXPECTED TO FIND NOTHING — they document known gaps and are not defects.
A3: Test case ID | B3: Version introduced | C3: Area | D3: Story / finding ref | E3: Type | F3: Priority | G3: Test case name | H3: Test description | I3: Preconditions | J3: Test steps (in order) | K3: Expected result | L3: Pinned by (automated) | M3: Actual result | N3: Status | O3: Tester | P3: Date executed | Q3: Defect ref
A4: TC-INS-001 | B4: v0.45.0 | C4: Install & OAuth | D4: ST-101 | E4: Positive | F4: P0 | G4: Install lands on the workspace Zoom names | H4: A bare install link completes OAuth and the account row is created for the Zoom account that authorised it, not for anything the caller supplied. | I4: MeetSync deployed with valid ZOOM_CLIENT_ID/SECRET and BASE_URL; a Zoom account that has not installed MeetSync before. | J4: 1. Open GET /oauth/start with no account_id parameter. 2. Follow the returned authorizeUrl and approve the app as a Zoom account owner. 3. Observe the redirect back to /oauth/callback. 4. Query the accounts table for the new row. | K4: Redirect is 302 to /welcome?account=<Zoom account_id>. The accounts row id equals the account_id Zoom reports at /users/me. installed_by_user_id and contact_email hold the installing user. An install.tenant audit row is written with allowed=true. | L4: s13.test.ts "installs on Zoom's account when the hint is empty or agrees" | N4: Not run
A5: TC-INS-002 | B5: v0.45.0 | C5: Install & OAuth | D5: ST-101 / PR-01 | E5: Negative | F5: P0 | G5: Install is refused when the caller claims a workspace it does not own | H5: The PR-01 cross-tenant takeover. A caller supplies another workspace's id as the attribution hint and completes OAuth with their own Zoom login. | I5: Two distinct Zoom accounts: VICTIM (already installed) and ATTACKER. Knowledge of the VICTIM account_id. | J5: 1. Open GET /oauth/start?account_id=<VICTIM account_id>. 2. Follow the authorizeUrl and approve using the ATTACKER Zoom login. 3. Observe the response at /oauth/callback. 4. Re-query the VICTIM accounts row and compare it to a copy taken before step 1. 5. Read the audit log. | K5: HTTP 403 with body {error:"tenant_mismatch"}. No Set-Cookie header. No account row is created for either id. The VICTIM row is byte-for-byte unchanged — tokens NOT repointed. An install.tenant audit row records allowed=false, the real ATTACKER user id, target=VICTIM and accountId=ATTACKER. | L5: s13.test.ts "refuses a state whose account differs from Zoom's answer"; "cannot repoint a live workspace's tokens" | N5: Not run
A6: TC-INS-003 | B6: v0.45.0 | C6: Install & OAuth | D6: ST-101 | E6: Positive | F6: P1 | G6: Install proceeds when the hint agrees with Zoom | H6: The ordinary marketplace path, where the listing link carries the installing workspace id. | I6: A Zoom account whose account_id is known. | J6: 1. Open GET /oauth/start?account_id=<correct id>&source=listing. 2. Complete OAuth with that account. 3. Check the install source recorded on the row. | K6: HTTP 302 to /welcome. Account row created with install_source=listing. No 403. | L6: s13.test.ts "installs on Zoom's account when the hint is empty or agrees" | N6: Not run
A7: TC-INS-004 | B7: v0.13.0 | C7: Install & OAuth | D7: M-F15 | E7: Negative | F7: P0 | G7: Callback refuses a missing, forged or foreign-signed state | H7: CSRF protection on the OAuth callback. | I7: A running deployment. | J7: 1. Call GET /oauth/callback?code=x with no state parameter. 2. Call it again with state=nonsense. 3. Mint a valid state, alter its final signature segment, and call with the tampered value. | K7: Step 1: 400 {error:"bad_state", reason:"missing"}. Step 2: reason "malformed". Step 3: reason "bad_signature". No account row is written in any case. | L7: app.test.ts "OAuth callback refuses a missing, forged or foreign-signed state" | N7: Not run
A8: TC-INS-005 | B8: v0.45.0 | C8: Install & OAuth | D8: ST-101 | E8: Negative | F8: P1 | G8: Zoom identity outage is reported as retryable, not as a rejection | H8: When Zoom answers 5xx to /users/me the installer should be told to try again, not that their token was refused. | I8: Ability to intercept or simulate the Zoom API response (staging). | J8: 1. Force /users/me to return 503. 2. Complete an install. | K8: HTTP 502 {error:"identity_failed"}. No account row written. The installer can retry. | L8: s13.test.ts "maps identity failures" | N8: Not run
A9: TC-INS-006 | B9: v0.45.0 | C9: Install & OAuth | D9: ST-101 | E9: Negative | F9: P1 | G9: A token Zoom itself rejects fails the install with 401 | H9: Distinguishes an outage from a credential problem. | I9: Staging with a controllable Zoom double. | J9: 1. Force /users/me to return 401. 2. Complete an install. | K9: HTTP 401 {error:"identity_failed"}. No account row. Retrying will not help and the status says so. | L9: s13.test.ts "maps identity failures" | N9: Not run
A10: TC-INS-007 | B10: v0.45.0 | C10: Install & OAuth | D10: ST-101 | E10: Negative | F10: P2 | G10: A malformed /users/me payload is a 502, not a crash | H10: Defensive parsing of the platform response. | I10: Staging with a controllable Zoom double. | J10: 1. Force /users/me to return 200 with a body containing no account_id. 2. Complete an install. | K10: HTTP 502 {error:"identity_failed"}. No unhandled exception in the error ledger beyond the recorded failure. | L10: identity.test.ts parseIdentity cases | N10: Not run
A11: TC-INS-008 | B11: v0.14.0 | C11: Install & OAuth | D11: VER-M01 / VER-M02 | E11: Positive | F11: P0 | G11: Token exchange uses Basic auth and the registered redirect_uri | H11: Zoom authenticates the client with an Authorization header, not form fields, and requires redirect_uri on the authorization_code grant. | I11: Network capture available on the outbound call. | J11: 1. Complete an install. 2. Capture the POST to https://zoom.us/oauth/token. 3. Inspect its headers and body. | K11: Authorization: Basic base64(client_id:client_secret) is present. The body carries grant_type=authorization_code, code and redirect_uri. client_id and client_secret do NOT appear in the body. | L11: zoomAuth.test.ts | N11: Not run
A12: TC-INS-009 | B12: v0.08.0 | C12: Install & OAuth | D12: ST-053 | E12: Positive | F12: P1 | G12: Re-install inside the retention window restores the archived account | H12: A customer who uninstalls and changes their mind within RETENTION_DAYS gets their configuration back. | I12: An installed account. | J12: 1. Trigger app_deauthorized for the account. 2. Confirm the row is archived and tokens are null. 3. Re-install the same Zoom account before the retention window expires. 4. Read the account row and the feature settings. | K12: uninstalledAt and deletionScheduledAt return to null, archived clears, installedAt is refreshed, and the feature configuration survives. | L12: lifecycle.test.ts; identity.test.ts "restores an archived account" | N12: Not run
A13: TC-INS-010 | B13: v0.08.0 | C13: Install & OAuth | D13: ST-052 | E13: Positive | F13: P0 | G13: Uninstall wipes tokens immediately | H13: Deauthorisation must not leave working Zoom credentials in the database. | I13: An installed account with tokens. | J13: 1. Send a signed app_deauthorized webhook for the account. 2. Immediately query the accounts row. | K13: access_token and refresh_token are NULL (not empty strings). uninstalledAt is set. deletionScheduledAt is set to now + RETENTION_DAYS. | L13: app.test.ts webhook deauthorization block | N13: Not run
A14: TC-INS-011 | B14: v0.45.0 | C14: Install & OAuth | D14: ST-103 | E14: Positive | F14: P1 | G14: Uninstall also ends every live session for that workspace | H14: An uninstalled workspace should have no usable sessions. | I14: An installed account with at least two active sessions in different browsers. | J14: 1. Note both sessions work by calling GET /session/me from each. 2. Send a signed app_deauthorized webhook. 3. Retry GET /session/me from both. | K14: Both return 401 with reason "revoked". Neither browser can act on the workspace. | L14: app.test.ts; s13.test.ts uninstall revocation | N14: Not run
A15: TC-INS-012 | B15: v0.08.0 | C15: Install & OAuth | D15: ST-056 | E15: Positive | F15: P2 | G15: Install source is attributed, and an unknown source does not fail the install | H15: Attribution feeds the funnel; a bad value must never block a customer. | I15: A fresh Zoom account. | J15: 1. Install with source=listing and check the row. 2. Uninstall, purge, and install again with source=banana. | K15: First install records install_source=listing. Second records "direct" and completes normally. | L15: lifecycle.test.ts attributeSource | N15: Not run
... A180: TC-MET-006 | B180: v0.45.0 | C180: Metrics | D180: ST-104 | E180: Positive | F180: P3 | G180: Rate-limit rejections are attributed by route class | H180: A burst should be diagnosable. | I180: Operator token; throttling has occurred on more than one class. | J180: 1. Read GET /analytics/rate-limits. | K180: Rejections are grouped by class — public, oauth, webhook, account, operator — busiest first, with ties broken by name. | L180: telemetry.test.ts rateLimitedCounts | N180: Not run

Sheet 09_Test_Summary
A1: TEST SUMMARY — live counts over 08_Test_Cases
A2: HOW TO USE THIS SHEET — DO NOT EDIT — every number is a formula over 08_Test_Cases and updates as the Status column is filled in. Open in Excel or LibreOffice to recalculate.
A3: Dimension | B3: Value | C3: Total cases | D3: Positive | E3: Negative | F3: Not run | G3: Pass | H3: Fail | I3: Blocked | J3: % executed
A4: Area | B4: Install & OAuth | C4: =COUNTIF('08_Test_Cases'!$C$4:$C$180,"Install & OAuth") | D4: =COUNTIFS('08_Test_Cases'!$C$4:$C$180,"Install & OAuth",'08_Test_Cases'!$E$4:$E$180,"Positive") | E4: =COUNTIFS('08_Test_Cases'!$C$4:$C$180,"Install & OAuth",'08_Test_Cases'!$E$4:$E$180,"Negative") | F4: =COUNTIFS('08_Test_Cases'!$C$4:$C$180,"Install & OAuth",'08_Test_Cases'!$N$4:$N$180,"Not run") | G4: =COUNTIFS('08_Test_Cases'!$C$4:$C$180,"Install & OAuth",'08_Test_Cases'!$N$4:$N$180,"Pass") | H4: =COUNTIFS('08_Test_Cases'!$C$4:$C$180,"Install & OAuth",'08_Test_Cases'!$N$4:$N$180,"Fail") | I4: =COUNTIFS('08_Test_Cases'!$C$4:$C$180,"Install & OAuth",'08_Test_Cases'!$N$4:$N$180,"Blocked") | J4: =IFERROR(1-COUNTIFS('08_Test_Cases'!$C$4:$C$180,"Install & OAuth",'08_Test_Cases'!$N$4:$N$180,"Not run")/COUNTIF('08_Test_Cases'!$C$4:$C$180,"Install & OAuth"),0)
A5: Area | B5: Sessions | C5: =COUNTIF('08_Test_Cases'!$C$4:$C$180,"Sessions") | D5: =COUNTIFS('08_Test_Cases'!$C$4:$C$180,"Sessions",'08_Test_Cases'!$E$4:$E$180,"Positive") | E5: =COUNTIFS('08_Test_Cases'!$C$4:$C$180,"Sessions",'08_Test_Cases'!$E$4:$E$180,"Negative") | F5: =COUNTIFS('08_Test_Cases'!$C$4:$C$180,"Sessions",'08_Test_Cases'!$N$4:$N$180,"Not run") | G5: =COUNTIFS('08_Test_Cases'!$C$4:$C$180,"Sessions",'08_Test_Cases'!$N$4:$N$180,"Pass") | H5: =COUNTIFS('08_Test_Cases'!$C$4:$C$180,"Sessions",'08_Test_Cases'!$N$4:$N$180,"Fail") | I5: =COUNTIFS('08_Test_Cases'!$C$4:$C$180,"Sessions",'08_Test_Cases'!$N$4:$N$180,"Blocked") | J5: =IFERROR(1-COUNTIFS('08_Test_Cases'!$C$4:$C$180,"Sessions",'08_Test_Cases'!$N$4:$N$180,"Not run")/COUNTIF('08_Test_Cases'!$C$4:$C$180,"Sessions"),0)
A6: Area | B6: HTTP hardening | C6: =COUNTIF('08_Test_Cases'!$C$4:$C$180,"HTTP hardening") | D6: =COUNTIFS('08_Test_Cases'!$C$4:$C$180,"HTTP hardening",'08_Test_Cases'!$E$4:$E$180,"Positive") | E6: =COUNTIFS('08_Test_Cases'!$C$4:$C$180,"HTTP hardening",'08_Test_Cases'!$E$4:$E$180,"Negative") | F6: =COUNTIFS('08_Test_Cases'!$C$4:$C$180,"HTTP hardening",'08_Test_Cases'!$N$4:$N$180,"Not run") | G6: =COUNTIFS('08_Test_Cases'!$C$4:$C$180,"HTTP hardening",'08_Test_Cases'!$N$4:$N$180,"Pass") | H6: =COUNTIFS('08_Test_Cases'!$C$4:$C$180,"HTTP hardening",'08_Test_Cases'!$N$4:$N$180,"Fail") | I6: =COUNTIFS('08_Test_Cases'!$C$4:$C$180,"HTTP hardening",'08_Test_Cases'!$N$4:$N$180,"Blocked") | J6: =IFERROR(1-COUNTIFS('08_Test_Cases'!$C$4:$C$180,"HTTP hardening",'08_Test_Cases'!$N$4:$N$180,"Not run")/COUNTIF('08_Test_Cases'!$C$4:$C$180,"HTTP hardening"),0)
A7: Area | B7: Operator surface | C7: =COUNTIF('08_Test_Cases'!$C$4:$C$180,"Operator surface") | D7: =COUNTIFS('08_Test_Cases'!$C$4:$C$180,"Operator surface",'08_Test_Cases'!$E$4:$E$180,"Positive") | E7: =COUNTIFS('08_Test_Cases'!$C$4:$C$180,"Operator surface",'08_Test_Cases'!$E$4:$E$180,"Negative") | F7: =COUNTIFS('08_Test_Cases'!$C$4:$C$180,"Operator surface",'08_Test_Cases'!$N$4:$N$180,"Not run") | G7: =COUNTIFS('08_Test_Cases'!$C$4:$C$180,"Operator surface",'08_Test_Cases'!$N$4:$N$180,"Pass") | H7: =COUNTIFS('08_Test_Cases'!$C$4:$C$180,"Operator surface",'08_Test_Cases'!$N$4:$N$180,"Fail") | I7: =COUNTIFS('08_Test_Cases'!$C$4:$C$180,"Operator surface",'08_Test_Cases'!$N$4:$N$180,"Blocked") | J7: =IFERROR(1-COUNTIFS('08_Test_Cases'!$C$4:$C$180,"Operator surface",'08_Test_Cases'!$N$4:$N$180,"Not run")/COUNTIF('08_Test_Cases'!$C$4:$C$180,"Operator surface"),0)
A8: Area | B8: Tenancy & RBAC | C8: =COUNTIF('08_Test_Cases'!$C$4:$C$180,"Tenancy & RBAC") | D8: =COUNTIFS('08_Test_Cases'!$C$4:$C$180,"Tenancy & RBAC",'08_Test_Cases'!$E$4:$E$180,"Positive") | E8: =COUNTIFS('08_Test_Cases'!$C$4:$C$180,"Tenancy & RBAC",'08_Test_Cases'!$E$4:$E$180,"Negative") | F8: =COUNTIFS('08_Test_Cases'!$C$4:$C$180,"Tenancy & RBAC",'08_Test_Cases'!$N$4:$N$180,"Not run") | G8: =COUNTIFS('08_Test_Cases'!$C$4:$C$180,"Tenancy & RBAC",'08_Test_Cases'!$N$4:$N$180,"Pass") | H8: =COUNTIFS('08_Test_Cases'!$C$4:$C$180,"Tenancy & RBAC",'08_Test_Cases'!$N$4:$N$180,"Fail") | I8: =COUNTIFS('08_Test_Cases'!$C$4:$C$180,"Tenancy & RBAC",'08_Test_Cases'!$N$4:$N$180,"Blocked") | J8: =IFERROR(1-COUNTIFS('08_Test_Cases'!$C$4:$C$180,"Tenancy & RBAC",'08_Test_Cases'!$N$4:$N$180,"Not run")/COUNTIF('08_Test_Cases'!$C$4:$C$180,"Tenancy & RBAC"),0)
A9: Area | B9: Data lifecycle | C9: =COUNTIF('08_Test_Cases'!$C$4:$C$180,"Data lifecycle") | D9: =COUNTIFS('08_Test_Cases'!$C$4:$C$180,"Data lifecycle",'08_Test_Cases'!$E$4:$E$180,"Positive") | E9: =COUNTIFS('08_Test_Cases'!$C$4:$C$180,"Data lifecycle",'08_Test_Cases'!$E$4:$E$180,"Negative") | F9: =COUNTIFS('08_Test_Cases'!$C$4:$C$180,"Data lifecycle",'08_Test_Cases'!$N$4:$N$180,"Not run") | G9: =COUNTIFS('08_Test_Cases'!$C$4:$C$180,"Data lifecycle",'08_Test_Cases'!$N$4:$N$180,"Pass") | H9: =COUNTIFS('08_Test_Cases'!$C$4:$C$180,"Data lifecycle",'08_Test_Cases'!$N$4:$N$180,"Fail") | I9: =COUNTIFS('08_Test_Cases'!$C$4:$C$180,"Data lifecycle",'08_Test_Cases'!$N$4:$N$180,"Blocked") | J9: =IFERROR(1-COUNTIFS('08_Test_Cases'!$C$4:$C$180,"Data lifecycle",'08_Test_Cases'!$N$4:$N$180,"Not run")/COUNTIF('08_Test_Cases'!$C$4:$C$180,"Data lifecycle"),0)
A10: Area | B10: Trust & claims | C10: =COUNTIF('08_Test_Cases'!$C$4:$C$180,"Trust & claims") | D10: =COUNTIFS('08_Test_Cases'!$C$4:$C$180,"Trust & claims",'08_Test_Cases'!$E$4:$E$180,"Positive") | E10: =COUNTIFS('08_Test_Cases'!$C$4:$C$180,"Trust & claims",'08_Test_Cases'!$E$4:$E$180,"Negative") | F10: =COUNTIFS('08_Test_Cases'!$C$4:$C$180,"Trust & claims",'08_Test_Cases'!$N$4:$N$180,"Not run") | G10: =COUNTIFS('08_Test_Cases'!$C$4:$C$180,"Trust & claims",'08_Test_Cases'!$N$4:$N$180,"Pass") | H10: =COUNTIFS('08_Test_Cases'!$C$4:$C$180,"Trust & claims",'08_Test_Cases'!$N$4:$N$180,"Fail") | I10: =COUNTIFS('08_Test_Cases'!$C$4:$C$180,"Trust & claims",'08_Test_Cases'!$N$4:$N$180,"Blocked") | J10: =IFERROR(1-COUNTIFS('08_Test_Cases'!$C$4:$C$180,"Trust & claims",'08_Test_Cases'!$N$4:$N$180,"Not run")/COUNTIF('08_Test_Cases'!$C$4:$C$180,"Trust & claims"),0)
A11: Area | B11: Webhooks | C11: =COUNTIF('08_Test_Cases'!$C$4:$C$180,"Webhooks") | D11: =COUNTIFS('08_Test_Cases'!$C$4:$C$180,"Webhooks",'08_Test_Cases'!$E$4:$E$180,"Positive") | E11: =COUNTIFS('08_Test_Cases'!$C$4:$C$180,"Webhooks",'08_Test_Cases'!$E$4:$E$180,"Negative") | F11: =COUNTIFS('08_Test_Cases'!$C$4:$C$180,"Webhooks",'08_Test_Cases'!$N$4:$N$180,"Not run") | G11: =COUNTIFS('08_Test_Cases'!$C$4:$C$180,"Webhooks",'08_Test_Cases'!$N$4:$N$180,"Pass") | H11: =COUNTIFS('08_Test_Cases'!$C$4:$C$180,"Webhooks",'08_Test_Cases'!$N$4:$N$180,"Fail") | I11: =COUNTIFS('08_Test_Cases'!$C$4:$C$180,"Webhooks",'08_Test_Cases'!$N$4:$N$180,"Blocked") | J11: =IFERROR(1-COUNTIFS('08_Test_Cases'!$C$4:$C$180,"Webhooks",'08_Test_Cases'!$N$4:$N$180,"Not run")/COUNTIF('08_Test_Cases'!$C$4:$C$180,"Webhooks"),0)
A12: Area | B12: Product loop | C12: =COUNTIF('08_Test_Cases'!$C$4:$C$180,"Product loop") | D12: =COUNTIFS('08_Test_Cases'!$C$4:$C$180,"Product loop",'08_Test_Cases'!$E$4:$E$180,"Positive") | E12: =COUNTIFS('08_Test_Cases'!$C$4:$C$180,"Product loop",'08_Test_Cases'!$E$4:$E$180,"Negative") | F12: =COUNTIFS('08_Test_Cases'!$C$4:$C$180,"Product loop",'08_Test_Cases'!$N$4:$N$180,"Not run") | G12: =COUNTIFS('08_Test_Cases'!$C$4:$C$180,"Product loop",'08_Test_Cases'!$N$4:$N$180,"Pass") | H12: =COUNTIFS('08_Test_Cases'!$C$4:$C$180,"Product loop",'08_Test_Cases'!$N$4:$N$180,"Fail") | I12: =COUNTIFS('08_Test_Cases'!$C$4:$C$180,"Product loop",'08_Test_Cases'!$N$4:$N$180,"Blocked") | J12: =IFERROR(1-COUNTIFS('08_Test_Cases'!$C$4:$C$180,"Product loop",'08_Test_Cases'!$N$4:$N$180,"Not run")/COUNTIF('08_Test_Cases'!$C$4:$C$180,"Product loop"),0)
A13: Area | B13: F1 Notes | C13: =COUNTIF('08_Test_Cases'!$C$4:$C$180,"F1 Notes") | D13: =COUNTIFS('08_Test_Cases'!$C$4:$C$180,"F1 Notes",'08_Test_Cases'!$E$4:$E$180,"Positive") | E13: =COUNTIFS('08_Test_Cases'!$C$4:$C$180,"F1 Notes",'08_Test_Cases'!$E$4:$E$180,"Negative") | F13: =COUNTIFS('08_Test_Cases'!$C$4:$C$180,"F1 Notes",'08_Test_Cases'!$N$4:$N$180,"Not run") | G13: =COUNTIFS('08_Test_Cases'!$C$4:$C$180,"F1 Notes",'08_Test_Cases'!$N$4:$N$180,"Pass") | H13: =COUNTIFS('08_Test_Cases'!$C$4:$C$180,"F1 Notes",'08_Test_Cases'!$N$4:$N$180,"Fail") | I13: =COUNTIFS('08_Test_Cases'!$C$4:$C$180,"F1 Notes",'08_Test_Cases'!$N$4:$N$180,"Blocked") | J13: =IFERROR(1-COUNTIFS('08_Test_Cases'!$C$4:$C$180,"F1 Notes",'08_Test_Cases'!$N$4:$N$180,"Not run")/COUNTIF('08_Test_Cases'!$C$4:$C$180,"F1 Notes"),0)
A14: Area | B14: F2 Actions | C14: =COUNTIF('08_Test_Cases'!$C$4:$C$180,"F2 Actions") | D14: =COUNTIFS('08_Test_Cases'!$C$4:$C$180,"F2 Actions",'08_Test_Cases'!$E$4:$E$180,"Positive") | E14: =COUNTIFS('08_Test_Cases'!$C$4:$C$180,"F2 Actions",'08_Test_Cases'!$E$4:$E$180,"Negative") | F14: =COUNTIFS('08_Test_Cases'!$C$4:$C$180,"F2 Actions",'08_Test_Cases'!$N$4:$N$180,"Not run") | G14: =COUNTIFS('08_Test_Cases'!$C$4:$C$180,"F2 Actions",'08_Test_Cases'!$N$4:$N$180,"Pass") | H14: =COUNTIFS('08_Test_Cases'!$C$4:$C$180,"F2 Actions",'08_Test_Cases'!$N$4:$N$180,"Fail") | I14: =COUNTIFS('08_Test_Cases'!$C$4:$C$180,"F2 Actions",'08_Test_Cases'!$N$4:$N$180,"Blocked") | J14: =IFERROR(1-COUNTIFS('08_Test_Cases'!$C$4:$C$180,"F2 Actions",'08_Test_Cases'!$N$4:$N$180,"Not run")/COUNTIF('08_Test_Cases'!$C$4:$C$180,"F2 Actions"),0)
A15: Area | B15: F3 CRM | C15: =COUNTIF('08_Test_Cases'!$C$4:$C$180,"F3 CRM") | D15: =COUNTIFS('08_Test_Cases'!$C$4:$C$180,"F3 CRM",'08_Test_Cases'!$E$4:$E$180,"Positive") | E15: =COUNTIFS('08_Test_Cases'!$C$4:$C$180,"F3 CRM",'08_Test_Cases'!$E$4:$E$180,"Negative") | F15: =COUNTIFS('08_Test_Cases'!$C$4:$C$180,"F3 CRM",'08_Test_Cases'!$N$4:$N$180,"Not run") | G15: =COUNTIFS('08_Test_Cases'!$C$4:$C$180,"F3 CRM",'08_Test_Cases'!$N$4:$N$180,"Pass") | H15: =COUNTIFS('08_Test_Cases'!$C$4:$C$180,"F3 CRM",'08_Test_Cases'!$N$4:$N$180,"Fail") | I15: =COUNTIFS('08_Test_Cases'!$C$4:$C$180,"F3 CRM",'08_Test_Cases'!$N$4:$N$180,"Blocked") | J15: =IFERROR(1-COUNTIFS('08_Test_Cases'!$C$4:$C$180,"F3 CRM",'08_Test_Cases'!$N$4:$N$180,"Not run")/COUNTIF('08_Test_Cases'!$C$4:$C$180,"F3 CRM"),0)
A16: Area | B16: F4 Deal risk | C16: =COUNTIF('08_Test_Cases'!$C$4:$C$180,"F4 Deal risk") | D16: =COUNTIFS('08_Test_Cases'!$C$4:$C$180,"F4 Deal risk",'08_Test_Cases'!$E$4:$E$180,"Positive") | E16: =COUNTIFS('08_Test_Cases'!$C$4:$C$180,"F4 Deal risk",'08_Test_Cases'!$E$4:$E$180,"Negative") | F16: =COUNTIFS('08_Test_Cases'!$C$4:$C$180,"F4 Deal risk",'08_Test_Cases'!$N$4:$N$180,"Not run") | G16: =COUNTIFS('08_Test_Cases'!$C$4:$C$180,"F4 Deal risk",'08_Test_Cases'!$N$4:$N$180,"Pass") | H16: =COUNTIFS('08_Test_Cases'!$C$4:$C$180,"F4 Deal risk",'08_Test_Cases'!$N$4:$N$180,"Fail") | I16: =COUNTIFS('08_Test_Cases'!$C$4:$C$180,"F4 Deal risk",'08_Test_Cases'!$N$4:$N$180,"Blocked") | J16: =IFERROR(1-COUNTIFS('08_Test_Cases'!$C$4:$C$180,"F4 Deal risk",'08_Test_Cases'!$N$4:$N$180,"Not run")/COUNTIF('08_Test_Cases'!$C$4:$C$180,"F4 Deal risk"),0)
A17: Area | B17: F5 Indic | C17: =COUNTIF('08_Test_Cases'!$C$4:$C$180,"F5 Indic") | D17: =COUNTIFS('08_Test_Cases'!$C$4:$C$180,"F5 Indic",'08_Test_Cases'!$E$4:$E$180,"Positive") | E17: =COUNTIFS('08_Test_Cases'!$C$4:$C$180,"F5 Indic",'08_Test_Cases'!$E$4:$E$180,"Negative") | F17: =COUNTIFS('08_Test_Cases'!$C$4:$C$180,"F5 Indic",'08_Test_Cases'!$N$4:$N$180,"Not run") | G17: =COUNTIFS('08_Test_Cases'!$C$4:$C$180,"F5 Indic",'08_Test_Cases'!$N$4:$N$180,"Pass") | H17: =COUNTIFS('08_Test_Cases'!$C$4:$C$180,"F5 Indic",'08_Test_Cases'!$N$4:$N$180,"Fail") | I17: =COUNTIFS('08_Test_Cases'!$C$4:$C$180,"F5 Indic",'08_Test_Cases'!$N$4:$N$180,"Blocked") | J17: =IFERROR(1-COUNTIFS('08_Test_Cases'!$C$4:$C$180,"F5 Indic",'08_Test_Cases'!$N$4:$N$180,"Not run")/COUNTIF('08_Test_Cases'!$C$4:$C$180,"F5 Indic"),0)
