Workbook

Sheet Version_Control
A1: VERSION CONTROL — VoiceBridge CTI
A3: Version | B3: Date | C3: Author | D3: Change | E3: Status
A4: v001-v004 | B4: 2026-09-05 | C4: Claude for Senthil/KP | D4: Lineage: marketplace master (868 entries) -> portfolio plan (12 products) -> wave-1 (RetainKit/ShiftDesk/EngageOS, v005) -> this product selected for wave-2 | E4: Released
A5: v006 | B5: 2026-09-05 19:46 | C5: Claude for Senthil/KP | D5: Full product workbook for VoiceBridge CTI on Salesforce AppExchange: spec, screen inventory, 100+ story backlog, live sprint board, 18-month financial model (editable assumptions), GTM execution tasks, platform launch checklist, metric targets, risk register | E5: Released
A6: v007 | B6: 2026-09-10 23:00 | C6: Claude for Senthil/KP | D6: Released: S1-S8 executed done-in-code under D13 (D17, interviews parked; supersedes the planned post-S0 re-baseline). 79 Done + 5 code-complete-pending-live of 100 stories; TypeScript codebase 20 Jest suites / 85 tests at 100% coverage; Full_Backlog statuses updated; Sprint_Board Done counts now live COUNTIFS; Sprint_Tracker_Log + Traceability_Matrix sheets added (companion tracker file claude_v001_voicebridge_sprint_tracker_traceability_20260910_2300). | E6: Released
A7: v008 | B7: 2026-09-11 08:46 | C7: Claude for Senthil/KP | D7: Released: S9 review prep executed done-in-code (WCAG widgets + axe audit, backup/restore drill, chaos degradation + /status comms Done; security evidence pack In progress pending pen-test vendor; listing copy A/B + asset plan Drafted) plus live-sweep pack (12-step, 30-min dev-org guide) and D18 packaging recommendation (hybrid-minimal 2GP shim). Codebase 24 suites / 101 tests at 100% coverage. 82 Done / 5 code-complete / 1 in progress / 2 drafted / 10 backlog (352/399 pts engaged). Companion tracker claude_v002_voicebridge_sprint_tracker_traceability_20260911_0846. | E7: Released
A8: v009 | B8: 2026-09-11 12:48 | C8: Claude for Senthil/KP | D8: Released: S10 review remediation executed done-in-code (help center 15+search, built-in chat SLA engine — vendor deferred D-V1, status page + incident template, pricing + trust from single sources; demo-data mode code-complete pending video capture; dry-run engine READY 11/11 automated + REVIEW_PACK.md, ST-097 In progress pending DR-12 external sign-off). Codebase 30 suites / 131 tests at 100% zero pragmas. 87 Done / 6 code-complete / 2 in progress / 2 drafted / 3 backlog (373/399 pts engaged). Companion tracker claude_v003_voicebridge_sprint_tracker_traceability_20260911_1248. | E8: Released
A9: v010 | B9: 2026-09-11 13:32 | C9: Claude for Senthil/KP | D9: Released: CODE PHASE COMPLETE — S11+S12 codeable scope (executable runbook Done; design-partner tracker CC pending outreach; SEO iteration engine CC pending post-listing data). Backlog ZERO. 33 suites / 150 tests at 100% zero pragmas. Final: 88 Done / 8 code-complete / 2 in progress / 2 drafted (380/399 pts); remaining 19 pts all Senthil-side (pen-test 8, DR-12 sign-off 3, copy pick 3, asset capture 5). Companion tracker claude_v004_voicebridge_sprint_tracker_traceability_20260911_1332. No further code sprints planned. | E9: Released
A10: v011 | B10: 2026-09-11 15:26 | C10: Claude for Senthil/KP | D10: Released: D18 shim package source built (sfdx project: CallCenter Open CTI definition, matrix-generated permission sets with drift tests, esbuild softphone bundle from new functional DI Open CTI adapter tested in jsdom) — O2 now turnkey; R-V5 code half closed. 35 suites / 162 tests at 100% zero pragmas. Story position unchanged (88 Done / 8 CC / 2 in progress / 2 drafted, 380/399 pts) — infrastructure release, statuses honest. Companion tracker claude_v005_voicebridge_sprint_tracker_traceability_20260911_1526. | E10: Released
A11: v012 | B11: 2026-09-11 22:09 | C11: Claude for Senthil/KP | D11: Released: cold-review pass 1 — 7 defects fixed with regressions (retention PII leak, missing payment recovery, unenforced trial expiry, unguarded invoices, unbounded ledgers, no-op production backoff, unenforced read-only → new billing write-gate) + 2 observations for disposition; Review_Findings sheet added. 36 suites / 176 tests at 100% zero pragmas. Story position unchanged (88/8/2/2, 380/399). Companion tracker claude_v006_voicebridge_sprint_tracker_traceability_20260911_2209. | E11: Released
A12: v013 | D12: PLANNED: cold-review pass 2 if directed, or live evidence / ratifications / dispositions. | E12: Planned
A13: v013 | B13: 2026-09-11 22:34 | C13: Claude for Senthil/KP | D13: COLD REVIEW COMPLETE (pass 2, all remaining modules) + EXTERNAL VERIFICATION SWEEP vs live Open CTI docs + artifact-gap audit. 13 defects fixed (F-V08..F-V20), 4 verification findings incl. 2 LIVE-BLOCKING (VER-V01/V02), missing /log route built, 2 observations logged for disposition. 39 suites / 217 tests at 100% zero pragmas. Story position unchanged: 88 Done / 8 code-complete / 2 in progress / 2 drafted (380/399). | E13: Released
A14: v014 | B14: 2026-09-13 10:39 | C14: Claude for Senthil/KP | D14: SCREEN SURFACE + OAUTH COMPLIANCE (code v0.14.0; companion tracker v008). GAP-V2 closed — 9 screens specified, 2 existed, 7 built as tested view-models + accessible renderer wired to the live modules and served at /ui; WCAG audit widened from 2 screens to 9 x populated+empty. External verification sweep #2 vs live Salesforce ISV docs: VER-V06 new Connected Apps cannot be created from Spring '26 (the 30-minute dev-org guide was unrunnable as written) — ECA across code, docs and sweep; VER-V07..V09 the four OAuth controls mandatory since 11 May 2026 and enforceable since 25 June 2026 — PKCE + single-use state, 30-day refresh idle timeout, rotation anomaly telemetry, refresh IP allowlist, sweep A9/A10 + operator O5. VER-V10: Checkout is NOT mandatory (ISVforce+COA alternative) — raised as D-V3. F-V21 logged UNFIXED: identity is caller-declared. 41 suites / 274 tests at 100% zero pragmas; story position deliberately unchanged at 88/8/2/2 (380 of 399 pts). | E14: Released
A15: v015 | B15: 2026-09-13 10:57 | C15: Claude for Senthil/KP | D15: ARTIFACT-GAP AUDIT (code v0.15.0; companion tracker v009). 5 gaps, 2 CRITICAL. GAP-V3: no process and no production OAuth gateway — createApp() had never been called by anything and every OAuthGateway was a test double, so the ECA callback, the sweep /health probe, the k6 harness and the softphone's /dial and /log posts all addressed a server that could not be started. GAP-V4: no schema behind the published 30-day retention policy, the ST-090 backup drill and sweep check A5. GAP-V5: CI on end-of-life Node 20. All fixed — server.ts/main.ts/npm start, SfOAuthGateway, 5 ordered migrations + guarded npm run migrate, Node 22. R-V11 logged: the migrations describe the store but the runtime is still in-memory. 42 suites / 296 tests at 100% zero pragmas; story position unchanged at 88/8/2/2 (380 of 399). | E15: Released
A16: v016 | B16: 2026-09-13 11:14 | C16: Claude for Senthil/KP | D16: COLD-REVIEW PASS 3 + IDENTITY BOUNDARY (code v0.16.0; companion tracker v010). Pass 3 over the surfaces the last two releases added found F-V23 — a defect introduced in v0.14.0 where the new /ui routes read the org from the URL and checked nothing, exposing any org's billing, invoices, analytics and support queue to any caller. Fixing it required the boundary F-V21 had been waiting for, so both closed: HMAC-signed sessions minted only at the install callback, identity never taken from body or URL, 401/403 split out of the blanket 400. Plus F-V24 (unbounded PKCE map behind a public route), F-V25 (no token-endpoint timeout), F-V26 (drain waited forever). 43 suites / 318 tests at 100% zero pragmas; story position unchanged at 88/8/2/2 (380 of 399). | E16: Released
A17: v017 | B17: 2026-09-13 11:36 | C17: Claude for Senthil/KP | D17: R-V11 STAGE 1 (code v0.17.0; companion tracker v011). Async Repository interface, InMemoryRepository, PgRepository against the migrations plus 006_sequences.sql, and a conformance suite running the same tests against both implementations. Staged because the conversion measures 91 store call sites across 20 modules and 277 test lines — one pass would leave the D13 gate unrunnable. NOT WIRED: createApp() still builds the sync Store, so R-V11 stays OPEN and stage 1 is not persistence. New operator step O6 gates closure on running the conformance suite against live Postgres. 44 suites / 340 tests at 100% zero pragmas; story position unchanged at 88/8/2/2 (380 of 399). | E17: Released
A18: v018 | B18: 2026-09-13 11:51 | C18: Claude for Senthil/KP | D18: R-V11 STAGE 2 + PLAN CORRECTION (code v0.18.0; companion tracker v012). The v0.17.0 conversion order was backwards — it started with audit/notifications as dependency leaves, but async cascades toward callers, so those are the most expensive modules to convert, not the cheapest. Corrected rule: convert a module only once all its callers are already async, working top-down from the routes. Stage 2 executed under the new order — supportChat.ts and screenData.ts on the async Repository, cascade contained at the route handlers. 44 suites / 340 tests at 100% zero pragmas; 2 of 20 modules converted; R-V11 remains OPEN; story position unchanged at 88/8/2/2. | E18: Released
A19: v019 | B19: 2026-09-13 11:58 | C19: Claude for Senthil/KP | D19: R-V11 STAGE 3 + SECOND PLAN CORRECTION (code v0.19.0; companion tracker v013). Planned stage 3 was vacuous — statusPage, helpCenter, pricingPage and trustPage never touch the store; they were listed because they looked like the right shape, and one grep before coding caught it. Real stage 3 executed: analytics.ts and onboarding.ts on the async Repository, cascade contained at routes/screenData/runbook. New R-V14: createApp() runs a sync Store and a shared InMemoryRepository side by side mid-migration, and backup.ts covers only the former — so the ST-090 drill is incomplete until the migration finishes. 44 suites / 340 tests at 100% zero pragmas; 4 of 20 modules converted; story position unchanged at 88/8/2/2. | E19: Released
A20: v020 | B20: 2026-09-13 12:05 | C20: Claude for Senthil/KP | D20: R-V11 STAGE 4 (code v0.20.0; companion tracker v014). Planned stage 4 (billing.ts) blocked — featureCore calls billing's writeBlocked and is still synchronous, so billing converts after featureCore. Shipped designPartners.ts instead (no src callers). demoMode attempted and reverted: it writes roles the unconverted feature modules read, so converting it alone split the data from its readers and the demo seed 403d — R-V14 made concrete. 44 suites / 340 tests at 100% zero pragmas; 5 of 20 modules converted; story position unchanged at 88/8/2/2. | E20: Released
A21: v021 | B21: 2026-09-13 16:38 | C21: Claude for Senthil/KP | D21: R-V11 STAGE 5 (code v0.21.0; companion tracker v015). The featureCore/permissions cluster — 13 modules — converted to the async Repository as one unit, because the roles, feature state and records they share cannot be split across two stores. createApp() now builds one shared repository; the legacy Store is reduced to PKCE state and the ST-090 snapshot drill, with the rest deleted rather than left dead. F-V27 found mid-conversion: flowActions.invoke() stored a floating promise, so rejections escaped the try/catch that records failed runs and rethrows — the Flow retry contract was silently broken. 44 suites / 340 tests at 100% zero pragmas; 16 of 20 modules converted; story position unchanged at 88/8/2/2. | E21: Released
A22: v022 | B22: 2026-09-13 16:51 | C22: Claude for Senthil/KP | D22: R-V11 STAGE 6 — LEGACY STORE DELETED (code v0.22.0; companion tracker v016). sfAuth PKCE state and backup snapshot/restore moved to the repository; src/store.ts and its test deleted; createApp() builds exactly one store. R-V14 CLOSED — the ST-090 drill now covers all the data. 20 of 20 modules converted across six staged releases; R-V11 code half COMPLETE. Only O6 (conformance suite against live Postgres) stands between it and closure. 43 suites / 339 tests at 100% zero pragmas; story position unchanged at 88/8/2/2. | E22: Released
A23: v023 | B23: 2026-09-13 17:25 | C23: Claude for Senthil/KP | D23: POST-CONVERSION REVIEW — F-V28 (code v0.23.0; companion tracker v017). The R-V11 conversion put an await between the read and the write in four check-then-write guards (cadence limit, duplicate-enrollment, activity dedupe, ten-slot partner cap), so two concurrent requests could both pass the check and both write — a limit of 10 admitting 11, a retried webhook logging twice. The logic never changed; the guarantee the synchronous model provided did. Fixed with a per-(org,resource) serial queue and 11 regressions that fire calls concurrently. F-V19 also found again at module level (cadence ids from a per-instance counter). R-V15 logged: this covers one process, and ST-092 blue/green runs two, so the guards need database enforcement at the PgRepository cutover. 44 suites / 350 tests at 100% zero pragmas; story position unchanged at 88/8/2/2. | E23: Released

Sheet ReadMe_Scope
A1: VoiceBridge CTI — Omnichannel CTI: click-to-dial, call logging, WhatsApp/SMS threads native in Salesforce
A3: PLATFORM: Salesforce AppExchange | CATEGORY: Sales Engagement / Telephony
A4: PROBLEM: Mid-market telephony connectors are either enterprise-priced (NICE/Genesys) or shallow loggers
A5: DIFFERENTIATION: Deep Flow/Einstein integration, transparent per-seat pricing, India+global carrier coverage
A6: ICP: B2B sales orgs 50-500 seats on Sales/Service Cloud, existing telephony spend, RevOps function present
A8: HOW TO USE: Full_Backlog is the single source of truth (edit Status column during execution). Sprint_Board recalculates points per sprint automatically. Financial_Model assumptions (yellow) are editable — the 18-month build recalculates. Launch_Checklist is the platform-specific gate before submission. All costs/timelines are market-standard estimates; verify platform terms (fees/review rules) during S0.
A10: STACK ASSUMPTION (market standard): TypeScript/Node or platform-mandated runtime, React frontends, Postgres, hosted on AWS/GCP/platform FaaS as required, GitHub Actions CI, PostHog + Sentry telemetry, Intercom-class support.

Sheet Product_Spec
A1: PRODUCT SPEC
A3: Module (feature) | B3: Scope in MVP | C3: Out of scope (v1) | D3: Non-functional requirements
A4: Click-to-dial + softphone | B4: Click-to-dial + softphone: end-to-end happy path + edge cases + permissions | C4: Advanced automation, AI beyond listed, multi-language beyond launch set | D4: p95 <500ms API / <2s UI loads
A5: Auto call/WhatsApp logging | B5: Auto call/WhatsApp logging: end-to-end happy path + edge cases + permissions | C5: Advanced automation, AI beyond listed, multi-language beyond launch set | D5: 99.5% monthly uptime
A6: Cadence/sequence lite | B6: Cadence/sequence lite: end-to-end happy path + edge cases + permissions | C6: Advanced automation, AI beyond listed, multi-language beyond launch set | D6: WCAG AA
A7: Coaching analytics | B7: Coaching analytics: end-to-end happy path + edge cases + permissions | C7: Advanced automation, AI beyond listed, multi-language beyond launch set | D7: SOC2-track controls
A8: Flow actions pack | B8: Flow actions pack: end-to-end happy path + edge cases + permissions | C8: Advanced automation, AI beyond listed, multi-language beyond launch set | D8: Rate-limit safe (backoff+queue)
A10: Persona | B10: Jobs-to-be-done
A11: RevOps lead | B11: Evaluates on admin effort, Flow compatibility, reporting
A12: Sales leader (VP) | B12: Buys on rep productivity metrics; needs dashboards
A13: Salesforce admin | B13: Gatekeeper; security review status and permission sets decide the deal

Sheet Screens_Wireframes
A1: SCREEN INVENTORY (attach Figma links in col E during S0)
A3: # | B3: Screen | C3: Purpose | D3: Key elements | E3: Wireframe link | F3: Built (v0.14.0)
A4: 1 | B4: Onboarding / first-run | C4: Reach aha in <1 day | D4: Checklist, sample data toggle, connect steps | F4: YES — /ui SCR-1 (src/views.ts), populated + empty, axe-clean
A5: 2 | B5: Home dashboard | C5: Daily habit surface | D5: KPI cards, activity feed, alerts | F5: YES — /ui SCR-2, degraded banner wired to platformHealth
A6: 3 | B6: Click-to-dial + softphone workspace | C6: Core value surface | D6: List+detail, bulk actions, status chips | F6: YES — widget/softphone.html (in-org Open CTI shell)
A7: 4 | B7: Auto call/WhatsApp logging builder | C7: Configure second pillar | D7: Rule builder, preview, test mode | F7: YES — /ui SCR-4, rules from the live calllogger feature state
A8: 5 | B8: Cadence/sequence lite view | C8: Differentiator surface | D8: Timeline/visual, export | F8: YES — /ui SCR-5, cadences + live enrolment counts
A9: 6 | B9: Settings & team | C9: Roles, notifications, data | D9: Role matrix, API keys, danger zone | F9: YES — widget/settings.html
A10: 7 | B10: Billing | C10: Plan/trial/invoices | D10: Plan cards, usage meter, invoices | F10: YES — /ui SCR-7, plan/seats/invoices + trial countdown
A11: 8 | B11: Analytics | C11: Prove ROI | D11: Funnel, cohort, export | F11: YES — /ui SCR-8, funnel KPIs + usage heatmap
A12: 9 | B12: Help & support | C12: Deflect + assist | D12: Search, chat, status | F12: YES — /ui SCR-9, help articles + open-chat SLA hint
B13: NOTE | C13: GAP-V2: before v0.14.0 only screens 3 and 6 existed, while ST-005/015/025/035/045 claimed the LWC surface worked end to end and ST-079 claimed empty states on every screen. The seven web screens now exist and are audited; whether they ship as LWC bundles in the package or as the static-resource/web surface is D-V2, still open.

Sheet Full_Backlog
A1: FULL BACKLOG
A3: ID | B3: Epic | C3: Story | D3: Points | E3: Priority | F3: Sprint | G3: Status
A4: ST-001 | B4: F1 | C4: As a RevOps lead, I can set up Click-to-dial + softphone with sensible defaults in one screen | D4: 5 | E4: P0 | F4: S2 | G4: Done
A5: ST-002 | B5: F1 | C5: As a RevOps lead, the Click-to-dial + softphone happy path completes without documentation | D5: 8 | E5: P0 | F5: S2 | G5: Done
A6: ST-003 | B6: F1 | C6: As a Sales leader, I can customise Click-to-dial + softphone rules/conditions for my workflow | D6: 5 | E6: P1 | F6: S2 | G6: Done
A7: ST-004 | B7: F1 | C7: As a user, Click-to-dial + softphone shows clear errors and retry paths on platform API failures | D7: 3 | E7: P0 | F7: S2 | G7: Done
A8: ST-005 | B8: F1 | C8: As a Salesforce admin, Click-to-dial + softphone works on the Lightning utility-bar softphone + LWC surface end-to-end | D8: 5 | E8: P0 | F8: S3 | G8: Done
A9: ST-006 | B9: F1 | C9: As a Sales leader, I can see Click-to-dial + softphone performance metrics and trends | D9: 3 | E9: P1 | F9: S3 | G9: Done
A10: ST-007 | B10: F1 | C10: As a user, Click-to-dial + softphone respects role permissions and audit logging | D10: 3 | E10: P1 | F10: S3 | G10: Done
A11: ST-008 | B11: F1 | C11: As a RevOps lead, I can pause/disable Click-to-dial + softphone without data loss | D11: 2 | E11: P2 | F11: S3 | G11: Done
A12: ST-009 | B12: F1 | C12: As a Sales leader, I can import/migrate existing data into Click-to-dial + softphone (CSV + competitor importer) | D12: 5 | E12: P1 | F12: S3 | G12: Done
A13: ST-010 | B13: F1 | C13: As a user, I get notifications (in-app + email) for key Click-to-dial + softphone events with per-type mute | D13: 3 | E13: P2 | F13: S3 | G13: Done
A14: ST-011 | B14: F2 | C14: As a RevOps lead, I can set up Auto call/WhatsApp logging with sensible defaults in one screen | D14: 5 | E14: P0 | F14: S3 | G14: Done
A15: ST-012 | B15: F2 | C15: As a RevOps lead, the Auto call/WhatsApp logging happy path completes without documentation | D15: 8 | E15: P0 | F15: S3 | G15: Done
... A103: ST-100 | B103: EL | C103: First 10 design-partner reviews scheduled | D103: 2 | E103: P1 | F103: S11 | G103: Code-complete (pending live)
A105: Total stories: 100. Epics: F1-F5 = product features; E1 install, E5 billing, E6 compliance, E7 telemetry, E8 onboarding/docs/support, EQ quality. Edit Status (Backlog/In progress/Done) during execution.

Sheet Sprint_Board
A1: SPRINT BOARD — live counts from Full_Backlog
A3: Sprint | B3: Focus | C3: Stories | D3: Points | E3: Done | F3: Exit criteria
A4: S0 | B4: Discovery & Design (2 wks) | C4: =COUNTIF(Full_Backlog!F4:F103,"S0") -> 0 | D4: =SUMIF(Full_Backlog!F4:F103,"S0",Full_Backlog!D4:D103) -> 0 | E4: =COUNTIFS(Full_Backlog!$F$4:$F$103,$A4,Full_Backlog!$G$4:$G$103,"Done")+COUNTIFS(Full_Backlog!$F$4:$F$103,$A4,Full_Backlog!$G$4:$G$103,"Code-complete (pending live)") -> 0 | F4: PRD signed off; prototype tested with 5 target users
A5: S1 | B5: Foundation (2 wks) | C5: =COUNTIF(Full_Backlog!F4:F103,"S1") -> 4 | D5: =SUMIF(Full_Backlog!F4:F103,"S1",Full_Backlog!D4:D103) -> 13 | E5: =COUNTIFS(Full_Backlog!$F$4:$F$103,$A5,Full_Backlog!$G$4:$G$103,"Done")+COUNTIFS(Full_Backlog!$F$4:$F$103,$A5,Full_Backlog!$G$4:$G$103,"Code-complete (pending live)") -> 4 | F5: App installs cleanly in dev store/org; telemetry firing
A6: S2 | B6: Core feature Click-to-dial + softphone - part 1 | C6: =COUNTIF(Full_Backlog!F4:F103,"S2") -> 6 | D6: =SUMIF(Full_Backlog!F4:F103,"S2",Full_Backlog!D4:D103) -> 29 | E6: =COUNTIFS(Full_Backlog!$F$4:$F$103,$A6,Full_Backlog!$G$4:$G$103,"Done")+COUNTIFS(Full_Backlog!$F$4:$F$103,$A6,Full_Backlog!$G$4:$G$103,"Code-complete (pending live)") -> 6 | F6: Click-to-dial + softphone happy path demoable
A7: S3 | B7: Core feature Click-to-dial + softphone - part 2 + Auto call/WhatsApp logging start | C7: =COUNTIF(Full_Backlog!F4:F103,"S3") -> 11 | D7: =SUMIF(Full_Backlog!F4:F103,"S3",Full_Backlog!D4:D103) -> 47 | E7: =COUNTIFS(Full_Backlog!$F$4:$F$103,$A7,Full_Backlog!$G$4:$G$103,"Done")+COUNTIFS(Full_Backlog!$F$4:$F$103,$A7,Full_Backlog!$G$4:$G$103,"Code-complete (pending live)") -> 11 | F7: Click-to-dial + softphone complete with tests; Auto call/WhatsApp logging skeleton
A8: S4 | B8: Core feature Auto call/WhatsApp logging | C8: =COUNTIF(Full_Backlog!F4:F103,"S4") -> 9 | D8: =SUMIF(Full_Backlog!F4:F103,"S4",Full_Backlog!D4:D103) -> 34 | E8: =COUNTIFS(Full_Backlog!$F$4:$F$103,$A8,Full_Backlog!$G$4:$G$103,"Done")+COUNTIFS(Full_Backlog!$F$4:$F$103,$A8,Full_Backlog!$G$4:$G$103,"Code-complete (pending live)") -> 9 | F8: MVP loop usable end-to-end internally
A9: S5 | B9: Feature Cadence/sequence lite + alpha hardening | C9: =COUNTIF(Full_Backlog!F4:F103,"S5") -> 12 | D9: =SUMIF(Full_Backlog!F4:F103,"S5",Full_Backlog!D4:D103) -> 50 | E9: =COUNTIFS(Full_Backlog!$F$4:$F$103,$A9,Full_Backlog!$G$4:$G$103,"Done")+COUNTIFS(Full_Backlog!$F$4:$F$103,$A9,Full_Backlog!$G$4:$G$103,"Code-complete (pending live)") -> 12 | F9: Internal alpha: team dogfoods daily
A10: S6 | B10: Billing + Coaching analytics | C10: =COUNTIF(Full_Backlog!F4:F103,"S6") -> 13 | D10: =SUMIF(Full_Backlog!F4:F103,"S6",Full_Backlog!D4:D103) -> 60 | E10: =COUNTIFS(Full_Backlog!$F$4:$F$103,$A10,Full_Backlog!$G$4:$G$103,"Done")+COUNTIFS(Full_Backlog!$F$4:$F$103,$A10,Full_Backlog!$G$4:$G$103,"Code-complete (pending live)") -> 13 | F10: Can charge a test customer; upgrade/downgrade paths work
A11: S7 | B11: Private beta (design partners) | C11: =COUNTIF(Full_Backlog!F4:F103,"S7") -> 5 | D11: =SUMIF(Full_Backlog!F4:F103,"S7",Full_Backlog!D4:D103) -> 15 | E11: =COUNTIFS(Full_Backlog!$F$4:$F$103,$A11,Full_Backlog!$G$4:$G$103,"Done")+COUNTIFS(Full_Backlog!$F$4:$F$103,$A11,Full_Backlog!$G$4:$G$103,"Code-complete (pending live)") -> 5 | F11: 3+ partners active weekly; NPS pulse >30
A12: S8 | B12: Beta iteration + Flow actions pack | C12: =COUNTIF(Full_Backlog!F4:F103,"S8") -> 22 | D12: =SUMIF(Full_Backlog!F4:F103,"S8",Full_Backlog!D4:D103) -> 87 | E12: =COUNTIFS(Full_Backlog!$F$4:$F$103,$A12,Full_Backlog!$G$4:$G$103,"Done")+COUNTIFS(Full_Backlog!$F$4:$F$103,$A12,Full_Backlog!$G$4:$G$103,"Code-complete (pending live)") -> 22 | F12: Retention of beta cohort week-over-week >60%
A13: S9 | B13: Marketplace review prep | C13: =COUNTIF(Full_Backlog!F4:F103,"S9") -> 7 | D13: =SUMIF(Full_Backlog!F4:F103,"S9",Full_Backlog!D4:D103) -> 30 | E13: =COUNTIFS(Full_Backlog!$F$4:$F$103,$A13,Full_Backlog!$G$4:$G$103,"Done")+COUNTIFS(Full_Backlog!$F$4:$F$103,$A13,Full_Backlog!$G$4:$G$103,"Code-complete (pending live)") -> 4 | F13: Review submission accepted into queue
A14: S10 | B14: Review remediation + docs | C14: =COUNTIF(Full_Backlog!F4:F103,"S10") -> 7 | D14: =SUMIF(Full_Backlog!F4:F103,"S10",Full_Backlog!D4:D103) -> 24 | E14: =COUNTIFS(Full_Backlog!$F$4:$F$103,$A14,Full_Backlog!$G$4:$G$103,"Done")+COUNTIFS(Full_Backlog!$F$4:$F$103,$A14,Full_Backlog!$G$4:$G$103,"Code-complete (pending live)") -> 6 | F14: Marketplace approval obtained (or final remediation cycle)
A15: S11 | B15: Launch | C15: =COUNTIF(Full_Backlog!F4:F103,"S11") -> 3 | D15: =SUMIF(Full_Backlog!F4:F103,"S11",Full_Backlog!D4:D103) -> 8 | E15: =COUNTIFS(Full_Backlog!$F$4:$F$103,$A15,Full_Backlog!$G$4:$G$103,"Done")+COUNTIFS(Full_Backlog!$F$4:$F$103,$A15,Full_Backlog!$G$4:$G$103,"Code-complete (pending live)") -> 3 | F15: First 10 installs; first 3 reviews; activation >40%
A16: S12 | B16: Iterate & scale decision | C16: =COUNTIF(Full_Backlog!F4:F103,"S12") -> 1 | D16: =SUMIF(Full_Backlog!F4:F103,"S12",Full_Backlog!D4:D103) -> 2 | E16: =COUNTIFS(Full_Backlog!$F$4:$F$103,$A16,Full_Backlog!$G$4:$G$103,"Done")+COUNTIFS(Full_Backlog!$F$4:$F$103,$A16,Full_Backlog!$G$4:$G$103,"Code-complete (pending live)") -> 1 | F16: Growth model doc with CAC/LTV first estimates
B17: TOTAL | C17: =SUM(C4:C16) -> 100 | D17: =SUM(D4:D16) -> 399 | E17: =SUM(E4:E16) -> 96
B18: Velocity check: points/sprint S2-S8 should sit within 30-45 for a 4-6 person team; rebalance Sprint column in backlog if a sprint exceeds capacity.

Sheet Financial_Model
A1: 18-MONTH FINANCIAL MODEL — Salesforce: enterprise pilot-led (edit yellow assumptions)
A3: Assumption | B3: Value
A4: Qualified pilots/mo (month 1) | B4: 4
A5: Monthly growth of that | B5: 0.1
A6: Pilot->paid % | B6: 0.3
A7: ARPU $/mo | B7: 600
A8: Monthly churn | B8: 0.012
A9: Marketplace fee | B9: 0.15
A10: Team cost month 1 (India-lean $) | B10: 40000
A11: Cost growth/mo | B11: 0.03
A12: Fee note: 15% PNR to Salesforce on net revenue
A14: Line | B14: M1 | C14: M2 | D14: M3 | E14: M4 | F14: M5 | G14: M6 | H14: M7 | I14: M8 | J14: M9 | K14: M10 | L14: M11 | M14: M12 | N14: M13 | O14: M14 | P14: M15 | Q14: M16 | R14: M17 | S14: M18
A15: Leads/installs | B15: =$B$4 -> 4 | C15: =B15*(1+$B$5) -> 4.4 | D15: =C15*(1+$B$5) -> 4.84 | E15: =D15*(1+$B$5) -> 5.324 | F15: =E15*(1+$B$5) -> 5.8564 | G15: =F15*(1+$B$5) -> 6.44204 | H15: =G15*(1+$B$5) -> 7.086244 | I15: =H15*(1+$B$5) -> 7.7948684 | J15: =I15*(1+$B$5) -> 8.5743552 | ... S15: =R15*(1+$B$5) -> 20.217881
A16: New paying | B16: =ROUND(B15*$B$6,1) -> 1.2 | C16: =ROUND(C15*$B$6,1) -> 1.3 | D16: =ROUND(D15*$B$6,1) -> 1.5 | E16: =ROUND(E15*$B$6,1) -> 1.6 | F16: =ROUND(F15*$B$6,1) -> 1.8 | G16: =ROUND(G15*$B$6,1) -> 1.9 | H16: =ROUND(H15*$B$6,1) -> 2.1 | I16: =ROUND(I15*$B$6,1) -> 2.3 | ... S16: =ROUND(S15*$B$6,1) -> 6.1
A17: Paying accounts | B17: =B16 -> 1.2 | C17: =ROUND(B17*(1-$B$8)+C16,1) -> 2.5 | D17: =ROUND(C17*(1-$B$8)+D16,1) -> 4 | E17: =ROUND(D17*(1-$B$8)+E16,1) -> 5.6 | F17: =ROUND(E17*(1-$B$8)+F16,1) -> 7.3 | G17: =ROUND(F17*(1-$B$8)+G16,1) -> 9.1 | H17: =ROUND(G17*(1-$B$8)+H16,1) -> 11.1 | I17: =ROUND(H17*(1-$B$8)+I16,1) -> 13.3 | J17: =ROUND(I17*(1-$B$8)+J16,1) -> 15.7 | ... S17: =ROUND(R17*(1-$B$8)+S16,1) -> 51
A18: MRR (net of fee) | B18: =ROUND(B17*$B$7*(1-$B$9),0) -> 612 | C18: =ROUND(C17*$B$7*(1-$B$9),0) -> 1275 | D18: =ROUND(D17*$B$7*(1-$B$9),0) -> 2040 | E18: =ROUND(E17*$B$7*(1-$B$9),0) -> 2856 | F18: =ROUND(F17*$B$7*(1-$B$9),0) -> 3723 | G18: =ROUND(G17*$B$7*(1-$B$9),0) -> 4641 | H18: =ROUND(H17*$B$7*(1-$B$9),0) -> 5661 | I18: =ROUND(I17*$B$7*(1-$B$9),0) -> 6783 | ... S18: =ROUND(S17*$B$7*(1-$B$9),0) -> 26010
A19: Team cost | B19: =$B$10 -> 40000 | C19: =ROUND(B19*(1+$B$11),0) -> 41200 | D19: =ROUND(C19*(1+$B$11),0) -> 42436 | E19: =ROUND(D19*(1+$B$11),0) -> 43709 | F19: =ROUND(E19*(1+$B$11),0) -> 45020 | G19: =ROUND(F19*(1+$B$11),0) -> 46371 | H19: =ROUND(G19*(1+$B$11),0) -> 47762 | I19: =ROUND(H19*(1+$B$11),0) -> 49195 | J19: =ROUND(I19*(1+$B$11),0) -> 50671 | ... S19: =ROUND(R19*(1+$B$11),0) -> 66115
A20: Net cash/mo | B20: =B18-B19 -> -39388 | C20: =C18-C19 -> -39925 | D20: =D18-D19 -> -40396 | E20: =E18-E19 -> -40853 | F20: =F18-F19 -> -41297 | G20: =G18-G19 -> -41730 | H20: =H18-H19 -> -42101 | I20: =I18-I19 -> -42412 | ... S20: =S18-S19 -> -40105
A21: Cumulative | B21: =B20 -> -39388 | C21: =B21+C20 -> -79313 | D21: =C21+D20 -> -119709 | E21: =D21+E20 -> -160562 | F21: =E21+F20 -> -201859 | G21: =F21+G20 -> -243589 | H21: =G21+H20 -> -285690 | I21: =H21+I20 -> -328102 | J21: =I21+J20 -> -370766 | ... S21: =R21+S20 -> -750126
A23: Reading: churn applies before adds; MRR nets the marketplace fee; costs use India-lean base from Team_Roles_Budget (v004). Breakeven = first month Net cash ≥ 0. This is a planning model, not a forecast — replace assumptions with S7-S8 beta actuals.

Sheet GTM_Execution
A1: GTM EXECUTION TASKS
A3: Phase | B3: Task | C3: Owner (role) | D3: Target sprint
A4: Pre-launch | B4: Positioning doc + message house (problem/promise/proof) | C4: Founder | D4: S7
A5: Pre-launch | B5: Listing SEO: keyword study in marketplace search + title/intro drafts | C5: Growth | D5: S8
A6: Pre-launch | B6: 10 design-partner mini case snippets with metric proof | C6: Founder | D6: S8
A7: Pre-launch | B7: 5 comparison/alternative pages drafted | C7: Growth | D7: S9
A8: Pre-launch | B8: Screenshots (5) + 2-min demo video produced | C8: Design | D8: S9
A9: Launch | B9: Listing live + launch post + video published | C9: Growth | D9: S11
A10: Launch | B10: Founder outreach: 100 named ICP accounts, 3-touch sequence | C10: Founder | D10: S11
A11: Launch | B11: Community value-posts (3 relevant communities) | C11: Founder | D11: S11
A12: Launch | B12: Review-generation program on (in-app ask post-aha) | C12: Eng | D12: S11
A13: Post-launch | B13: Weekly SEO/how-to content cadence starts | C13: Growth | D13: S12
A14: Post-launch | B14: Marketplace paid placement pilot (where offered) | C14: Growth | D14: S12
... A16: Post-launch | B16: G2/Capterra profiles + first 10 reviews | C16: Growth | D16: S12+

Sheet Launch_Checklist
A1: PLATFORM LAUNCH CHECKLIST — Salesforce AppExchange
A3: # | B3: Item | C3: Status
A4: 1 | B4: ISV Partner Program application + agreement executed | C4: Open
A5: 2 | B5: Developer/scratch orgs + managed package namespace registered | C5: Open — VER-V06: EXTERNAL CLIENT APP, not Connected App (creation withdrawn in Spring '26); ECAs are packageable
A6: 3 | B6: AppExchange Security Review: pen-test evidence, code scan clean, Trust questionnaire | C6: Open — VER-V07..V09: four mandatory OAuth controls implemented/configured; O5 self-attestation owed; $999 per paid-app submission; F-V21 open review-blocker | GAP-V3/V4 closed (runnable service + schema); R-V11 (in-memory runtime) and F-V21 (caller-declared identity) remain open review-blockers | F-V21/F-V23 CLOSED (identity boundary shipped v0.16.0). R-V11 (in-memory runtime) is the last open review-blocker.
A7: 4 | B7: Open CTI / Service Cloud Voice compatibility decision documented | C7: Open — D18 recommendation stands; surface question re-opened as D-V2 (LWC vs static-resource)
A8: 5 | B8: Permission sets + profiles install experience tested in 3 org shapes | C8: Open
A9: 6 | B9: Data residency: Hyperforce region support statement | C9: Open
A10: 7 | B10: Managed package upgrade path tested (push upgrades) | C10: Open
A11: 8 | B11: AppExchange listing: demo org, video, security tab complete | C11: Open
A12: 9 | B12: Pricing: per-seat tiers + annual; PNR reporting process set up | C12: Open — VER-V10: Checkout NOT mandatory; ISVforce+COA alternative; 15% rev share (25% OEM), ~$150/yr renewal. D-V3 open
A13: 10 | B13: 2 lighthouse customers referenced (logo permission) before listing | C13: Open

Sheet Metrics_Targets
A1: METRIC TARGETS (first 12 months post-launch)
A3: Metric | B3: M1 | C3: M3 | D3: M6 | E3: M12 | F3: Notes
A4: Installs/signups cumulative | B4: varies | C4: 3x M1 | D4: 8x M1 | E4: 20x M1 | F4: Drive via listing SEO + outbound
A5: Activation % (24h) | B5: 30% | C5: 40% | D5: 45% | E5: 50% | F5: Onboarding iterations S12+
A6: Trial→paid % | B6: baseline | C6: +2pts | D6: +4pts | E6: +6pts | F6: Pricing test at S12
A7: Rating | B7: 4.5+ | C7: 4.6+ | D7: 4.7+ | E7: 4.7+ | F7: Review program + support speed
A8: MRR | B8: first $ | C8: 3x | D8: 8x | E8: 20x | F8: Model sheet has the math
A9: Logo churn/mo | B9: <5% | C9: <4% | D9: <3% | E9: <3% | F9: Health-score saves

Sheet Risk_Register
A1: PRODUCT RISK REGISTER
A3: Risk | B3: Impact | C3: Likelihood | D3: Mitigation
A4: Security review cycles exceed 2 iterations (3+ months delay) | B4: High | C4: High | D4: Specialist review consultant pre-submission; scopes austerity
A5: Service Cloud Voice bundling squeezes third-party CTI | B5: High | C5: Medium | D5: Mid-market focus + WhatsApp/SMS omnichannel angle SCV lacks
A6: Enterprise sales cycle vs cash runway | B6: High | C6: Medium | D6: Paid pilots; annual prepay; partner-sourced deals
A7: R-V9 | B7: Platform-policy drift is invisible to the test suite — VER-V06..V09 were correct code against a platform that had moved (Connected App creation withdrawn, four OAuth controls mandated and enforced since 25 Jun 2026). 100% coverage and two cold-review passes found none of it. | C7: High / High | D7: Docs-verification sweep is a standing step before any live day and before submission.
A8: R-V10 | B8: AppExchange listing lead time is 5-9 months end to end for a first-time ISV, plus $999 per paid-app security review and ~$150 annual renewal — so G-01 and G-02 are months out regardless of code completeness. | C8: High / High | D8: Feed directly into D15; start LC-1 now since it gates everything downstream.
A9: R-V11 | B9: The migrations describe the store; the runtime is still the in-memory Store. Nothing reads or writes Postgres yet, so every cap, purge, role and entitlement is process-local and dies on restart, and the published 30-day retention policy has no durable enforcement. db/migrations/ must not be mistaken for persistence. | C9: High / High | D9: docs/runtime-and-schema.md states it explicitly. Sequence the Postgres adapter with the F-V21 auth boundary before any pilot holding real customer data.
A10: R-V12 | B10: Every deploy now requires VB_SESSION_SECRET (32+ chars) alongside the Salesforce credentials and DATABASE_URL. The service refuses to boot without it, deliberately — a shared or default session secret would let anyone mint an owner session for any org. Rotating it invalidates every live session. | C10: Medium / High | D10: Generate with `openssl rand -base64 32`, store in the deploy secret manager, and rotate only during a maintenance window.
A11: R-V13 | B11: PgRepository is verified against a recording double, not a live database. The double proves the right statements are sent; it cannot prove Postgres enforces the FIFO cap, the ON DELETE CASCADE or the atomic counter — the three behaviours the design rests on. | C11: Medium / High | D11: Operator step O6: run the conformance suite against live Postgres before R-V11 is called closed.
A12: R-V14 | B12: Transitional split-brain during the R-V11 migration: createApp() builds both a synchronous Store (18 unconverted modules) and a shared InMemoryRepository (4 converted). backup.ts snapshots the Store only, so support tickets, funnel events and onboarding progress sit outside the ST-090 backup/restore drill until the migration completes. | C12: Medium / High | D12: CLOSED v0.22.0 — the legacy Store is deleted, so no part of the data sits outside the ST-090 drill.
A13: R-V15 | B13: The F-V28 guards are serialised in-process only. ST-092 blue/green runs two instances at once, where an in-process lock does nothing: the caps and the dedupe fail again. | C13: High / High | D13: Database enforcement at the PgRepository cutover — unique index for the dedupe, SELECT..FOR UPDATE or a counted constraint for the caps. Do not run blue/green with real tenants before this.
A14: R-V16 | B14: dialer.ts still mints call ids from a per-instance counter, the same shape as the cadence defect fixed in v0.23.0. Harmless today because call ids are not cross-record keys; breaks the moment two processes run. | C14: Low / Medium | D14: Move to repository nextSeq alongside the R-V15 work.

Sheet Sprint_Tracker_Log
A1: SPRINT TRACKER LOG — mirrored from tracker v001 (same release, 2026-09-10 23:00)
A2: Live log of record: claude_v001_voicebridge_sprint_tracker_traceability_20260910_2300.xlsx
A3: ID | B3: Date/Time | C3: Sprint | D3: What happened | E3: Refs | F3: State changes | G3: Blockers | H3: Next
A4: E001 | B4: 2026-09-10 23:00 | C4: — | D4: D17 RECORDED — Senthil instruction 23:00: 'continue work as per sprint... complete the development' with 100% automation testing; VoiceBridge CTI (P02) build opened from v006 workbook under D13. Ninth concurrent build; D15 (sequencing mode) still open. | E4: D13,D15,D17 | F4: VoiceBridge S1 opened | G4: None | H4: S1 build
A5: E002 | B5: 2026-09-10 23:00 | C5: S1 | D5: S1 FOUNDATION BUILT (TypeScript/Node/Express per v006 stack assumption, D18): config w/ secrets fail-fast + Hyperforce region, typed Store repository (R-V4), Connected-App OAuth install→welcome, uninstall token-wipe + retention-scheduled deletion sweep, rotation-safe token refresh, install source attribution. | E5: ST-051,ST-052,ST-055,ST-056 | F5: 4 S1 stories Done-in-code (13 pts) | G5: Live dev-org install = Senthil (ISV agreement + Connected App) | H5: E003
A6: E003 | B6: 2026-09-10 23:00 | C6: S2 | D6: S2 CORE PT-1 — click-to-dial dial state machine (dialing→connected→ended/failed, outcome capture, E.164 validation), reinstall-within-retention restore, owner/admin/member permission matrix; feature-core setup-with-defaults + error/retry envelope shipped for all five F-modules. | E6: ST-001..004,ST-053,ST-054 | F6: 6 S2 stories Done (29 pts) | G6: None | H6: E004
A7: E004 | B7: 2026-09-10 23:00 | C7: S3 | D7: S3 CORE PT-2 + F2 START — F1 completed (utility-bar surface, metrics, permissions+audit, pause-no-data-loss, import, notifications); auto call/WhatsApp logging built: provider-event ingestion deduped by externalId → activity records, contact threads; D13 coverage gate story closed (100% supersedes >=70%). | E7: ST-005..014,ST-085 | F7: 11 S3 stories Done (47 pts) | G7: None | H7: E005
A8: E005 | B8: 2026-09-10 23:00 | C8: S4 | D8: S4 MVP LOOP — F2 completed; activation funnel (install→setup→aha→habit), release-tagged error tracking + spike alert, E2E smoke suite wired as CI deploy gate. MVP loop (install→setup→dial→auto-log) usable end-to-end in E2E harness. | E8: ST-015..020,ST-071,ST-072,ST-086 | F8: 9 S4 stories Done (34 pts) | G8: None | H8: E006
A9: E006 | B9: 2026-09-10 23:00 | C9: S5 | D9: S5 CADENCE + ALPHA HARDENING — cadence/sequence lite: step sequences w/ cumulative delays, enrollment, due-step engine, advance-to-complete; first-run checklist reaching aha at 3/4 steps; teaching empty states on all surfaces. | E9: ST-021..030,ST-078,ST-079 | F9: 12 S5 stories Done (50 pts) | G9: Internal dogfood needs live org | H9: E007
A10: E007 | B10: 2026-09-10 23:00 | C10: S6 | D10: S6 BILLING + COACHING — coaching scorecards (connect rate, avg duration, leaderboard, zero-guards); 14-day no-card trial + banner; mid-cycle proration. ST-059 provider abstraction (AppExchange Checkout | Stripe fallback) CODE-COMPLETE — live Checkout wiring needs ISV agreement. | E10: ST-031..040,ST-057..059 | F10: 12 Done + 1 code-complete (60 pts) | G10: ISV agreement = Senthil | H10: E008
A11: E008 | B11: 2026-09-10 23:00 | C11: S7 | D11: S7 BILLING EDGE + TRUST — dunning (7d grace, 3 emails, read-only), plan limits w/ 80%/100% prompts, GST/VAT invoices, cancellation save-offer + exit survey; least-privilege scope map doc (scopes 1:1 features). | E11: ST-060..064 | F11: 5 S7 stories Done (15 pts) | G11: None | H11: E009
A12: E009 | B12: 2026-09-10 23:00 | C12: S8 | D12: S8 FLOW PACK + SCALE — Flow actions pack (StartCall / EnrollInCadence / SendNotification invocables, validated inputs, run ledger incl. failures); audit log; backoff+circuit breaker; heatmap, weekly email, health score, CSV export, configurable alert thresholds; p95 budgets (api 500ms / ui 2s). ST-082 review-ask + ST-069 export/delete-my-data pulled early. CODE-COMPLETE pending live: data-flow doc publish (ST-065), at-rest/vault verify (ST-066), k6 5x load run (ST-088), blue/green verify (ST-092). | E12: ST-041..050,ST-065..067,ST-069,ST-070,ST-073..077,ST-082,ST-087,ST-088,ST-092 | F12: 18 Done + 4 code-complete (87 pts) + 2 pulled-early stories | G12: Live infra = Senthil | H12: E010
A13: E010 | B13: 2026-09-10 23:00 | C13: — | D13: D13 TEST GATE MET — 20 Jest suites / 85 tests, coverage 100% statements/branches/functions/lines (jest coverageThreshold 100x4, CI-enforced); tsc --noEmit clean; E2E smoke + blue/green jobs in ci.yml; k6 harness at load/k6-load.js. | E13: D13 | F13: Evidence in Traceability col K | G13: None | H13: E011
A14: E011 | B14: 2026-09-10 23:00 | C14: — | D14: RELEASE — this tracker v001 + product workbook v007 (Full_Backlog statuses updated; Sprint_Board Done counts now live COUNTIFS; tracker sheets embedded). Next sprint S9 (marketplace review prep) blocked on live-org items. | E14: D17 | F14: v001 + v007 released | G14: S1-live items; D15; D18 | H14: v002
... A35: E032 | B35: 2026-09-11 22:34 | C35: — | D35: D13 GATE RE-MET + RELEASE — 39 Jest suites / 217 tests, 100% statements/branches/functions/lines, zero pragmas (was 36/176). Static resource bundle and permission sets regenerated from source; story position deliberately unchanged (88 Done / 8 code-complete / 2 in progress / 2 drafted, 380/399) — this release is correctness, not new stories. | E35: D13 | F35: v007 + v013 released | G35: All remaining items Senthil-side | H35: v008
A36: SPRINT TRACKER LOG — every execution event, newest last
A37: E033 | B37: 2026-09-13 09:59 | C37: — | D37: CONTINUE directive 09:59 — plan approved 10:25. Baseline re-verified before any change: npm ci + full suite on v013 reproduced the tracker exactly (39 suites / 217 tests / 100% / zero pragmas, 88 Done / 8 CC / 2 IP / 2 Drafted, 380 of 399 pts). | E37: D13 | F37: Sprint opened on verified baseline | G37: None | H37: E034
A38: E034 | B38: 2026-09-13 10:25 | C38: — | D38: GAP-V2 FOUND AND CLOSED — Screens_Wireframes specifies 9 screens; the codebase shipped 2 (widget/softphone.html, widget/settings.html) while ST-005/015/025/035/045 (5 P0, 25 pts) claimed the Lightning utility-bar + LWC surface worked end to end, ST-079 claimed empty states on EVERY screen, and ST-089 claimed a WCAG pass on 'primary flows'. Built the 7 missing screens as typed view-models + one accessible renderer (src/views.ts), an adapter reading the live store/modules (src/screenData.ts) so they are a real surface not a self-tested module, and /ui routes. WCAG audit now covers 9 screens x populated+empty (18 axe assertions). One unreachable defensive branch deleted rather than pragma'd. | E38: GAP-V2,ST-079,ST-089,ST-x5 | F38: 7 screens built; a11y 2→9 screens | G38: D-V2 (LWC vs static-resource surface) = Senthil | H38: E035
A39: E035 | B39: 2026-09-13 10:39 | C39: — | D39: EXTERNAL VERIFICATION SWEEP #2 vs live Salesforce ISV docs — 5 findings, 1 of them structural. VER-V06: new Connected Apps cannot be created as of Spring '26; External Client Apps are the only path for a new ISV integration. Step 2 of the 30-minute dev-org guide was therefore not executable in any org today, and sweep A1/A2 + operator O1 + the data-flow diagram all encoded it. VER-V07..V09: four OAuth controls became mandatory for every partner CA/ECA on 11 May 2026, enforceable by interoperability suspension since 25 June 2026 — PKCE (missing from our code), refresh-token rotation, a 30-day refresh idle timeout (missing), and a refresh-token IP allowlist (missing). All fixed with pinned regressions. Invisible to 100% coverage and to two cold-review passes because nothing was wrong IN the code — it was wrong about the platform (FlowCast VER-001 / OnCall VER-OC1 class). | E39: VER-V06..V09 | F39: PKCE+state, idle timeout, rotation telemetry, IP allowlist; ECA across code+docs+sweep | G39: O5 self-attestation + ECA build = Senthil | H39: E036
A40: E036 | B40: 2026-09-13 10:39 | C40: — | D40: VER-V10 COMMERCIAL VERIFICATION — AppExchange Checkout is NOT mandatory for a paid listing. The alternative is an ISVforce licence agreement with each order reported via the Channel Order Application (COA). Revenue share 15% ISVforce / 25% OEM; $999 security-review fee per paid-app submission; ~$150 annual listing renewal; 5-9 months typical end-to-end for a first listing. ST-059's provider abstraction already covers both; what was missing was the decision. Raised as D-V3 and fed into LC-1/LC-9 and the D15 sequencing math. | E40: VER-V10,ST-059,LC-1,LC-9,D15 | F40: D-V3 raised | G40: Checkout vs ISVforce+COA = Senthil | H40: E037
A41: E037 | B41: 2026-09-13 10:39 | C41: — | D41: F-V21 LOGGED UNFIXED (High) — identity is caller-declared: every route takes userId from the request body and assertCan trusts it, so anyone who knows an orgId and an owner's userId acts as owner. Same class as MeetSync M-F11. AppExchange security review would fail on it. Deliberately NOT patched in this release: it needs a signed-session boundary across ~20 routes, which is a release of its own. Senthil directed 'continue' (not 'continue + auth') at 10:39, so it stands as his open disposition. | E41: F-V21 | F41: Logged, not fixed | G41: Senthil decision: schedule the auth-boundary release | H41: E038
A42: E038 | B42: 2026-09-13 10:39 | C42: — | D42: D13 GATE RE-MET + RELEASE — 41 Jest suites / 274 tests, 100% statements/branches/functions/lines, zero pragmas. Story position deliberately UNCHANGED at 88 Done / 8 code-complete / 2 in progress / 2 drafted (380 of 399 pts): this is a correctness and surface release, and the 5 surface stories stay as they were until D-V2 is ratified and the org proves them. Tracker v008 + workbook v014 + code v0.14.0 released. | E42: D13 | F42: v008 + v014 + v0.14.0 released | G42: All remaining items Senthil-side | H42: v009
A43: E039 | B43: 2026-09-13 10:57 | C43: — | D43: CONTINUE directive 10:57 — ARTIFACT-GAP AUDIT opened, applying the sibling class that found OnCall GAP-OC1/OC2 and EngageOS GAP-E1/E2: for every artefact the docs, sweep, CI, k6 harness and manifests reference, does the thing actually exist? | E43: GAP-V3..V5 | F43: Audit opened | G43: None | H43: E040
A44: E040 | B44: 2026-09-13 10:57 | C44: — | D44: GAP-V3 CRITICAL — NO PROCESS. createApp() has existed since S1 and nothing in the repo ever called listen(); there was also no production OAuthGateway, only test doubles. So the ECA callback URL, sweep check A7's /health probe, the k6 harness, and the softphone's /dial and /log posts all pointed at a server that could not be started, and the install flow the dev-org guide describes had no code path at all. FIXED — src/server.ts (PORT-aware start(), logs on listen, drains on SIGTERM/SIGINT), src/main.ts one-line entry, src/sfGateway.ts real token-endpoint client sending code_verifier with 5xx-retryable/4xx-terminal classification, npm start + npm run dev. 12 regressions incl. a real request over the real transport against a real listening port. | E44: GAP-V3,ST-051,ST-086 | F44: Service is runnable; 30-min guide executable end to end | G44: None | H44: E041
A45: E041 | B45: 2026-09-13 10:57 | C45: — | D45: GAP-V4 CRITICAL — NO SCHEMA. Sweep check A5 demanded DATABASE_URL, backup.ts ran a backup/restore drill and lifecycle.sweep() implemented the published 30-day deletion policy — every one of them against an in-memory Map. FIXED — 5 ordered migrations (orgs, org_tokens, org_roles, org_records with per-(org,kind) monotonic seq, org_record_drops, pkce_states, schema_migrations), npm run migrate, and a tested planner enforcing filename order, never-re-run, and checksum-drift-is-a-hard-error. Every org-scoped table cascades on delete so the F-V01/F-V08 breach class cannot recur at the storage layer. 8 regressions. | E45: GAP-V4,ST-052,ST-090,R-V4 | F45: Schema exists and is applied by a guarded runner | G45: R-V11: runtime still in-memory | H45: E042
A46: E042 | B46: 2026-09-13 10:57 | C46: — | D46: GAP-V5 — CI pinned Node 20 on both jobs; Node 20 reached end of life in April 2026 and the local toolchain already runs 22. FIXED with a regression that fails the build if a past-EOL pin returns. Same staleness class as TestPulse's nodejs20→22 and VoiceBridge's own VER-V04 sourceApiVersion 61.0→67.0. | E46: GAP-V5 | F46: CI on Node 22 | G46: None | H46: E043
A47: E043 | B47: 2026-09-13 10:57 | C47: — | D47: R-V11 LOGGED, NOT HIDDEN — the migrations describe the store; the running code still uses the in-memory Store. Nothing reads or writes Postgres yet, because the swap means making the repository async across every module. docs/runtime-and-schema.md says so in terms: the presence of db/migrations/ must not be read as persistence. Until the adapter lands, every cap, purge, role and entitlement is process-local and dies on restart (MeetSync OBS-M3 class). Shipping the schema without saying this would have created exactly the artifact-vs-code gap this audit exists to close. | E47: R-V11,R-V4 | F47: Divergence documented | G47: Adapter + F-V21 both owed before a real-data pilot | H47: E044
A48: E044 | B48: 2026-09-13 10:57 | C48: — | D48: D13 GATE RE-MET + RELEASE — 42 Jest suites / 296 tests, 100% statements/branches/functions/lines, zero pragmas (the one entry-point istanbul-ignore written during the sprint was removed in favour of a one-line main.ts that the suite actually starts). Story position unchanged at 88 Done / 8 code-complete / 2 in progress / 2 drafted (380 of 399) — infrastructure, not stories. Tracker v009 + workbook v015 + code v0.15.0 released. | E48: D13 | F48: v009 + v015 + v0.15.0 released | G48: All remaining items Senthil-side | H48: v010
... A81: E077 | B81: 2026-09-13 17:25 | C81: — | D81: D13 GATE RE-MET + RELEASE — 44 Jest suites / 350 tests, 100% statements/branches/functions/lines, zero pragmas. Story position unchanged at 88 Done / 8 code-complete / 2 in progress / 2 drafted (380 of 399). Tracker v017 + workbook v023 + code v0.23.0. | E81: D13 | F81: v017 + v023 + v0.23.0 | G81: O6 and R-V15 both need live Postgres | H81: v018

Sheet Traceability_Matrix
A1: TRACEABILITY MATRIX — 100 stories: module → epic → story → sprint → verification → status → evidence
A2: Source: Full_Backlog (single source of truth). Status values: Done | Code-complete (pending live) | Backlog.
A3: Story ID | B3: Epic | C3: Module / feature | D3: Story | E3: Points | F3: Priority | G3: Sprint | H3: Primary screen | I3: Verification | J3: Status | K3: Evidence
A4: ST-001 | B4: F1 | C4: Click-to-dial + softphone | D4: As a RevOps lead, I can set up Click-to-dial + softphone with sensible defaults in one screen | E4: 5 | F4: P0 | G4: S2 | H4: SCR-3 Call workspace | I4: Automated (Jest, 100% cov) + E2E smoke | J4: Done | K4: src/dialer.ts.setup defaults + featureCore — dialer.test.ts
A5: ST-002 | B5: F1 | C5: Click-to-dial + softphone | D5: As a RevOps lead, the Click-to-dial + softphone happy path completes without documentation | E5: 8 | F5: P0 | G5: S2 | H5: SCR-3 Call workspace | I5: Automated (Jest, 100% cov) + E2E smoke | J5: Done | K5: src/dialer.ts happy-path state machine — dialer.test.ts + app.e2e.test.ts
A6: ST-003 | B6: F1 | C6: Click-to-dial + softphone | D6: As a Sales leader, I can customise Click-to-dial + softphone rules/conditions for my workflow | E6: 5 | F6: P1 | G6: S2 | H6: SCR-3 Call workspace | I6: Automated (Jest, 100% cov) + E2E smoke | J6: Done | K6: featureCore.customise rules merge — featureCore.test.ts
A7: ST-004 | B7: F1 | C7: Click-to-dial + softphone | D7: As a user, Click-to-dial + softphone shows clear errors and retry paths on platform API failures | E7: 3 | F7: P0 | G7: S2 | H7: SCR-3 Call workspace | I7: Automated (Jest, 100% cov) + E2E smoke | J7: Done | K7: errors.ts retry envelope + src/dialer.ts error paths — dialer.test.ts
A8: ST-005 | B8: F1 | C8: Click-to-dial + softphone | D8: As a Salesforce admin, Click-to-dial + softphone works on the Lightning utility-bar softphone + LWC surface end-to-end | E8: 5 | F8: P0 | G8: S3 | H8: SCR-3 Call workspace | I8: Automated (Jest, 100% cov) + E2E smoke | J8: Done | K8: featureCore.availableOn lightning-utility-bar — featureCore.test.ts | GAP-V2: the web screen now exists (src/views.ts, /ui route) but no LWC bundle does — status held pending D-V2 ruling + in-org proof.
A9: ST-006 | B9: F1 | C9: Click-to-dial + softphone | D9: As a Sales leader, I can see Click-to-dial + softphone performance metrics and trends | E9: 3 | F9: P1 | G9: S3 | H9: SCR-3 Call workspace | I9: Automated (Jest, 100% cov) + E2E smoke | J9: Done | K9: featureCore.metrics total/24h — featureCore.test.ts
A10: ST-007 | B10: F1 | C10: Click-to-dial + softphone | D10: As a user, Click-to-dial + softphone respects role permissions and audit logging | E10: 3 | F10: P1 | G10: S3 | H10: SCR-3 Call workspace | I10: Automated (Jest, 100% cov) + E2E smoke | J10: Done | K10: permissions.ts matrix + audit.ts on every admin op — permissions/audit tests
A11: ST-008 | B11: F1 | C11: Click-to-dial + softphone | D11: As a RevOps lead, I can pause/disable Click-to-dial + softphone without data loss | E11: 2 | F11: P2 | G11: S3 | H11: SCR-3 Call workspace | I11: Automated (Jest, 100% cov) + E2E smoke | J11: Done | K11: featureCore.setEnabled pause, data bags untouched — featureCore.test.ts
A12: ST-009 | B12: F1 | C12: Click-to-dial + softphone | D12: As a Sales leader, I can import/migrate existing data into Click-to-dial + softphone (CSV + competitor importer) | E12: 5 | F12: P1 | G12: S3 | H12: SCR-3 Call workspace | I12: Automated (Jest, 100% cov) + E2E smoke | J12: Done | K12: featureCore.importData validation report — featureCore.test.ts
A13: ST-010 | B13: F1 | C13: Click-to-dial + softphone | D13: As a user, I get notifications (in-app + email) for key Click-to-dial + softphone events with per-type mute | E13: 3 | F13: P2 | G13: S3 | H13: SCR-3 Call workspace | I13: Automated (Jest, 100% cov) + E2E smoke | J13: Done | K13: notifications.ts in-app+email — notifications.test.ts
A14: ST-011 | B14: F2 | C14: Auto call/WhatsApp logging | D14: As a RevOps lead, I can set up Auto call/WhatsApp logging with sensible defaults in one screen | E14: 5 | F14: P0 | G14: S3 | H14: SCR-4 Logging builder | I14: Automated (Jest, 100% cov) + E2E smoke | J14: Done | K14: src/callLogger.ts.setup defaults + featureCore — callLogger.test.ts
A15: ST-012 | B15: F2 | C15: Auto call/WhatsApp logging | D15: As a RevOps lead, the Auto call/WhatsApp logging happy path completes without documentation | E15: 8 | F15: P0 | G15: S3 | H15: SCR-4 Logging builder | I15: Automated (Jest, 100% cov) + E2E smoke | J15: Done | K15: src/callLogger.ts happy-path state machine — callLogger.test.ts + app.e2e.test.ts
... A103: ST-100 | B103: EL | C103: Launch & listing | D103: First 10 design-partner reviews scheduled | E103: 2 | F103: P1 | G103: S11 | H103: — | I103: Integration test + manual QA | J103: Code-complete (pending live) | K103: src/designPartners.ts + test — 10-slot tracker: invited→scheduled→reviewed|declined with guards, 3-day stale-nudge queue (longest-silent first), honest exit math separating reviews from G-02 paying-stranger installs; LIVE half (actual outreach + scheduling) = Senthil

Sheet Review_Findings
A1: REVIEW FINDINGS — mirrored from tracker v006 (dispositions live there)
A2: Pass 1 (22:09): billing, store, lifecycle, sfClient, featureCore + write entry points. Pass 2 (22:34): the remaining ~28 modules — dialer, callLogger, cadence, coaching, analytics, flowActions, onboarding, notifications, audit, permissions, permSets, sfAuth, resilience, backup, config, app, helpCenter, supportChat, demoMode, statusPage, pricingPage, trustPage, dryRun, runbook, designPartners, listingSeo, sweepChecks, softphoneAdapter — plus an external verification sweep vs live Open CTI docs and an artifact-gap audit. COLD REVIEW NOW COMPLETE. Dispositions column is Senthil's.
A3: ID | B3: Severity | C3: Module(s) | D3: Finding | E3: Resolution | F3: Story | G3: Sibling precedent | H3: Disposition (Senthil)
A4: F-V01 | B4: High | C4: store.ts / lifecycle.ts | D4: Retention sweep deleted feature bags only — user ROLE records survived forever and the account tombstone kept install source + lifecycle timestamps. Published "permanently deleted" policy (trust page, data-flow doc) was breached. | E4: FIXED — sweep now deletes all org roles (store.deleteRolesForOrg) and writes a minimal tombstone (orgId, deleted, deletedAt only); regression asserts post-sweep snapshot contains no user ids. | F4: ST-052 | G4: FlowCast F-007
A5: F-V02 | B5: High | C5: billing.ts | D5: No payment-recovery path: grace/read-only was a one-way street — a successful payment could not restore active status, reset dunning, or clear grace. Help article HC-10 promised "restores full access immediately"; the code could not deliver it. | E5: FIXED — paymentRecovered(): grace|read-only → active, dunningEmails 0, graceStartedAt cleared, billing.recovered notification; recovering an active account rejected. | F5: ST-060 | G5: ShiftDesk F-001 / OnCall F-005
A6: F-V03 | B6: High | C6: billing.ts | D6: Trial expiry unenforced: after trialEndsAt the org stayed status=trialing with full write access forever, and the banner showed "Trial: 0 day(s) remaining" indefinitely. The 14-day trial was a label. | E6: FIXED — writeBlocked() treats expired trial as blocked ("Trial ended — choose a plan"), banner states it plainly; choosing a plan unblocks. Old test that pinned the buggy 0-days banner corrected. | F6: ST-057 | G6: ShiftDesk F-013 class
A7: F-V04 | B7: Medium | C7: billing.ts | D7: issueInvoice was the only unguarded billing mutation: no role check (any caller) and no amount validation — zero, negative, and NaN invoices accepted. | E7: FIXED — assertCan billing.manage + positive-finite amount guard; signature now takes userId. | F7: ST-062 | G7: ShiftDesk F-005 class
A8: F-V05 | B8: Medium | C8: store.ts | D8: Every per-org ledger unbounded (notifications 2-per-event, analytics events, audit, activities...) — memory growth defect in a long-lived process; dunning alone kept appending. | E8: FIXED — FIFO cap 10,000 per (org, kind) with droppedCount() telemetry; oldest evicted; "current subscription = last item" semantics regression-pinned. Live Postgres gets a retention policy instead (noted for deploy). | F8: ST-070 infra | G8: FlowCast F-001 / ShiftDesk F-003
A9: F-V06 | B9: High | C9: sfClient.ts | D9: Exponential backoff was a NO-OP in production: default sleep was () => Promise.resolve() — every retry against a struggling platform API fired with zero delay, defeating the documented backoff and hammering Salesforce during 429/503 storms. Tests always injected their own sleep, so 100% coverage never caught it. | E9: FIXED — default sleep is a real setTimeout wait; fake-timer regression asserts a pending 375ms timer between attempts on a bare new SfClient(). | F9: ST-070 | G9: ShiftDesk F-004 (exact class)
