Workbook

Sheet Version_Control
A1: VERSION CONTROL — ShiftDesk
A3: Version | B3: Date | C3: Author | D3: Change | E3: Status
A4: v001-v004 | B4: 2026-09-05 | C4: Claude for Senthil/KP | D4: Lineage: marketplace master (868 entries) -> portfolio plan (12 products) -> this product selected for wave-1 | E4: Released
A5: v005 | B5: 2026-09-05 19:34 | C5: Claude for Senthil/KP | D5: Full product workbook for ShiftDesk on Microsoft Teams App Store / AppSource: spec, screen inventory, 100+ story backlog, live sprint board, 18-month financial model (editable assumptions), GTM execution tasks, platform launch checklist, metric targets, risk register | E5: Released
A6: v006 | D6: PLANNED: post-S0 re-baseline after discovery interviews; verified platform terms; wireframe links added to Screens sheet | E6: Planned
A7: v006 | B7: 2026-09-10 22:26 | C7: Claude for Senthil/KP | D7: Development executed per sprint board S1-S8 + S9 partials: 16 TS modules + 9 React screens built; 15 Jest suites / 67 tests at 100% coverage (statements/branches/functions/lines gate enforced, per D13); CI workflow; least-privilege + retention docs. Backlog statuses updated (75 Done, 8 code-complete pending live, 1 in progress, 16 backlog). Added Sprint_Tracker_Log and Traceability_Matrix sheets. | E7: Released
A8: v007 | B8: 2026-09-10 22:54 | C8: Claude for Senthil/KP | D8: Session 2: jest-axe WCAG suite on all 9 screens in CI (ST-089; 16 suites/76 tests, 100% coverage held); submission dry-run recorded in Launch_Checklist (ST-097); launch content drafted — listing A/B, pricing+FAQ, trust page, 15 help articles, admin guide, positioning one-pager, runbook, incident template, video script (ST-080/083/084/093/095/096/098). Statuses: 75 Done / 9 pending live / 2 in progress / 6 drafted / 8 backlog. | E8: Released
A9: v008 | B9: 2026-09-10 23:10 | C9: Claude for Senthil/KP | D9: Session 3 — live-sweep readiness: Teams app manifest v1.17 + icons (teams-app/, sideload-ready), typed env config loader with fail-fast validation + redacted print, 12-step scripted live verification sweep mapped to the pending-live stories, 30-min dev tenant + Partner Center guide. 18 suites / 85 tests, 100% coverage held. Story statuses unchanged (live-gated); Launch_Checklist #2 advanced. | E9: Released
A10: v009 | B10: 2026-09-11 08:20 | C10: Claude for Senthil/KP | D10: Session 4 (morning) — ops parity pack: k6 load harness at 5x launch traffic with perf-budget thresholds (ST-088), blue/green deploy workflow with 100%-test gate + smoke + approval-gated switch (ST-092), scripted backup/restore drill with RTO/RPO pass bar (ST-090) — all Drafted (execution live-gated). Statuses: 75 Done / 9 pending live / 2 in progress / 9 drafted / 5 backlog. 18 suites / 85 tests at 100% unchanged. | E10: Released
A11: v010 | B11: 2026-09-11 12:51 | C11: Claude for Senthil/KP | D11: Session 5 — adversarial cold-review pass 1: 6 defects found and FIXED with regression tests (F-001 no payment-recovery path, F-002 duplicate-install data loss, F-003 unbounded ledgers, F-004 backoff never applied, F-005 negative amounts auto-approved, F-006 CSV quoting), 2 findings OPEN for disposition (F-007 breaker half-open, F-008 audit-log persistence), 1 evidence-discipline finding corrected by building ST-066 crypto module (AES-256-GCM + SecretsVault). REVIEW_PACK.md for external second reviewer. 20 suites / 94 tests, 100% x4, zero pragmas. New Review_Findings sheet. | E11: Released
A12: v011 | B12: 2026-09-11 20:30 | C12: Claude for Senthil/KP | D12: Session 6 — cold-review pass 2 (F-010 importer RFC-4180 closing RAID R-S7, F-011 alert dedupe+cap, F-012 latency rolling window, F-013 trial banner shown to paying accounts; OBS-SD1 pause semantics for disposition — review complete across all modules, 10 defects total) + completion wave (ST-081 chat SLA engine making vendor optional per D-SD4, ST-100 partner tracker with honest G-02 math, ST-099 SEO engine sandbox half, ST-080 ranked help search + manifest gate, ST-068 SECURITY_EVIDENCE.md, ST-094 ASSET_PLAN.md, ST-095 pricing drift gate). BACKLOG ZERO — SHIFTDESK CODE PHASE COMPLETE (fourth product). 75 Done / 13 code-complete pending live / 3 in progress / 9 drafted / 0 backlog. 22 suites / 109 tests at 100% zero pragmas. | E12: Released
A13: v012 | B13: 2026-09-13 09:52 | C13: Claude for Senthil/KP | D13: Session 7 — external verification sweep vs live Microsoft docs + artifact-gap audit: 2 STORE-BLOCKING findings fixed (VER-SD01 screenshot spec was 1920x1080, actual 1366x768/1MB/min-3/mobile-mandatory; VER-SD02 manifest schema v1.17 -> v1.19), 1 LIVE-BLOCKING gap closed (VER-SD08 static tabs had no TeamsJS handshake — would have rendered blank in Teams), VER-SD03 deprecated permissions block removed, VER-SD04 permission model corrected from org-wide Graph .All scopes to resource-specific consent (LC-5 was wrongly Done), VER-SD06 outline icon tightly cropped, VER-SD05 verified-correct items pinned, VER-SD07 Microsoft Marketplace naming noted (3% fee confirmed). Live sweep 12 -> 14 steps. 24 suites / 120 tests at 100% zero pragmas. Story counts unchanged. | E13: Released
A14: v013 | B14: 2026-09-13 10:01 | C14: Claude for Senthil/KP | D14: Session 8 — artifact-gap audit round 2 (manifest promises vs shipped code): GAP-SD1 LIVE-BLOCKING three declared static tabs had no page behind them — web/ layer built (TabShell, typed TabApi, entry mount, index.html with TeamsJS ordered before the bundle, esbuild -> web-dist/); GAP-SD2 the three advertised bot commands had no handler — botRouter built; GAP-SD3 store package hygiene (bundles moved out of teams-app/, contents asserted); GAP-SD4 ST-094 partially unblocked via a headless-verified 1366x768 demo capture surface. 26 suites / 145 tests at 100% across src/ AND web/, zero pragmas. | E14: Released
A15: v014 | B15: 2026-09-13 10:24 | C15: Claude for Senthil/KP | D15: Session 9 — cold-review pass 3 over the previously unreviewed session 5-8 code: 6 defects fixed with pinned regressions (F-014 Infinity approval amounts, F-015 empty checklist title promoted the first task, F-016 SSO token validated then never sent so every tab call was unauthenticated, F-017 non-idempotent TeamsJS bootstrap, F-018 internal error codes shown to frontline users, F-019 configured trial length ignored by the billing engine) plus OBS-SD2 dead defensive branch removed. Running total 19 defects + 3 observations across three passes. 27 suites / 151 tests at 100% zero pragmas; story counts unchanged (correctness release). | E15: Released
A16: v015 | B16: 2026-09-13 10:37 | C16: Claude for Senthil/KP | D16: Session 10 — artifact-gap audit round 3 (client calls vs server routes): GAP-SD5 LIVE-BLOCKING — no HTTP server existed and three of five tab paths plus the Azure Bot messaging endpoint had no handler; every tab would have loaded then failed on first call. Built src/server.ts (auth-enforced router incl. /api/messages, /health, /status) + src/bootstrap.ts (node:http, config-driven, verified over a real socket) and the dispatcher routes behind them; added a parity test that reads web/tabApi.ts so the gap class now fails CI. Sweep 14 -> 15 steps. OBS-SD3 second dead defensive branch removed. 29 suites / 163 tests at 100% zero pragmas; story counts unchanged. | E16: Released
A17: v016 | B17: 2026-09-13 10:42 | C17: Claude for Senthil/KP | D17: Session 11 — verification sweep 2 over the bot transport seam: 2 LIVE-BLOCKING defects introduced by session 10 and caught here (VER-SD09 endpoint demanded our tab SSO token and a {text} body where Teams sends a Connector JWT and an Activity; VER-SD10 replies were returned in the HTTP body instead of posted to the Connector at serviceUrl) plus VER-SD11 identity source and VER-SD12 conversationUpdate/welcome + activity ack and retry dedupe. src/botTransport.ts built as a distinct trust boundary, server gains an async activity path, bootstrap takes bot deps; k6 harness, sweep wording and dev guide corrected. 30 suites / 174 tests at 100% zero pragmas; story counts unchanged. | E17: Released
A18: v017 | B18: 2026-09-13 10:57 | C18: Claude for Senthil/KP | D18: Session 12 — verification sweep 3 over the tab SSO seam: VER-SD13 LIVE-BLOCKING — the tab had been sending the literal string "teams-sso" as its token since session 8, while the manifest has declared SSO since session 3. Real flow implemented end to end: getAuthToken() with caching and consent-error handling client-side; full Entra v2 claim validation server-side (four audience forms, issuer-tenant match, version, oid/tid, exp/nbf, access_as_user scope) with the JWKS check as an explicit injected seam. VER-SD14: Expose-an-API step added to the dev-tenant guide without which SSO cannot work at all. Sweep 15 -> 16 steps. 31 suites / 181 tests at 100% zero pragmas; story counts unchanged. | E18: Released
... A47: v046 | B47: 2026-09-20 16:40 | C47: Claude for Senthil/KP | D47: Session 41: independent review V001 actioned in full. Full_Backlog +47 SD stories (147 total, none dropped) with Sprint_Board extended to S20 and its ranges retargeted. Review_Findings carries the disposition of all 20 P-series findings and all 8 D-series decisions, generated from the shipped REVIEW_PACK.md so workbook and code cannot disagree, plus own goals F-071 and F-072. Financial_Model rebuilt (P-018/D-01/D-02): cash-in and opening-cash inputs, closing-cash and runway rows, a computed breakeven month, a stated funding requirement, and a per-site pricing scenario beside the per-seat one — the reviewer's Scenario A result is reproduced rather than argued with. Metrics_Targets restated with absolute values and a named measurement source per row (D-03). Risk_Register rewritten with the free first-party overlap as the top risk (D-04). Launch_Checklist gains #11 Fulfillment (D-08), #12 residency/legal, #13 durability and #14 recording that the trust page stays unpublished (D-07). Companion tracker v040; codebase v0.14.0 at 68 suites / 552 tests, 100% four ways with zero pragmas, 9/9 real-Postgres integration tests, backup drill PASS at RPO 0s / RTO 0s. Own goals F-071..F-074 recorded, two of them in the release gate itself. | E47: Released

Sheet ReadMe_Scope
A1: ShiftDesk — Shift comms + approvals + checklists bot for frontline teams inside Teams
A3: PLATFORM: Microsoft Teams App Store / AppSource | CATEGORY: Frontline Workforce
A4: PROBLEM: 320M+ Teams MAU but frontline tooling is either heavy (dedicated WFM) or absent
A5: DIFFERENTIATION: Bot-first UX, works on Teams mobile, per-frontline-seat pricing far under WFM suites
A6: ICP: Enterprises 500-20k employees with frontline workforce (retail, logistics, healthcare) on M365 F/E plans
A8: HOW TO USE: Full_Backlog is the single source of truth (edit Status column during execution). Sprint_Board recalculates points per sprint automatically. Financial_Model assumptions (yellow) are editable — the 18-month build recalculates. Launch_Checklist is the platform-specific gate before submission. All costs/timelines are market-standard estimates; verify platform terms (fees/review rules) during S0.
A10: STACK ASSUMPTION (market standard): TypeScript/Node or platform-mandated runtime, React frontends, Postgres, hosted on AWS/GCP/platform FaaS as required, GitHub Actions CI, PostHog + Sentry telemetry, Intercom-class support.

Sheet Product_Spec
A1: PRODUCT SPEC
A3: Module (feature) | B3: Scope in MVP | C3: Out of scope (v1) | D3: Non-functional requirements
A4: Shift handover threads | B4: Shift handover threads: end-to-end happy path + edge cases + permissions | C4: Advanced automation, AI beyond listed, multi-language beyond launch set | D4: p95 <500ms API / <2s UI loads
A5: Approval workflows | B5: Approval workflows: end-to-end happy path + edge cases + permissions | C5: Advanced automation, AI beyond listed, multi-language beyond launch set | D5: 99.5% monthly uptime
A6: Digital checklists | B6: Digital checklists: end-to-end happy path + edge cases + permissions | C6: Advanced automation, AI beyond listed, multi-language beyond launch set | D6: WCAG AA
A7: Kudos/recognition | B7: Kudos/recognition: end-to-end happy path + edge cases + permissions | C7: Advanced automation, AI beyond listed, multi-language beyond launch set | D7: SOC2-track controls
A8: Manager dashboard | B8: Manager dashboard: end-to-end happy path + edge cases + permissions | C8: Advanced automation, AI beyond listed, multi-language beyond launch set | D8: Rate-limit safe (backoff+queue)
A10: Persona | B10: Jobs-to-be-done
A11: Ops director | B11: Buys on compliance + task completion rates
A12: IT admin (M365) | B12: Gatekeeper; conditional access, app permission policies
A13: Frontline supervisor | B13: Daily user; mobile-first, zero training tolerance

Sheet Screens_Wireframes
A1: SCREEN INVENTORY (attach Figma links in col E during S0)
A3: # | B3: Screen | C3: Purpose | D3: Key elements | E3: Wireframe link
A4: 1 | B4: Onboarding / first-run | C4: Reach aha in <1 day | D4: Checklist, sample data toggle, connect steps
A5: 2 | B5: Home dashboard | C5: Daily habit surface | D5: KPI cards, activity feed, alerts
A6: 3 | B6: Shift handover threads workspace | C6: Core value surface | D6: List+detail, bulk actions, status chips
A7: 4 | B7: Approval workflows builder | C7: Configure second pillar | D7: Rule builder, preview, test mode
A8: 5 | B8: Digital checklists view | C8: Differentiator surface | D8: Timeline/visual, export
A9: 6 | B9: Settings & team | C9: Roles, notifications, data | D9: Role matrix, API keys, danger zone
A10: 7 | B10: Billing | C10: Plan/trial/invoices | D10: Plan cards, usage meter, invoices
A11: 8 | B11: Analytics | C11: Prove ROI | D11: Funnel, cohort, export
A12: 9 | B12: Help & support | C12: Deflect + assist | D12: Search, chat, status

Sheet Full_Backlog
A1: FULL BACKLOG — 147 stories (100 original ST + 47 SD from independent review V001, none dropped)
A3: ID | B3: Epic | C3: Story | D3: Points | E3: Priority | F3: Sprint | G3: Status
A4: ST-001 | B4: F1 | C4: As a Ops director, I can set up Shift handover threads with sensible defaults in one screen | D4: 5 | E4: P0 | F4: S2 | G4: Done
A5: ST-002 | B5: F1 | C5: As a Ops director, the Shift handover threads happy path completes without documentation | D5: 8 | E5: P0 | F5: S2 | G5: Done
A6: ST-003 | B6: F1 | C6: As a IT admin, I can customise Shift handover threads rules/conditions for my workflow | D6: 5 | E6: P1 | F6: S2 | G6: Done
A7: ST-004 | B7: F1 | C7: As a user, Shift handover threads shows clear errors and retry paths on platform API failures | D7: 3 | E7: P0 | F7: S2 | G7: Done
A8: ST-005 | B8: F1 | C8: As a Frontline supervisor, Shift handover threads works on the Teams tab + bot surface end-to-end | D8: 5 | E8: P0 | F8: S3 | G8: Code-complete pending live
A9: ST-006 | B9: F1 | C9: As a IT admin, I can see Shift handover threads performance metrics and trends | D9: 3 | E9: P1 | F9: S3 | G9: Done
A10: ST-007 | B10: F1 | C10: As a user, Shift handover threads respects role permissions and audit logging | D10: 3 | E10: P1 | F10: S3 | G10: Done
A11: ST-008 | B11: F1 | C11: As a Ops director, I can pause/disable Shift handover threads without data loss | D11: 2 | E11: P2 | F11: S3 | G11: Done
A12: ST-009 | B12: F1 | C12: As a IT admin, I can import/migrate existing data into Shift handover threads (CSV + competitor importer) | D12: 5 | E12: P1 | F12: S3 | G12: Done
A13: ST-010 | B13: F1 | C13: As a user, I get notifications (in-app + email) for key Shift handover threads events with per-type mute | D13: 3 | E13: P2 | F13: S3 | G13: Done
A14: ST-011 | B14: F2 | C14: As a Ops director, I can set up Approval workflows with sensible defaults in one screen | D14: 5 | E14: P0 | F14: S3 | G14: Done
A15: ST-012 | B15: F2 | C15: As a Ops director, the Approval workflows happy path completes without documentation | D15: 8 | E15: P0 | F15: S3 | G15: Done
... A150: SD247 | B150: E20 | C150: 5 paid pilots with signed order forms | D150: 6 | E150: P1 | F150: S20 | G150: To do — Senthil
A152: Total stories: 147 (rows 4-103 = the original 100 ST stories; rows 104-150 = the 47 SD stories from review V001 sprint plan S13-S20). Epics: F1-F5 product features; E1 install, E5 billing, E6 compliance, E7 telemetry, E8 onboarding/docs/support, EQ quality; E13-E20 the review sprints. Status vocabulary per tracker decision D-SD2, extended by D-SD8: "To do — Senthil" marks the 11 stories that are live- or human-gated and can never be closed from a sandbox.

Sheet Sprint_Board
A1: SPRINT BOARD — live counts from Full_Backlog
A3: Sprint | B3: Focus | C3: Stories | D3: Points | E3: Done | F3: Exit criteria
A4: S0 | B4: Discovery & Design (2 wks) | C4: =COUNTIF(Full_Backlog!F4:F150,"S0") | D4: =SUMIF(Full_Backlog!F4:F150,"S0",Full_Backlog!D4:D150) | E4: =COUNTIFS(Full_Backlog!F4:F150,"S0",Full_Backlog!G4:G150,"Done") | F4: PRD signed off; prototype tested with 5 target users
A5: S1 | B5: Foundation (2 wks) | C5: =COUNTIF(Full_Backlog!F4:F150,"S1") | D5: =SUMIF(Full_Backlog!F4:F150,"S1",Full_Backlog!D4:D150) | E5: =COUNTIFS(Full_Backlog!F4:F150,"S1",Full_Backlog!G4:G150,"Done") | F5: App installs cleanly in dev store/org; telemetry firing
A6: S2 | B6: Core feature Shift handover threads - part 1 | C6: =COUNTIF(Full_Backlog!F4:F150,"S2") | D6: =SUMIF(Full_Backlog!F4:F150,"S2",Full_Backlog!D4:D150) | E6: =COUNTIFS(Full_Backlog!F4:F150,"S2",Full_Backlog!G4:G150,"Done") | F6: Shift handover threads happy path demoable
A7: S3 | B7: Core feature Shift handover threads - part 2 + Approval workflows start | C7: =COUNTIF(Full_Backlog!F4:F150,"S3") | D7: =SUMIF(Full_Backlog!F4:F150,"S3",Full_Backlog!D4:D150) | E7: =COUNTIFS(Full_Backlog!F4:F150,"S3",Full_Backlog!G4:G150,"Done") | F7: Shift handover threads complete with tests; Approval workflows skeleton
A8: S4 | B8: Core feature Approval workflows | C8: =COUNTIF(Full_Backlog!F4:F150,"S4") | D8: =SUMIF(Full_Backlog!F4:F150,"S4",Full_Backlog!D4:D150) | E8: =COUNTIFS(Full_Backlog!F4:F150,"S4",Full_Backlog!G4:G150,"Done") | F8: MVP loop usable end-to-end internally
A9: S5 | B9: Feature Digital checklists + alpha hardening | C9: =COUNTIF(Full_Backlog!F4:F150,"S5") | D9: =SUMIF(Full_Backlog!F4:F150,"S5",Full_Backlog!D4:D150) | E9: =COUNTIFS(Full_Backlog!F4:F150,"S5",Full_Backlog!G4:G150,"Done") | F9: Internal alpha: team dogfoods daily
A10: S6 | B10: Billing + Kudos/recognition | C10: =COUNTIF(Full_Backlog!F4:F150,"S6") | D10: =SUMIF(Full_Backlog!F4:F150,"S6",Full_Backlog!D4:D150) | E10: =COUNTIFS(Full_Backlog!F4:F150,"S6",Full_Backlog!G4:G150,"Done") | F10: Can charge a test customer; upgrade/downgrade paths work
A11: S7 | B11: Private beta (design partners) | C11: =COUNTIF(Full_Backlog!F4:F150,"S7") | D11: =SUMIF(Full_Backlog!F4:F150,"S7",Full_Backlog!D4:D150) | E11: =COUNTIFS(Full_Backlog!F4:F150,"S7",Full_Backlog!G4:G150,"Done") | F11: 3+ partners active weekly; NPS pulse >30
A12: S8 | B12: Beta iteration + Manager dashboard | C12: =COUNTIF(Full_Backlog!F4:F150,"S8") | D12: =SUMIF(Full_Backlog!F4:F150,"S8",Full_Backlog!D4:D150) | E12: =COUNTIFS(Full_Backlog!F4:F150,"S8",Full_Backlog!G4:G150,"Done") | F12: Retention of beta cohort week-over-week >60%
A13: S9 | B13: Marketplace review prep | C13: =COUNTIF(Full_Backlog!F4:F150,"S9") | D13: =SUMIF(Full_Backlog!F4:F150,"S9",Full_Backlog!D4:D150) | E13: =COUNTIFS(Full_Backlog!F4:F150,"S9",Full_Backlog!G4:G150,"Done") | F13: Review submission accepted into queue
A14: S10 | B14: Review remediation + docs | C14: =COUNTIF(Full_Backlog!F4:F150,"S10") | D14: =SUMIF(Full_Backlog!F4:F150,"S10",Full_Backlog!D4:D150) | E14: =COUNTIFS(Full_Backlog!F4:F150,"S10",Full_Backlog!G4:G150,"Done") | F14: Marketplace approval obtained (or final remediation cycle)
A15: S11 | B15: Launch | C15: =COUNTIF(Full_Backlog!F4:F150,"S11") | D15: =SUMIF(Full_Backlog!F4:F150,"S11",Full_Backlog!D4:D150) | E15: =COUNTIFS(Full_Backlog!F4:F150,"S11",Full_Backlog!G4:G150,"Done") | F15: First 10 installs; first 3 reviews; activation >40%
A16: S12 | B16: Iterate & scale decision | C16: =COUNTIF(Full_Backlog!F4:F150,"S12") | D16: =SUMIF(Full_Backlog!F4:F150,"S12",Full_Backlog!D4:D150) | E16: =COUNTIFS(Full_Backlog!F4:F150,"S12",Full_Backlog!G4:G150,"Done") | F16: Growth model doc with CAC/LTV first estimates
A17: S13 | B17: Trust boundaries for real | C17: =COUNTIF(Full_Backlog!F4:F150,"S13") | D17: =SUMIF(Full_Backlog!F4:F150,"S13",Full_Backlog!D4:D150) | E17: =COUNTIFS(Full_Backlog!F4:F150,"S13",Full_Backlog!G4:G150,"Done") | F17: A Teams dev tenant loads the tab with a real Entra token and the bot answers a real message, dev bypass disabled
A18: S14 | B18: Durability for real | C18: =COUNTIF(Full_Backlog!F4:F150,"S14") | D18: =SUMIF(Full_Backlog!F4:F150,"S14",Full_Backlog!D4:D150) | E18: =COUNTIFS(Full_Backlog!F4:F150,"S14",Full_Backlog!G4:G150,"Done") | F18: Restart, two-instance and restore drills green in CI against real Postgres, unattended
A19: S15 | B19: Scale and data model | C19: =COUNTIF(Full_Backlog!F4:F150,"S15") | D19: =SUMIF(Full_Backlog!F4:F150,"S15",Full_Backlog!D4:D150) | E19: =COUNTIFS(Full_Backlog!F4:F150,"S15",Full_Backlog!G4:G150,"Done") | F19: 5x load sweep passes on staging with per-record persistence and published numbers
A20: S16 | B20: Teams-native experience | C20: =COUNTIF(Full_Backlog!F4:F150,"S16") | D20: =SUMIF(Full_Backlog!F4:F150,"S16",Full_Backlog!D4:D150) | E20: =COUNTIFS(Full_Backlog!F4:F150,"S16",Full_Backlog!G4:G150,"Done") | F20: End-to-end handover completed on Teams mobile using cards, acknowledgement nudge arriving proactively
A21: S17 | B21: Enterprise admin and governance | C21: =COUNTIF(Full_Backlog!F4:F150,"S17") | D21: =SUMIF(Full_Backlog!F4:F150,"S17",Full_Backlog!D4:D150) | E21: =COUNTIFS(Full_Backlog!F4:F150,"S17",Full_Backlog!G4:G150,"Done") | F21: IT-admin dry run (install, consent, rollout, export, delete) completed by someone who did not build it
A22: S18 | B22: Assurance and certification | C22: =COUNTIF(Full_Backlog!F4:F150,"S18") | D22: =SUMIF(Full_Backlog!F4:F150,"S18",Full_Backlog!D4:D150) | E22: =COUNTIFS(Full_Backlog!F4:F150,"S18",Full_Backlog!G4:G150,"Done") | F22: Attestation submitted, pen-test Highs closed, accessibility audit signed
A23: S19 | B23: Commercial machinery and observability | C23: =COUNTIF(Full_Backlog!F4:F150,"S19") | D23: =SUMIF(Full_Backlog!F4:F150,"S19",Full_Backlog!D4:D150) | E23: =COUNTIFS(Full_Backlog!F4:F150,"S19",Full_Backlog!G4:G150,"Done") | F23: A test customer transacts through the marketplace and the entitlement is enforced end to end
A24: S20 | B24: Demand validation and go/no-go | C24: =COUNTIF(Full_Backlog!F4:F150,"S20") | D24: =SUMIF(Full_Backlog!F4:F150,"S20",Full_Backlog!D4:D150) | E24: =COUNTIFS(Full_Backlog!F4:F150,"S20",Full_Backlog!G4:G150,"Done") | F24: G-01/G-02 become achievable on evidence, or kill criteria fire
B25: TOTAL | C25: =SUM(C4:C24) | D25: =SUM(D4:D24) | E25: =SUM(E4:E24)
B26: Velocity check: S2-S8 sat at 30-45 pts/sprint. The review plan S13-S20 is 266 pts across 8 sprints (~33/sprint), the same shape — but 62 of those points are human-gated (D-SD8) and cannot be burned down by building.

Sheet Sprint_Tracker_Log
A1: SPRINT TRACKER LOG — ShiftDesk (execution session 10/09/2026 22:26-22:40, Claude for Senthil/KP)
A3: Sprint | B3: Date executed | C3: Scope executed this session | D3: Stories Done | E3: Points Done | F3: Exit criteria status | G3: Notes
A4: S0 | B4: 2026-09-10 | C4: Skipped per D13 (discovery interviews parked); spec taken from v005 as-is | D4: 0 | E4: 0 | F4: N/A — D13 | G4: Re-baseline in v007 if interviews resume
A5: S1 | B5: 2026-09-10 | C5: Install lifecycle: OAuth install->welcome, uninstall webhook + 30-day deletion, token rotation survival, source attribution (install.ts) | D5: 3 | E5: 8 | F5: Partial — installs cleanly in mock gateway; live dev-store install pending (ST-051) | G5: Bot Framework transport mocked at gateway seam
A6: S2 | B6: 2026-09-10 | C6: Handover threads part 1: defaults setup, happy path, custom rules, error/retry, re-install restore, role matrix (handover.ts, moduleBase.ts, rbac.ts) | D6: 6 | E6: 29 | F6: Met — happy path demoable via E2E suite
A7: S3 | B7: 2026-09-10 | C7: Handover part 2 + approvals skeleton: mobile/bot surface code, metrics, permissions+audit, pause, CSV import, notifications; approvals policy builder; ST-085 coverage gate | D7: 10 | E7: 42 | F7: Met — handover complete with tests; approvals skeleton up | G7: ST-085 delivered at 100% (D13 supersedes >=70%)
A8: S4 | B8: 2026-09-10 | C8: Approval workflows complete: evaluate/auto-approve/block, preview test mode; funnel events + error tracking (approvals.ts, telemetry.ts); E2E smoke suite (ST-086) | D8: 8 | E8: 29 | F8: Met — MVP loop usable end-to-end in tests
A9: S5 | B9: 2026-09-10 | C9: Digital checklists + alpha hardening: create/tick/export, first-run checklist to aha, empty states (checklists.ts, onboarding.ts) | D9: 11 | E9: 45 | F9: Partial — code hardened; live dogfooding pending
A10: S6 | B10: 2026-09-10 | C10: Billing + kudos: trial/banner, proration, marketplace-vs-Stripe rail, kudos + leaderboard (billing.ts, kudos.ts) | D10: 11 | E10: 47 | F10: Partial — test customer chargeable via mock rail; live marketplace billing pending (ST-059)
A11: S7 | B11: 2026-09-10 | C11: Dunning/grace/read-only, plan-limit prompts, invoices GST/VAT, cancellation save-offer, least-privilege scope doc | D11: 5 | E11: 15 | F11: Not met — design partners not yet recruited (human-dependent) | G11: All S7 code stories Done
A12: S8 | B12: 2026-09-10 | C12: Manager dashboard: KPI aggregation, trends, open items; retention docs, audit log, backoff+circuit breaker, latency budgets, heatmap/health/alerts | D12: 18 | E12: 69 | F12: Partial — beta cohort retention unmeasurable pre-live | G12: Zero-downtime deploy (ST-092) needs live infra
A13: S9 | B13: 2026-09-10 | C13: Chaos degrade path automated (ST-091); WCAG structure in components; pen test + backup drill deferred to live | D13: 2 | E13: 8 | F13: Not met — submission needs live tenant + assets | G13: 2 of 7 stories Done
A14: S10 | B14: 2026-09-10 | C14: No content stories executed (help articles, pricing/trust pages are launch content) | D14: 0 | E14: 0 | F14: Not met | G14: Backlog
A15: S11 | B15: 2026-09-10 | C15: Launch stories untouched (require approved listing) | D15: 1 | E15: 3 | F15: Not met | G15: Backlog
A16: S12 | B16: 2026-09-10 | C16: Not started | D16: 0 | E16: 0 | F16: Not met | G16: Backlog
C17: TOTALS (live from Full_Backlog) | D17: =COUNTIF(Full_Backlog!G4:G103,"Done") | E17: =SUMIF(Full_Backlog!G4:G103,"Done",Full_Backlog!D4:D103)
A19: Session summary 10/09/2026: sprints S1-S8 development complete in code; 75 stories Done, 8 code-complete pending live platform (ST-005/015/025/035/045/051/059/066), 1 in progress (ST-083 sandbox shipped, video outstanding), 16 backlog (pen test, load/WCAG/backup/deploy drills, content, S10-S12 listing/launch).
A20: Quality gate: 15 Jest suites, 67 tests, 100% statements/branches/functions/lines enforced via jest.config.js coverageThreshold (D13). TypeScript strict, tsc --noEmit clean. CI: .github/workflows/ci.yml.
A21: Assumption: platform transport (Bot Framework/Graph, marketplace billing API) mocked at the PlatformGateway seam — no Microsoft credentials in build environment; wiring unchanged for live swap. Source: shiftdesk_v006_source.zip delivered with this workbook.
A23: SESSION 2 — 10/09/2026 22:54
A24: S9 | B24: 2026-09-10 | C24: ST-089 WCAG: jest-axe automated suite added over all 9 screens, wired into CI (16 suites / 76 tests, 100% coverage held). ST-097 submission dry-run executed against Launch_Checklist; 10 item statuses recorded. | D24: 0 | E24: 0 | F24: S9 partial — pen test + live asset items remain | G24: ST-089 now code-complete pending live audit
A25: S10 | B25: 2026-09-10 | C25: Content drafted: listing copy A/B (ST-093), pricing matrix + FAQ (ST-095), security/trust page (ST-096), 15 help articles (ST-080), admin deployment guide, positioning one-pager. | D25: 0 | E25: 0 | F25: S10 partial — publishing needs live site/listing | G25: All drafts in content/, external-facing, no company name per rule
A26: S11 | B26: 2026-09-10 | C26: Launch-day runbook with rollback triggers + comms tree (ST-098); incident comms template (ST-084); demo video script (ST-083). | D26: 0 | E26: 0 | F26: S11 partial — listing + installs still gate exit | G26: Video recording + screenshots (ST-094) need live product UI
A27: Portfolio position after session 2: 75 Done / 9 code-complete pending live / 2 in progress / 6 drafted / 8 backlog. Remaining backlog is entirely Senthil-gated or live-gated: pen test (068), chat vendor (081), load test (088), backup drill (090), deploy drill (092), screenshots+video assets (094), post-launch SEO (099), design-partner reviews (100). ShiftDesk sandbox work is exhausted pending: Partner Center enrollment, live Teams dev tenant, D15.
A29: SESSION 3 — 10/09/2026 23:10
A30: S1/S9 | B30: 2026-09-10 | C30: Live-sweep readiness pack: teams-app/manifest.json (v1.17, bot + 3 static tabs + valid domains placeholders) with generated icons; src/config.ts typed loader (fail-fast, redacted print); src/liveSweep.ts 12-step scripted verification sweep mapped to ST-051/005/015/025/054/055/052/053; content/dev-tenant-setup-guide.md (30-min path, sideload does not need Partner Center). | D30: 0 | E30: 0 | F30: Shortens S1-07 to wiring-only on install day | G30: 18 suites / 85 tests, 100% coverage held; statuses unchanged (live-gated)
A32: SESSION 4 — 11/09/2026 08:20
A33: S9/S11 | B33: 2026-09-11 | C33: Ops parity with portfolio standard: k6 5x harness (ST-088), blue/green deploy workflow (ST-092), backup/restore drill script (ST-090). Remaining backlog now only 5 items, all external: pen test (068), chat vendor (081), listing assets (094), post-launch SEO (099), design-partner reviews (100). | D33: 0 | E33: 0 | F33: Execution of all three live-gated | G33: Coverage gate re-verified 18/85 at 100%
A35: SESSION 5 — 11/09/2026 12:51
A36: S9 | B36: 2026-09-11 | C36: Cold-review pass 1: F-001..F-006 fixed + pinned, F-007/F-008 for disposition, F-009 corrected by building src/crypto.ts (ST-066 now genuinely coded); REVIEW_PACK.md for external reviewer (ST-097 stays In progress — same-AI review is not independent). | D36: 0 | E36: 0 | F36: Statuses unchanged except evidence corrections | G36: 20 suites / 94 tests at 100%; importer CSV-quoting flagged as pass-2 candidate
A38: SESSION 6 — 11/09/2026 20:30
A39: S9-S12 | B39: 2026-09-11 | C39: Cold-review pass 2 (4 fixes F-010..F-013, OBS-SD1 open; review complete, 10 defects total across both passes) + sibling-validated completion wave (chat SLA, partner tracker, SEO engine, help search, security evidence, asset plan, pricing drift gate). CODE PHASE COMPLETE — backlog zero. | D39: 0 | E39: 0 | F39: Remaining chain 100% Senthil/live | G39: 22 suites / 109 tests at 100%
A41: SESSION 7 — 13/09/2026 09:52
A42: S9 | B42: 2026-09-13 | C42: External verification sweep vs live Microsoft docs (manifest schema, RSC vs Graph scopes, store validation guidelines, icon rules, marketplace fee) + artifact-gap audit. 6 fixes incl. 2 store-blocking and 1 live-blocking; 1 verified-correct set pinned; LC-5 reopened and corrected. | D42: 0 | E42: 0 | F42: Sweep extended to 14 steps | G42: 24 suites / 120 tests at 100%; story counts deliberately unchanged
A44: SESSION 8 — 13/09/2026 10:01
A45: S2-S5/S9 | B45: 2026-09-13 | C45: Artifact-gap audit round 2: built the tab surface the manifest had been promising (shell, API client, entry, bundles) and the bot command router behind the advertised commands; package hygiene fixed; demo capture surface unblocks draft listing screenshots pre-tenant. | D45: 0 | E45: 0 | F45: Five surface stories now full-stack pending in-client render | G45: 26 suites / 145 tests at 100% incl. new web/ layer
A47: SESSION 9 — 13/09/2026 10:24
A48: S9 | B48: 2026-09-13 | C48: Cold-review pass 3 over sessions 5-8 code (tab layer, bot router, completion wave, config, crypto): 6 defects fixed with regressions, 1 observation closed. Headline: the tab API validated the SSO token and then dropped it — every call unauthenticated in production, invisible because the fetcher was injected and never asserted on headers. | D48: 0 | E48: 0 | F48: No story flips — correctness only | G48: 27 suites / 151 tests at 100%; 19 defects total across three review passes
A50: SESSION 10 — 13/09/2026 10:37
A51: S1/S9 | B51: 2026-09-13 | C51: Artifact-gap audit round 3: built the HTTP server the tab and bot endpoint had been calling into thin air, with bearer auth, health/status, node:http bootstrap and a CI parity test binding client paths to served routes. | D51: 0 | E51: 0 | F51: Tab + bot surfaces now end-to-end in code | G51: 29 suites / 163 tests at 100%; sweep now 15 steps
...

Sheet Financial_Model
A1: 18-MONTH FINANCIAL MODEL v046 — repaired per review findings P-018 / D-01 / D-02 (SD246). Yellow cells are inputs. Two pricing scenarios; cash-in, runway, breakeven and funding requirement are computed, not asserted.
A2: The reviewer recomputed the v045 sheet and found M18 net -$23,822/mo and cumulative -$574,601, with no cash-in or runway row anywhere. Scenario A below reproduces that result on the original assumptions rather than arguing with it. Scenario B models the per-site pricing the review asked for. Neither is a forecast: every input is a planning number until the SD244 interviews and SD247 pilots replace it.
A4: SCENARIO A — per-seat pricing, as modelled in v045
A5: Assumption | B5: Value | C5: Note
A6: Qualified pilots/mo (month 1) | B6: 6 | C6: v005 assumption, unchanged
A7: Monthly growth of that | B7: 0.1 | C7: v005 assumption, unchanged
A8: Pilot->paid % | B8: 0.35 | C8: v005 assumption, unchanged
A9: ARPU $/mo (per-seat scenario) | B9: 400 | C9: Review D-02: at a $2/seat frontline price this implies ~200 seats per "pilot", which contradicts a 6-pilots-a-month founder-led motion. Kept here so the reviewer's numbers reproduce; Scenario B is the honest alternative.
A10: Monthly churn | B10: 0.015 | C10: v005 assumption, unchanged
A11: Marketplace fee | B11: 0.03 | C11: Microsoft transactable fee. Verify at offer setup (Launch_Checklist #6).
A12: Team cost month 1 ($) | B12: 35000 | C12: India-lean base from Team_Roles_Budget (v004)
A13: Cost growth/mo | B13: 0.03 | C13: v005 assumption, unchanged
A14: Opening cash at M1 ($) | B14: 0 | C14: INPUT OWED — Senthil. Left at zero deliberately: the model must not invent a cash position. With 0 here, "funding requirement" below IS the cash this plan needs.
A15: Other monthly cash-in ($) | B15: 0 | C15: INPUT OWED — Senthil. Consulting or other income applied to this product, if any. The absence of this row is what review finding P-018 called out.
A17: Line | B17: M1 | C17: M2 | D17: M3 | E17: M4 | F17: M5 | G17: M6 | H17: M7 | I17: M8 | J17: M9 | K17: M10 | L17: M11 | M17: M12 | N17: M13 | O17: M14 | P17: M15 | Q17: M16 | R17: M17 | S17: M18
A18: A leads/installs | B18: =$B$6 | C18: =B18*(1+$B$7) | D18: =C18*(1+$B$7) | E18: =D18*(1+$B$7) | F18: =E18*(1+$B$7) | G18: =F18*(1+$B$7) | H18: =G18*(1+$B$7) | I18: =H18*(1+$B$7) | J18: =I18*(1+$B$7) | ... S18: =R18*(1+$B$7)
A19: A new paying | B19: =ROUND(B18*$B$8,1) | C19: =ROUND(C18*$B$8,1) | D19: =ROUND(D18*$B$8,1) | E19: =ROUND(E18*$B$8,1) | F19: =ROUND(F18*$B$8,1) | G19: =ROUND(G18*$B$8,1) | H19: =ROUND(H18*$B$8,1) | I19: =ROUND(I18*$B$8,1) | ... S19: =ROUND(S18*$B$8,1)
A20: A paying accounts | B20: =B19 | C20: =ROUND(B20*(1-$B$10)+C19,1) | D20: =ROUND(C20*(1-$B$10)+D19,1) | E20: =ROUND(D20*(1-$B$10)+E19,1) | F20: =ROUND(E20*(1-$B$10)+F19,1) | G20: =ROUND(F20*(1-$B$10)+G19,1) | H20: =ROUND(G20*(1-$B$10)+H19,1) | I20: =ROUND(H20*(1-$B$10)+I19,1) | J20: =ROUND(I20*(1-$B$10)+J19,1) | ... S20: =ROUND(R20*(1-$B$10)+S19,1)
A21: A MRR net of fee | B21: =ROUND(B20*$B$9*(1-$B$11),0) | C21: =ROUND(C20*$B$9*(1-$B$11),0) | D21: =ROUND(D20*$B$9*(1-$B$11),0) | E21: =ROUND(E20*$B$9*(1-$B$11),0) | F21: =ROUND(F20*$B$9*(1-$B$11),0) | G21: =ROUND(G20*$B$9*(1-$B$11),0) | H21: =ROUND(H20*$B$9*(1-$B$11),0) | I21: =ROUND(I20*$B$9*(1-$B$11),0) | ... S21: =ROUND(S20*$B$9*(1-$B$11),0)
A22: A team cost | B22: =$B$12 | C22: =ROUND(B22*(1+$B$13),0) | D22: =ROUND(C22*(1+$B$13),0) | E22: =ROUND(D22*(1+$B$13),0) | F22: =ROUND(E22*(1+$B$13),0) | G22: =ROUND(F22*(1+$B$13),0) | H22: =ROUND(G22*(1+$B$13),0) | I22: =ROUND(H22*(1+$B$13),0) | J22: =ROUND(I22*(1+$B$13),0) | ... S22: =ROUND(R22*(1+$B$13),0)
A23: A other cash-in | B23: =$B$15 | C23: =$B$15 | D23: =$B$15 | E23: =$B$15 | F23: =$B$15 | G23: =$B$15 | H23: =$B$15 | I23: =$B$15 | ... S23: =$B$15
A24: A net cash/mo | B24: =B21+B23-B22 | C24: =C21+C23-C22 | D24: =D21+D23-D22 | E24: =E21+E23-E22 | F24: =F21+F23-F22 | G24: =G21+G23-G22 | H24: =H21+H23-H22 | I24: =I21+I23-I22 | ... S24: =S21+S23-S22
A25: A cumulative net | B25: =B24 | C25: =B25+C24 | D25: =C25+D24 | E25: =D25+E24 | F25: =E25+F24 | G25: =F25+G24 | H25: =G25+H24 | I25: =H25+I24 | J25: =I25+J24 | ... S25: =R25+S24
A26: A closing cash | B26: =$B$14+B25 | C26: =$B$14+C25 | D26: =$B$14+D25 | E26: =$B$14+E25 | F26: =$B$14+F25 | G26: =$B$14+G25 | H26: =$B$14+H25 | I26: =$B$14+I25 | ... S26: =$B$14+S25
A27: A breakeven flag (net>=0) | B27: =IF(B24>=0,1,0) | C27: =IF(C24>=0,1,0) | D27: =IF(D24>=0,1,0) | E27: =IF(E24>=0,1,0) | F27: =IF(F24>=0,1,0) | G27: =IF(G24>=0,1,0) | H27: =IF(H24>=0,1,0) | I27: =IF(I24>=0,1,0) | ... S27: =IF(S24>=0,1,0)
A28: A cash-out flag (closing<0) | B28: =IF(B26<0,1,0) | C28: =IF(C26<0,1,0) | D28: =IF(D26<0,1,0) | E28: =IF(E26<0,1,0) | F28: =IF(F26<0,1,0) | G28: =IF(G26<0,1,0) | H28: =IF(H26<0,1,0) | I28: =IF(I26<0,1,0) | ... S28: =IF(S26<0,1,0)
A30: SCENARIO B — per-site pricing (what review finding D-02 asked for)
A31: Assumption | B31: Value | C31: Note
A32: Price per site $/mo | B32: 750 | C32: A site = one depot, ward, store or plant: the unit an ops director actually buys, and the unit an auditor asks about. Planning number, to be tested in the SD244 interviews (SD245/SD246).
A33: Sites per paying customer | B33: 2 | C33: Planning number. A single-site pilot that expands is the motion the 6-pilots/month assumption describes.
A34: Implied ARPU $/mo (B) | B34: =$B$32*$B$33
A36: Line | B36: M1 | C36: M2 | D36: M3 | E36: M4 | F36: M5 | G36: M6 | H36: M7 | I36: M8 | J36: M9 | K36: M10 | L36: M11 | M36: M12 | N36: M13 | O36: M14 | P36: M15 | Q36: M16 | R36: M17 | S36: M18
A37: B leads/installs | B37: =$B$6 | C37: =B37*(1+$B$7) | D37: =C37*(1+$B$7) | E37: =D37*(1+$B$7) | F37: =E37*(1+$B$7) | G37: =F37*(1+$B$7) | H37: =G37*(1+$B$7) | I37: =H37*(1+$B$7) | J37: =I37*(1+$B$7) | ... S37: =R37*(1+$B$7)
A38: B new paying | B38: =ROUND(B37*$B$8,1) | C38: =ROUND(C37*$B$8,1) | D38: =ROUND(D37*$B$8,1) | E38: =ROUND(E37*$B$8,1) | F38: =ROUND(F37*$B$8,1) | G38: =ROUND(G37*$B$8,1) | H38: =ROUND(H37*$B$8,1) | I38: =ROUND(I37*$B$8,1) | ... S38: =ROUND(S37*$B$8,1)
A39: B paying accounts | B39: =B38 | C39: =ROUND(B39*(1-$B$10)+C38,1) | D39: =ROUND(C39*(1-$B$10)+D38,1) | E39: =ROUND(D39*(1-$B$10)+E38,1) | F39: =ROUND(E39*(1-$B$10)+F38,1) | G39: =ROUND(F39*(1-$B$10)+G38,1) | H39: =ROUND(G39*(1-$B$10)+H38,1) | I39: =ROUND(H39*(1-$B$10)+I38,1) | J39: =ROUND(I39*(1-$B$10)+J38,1) | ... S39: =ROUND(R39*(1-$B$10)+S38,1)
A40: B MRR net of fee | B40: =ROUND(B39*$B$34*(1-$B$11),0) | C40: =ROUND(C39*$B$34*(1-$B$11),0) | D40: =ROUND(D39*$B$34*(1-$B$11),0) | E40: =ROUND(E39*$B$34*(1-$B$11),0) | F40: =ROUND(F39*$B$34*(1-$B$11),0) | G40: =ROUND(G39*$B$34*(1-$B$11),0) | H40: =ROUND(H39*$B$34*(1-$B$11),0) | I40: =ROUND(I39*$B$34*(1-$B$11),0) | ... S40: =ROUND(S39*$B$34*(1-$B$11),0)
A41: B team cost | B41: =$B$12 | C41: =ROUND(B41*(1+$B$13),0) | D41: =ROUND(C41*(1+$B$13),0) | E41: =ROUND(D41*(1+$B$13),0) | F41: =ROUND(E41*(1+$B$13),0) | G41: =ROUND(F41*(1+$B$13),0) | H41: =ROUND(G41*(1+$B$13),0) | I41: =ROUND(H41*(1+$B$13),0) | J41: =ROUND(I41*(1+$B$13),0) | ... S41: =ROUND(R41*(1+$B$13),0)
A42: B other cash-in | B42: =$B$15 | C42: =$B$15 | D42: =$B$15 | E42: =$B$15 | F42: =$B$15 | G42: =$B$15 | H42: =$B$15 | I42: =$B$15 | ... S42: =$B$15
A43: B net cash/mo | B43: =B40+B42-B41 | C43: =C40+C42-C41 | D43: =D40+D42-D41 | E43: =E40+E42-E41 | F43: =F40+F42-F41 | G43: =G40+G42-G41 | H43: =H40+H42-H41 | I43: =I40+I42-I41 | ... S43: =S40+S42-S41
A44: B cumulative net | B44: =B43 | C44: =B44+C43 | D44: =C44+D43 | E44: =D44+E43 | F44: =E44+F43 | G44: =F44+G43 | H44: =G44+H43 | I44: =H44+I43 | J44: =I44+J43 | ... S44: =R44+S43
...

Sheet Metrics_Targets
A1: METRIC TARGETS — restated per review finding D-03: absolute values with a named measurement source, not multiples of an unknown baseline
A2: D-03 said these targets were unfalsifiable: "3x M1" cannot be missed if M1 is undefined. Every row below now has an absolute number and the code path that measures it, so a miss is visible. M1 = first full calendar month after the listing goes live (G-01).
A3: Metric | B3: M1 | C3: M3 | D3: M6 | E3: M12 | F3: Measured by | G3: Fails if
A4: Paying tenants (cumulative) | B4: 3 | C4: 10 | D4: 25 | E4: 60 | F4: src/billing.ts subscriptions with status=active; G-02 counts only paying strangers | G4: Fewer than 10 by M3 — G-02 unreachable and the S12 kill criteria are evaluated
A5: Installs (cumulative) | B5: 15 | C5: 60 | D5: 150 | E5: 400 | F5: src/install.ts install events, deduplicated by tenant (F-002) | G5: Fewer than 60 by M3 with listing live: the listing, not the product, is the problem
A6: Activation % within 24h | B6: 40% | C6: 45% | D6: 50% | E6: 55% | F6: src/telemetry.ts funnel install->setup->aha, wired at the request boundary since session 24 | G6: Below 35% at M3 — onboarding, not demand
A7: Trial->paid % | B7: 25% | C7: 30% | D7: 33% | E7: 35% | F7: src/entitlements.ts trial expiry vs subscription activation | G7: Below 20% at M3 — pricing or wedge is wrong (SD245)
A8: Week-4 retention of activated tenants | B8: 55% | C8: 60% | D8: 65% | E8: 70% | F8: src/dashboardManager.ts cohort retention | G8: Below 50% — the evidence wedge is not being used after the first shift
A9: Store rating | B9: 4.5+ | C9: 4.6+ | D9: 4.7+ | E9: 4.7+ | F9: Partner Center listing (manual read, monthly) | G9: Below 4.3 — review programme and support speed
A10: MRR $ net of fee | B10: 1200 | C10: 4000 | D10: 10000 | E10: 24000 | F10: Financial_Model Scenario A/B actuals replace the planning inputs | G10: Below half the M6 figure — the funding requirement in Financial_Model is the live question
A11: Logo churn /mo | B11: <5% | C11: <4% | D11: <3% | E11: <3% | F11: src/dashboardManager.ts health score + cancellation reasons (ST-063 exit survey) | G11: Above 6% for two consecutive months
A12: API p95 / bot p95 (ms) | B12: 500 / 800 | C12: 500 / 800 | D12: 450 / 700 | E12: 400 / 650 | F12: src/perf.ts latency budgets; src/slo.ts alert rules | G12: Any month over budget — the rollback signal in ops/incident-response-runbook.md
A13: Availability (SLO 99.5%) | B13: 99.5% | C13: 99.5% | D13: 99.5% | E13: 99.5% | F13: src/slo.ts — 216 minutes of error budget per month, stated as minutes rather than nines | G13: Two consecutive months of budget exhaustion

Sheet Risk_Register
A1: PRODUCT RISK REGISTER — rewritten per review finding D-04 (the free first-party overlap was understated)
A2: The review was blunt: two of the three product pillars overlap Microsoft apps the customer already has at no marginal cost. That is a commercial risk, not a feature gap, and it belongs at the top of this register rather than as a line about a future Shifts release.
A3: Risk | B3: Impact | C3: Likelihood | D3: Mitigation | E3: Owner / story
A4: Two of three pillars overlap FREE first-party Microsoft apps: Approvals and Planner task publishing ship inside Microsoft 365 at zero marginal cost. A per-seat frontline price competes with free, and an IT buyer will ask why. | B4: High | C4: High (already true, not a future release) | D4: Reposition onto the one thing the free tools do not produce: retained, queryable handover evidence with an audit trail an inspector can read. Listing copy, one-pager and comparison pages rewritten explicitly against Approvals and Planner rather than around them (SD245). Per-site pricing modelled so the price is not a per-seat tax on a suite the customer already owns (SD246). The wedge is tested in the SD244 interviews before launch spend. | E4: Senthil — SD244 / SD245
A5: Microsoft ships native Shifts upgrades that absorb the handover thread itself | B5: High | C5: Medium | D5: Depth in approvals and checklists plus the evidence retention story; co-sell alignment so an upgrade is a distribution event rather than an extinction event. Reassess at each Microsoft 365 roadmap release. | E5: Senthil
A6: Demand is unvalidated: the category grows 18.65% CAGR to $45.06bn by 2031, and not one customer has said this product solves a problem they pay for. D13 parked discovery interviews portfolio-wide. | B6: High | C6: High | D6: 15 discovery interviews in regulated frontline sectors on how handover evidence is produced today and what an audit failure costs (SD244). This is the programme gate: G-01/G-02 become achievable on evidence, or the kill criteria fire. | E6: Senthil — SD244
A7: Enterprise sales cycle starves cash before S12: on the v045 per-seat assumptions the model never breaks even and the funding requirement was never stated. | B7: High | C7: Medium | D7: Financial_Model repaired to state the funding requirement, runway and breakeven outright (SD246). Pilot pricing and design-partner order forms by SD247. Per-site pricing gives a smaller first cheque with an expansion path. | E7: Senthil — SD246 / SD247
A8: Store certification loops exceed 2 cycles | B8: Medium | C8: High | D8: Pre-submission consult; validation self-check automated where possible (manifest and command parity assertions in CI); dry run recorded. Attestation and pen test start early because of lead times (SD234/SD235). | E8: Senthil — SD235
A9: Assurance items have long lead times and real money attached: pen test, Publisher Attestation, SOC 2 (audit fee $15k-$50k plus ~6 months observation for Type II). | B9: Medium | C9: High | D9: Evidence packs and control maps are built and bound to tests (SD236/SD237) so the engagements start without a discovery phase. The spend and the timing are Senthil decisions, stated rather than buried. | E9: Senthil — SD237
A10: Perimeter code written from vendor documentation rather than against live endpoints: Entra metadata, Connector JWT rules, Fulfillment API v2, Key Vault managed identity. | B10: Medium | C10: Medium | D10: Same class as tracker risk R-S12, which is why that risk exists: every seam gets a documentation sweep and then live verification before it is called done. SD228, SD232, SD239 and SD240 are those verifications. | E10: Claude + Senthil
A11: This release wrote 19 new modules and 11 new suites; on this project's own history, newly written code is the least-reviewed code (six defects in twelve modules at 100% coverage in sessions 5-8). | B11: Medium | C11: High | D11: The next session opens with a cold review of the S13-S20 code before any new feature work. F-071 and F-072 are already on the register as evidence the pattern held again. | E11: Claude — tracker R-S21

Sheet Traceability_Matrix
A1: TRACEABILITY MATRIX — story -> code -> test -> evidence (v006, 10/09/2026 22:26)
A3: ID | B3: Epic | C3: Sprint | D3: Points | E3: Module / file | F3: Test suite | G3: Status | H3: Evidence / note
A4: ST-001 | B4: F1 | C4: S2 | D4: 5 | E4: src/handover.ts + src/moduleBase.ts | F4: tests/features.test.ts + tests/moduleBase.test.ts | G4: Done | H4: Built + covered at 100% this session
A5: ST-002 | B5: F1 | C5: S2 | D5: 8 | E5: src/handover.ts + src/moduleBase.ts | F5: tests/features.test.ts + tests/moduleBase.test.ts | G5: Done | H5: Built + covered at 100% this session | State now persisted via src/persistence.ts — survives restart/blue-green (GAP-SD8b)
A6: ST-003 | B6: F1 | C6: S2 | D6: 5 | E6: src/handover.ts + src/moduleBase.ts | F6: tests/features.test.ts + tests/moduleBase.test.ts | G6: Done | H6: Built + covered at 100% this session
A7: ST-004 | B7: F1 | C7: S2 | D7: 3 | E7: src/handover.ts + src/moduleBase.ts | F7: tests/features.test.ts + tests/moduleBase.test.ts | G7: Done | H7: Built + covered at 100% this session
A8: ST-005 | B8: F1 | C8: S3 | D8: 5 | E8: src/ui/screens.tsx + web/TabShell.tsx + src/server.ts | F8: tests/ui.screens.test.tsx + tests/tab.test.tsx | G8: Code-complete pending live | H8: Surface now full-stack incl. HTTP layer (GAP-SD5): client paths served + authenticated; only in-client render pending | Tab assets served by the app itself at /tab (F-058)
A9: ST-006 | B9: F1 | C9: S3 | D9: 3 | E9: src/handover.ts + src/moduleBase.ts | F9: tests/features.test.ts + tests/moduleBase.test.ts | G9: Done | H9: Built + covered at 100% this session
A10: ST-007 | B10: F1 | C10: S3 | D10: 3 | E10: src/handover.ts + src/moduleBase.ts | F10: tests/features.test.ts + tests/moduleBase.test.ts | G10: Done | H10: Built + covered at 100% this session
A11: ST-008 | B11: F1 | C11: S3 | D11: 2 | E11: src/handover.ts + src/moduleBase.ts | F11: tests/features.test.ts + tests/moduleBase.test.ts | G11: Done | H11: Built + covered at 100% this session
A12: ST-009 | B12: F1 | C12: S3 | D12: 5 | E12: src/handover.ts + src/moduleBase.ts | F12: tests/features.test.ts + tests/moduleBase.test.ts | G12: Done | H12: Built + covered at 100% this session
A13: ST-010 | B13: F1 | C13: S3 | D13: 3 | E13: src/notifications.ts + src/notificationDispatcher.ts | F13: tests/notificationDispatcher.test.ts | G13: Done | H13: Delivery implemented on both channels with independent failure handling (F-034); live send verified by sweep step SW-18
A14: ST-011 | B14: F2 | C14: S3 | D14: 5 | E14: src/approvals.ts + src/moduleBase.ts | F14: tests/features.test.ts + tests/moduleBase.test.ts | G14: Done | H14: Built + covered at 100% this session
A15: ST-012 | B15: F2 | C15: S3 | D15: 8 | E15: src/approvals.ts + src/moduleBase.ts | F15: tests/features.test.ts + tests/moduleBase.test.ts | G15: Done | H15: Built + covered at 100% this session | State now persisted via src/persistence.ts — survives restart/blue-green (GAP-SD8b)
... A150: SD247 | B150: E20 | C150: S20 | D150: 6 | E150: src/telemetry.ts funnel (wired at the boundary since session 24) | F150: tests/observability.test.ts | G150: To do — Senthil | H150: Closes G-02. The funnel that would measure this is real and wired. The five customers are not, and G-02 counts only paying strangers.
A152: Coverage evidence (v0.14.0): jest --ci — 68 unit suites / 555 tests passed at 100% statements, branches, functions and lines, zero pragmas; plus a real-Postgres integration tier (9/9, tests/integration/) and a production-seam wiring assertion that also runs at boot — the three tiers of decision D-SD7. Status colours: green=Done, amber=pending live, blue=drafted, orange=owed to Senthil (D-SD8).

Sheet Review_Findings
A1: COLD-REVIEW PASS 1 — 11/09/2026 12:51 (adversarial self-review; external second review still owed per ST-097)
A3: ID | B3: Severity | C3: Finding | D3: Resolution | E3: Status / Disposition
A4: F-001 | B4: High | C4: Billing had no payment-recovery path: an account in grace or read-only could never return to active; dunning counter never reset. | D4: paymentRecovered() added — grace/read_only -> active, dunning + graceStart reset, recovery email logged; dunning restarts fresh on a later failure. Regression pinned. | E4: FIXED (regression tests)
A5: F-002 | B5: High | C5: Duplicate install webhook silently overwrote an existing tenant account — full data loss on a repeated Teams install event. | D5: install() made idempotent: existing account returned untouched, install_duplicate_ignored telemetry row. Regression pinned. | E5: FIXED (regression tests)
A6: F-003 | B6: Medium | C6: Unbounded in-memory ledgers: telemetry error list and notification sent-log grew forever (memory exhaustion under sustained traffic). | D6: Both FIFO-capped at 10,000 entries. Regression pinned. Audit log deliberately NOT capped — see F-008. | E6: FIXED (regression tests)
A7: F-004 | B7: Medium | C7: Retry backoff delays were computed (backoffDelay) but never applied — retries hammered the platform API instantly, defeating ST-070 intent. | D7: Injectable sleeper wired between failed attempts (exponential, none after final attempt); no-op default in tests, setTimeout at live bootstrap. Regression pinned. | E7: FIXED (regression tests)
A8: F-005 | B8: Medium | C8: Approval engine auto-approved zero and negative amounts (amount <= threshold held for -50). | D8: submit() validates amount > 0 -> AMOUNT_INVALID. Regression pinned. | E8: FIXED (regression tests)
A9: F-006 | B9: Low | C9: Checklist CSV export corrupted by commas/quotes in task text (column drift in compliance evidence). | D9: RFC-4180 quoting applied. Regression pinned. NOTE: CSV importer (moduleBase.importCsv) is still naive-split — flagged in REVIEW_PACK probes as candidate finding for pass 2. | E9: FIXED (regression tests)
A10: F-007 | B10: Medium | C10: Circuit breaker has no half-open probe: once open it stays open until manual reset() — a transient Teams outage requires operator action to recover. | D10: Options: (a) half-open probe after cooldown N seconds, (b) keep manual-reset semantics + ops alert. Same class as OnCall F-006. | E10: OPEN — Senthil disposition
A11: F-008 | B11: Low | C11: AuditLog grows unbounded in-memory. Capping would truncate a compliance trail, so no FIFO applied. | D11: Postgres-backed audit table at S1-08 live wiring; in-memory mode acceptable for sandbox/tests only. | E11: OPEN — Senthil disposition
A12: F-009 | B12: Process | C12: Evidence discipline: v006 traceability for ST-066 said "vault/encryption pattern coded" before any such module existed in the repo. | D12: Corrected this session: src/crypto.ts built (AES-256-GCM, unique IVs, tamper rejection, SecretsVault with redacted dump + key rotation) — the claim is now true; ST-066 stays Code-complete pending live KMS wiring. Lesson logged: evidence strings must name an existing file. | E12: CLOSED — corrective action done
A14: COLD-REVIEW PASS 2 — 11/09/2026 20:30 (modules pass 1 skipped) — review COMPLETE across all modules
A15: F-010 | B15: Medium | C15: CSV importer was naive comma-split (RAID R-S7): quoted fields with commas mis-parsed on import while export was already RFC-4180. | D15: parseCsvLine RFC-4180 parser wired into importCsv. Regression pinned. R-S7 closed. | E15: FIXED (regression tests)
A16: F-011 | B16: Medium | C16: Telemetry alert ledger unbounded AND spammed — churn/activation alerts re-fired on every call (same low health score pushed 50 identical alerts). | D16: fireAlert(): consecutive-duplicate dedupe + FIFO cap 1000. Regression pinned. | E16: FIXED (regression tests)
A17: F-012 | B17: Low | C17: Latency monitor samples unbounded per surface; p95 sorted an ever-growing array (same ledger class as F-003, missed in pass 1). | D17: Rolling 10k window per surface. Regression pinned. | E17: FIXED (regression tests)
A18: F-013 | B18: Medium | C18: Trial banner shown to NON-trial accounts — a paying customer saw "Trial ended — choose a plan"; grace/read-only accounts likewise. | D18: bannerText returns empty for any state other than trial. Regression pinned. | E18: FIXED (regression tests)
A19: OBS-SD1 | B19: Obs | C19: complete()/acknowledge on a PAUSED module still succeeds — pause blocks new items only. Plausibly intended (finish in-flight work) but undocumented. | D19: Options: (a) document as intended, (b) block all writes on pause. | E19: OPEN — Senthil disposition
A21: EXTERNAL VERIFICATION SWEEP — 13/09/2026 09:52 (assumptions checked against live Microsoft Teams/Partner Center docs + artifact-gap audit)
A22: VER-SD01 | B22: STORE-BLOCKING | C22: ASSET_PLAN specified 5 screenshots at 1920x1080. Verified Teams Store spec is 1366x768, max 1,024 KB each, minimum 3 / maximum 5, and at least one MUST show mobile functionality. Assets produced to the old spec would have failed validation. Video also takes a YouTube/Vimeo URL, not an upload. | D22: ASSET_PLAN.md rewritten to the verified spec (mobile shot already slot 3); pinned by tests/manifest.test.ts so the old figure cannot return. | E22: FIXED (test-pinned)
A23: VER-SD02 | B23: STORE-BLOCKING | C23: Manifest declared schema v1.17. Current is v1.19 (v1.18 does not exist) and store submission requires referencing the latest schema. | D23: Manifest bumped to v1.19 ($schema + manifestVersion); assertion added to the package-validation suite. | E23: FIXED (test-pinned)
A24: VER-SD03 | B24: High | C24: Manifest carried the top-level "permissions": ["identity","messageTeamMembers"] block — this property is deprecated in the current manifest reference. | D24: Removed; replaced by authorization.permissions.resourceSpecific. Absence asserted in tests. | E24: FIXED (test-pinned)
A25: VER-SD04 | B25: High | C25: Least-privilege doc (ST-064, gate LC-5 previously marked Done) claimed org-wide Graph scopes incl. TeamMember.Read.All — far broader than needed and inconsistent with a Teams bot. Correct model is resource-specific consent, scoped to the installed team. Manifest also declared no RSC block at all, so the bot could not read members or post without @mention. | D25: SCOPE_MAP + docs rewritten to RSC (ChannelMessage.Send.Group, ChannelMessage.Read.Group, TeamMember.Read.Group, delegated User.Read); manifest gains the RSC block; test asserts manifest RSC names equal the published map and that no ".Read.All" string exists anywhere. | E25: FIXED (test-pinned)
A26: VER-SD05 | B26: Verified OK | C26: botId vs webApplicationInfo.id match, validDomains present, resource URI shape, colour icon 192x192, 3% Microsoft store service fee in the financial model. | D26: No change; match now asserted in tests so it cannot drift. | E26: VERIFIED
A27: VER-SD06 | B27: Medium | C27: Outline icon was white-on-transparent but had padding on all sides; store guideline requires it tightly cropped with no extra padding. | D27: Icon regenerated edge-to-edge (bbox 0,0,32,32), white + transparency only; dimensions asserted from PNG headers in tests. | E27: FIXED (test-pinned)
A28: VER-SD07 | B28: Doc | C28: AppSource is now presented as "Microsoft Marketplace"; publisher docs describe the 3% charge as a standard store service fee. | D28: Naming noted for listing/GTM copy; economics unchanged (3% verified), financial model needs no revision. | E28: NOTED
A29: VER-SD08 | B29: LIVE-BLOCKING (gap) | C29: Artifact-gap audit: the manifest declares three static tabs but no code ever performed the TeamsJS handshake. A contentUrl page that never calls app.initialize()/notifySuccess renders a blank, error-less tab inside Teams — invisible to the whole suite, same class as the sibling-product SDK gaps. | D29: src/teamsClient.ts boundary built — initialize, context validation, theme handler, notifySuccess/notifyFailure, and an explicit user-facing error when the TeamsJS script is absent (never a blank tab); 5 tests covering every path. Sweep extended 12 -> 14 steps (RSC consent + tab handshake); dev-tenant guide gains the bootstrap step. | E29: FIXED (test-pinned)
A31: ARTIFACT-GAP AUDIT ROUND 2 — 13/09/2026 10:01 (manifest promises vs shipped code)
A32: GAP-SD1 | B32: LIVE-BLOCKING | C32: Manifest declared three static tabs (home, handovers, checklists) pointing at contentUrl pages that did not exist — no entry page, no bundle, no mount. Session 7 built only the TeamsJS boundary, not the page behind it. Installing the app would have shown three broken tabs. | D32: web/ layer built: TabShell (bootstrap -> entity routing -> real screens with loading/error states), typed TabApi with injected fetcher (401/403/outage mapped to distinct human messages), entry.tsx mount reading ?entity=, index.html loading TeamsJS BEFORE the bundle, esbuild build script -> web-dist/. 20 tests incl. unmount-in-flight paths. | E32: FIXED (test-pinned)
