Workbook

Sheet Version_Control
A1: VERSION CONTROL — FlowCast
A3: Version | B3: Date | C3: Author | D3: Change | E3: Status
A4: v001-v004 | B4: 2026-09-05 | C4: Claude for Senthil/KP | D4: Lineage: marketplace master (868 entries) -> portfolio plan (12 products) -> wave-1 (RetainKit/ShiftDesk/EngageOS, v005) -> this product selected for wave-3 | E4: Released
A5: v007 | B5: 2026-09-05 19:50 | C5: Claude for Senthil/KP | D5: Full product workbook for FlowCast on Xero App Store: spec, screen inventory, 100+ story backlog, live sprint board, 18-month financial model (editable assumptions), GTM execution tasks, platform launch checklist, metric targets, risk register | E5: Released
A6: v008 | B6: 2026-09-10 22:01 | C6: Claude for Senthil/KP | D6: Sprint_Tracker_Log + Traceability_Matrix sheets added; D13 100% coverage gate applied (ST-085 amended); S1 foundation + code-completable S2-S8 stories built in TypeScript with 11 Jest suites / 120 tests at 100% stmts/branches/funcs/lines; Full_Backlog statuses updated (58 Done, 4 pending-live, 2 in progress); portfolio D15 note logged | E6: Released
A7: v009 | B7: 2026-09-10 22:20 | C7: Claude for Senthil/KP | D7: UI surfaces (5 React screens + MetricsPanel) with Xero deep links; ST-003 rule builder; notifications w/ per-type mute; pause toggles; portal rules; per-feature metrics/trends; CI workflow (ST-086). 13 suites / 148 tests at 100% coverage incl. components; statuses now 74 Done / 5 pending-live / 21 backlog | E7: Released
A8: v010 | B8: 2026-09-10 22:27 | C8: Claude for Senthil/KP | D8: Reliability + a11y code (latency budgets, degradation comms, jest-axe WCAG pass), demo-data mode, scenario/portal notification events; 12 content artifacts (15 help articles, chat SLA, video script, listing copy A/B, asset specs, pricing, trust page, dry-run gap report, 3 runbooks). 14 suites/155 tests at 100%. Dry-run found webhook build gap -> v011 | E8: Released
A9: v011 | B9: 2026-09-10 22:51 | C9: Claude for Senthil/KP | D9: Content webhooks built (dry-run gap #4): signature verify, fast-ack idempotent queue, retry/dead-letter/heal, payment->cancel-nudges mapping; bank-txn 15-min polling (platform has no such webhook). Launch_Checklist statuses updated honestly. 15 suites / 170 tests at 100%. Sandbox work exhausted — remaining items need Senthil | E9: Released
A10: v012 | B10: 2026-09-10 22:56 | C10: Claude for Senthil/KP | D10: Per-tenant 60/min rate limiter; 20-client + 12-month QA drills executed (found+fixed batch-isolation anomaly blind spot via detectWithHistory); k6 load harness (5x); blue/green deploy workflow; HTTP wiring layer. 16 suites / 182 tests at 100%. Backlog down to 4 (all require live infra/humans) | E10: Released
A11: v013 | B11: 2026-09-10 23:03 | C11: Claude for Senthil/KP | D11: Live-sweep readiness: typed config loader + .env.example, 30-min dev-org setup guide, 12-step scripted verification sweep. Portfolio action board issued as separate workbook. 17 suites / 186 tests at 100% | E11: Released
A12: v014 | B12: 2026-09-11 11:09 | C12: Claude for Senthil/KP | D12: Cold-review pass 1: 5 defects found + fixed with regression tests (F-001 unbounded webhook idempotency ledger -> FIFO 10k; F-002 signed-but-malformed payload crashed fast-ack -> guarded parse; F-003 rate-limiter idle tenants never evicted -> prune(); F-004 duplicate anomaly repeated per txn with 3+ matches -> deduped; F-005 nudgesPerMonth had no cycle-scoped counter/reset -> UsageCycle built). ST-066 encryption at rest built (AES-256-GCM envelope, SecretsVault boundary, token sealing, TLS assertion, self-verifying evidence drill). Security evidence pack (sandbox half of ST-068) + REVIEW_PACK.md for external second reviewer. 18 suites / 207 tests at 100% zero pragmas; tsc clean. Review_Findings sheet added for Senthil dispositions | E12: Released
A13: v015 | B13: 2026-09-11 12:47 | C13: Claude for Senthil/KP | D13: Cold-review pass 2 (the 10 modules pass 1 did not deep-read): 4 defects found + fixed with regressions — F-006 nudge planner re-sent the same tier daily (no sent-history) -> SentHistory, tier fires once, test-mode not recorded, failed sends retried; F-007 purgeExpired flagged accounts but never deleted the record -> record deleted (data deletion honoured), purged status removed; F-008 non-finite platform dates silently dropped items from the forecast -> validated with clear errors, plus traffic light now judged on displayed rounded balance; F-009 monthly scenario cost omitted its 4th occurrence inside the 13-week horizon (week 13) -> 4 occurrences, optimism bias removed. 2 observations logged without fix (no backoff jitter; unlimited half-open breaker probes). 2 pre-existing assertions updated (one encoded F-009). 19 suites / 219 tests at 100% zero pragmas; tsc clean. Cold review COMPLETE across all 27 modules | E13: Released
A14: v016 | B14: 2026-09-11 15:27 | C14: Claude for Senthil/KP | D14: CODE-PHASE-COMPLETION WAVE (sibling-validated TeleField/VoiceBridge pattern): ST-081 built-in chat + 4-business-hour SLA engine (business-hours math skips weekends/out-of-hours; queue sorts tightest deadline; chat-vendor decision now OPTIONAL — D-F6); ST-099 listing SEO iteration engine sandbox half (promote/keyword/demote rules with 100-impression thin-data floor; live half needs post-launch search-term data); ST-100 10-slot design-partner tracker (stale-nudge at 7 days; honest exit math separates reviews from G-02 paying strangers); ST-080 ranked help-center search over the 15 launch articles (manifest test-gated against docs/help); ST-095 pricing plan-matrix generated from billing.ts single source + DRIFT GATE test binding the published page to the enforced constants. 20 suites / 243 tests at 100% zero pragmas; tsc clean. FLOWCAST CODE PHASE COMPLETE — backlog zero, no further code sprints planned | E14: Released
... A31: v033 | B31: 2026-09-13 18:48 | C31: Claude for Senthil/KP | D31: ASYNC-OWNERSHIP GATE (sixth, and the last derived from a shipped defect) + REVIEW PLAYBOOK. A real defect found first: the worker tick called drainOnce with no catch, and drainOnce RETHROWS after re-queuing (F4-04) — so every store or sink failure produced an unhandled rejection that the degradation counter never saw and /ready never showed. The process guards stopped it being fatal, but it was invisible. Both that and the SIGTERM shutdown call now have owners; shutdown failures are reported with credentials redacted. Sixth gate: a promise started and not awaited must have an owner (safely(), or an explicit .catch). Only resilience.ts is exempt — it IS the owner of last resort and cannot wrap itself. Proved against the exact CHAOS-1 shape; all five provable gates now print PROVED. REVIEW PLAYBOOK written (gates/REVIEW_PLAYBOOK.md): the eight review passes in the order that proved productive — cold review by module, external verification sweep, artifact-gap audit, integration audit, review-the-previous-session, environment assumptions, artifact pairing, outsider-first document review — plus the rules learned the hard way and how to run them on another product. ~40 defects were found in code that was already at 100% coverage with zero backlog; the gates catch recurrence, the passes find what nobody has thought of yet. 36 suites / 500 tests at 100% zero pragmas; six gates in CI. Recommendation recorded: this is a natural stopping point for sandbox work | E31: Released
A32: v034 | D32: PLANNED: opens on live evidence (dev org + DATABASE_URL) or dispositions — no further sandbox sprints recommended | E32: Planned

Sheet ReadMe_Scope
A1: FlowCast — 13-week cash forecast, scenario planning, invoice-chasing nudges for SMB owners and their accountants
A3: PLATFORM: Xero App Store | CATEGORY: Cash Flow Forecasting
A4: PROBLEM: Float/Fathom serve accountants; owner-facing simple forecasting still underserved at low price points
A5: DIFFERENTIATION: Plain-language forecast, WhatsApp/email nudge integration, accountant multi-client view
A6: ICP: SMBs 1-50 staff on Xero + their accountants/bookkeepers (multi-client)
A8: HOW TO USE: Full_Backlog is the single source of truth (edit Status column during execution). Sprint_Board recalculates points per sprint automatically. Financial_Model assumptions (yellow) are editable — the 18-month build recalculates. Launch_Checklist is the platform-specific gate before submission. All costs/timelines are market-standard estimates; verify platform terms (fees/review rules) during S0.
A10: STACK ASSUMPTION (market standard): TypeScript/Node or platform-mandated runtime, React frontends, Postgres, hosted on AWS/GCP/platform FaaS as required, GitHub Actions CI, PostHog + Sentry telemetry, Intercom-class support.

Sheet Senthil_Handover
A1: FLOWCAST — EVERYTHING BLOCKED ON SENTHIL (as of 13 Sep 2026 12:03, workbook v026)
A2: Ordered by leverage: external lead times first (they queue while you do everything else), then same-day unlocks, then decisions, then post-launch.
A4: # | B4: Item | C4: Why it is blocked on you | D4: What it unlocks | E4: Effort | F4: Lead time | G4: Type
A5: 1 | B5: Xero dev org + app registration | C5: Needs your Xero account; scopes, webhook key and redirect URI come from it. ALSO NOW: a Postgres DATABASE_URL — since v027 tenant state is durable, and without the database the app falls back to memory (visible as durableStore:false on /health) | D5: THE big one: the 12-step live sweep, which flips 16 code-complete stories to Done. Step 1 is now npm ci && npm run build && npm run migrate && npm start | E5: ~30 min | F5: Same day | G5: External access
A6: 2 | B6: Pen-test vendor engagement | C6: Vendor selection and budget are yours; it is the external half of ST-068 | D6: Security evidence pack completion → Xero App Partner certification (LC-5) | E6: Email + scoping | F6: 2-4 weeks | G6: External vendor
A7: 3 | B7: External second reviewer (REVIEW_PACK.md) | C7: Same-AI review is not independent; ST-097 stays In progress until a human or different AI signs off | D7: Submission dry-run credibility; independent check on ~30 findings I both made and fixed | E7: 2-3 hrs of their time | F7: Days | G7: External person
A8: 4 | B8: Xero App Store partner application | C8: Your company details and bank/tax info | D8: In-store subscription billing (ST-059); sweep step 9 test purchase. NOTE: App Store Subscriptions confirmed for UK/AU/NZ; re-check current region list at onboarding | E8: ~1 hr | F8: 1-3 weeks | G8: External queue
A9: 5 | B9: F-001..F-009, INT-F1..F5, VER-001..003, F3-01..04, F4-01..04, HOLE-1/2 dispositions | C9: ~30 findings in the Review_Findings sheet are all fixed but marked Pending your disposition — you may disagree with a fix or want one reverted | D9: Closes the review record; anything you reject, I change | E9: ~45 min reading | F9: — | G9: Decision
A10: 6 | B10: OBS-001 / OBS-002 dispositions | C10: Logged no-fix deliberately: no backoff jitter (retry herds) and unlimited half-open breaker probes. Both are judgement calls on launch traffic | D10: Either accept as-is for launch or I build them | E10: ~10 min | F10: — | G10: Decision
A11: 7 | B11: Listing copy A/B pick | C11: Two full drafts exist (listing-copy-A.md, listing-copy-B.md); the choice is positioning, which is yours | D11: ST-093; listing submission | E11: ~20 min | F11: — | G11: Decision
A12: 8 | B12: D-F6 chat vendor ratification | C12: The built-in chat + 4-business-hour SLA engine works, so a vendor is OPTIONAL — a later transport swap, not a launch blocker | D12: Formally closes ST-081 | E12: ~5 min | F12: — | G12: Decision
A13: 9 | B13: D15 portfolio sequencing | C13: Open since 10 Sep across all products: parallel builds vs strict WIN order | D13: Affects whether FlowCast launches before the rank-1..11 products | E13: — | F13: — | G13: Decision
A14: 10 | B14: Screenshot/video capture | C14: Needs the app running against a real org with real data — i.e. item 1 first | D14: ST-094; listing assets | E14: ~2 hrs | F14: After item 1 | G14: Post-dev-org
A15: 11 | B15: Design-partner outreach | C15: The 10-slot tracker with honest exit math is built and empty; sending the emails is yours | D15: ST-100; the G-02 gate needs 10 PAYING strangers — reviews do not count | E15: ~1 hr | F15: Weeks | G15: Post-launch
A16: 12 | B16: Port the gate pack to other products | C16: gates/README.md + npm run prove:gates are ready; which products get them is a portfolio call | D16: Would catch the same defect classes in the other 10 builds — but competes with getting this one live | E16: ~1 hr each | F16: — | G16: Decision
A18: Nothing on this list is codeable in the sandbox. FlowCast code is 29 suites / 395 tests at 100% coverage, zero pragmas, three proved gates in CI, and boots end to end (npm start → /health → signed webhook).

Sheet Product_Spec
A1: PRODUCT SPEC
A3: Module (feature) | B3: Scope in MVP | C3: Out of scope (v1) | D3: Non-functional requirements
A4: 13-week forecast engine | B4: 13-week forecast engine: end-to-end happy path + edge cases + permissions | C4: Advanced automation, AI beyond listed, multi-language beyond launch set | D4: p95 <500ms API / <2s UI loads
A5: Scenario sliders | B5: Scenario sliders: end-to-end happy path + edge cases + permissions | C5: Advanced automation, AI beyond listed, multi-language beyond launch set | D5: 99.5% monthly uptime
A6: Invoice chase nudges | B6: Invoice chase nudges: end-to-end happy path + edge cases + permissions | C6: Advanced automation, AI beyond listed, multi-language beyond launch set | D6: WCAG AA
A7: Accountant portal | B7: Accountant portal: end-to-end happy path + edge cases + permissions | C7: Advanced automation, AI beyond listed, multi-language beyond launch set | D7: SOC2-track controls
A8: Bank-feed anomaly alerts | B8: Bank-feed anomaly alerts: end-to-end happy path + edge cases + permissions | C8: Advanced automation, AI beyond listed, multi-language beyond launch set | D8: Rate-limit safe (backoff+queue)
A10: Persona | B10: Jobs-to-be-done
A11: SMB owner | B11: Anxiety about cash; wants traffic-light simplicity
A12: Accountant partner | B12: Advisory revenue tool across client base
A13: Bookkeeper | B13: Data hygiene; bank-feed exceptions

Sheet Screens_Wireframes
A1: SCREEN INVENTORY (attach Figma links in col E during S0)
A3: # | B3: Screen | C3: Purpose | D3: Key elements | E3: Wireframe link
A4: 1 | B4: Onboarding / first-run | C4: Reach aha in <1 day | D4: Checklist, sample data toggle, connect steps
A5: 2 | B5: Home dashboard | C5: Daily habit surface | D5: KPI cards, activity feed, alerts
A6: 3 | B6: 13-week forecast engine workspace | C6: Core value surface | D6: List+detail, bulk actions, status chips
A7: 4 | B7: Scenario sliders builder | C7: Configure second pillar | D7: Rule builder, preview, test mode
A8: 5 | B8: Invoice chase nudges view | C8: Differentiator surface | D8: Timeline/visual, export
A9: 6 | B9: Settings & team | C9: Roles, notifications, data | D9: Role matrix, API keys, danger zone
A10: 7 | B10: Billing | C10: Plan/trial/invoices | D10: Plan cards, usage meter, invoices
A11: 8 | B11: Analytics | C11: Prove ROI | D11: Funnel, cohort, export
A12: 9 | B12: Help & support | C12: Deflect + assist | D12: Search, chat, status

Sheet Full_Backlog
A1: FULL BACKLOG | H1: As-built verification (13 Sep 12:03)
A3: ID | B3: Epic | C3: Story | D3: Points | E3: Priority | F3: Sprint | G3: Status
A4: ST-001 | B4: F1 | C4: As a SMB owner, I can set up 13-week forecast engine with sensible defaults in one screen | D4: 5 | E4: P0 | F4: S2 | G4: Done
A5: ST-002 | B5: F1 | C5: As a SMB owner, the 13-week forecast engine happy path completes without documentation | D5: 8 | E5: P0 | F5: S2 | G5: Done
A6: ST-003 | B6: F1 | C6: As a Accountant partner, I can customise 13-week forecast engine rules/conditions for my workflow | D6: 5 | E6: P1 | F6: S2 | G6: Done
A7: ST-004 | B7: F1 | C7: As a user, 13-week forecast engine shows clear errors and retry paths on platform API failures | D7: 3 | E7: P0 | F7: S2 | G7: Done
A8: ST-005 | B8: F1 | C8: As a Bookkeeper, 13-week forecast engine works on the web app with Xero deep links + accountant portal surface end-to-end | D8: 5 | E8: P0 | F8: S3 | G8: Done
A9: ST-006 | B9: F1 | C9: As a Accountant partner, I can see 13-week forecast engine performance metrics and trends | D9: 3 | E9: P1 | F9: S3 | G9: Done
A10: ST-007 | B10: F1 | C10: As a user, 13-week forecast engine respects role permissions and audit logging | D10: 3 | E10: P1 | F10: S3 | G10: Done
A11: ST-008 | B11: F1 | C11: As a SMB owner, I can pause/disable 13-week forecast engine without data loss | D11: 2 | E11: P2 | F11: S3 | G11: Done
A12: ST-009 | B12: F1 | C12: As a Accountant partner, I can import/migrate existing data into 13-week forecast engine (CSV + competitor importer) | D12: 5 | E12: P1 | F12: S3 | G12: Done
A13: ST-010 | B13: F1 | C13: As a user, I get notifications (in-app + email) for key 13-week forecast engine events with per-type mute | D13: 3 | E13: P2 | F13: S3 | G13: Done
A14: ST-011 | B14: F2 | C14: As a SMB owner, I can set up Scenario sliders with sensible defaults in one screen | D14: 5 | E14: P0 | F14: S3 | G14: Done
A15: ST-012 | B15: F2 | C15: As a SMB owner, the Scenario sliders happy path completes without documentation | D15: 8 | E15: P0 | F15: S3 | G15: Done
... A24: ST-021 | B24: F3 | C24: As a SMB owner, I can set up Invoice chase nudges with sensible defaults in one screen | D24: 5 | E24: P0 | F24: S5 | G24: Done
A25: ST-022 | B25: F3 | C25: As a SMB owner, the Invoice chase nudges happy path completes without documentation | D25: 8 | E25: P0 | F25: S5 | G25: Done | H25: Marked Done at build, but planNudges had NO driver until v020 (GAP-F2) — the daily cycle never ran. True as built since v020
A26: ST-023 | B26: F3 | C26: As a Accountant partner, I can customise Invoice chase nudges rules/conditions for my workflow | D26: 5 | E26: P1 | F26: S5 | G26: Done
A27: ST-024 | B27: F3 | C27: As a user, Invoice chase nudges shows clear errors and retry paths on platform API failures | D27: 3 | E27: P0 | F27: S5 | G27: Done | H27: Retry existed at build; the send path only ran from v020 (GAP-F2), once-per-tier from v015 (F-006). True as built since v020
A28: ST-025 | B28: F3 | C28: As a Bookkeeper, Invoice chase nudges works on the web app with Xero deep links + accountant portal surface end-to-end | D28: 5 | E28: P0 | F28: S5 | G28: Done
A29: ST-026 | B29: F3 | C29: As a Accountant partner, I can see Invoice chase nudges performance metrics and trends | D29: 3 | E29: P1 | F29: S5 | G29: Done
A30: ST-027 | B30: F3 | C30: As a user, Invoice chase nudges respects role permissions and audit logging | D30: 3 | E30: P1 | F30: S5 | G30: Done
A31: ST-028 | B31: F3 | C31: As a SMB owner, I can pause/disable Invoice chase nudges without data loss | D31: 2 | E31: P2 | F31: S5 | G31: Done
A32: ST-029 | B32: F3 | C32: As a Accountant partner, I can import/migrate existing data into Invoice chase nudges (CSV + competitor importer) | D32: 5 | E32: P1 | F32: S5 | G32: Done
A33: ST-030 | B33: F3 | C33: As a user, I get notifications (in-app + email) for key Invoice chase nudges events with per-type mute | D33: 3 | E33: P2 | F33: S5 | G33: Done
A34: ST-031 | B34: F4 | C34: As a SMB owner, I can set up Accountant portal with sensible defaults in one screen | D34: 5 | E34: P0 | F34: S6 | G34: Done
A35: ST-032 | B35: F4 | C35: As a SMB owner, the Accountant portal happy path completes without documentation | D35: 8 | E35: P0 | F35: S6 | G35: Done
A36: ST-033 | B36: F4 | C36: As a Accountant partner, I can customise Accountant portal rules/conditions for my workflow | D36: 5 | E36: P1 | F36: S6 | G36: Done
A37: ST-034 | B37: F4 | C37: As a user, Accountant portal shows clear errors and retry paths on platform API failures | D37: 3 | E37: P0 | F37: S6 | G37: Done
A38: ST-035 | B38: F4 | C38: As a Bookkeeper, Accountant portal works on the web app with Xero deep links + accountant portal surface end-to-end | D38: 5 | E38: P0 | F38: S6 | G38: Done
A39: ST-036 | B39: F4 | C39: As a Accountant partner, I can see Accountant portal performance metrics and trends | D39: 3 | E39: P1 | F39: S6 | G39: Done
... A43: ST-040 | B43: F4 | C43: As a user, I get notifications (in-app + email) for key Accountant portal events with per-type mute | D43: 3 | E43: P2 | F43: S6 | G43: Done
A44: ST-041 | B44: F5 | C44: As a SMB owner, I can set up Bank-feed anomaly alerts with sensible defaults in one screen | D44: 5 | E44: P0 | F44: S8 | G44: Done | H44: Detection existed at build; polling — the ENTIRE mechanism under D-F4 — only ran from v020 (GAP-F2), per-tenant from v022 (F4-01). True as built since v022
A45: ST-042 | B45: F5 | C45: As a SMB owner, the Bank-feed anomaly alerts happy path completes without documentation | D45: 8 | E45: P0 | F45: S8 | G45: Done | H45: Happy path could not complete before v020 (no poll driver) and ran for only ONE org until v022 (F4-01). True as built since v022
A46: ST-043 | B46: F5 | C46: As a Accountant partner, I can customise Bank-feed anomaly alerts rules/conditions for my workflow | D46: 5 | E46: P1 | F46: S8 | G46: Done
A47: ST-044 | B47: F5 | C47: As a user, Bank-feed anomaly alerts shows clear errors and retry paths on platform API failures | D47: 3 | E47: P0 | F47: S8 | G47: Done | H47: Error/retry paths unreachable before the poll ran (v020); breaker protection verified v021. True as built since v021
A48: ST-045 | B48: F5 | C48: As a Bookkeeper, Bank-feed anomaly alerts works on the web app with Xero deep links + accountant portal surface end-to-end | D48: 5 | E48: P0 | F48: S8 | G48: Done
A49: ST-046 | B49: F5 | C49: As a Accountant partner, I can see Bank-feed anomaly alerts performance metrics and trends | D49: 3 | E49: P1 | F49: S8 | G49: Done
A50: ST-047 | B50: F5 | C50: As a user, Bank-feed anomaly alerts respects role permissions and audit logging | D50: 3 | E50: P1 | F50: S8 | G50: Done
A51: ST-048 | B51: F5 | C51: As a SMB owner, I can pause/disable Bank-feed anomaly alerts without data loss | D51: 2 | E51: P2 | F51: S8 | G51: Done
A52: ST-049 | B52: F5 | C52: As a Accountant partner, I can import/migrate existing data into Bank-feed anomaly alerts (CSV + competitor importer) | D52: 5 | E52: P1 | F52: S8 | G52: Done
...

Sheet Sprint_Board
A1: SPRINT BOARD — live counts from Full_Backlog
A3: Sprint | B3: Focus | C3: Stories | D3: Points | E3: Done | F3: Exit criteria
A4: S0 | B4: Discovery & Design (2 wks) | C4: =COUNTIF(Full_Backlog!F4:F103,"S0") -> 0 | D4: =SUMIF(Full_Backlog!F4:F103,"S0",Full_Backlog!D4:D103) -> 0 | E4: =COUNTIFS(Full_Backlog!F4:F103,"S0",Full_Backlog!G4:G103,"Done") -> 0 | F4: PRD signed off; prototype tested with 5 target users
A5: S1 | B5: Foundation (2 wks) | C5: =COUNTIF(Full_Backlog!F4:F103,"S1") -> 4 | D5: =SUMIF(Full_Backlog!F4:F103,"S1",Full_Backlog!D4:D103) -> 13 | E5: =COUNTIFS(Full_Backlog!F4:F103,"S1",Full_Backlog!G4:G103,"Done") -> 1 | F5: App installs cleanly in dev store/org; telemetry firing
A6: S2 | B6: Core feature 13-week forecast engine - part 1 | C6: =COUNTIF(Full_Backlog!F4:F103,"S2") -> 6 | D6: =SUMIF(Full_Backlog!F4:F103,"S2",Full_Backlog!D4:D103) -> 29 | E6: =COUNTIFS(Full_Backlog!F4:F103,"S2",Full_Backlog!G4:G103,"Done") -> 6 | F6: 13-week forecast engine happy path demoable
A7: S3 | B7: Core feature 13-week forecast engine - part 2 + Scenario sliders start | C7: =COUNTIF(Full_Backlog!F4:F103,"S3") -> 11 | D7: =SUMIF(Full_Backlog!F4:F103,"S3",Full_Backlog!D4:D103) -> 47 | E7: =COUNTIFS(Full_Backlog!F4:F103,"S3",Full_Backlog!G4:G103,"Done") -> 11 | F7: 13-week forecast engine complete with tests; Scenario sliders skeleton
A8: S4 | B8: Core feature Scenario sliders | C8: =COUNTIF(Full_Backlog!F4:F103,"S4") -> 9 | D8: =SUMIF(Full_Backlog!F4:F103,"S4",Full_Backlog!D4:D103) -> 34 | E8: =COUNTIFS(Full_Backlog!F4:F103,"S4",Full_Backlog!G4:G103,"Done") -> 8 | F8: MVP loop usable end-to-end internally
A9: S5 | B9: Feature Invoice chase nudges + alpha hardening | C9: =COUNTIF(Full_Backlog!F4:F103,"S5") -> 12 | D9: =SUMIF(Full_Backlog!F4:F103,"S5",Full_Backlog!D4:D103) -> 50 | E9: =COUNTIFS(Full_Backlog!F4:F103,"S5",Full_Backlog!G4:G103,"Done") -> 12 | F9: Internal alpha: team dogfoods daily
A10: S6 | B10: Billing + Accountant portal | C10: =COUNTIF(Full_Backlog!F4:F103,"S6") -> 13 | D10: =SUMIF(Full_Backlog!F4:F103,"S6",Full_Backlog!D4:D103) -> 60 | E10: =COUNTIFS(Full_Backlog!F4:F103,"S6",Full_Backlog!G4:G103,"Done") -> 12 | F10: Can charge a test customer; upgrade/downgrade paths work
A11: S7 | B11: Private beta (design partners) | C11: =COUNTIF(Full_Backlog!F4:F103,"S7") -> 5 | D11: =SUMIF(Full_Backlog!F4:F103,"S7",Full_Backlog!D4:D103) -> 15 | E11: =COUNTIFS(Full_Backlog!F4:F103,"S7",Full_Backlog!G4:G103,"Done") -> 5 | F11: 3+ partners active weekly; NPS pulse >30
A12: S8 | B12: Beta iteration + Bank-feed anomaly alerts | C12: =COUNTIF(Full_Backlog!F4:F103,"S8") -> 22 | D12: =SUMIF(Full_Backlog!F4:F103,"S8",Full_Backlog!D4:D103) -> 87 | E12: =COUNTIFS(Full_Backlog!F4:F103,"S8",Full_Backlog!G4:G103,"Done") -> 18 | F12: Retention of beta cohort week-over-week >60%
A13: S9 | B13: Marketplace review prep | C13: =COUNTIF(Full_Backlog!F4:F103,"S9") -> 7 | D13: =SUMIF(Full_Backlog!F4:F103,"S9",Full_Backlog!D4:D103) -> 30 | E13: =COUNTIFS(Full_Backlog!F4:F103,"S9",Full_Backlog!G4:G103,"Done") -> 1 | F13: Review submission accepted into queue
A14: S10 | B14: Review remediation + docs | C14: =COUNTIF(Full_Backlog!F4:F103,"S10") -> 7 | D14: =SUMIF(Full_Backlog!F4:F103,"S10",Full_Backlog!D4:D103) -> 24 | E14: =COUNTIFS(Full_Backlog!F4:F103,"S10",Full_Backlog!G4:G103,"Done") -> 1 | F14: Marketplace approval obtained (or final remediation cycle)
A15: S11 | B15: Launch | C15: =COUNTIF(Full_Backlog!F4:F103,"S11") -> 3 | D15: =SUMIF(Full_Backlog!F4:F103,"S11",Full_Backlog!D4:D103) -> 8 | E15: =COUNTIFS(Full_Backlog!F4:F103,"S11",Full_Backlog!G4:G103,"Done") -> 2 | F15: First 10 installs; first 3 reviews; activation >40%
A16: S12 | B16: Iterate & scale decision | C16: =COUNTIF(Full_Backlog!F4:F103,"S12") -> 1 | D16: =SUMIF(Full_Backlog!F4:F103,"S12",Full_Backlog!D4:D103) -> 2 | E16: =COUNTIFS(Full_Backlog!F4:F103,"S12",Full_Backlog!G4:G103,"Done") -> 0 | F16: Growth model doc with CAC/LTV first estimates
B17: TOTAL | C17: =SUM(C4:C16) -> 100 | D17: =SUM(D4:D16) -> 399
B18: Velocity check: points/sprint S2-S8 should sit within 30-45 for a 4-6 person team; rebalance Sprint column in backlog if a sprint exceeds capacity.

Sheet Financial_Model
A1: 18-MONTH FINANCIAL MODEL — Xero: accountant-channel PLG (edit yellow assumptions)
A3: Assumption | B3: Value
A4: Trials/mo (month 1) | B4: 50
A5: Monthly growth of that | B5: 0.12
A6: Trial->paid % | B6: 0.14
A7: ARPU $/mo | B7: 25
A8: Monthly churn | B8: 0.04
A9: Marketplace fee | B9: 0.15
A10: Team cost month 1 (India-lean $) | B10: 14000
A11: Cost growth/mo | B11: 0.03
A12: Fee note: 15% via Xero in-store subscriptions (external billing where permitted)
A14: Line | B14: M1 | C14: M2 | D14: M3 | E14: M4 | F14: M5 | G14: M6 | H14: M7 | I14: M8 | J14: M9 | K14: M10 | L14: M11 | M14: M12 | N14: M13 | O14: M14 | P14: M15 | Q14: M16 | R14: M17 | S14: M18
A15: Leads/installs | B15: =$B$4 -> 50 | C15: =B15*(1+$B$5) -> 56 | D15: =C15*(1+$B$5) -> 62.72 | E15: =D15*(1+$B$5) -> 70.2464 | F15: =E15*(1+$B$5) -> 78.675968 | G15: =F15*(1+$B$5) -> 88.117084 | H15: =G15*(1+$B$5) -> 98.691134 | I15: =H15*(1+$B$5) -> 110.53407 | J15: =I15*(1+$B$5) -> 123.79816 | ... S15: =R15*(1+$B$5) -> 343.30204
A16: New paying | B16: =ROUND(B15*$B$6,1) -> 7 | C16: =ROUND(C15*$B$6,1) -> 7.8 | D16: =ROUND(D15*$B$6,1) -> 8.8 | E16: =ROUND(E15*$B$6,1) -> 9.8 | F16: =ROUND(F15*$B$6,1) -> 11 | G16: =ROUND(G15*$B$6,1) -> 12.3 | H16: =ROUND(H15*$B$6,1) -> 13.8 | I16: =ROUND(I15*$B$6,1) -> 15.5 | ... S16: =ROUND(S15*$B$6,1) -> 48.1
A17: Paying accounts | B17: =B16 -> 7 | C17: =ROUND(B17*(1-$B$8)+C16,1) -> 14.5 | D17: =ROUND(C17*(1-$B$8)+D16,1) -> 22.7 | E17: =ROUND(D17*(1-$B$8)+E16,1) -> 31.6 | F17: =ROUND(E17*(1-$B$8)+F16,1) -> 41.3 | G17: =ROUND(F17*(1-$B$8)+G16,1) -> 51.9 | H17: =ROUND(G17*(1-$B$8)+H16,1) -> 63.6 | I17: =ROUND(H17*(1-$B$8)+I16,1) -> 76.6 | J17: =ROUND(I17*(1-$B$8)+J16,1) -> 90.8 | ... S17: =ROUND(R17*(1-$B$8)+S16,1) -> 315.2
A18: MRR (net of fee) | B18: =ROUND(B17*$B$7*(1-$B$9),0) -> 149 | C18: =ROUND(C17*$B$7*(1-$B$9),0) -> 308 | D18: =ROUND(D17*$B$7*(1-$B$9),0) -> 482 | E18: =ROUND(E17*$B$7*(1-$B$9),0) -> 672 | F18: =ROUND(F17*$B$7*(1-$B$9),0) -> 878 | G18: =ROUND(G17*$B$7*(1-$B$9),0) -> 1103 | H18: =ROUND(H17*$B$7*(1-$B$9),0) -> 1352 | I18: =ROUND(I17*$B$7*(1-$B$9),0) -> 1628 | ... S18: =ROUND(S17*$B$7*(1-$B$9),0) -> 6698
A19: Team cost | B19: =$B$10 -> 14000 | C19: =ROUND(B19*(1+$B$11),0) -> 14420 | D19: =ROUND(C19*(1+$B$11),0) -> 14853 | E19: =ROUND(D19*(1+$B$11),0) -> 15299 | F19: =ROUND(E19*(1+$B$11),0) -> 15758 | G19: =ROUND(F19*(1+$B$11),0) -> 16231 | H19: =ROUND(G19*(1+$B$11),0) -> 16718 | I19: =ROUND(H19*(1+$B$11),0) -> 17220 | J19: =ROUND(I19*(1+$B$11),0) -> 17737 | ... S19: =ROUND(R19*(1+$B$11),0) -> 23142
A20: Net cash/mo | B20: =B18-B19 -> -13851 | C20: =C18-C19 -> -14112 | D20: =D18-D19 -> -14371 | E20: =E18-E19 -> -14627 | F20: =F18-F19 -> -14880 | G20: =G18-G19 -> -15128 | H20: =H18-H19 -> -15366 | I20: =I18-I19 -> -15592 | ... S20: =S18-S19 -> -16444
A21: Cumulative | B21: =B20 -> -13851 | C21: =B21+C20 -> -27963 | D21: =C21+D20 -> -42334 | E21: =D21+E20 -> -56961 | F21: =E21+F20 -> -71841 | G21: =F21+G20 -> -86969 | H21: =G21+H20 -> -102335 | I21: =H21+I20 -> -117927 | J21: =I21+J20 -> -133734 | ... S21: =R21+S20 -> -281474
A23: Reading: churn applies before adds; MRR nets the marketplace fee; costs use India-lean base from Team_Roles_Budget (v004). Breakeven = first month Net cash ≥ 0. This is a planning model, not a forecast — replace assumptions with S7-S8 beta actuals.

Sheet GTM_Execution
A1: GTM EXECUTION TASKS
A3: Phase | B3: Task | C3: Owner (role) | D3: Target sprint
A4: Pre-launch | B4: Positioning doc + message house (problem/promise/proof) | C4: Founder | D4: S7
A5: Pre-launch | B5: Listing SEO: keyword study in marketplace search + title/intro drafts | C5: Growth | D5: S8
A6: Pre-launch | B6: 10 design-partner mini case snippets with metric proof | C6: Founder | D6: S8
A7: Pre-launch | B7: 5 comparison/alternative pages drafted | C7: Growth | D7: S9
A8: Pre-launch | B8: Screenshots (5) + 2-min demo video produced | C8: Design | D8: S9
A9: Launch | B9: Listing live + launch post + video published | C9: Growth | D9: S11
A10: Launch | B10: Founder outreach: 100 named ICP accounts, 3-touch sequence | C10: Founder | D10: S11
A11: Launch | B11: Community value-posts (3 relevant communities) | C11: Founder | D11: S11
A12: Launch | B12: Review-generation program on (in-app ask post-aha) | C12: Eng | D12: S11
A13: Post-launch | B13: Weekly SEO/how-to content cadence starts | C13: Growth | D13: S12
A14: Post-launch | B14: Marketplace paid placement pilot (where offered) | C14: Growth | D14: S12
... A16: Post-launch | B16: G2/Capterra profiles + first 10 reviews | C16: Growth | D16: S12+

Sheet Launch_Checklist
A1: PLATFORM LAUNCH CHECKLIST — Xero App Store
A3: # | B3: Item | C3: Status
A4: 1 | B4: Xero developer account + app partner program application | C4: BLOCKED — needs Senthil: dev account + partner application
A5: 2 | B5: OAuth2 + tenant handling for multi-org accountants tested | C5: Code-complete — pending live dev-org test
A6: 3 | B6: API rate limits (60/min per tenant) queue + backoff verified | C6: Code-complete: proactive 60/min per-tenant limiter (v012) + reactive backoff/breaker — pending live verification
A7: 4 | B7: Webhooks (invoices, payments, bank transactions) resilience tested | C7: Code-complete — webhooks (INVOICE/CONTACT/SUBSCRIPTION) + bank-txn polling built v011; pending live wiring. NOTE: platform has no bank-txn webhook — polling every 15 min is the documented substitute
A8: 5 | B8: App partner certification: API best practice + security questionnaire + brand review | C8: Trust page drafted; SECURITY_EVIDENCE.md pack compiled v014 (auth, encryption-at-rest AES-256-GCM + vault, webhook HMAC, rate limiting, data lifecycle, 100% gate); questionnaire answerable from pack + brand review pending live artefacts
A9: 6 | B9: In-store subscription configuration + test purchase | C9: Rail logic coded; store config + test purchase pending dev org
A10: 7 | B10: Accountant multi-client portal tested with 20-client dataset | C10: DONE at logic level: 20-client dataset drill passed (risk-first sort + rules at scale); live UI pass pending
A11: 8 | B11: Bank-feed anomaly logic QA on 12 months of demo data | C11: DONE at logic level: 12-month dataset QA passed — found + fixed batch-isolation blind spot (detectWithHistory); live-feed QA pending
A12: 9 | B12: Listing: accountant-channel messaging + partner directory entry | C12: Listing copy A/B drafted (B = accountant channel) — Senthil review pending
A13: 10 | B13: UK/AU/NZ tax-locale display verified (GST/VAT labels) | C13: GST/VAT fields coded + tested; UI locale pass pending deployed UI

Sheet Metrics_Targets
A1: METRIC TARGETS (first 12 months post-launch)
A3: Metric | B3: M1 | C3: M3 | D3: M6 | E3: M12 | F3: Notes
A4: Installs/signups cumulative | B4: varies | C4: 3x M1 | D4: 8x M1 | E4: 20x M1 | F4: Drive via listing SEO + outbound
A5: Activation % (24h) | B5: 30% | C5: 40% | D5: 45% | E5: 50% | F5: Onboarding iterations S12+
A6: Trial→paid % | B6: baseline | C6: +2pts | D6: +4pts | E6: +6pts | F6: Pricing test at S12
A7: Rating | B7: 4.5+ | C7: 4.6+ | D7: 4.7+ | E7: 4.7+ | F7: Review program + support speed
A8: MRR | B8: first $ | C8: 3x | D8: 8x | E8: 20x | F8: Model sheet has the math
A9: Logo churn/mo | B9: <5% | C9: <4% | D9: <3% | E9: <3% | F9: Health-score saves

Sheet Risk_Register
A1: PRODUCT RISK REGISTER
A3: Risk | B3: Impact | C3: Likelihood | D3: Mitigation
A4: Xero native short-term cash flow improves | B4: High | C4: Medium | D4: Scenario depth + accountant multi-client portal moat
A5: Accountant channel slow to activate | B5: Medium | C5: High | D5: Partner program with rev share; 10 pilot firms by S8
A6: Float/Fathom price moves | B6: Medium | C6: Medium | D6: Owner-facing simplicity positioning; annual bundles

Sheet Sprint_Tracker_Log
A1: SPRINT TRACKER LOG — FlowCast (created v008 per directive, 10 Sep 2026 22:01)
A3: Date/Time | B3: Sprint | C3: Action | D3: Stories touched | E3: Evidence | F3: Decision ref
A4: 2026-09-05 19:50 | B4: S0 | C4: v007 full product workbook released (spec, backlog, board, model) | D4: — | E4: v007 Version_Control | F4: —
A5: 2026-09-10 22:01 | B5: — | C5: v008 opened: Sprint_Tracker_Log + Traceability_Matrix sheets added per directive | D5: — | E5: This file | F5: Directive 10 Sep 22:01
A6: 2026-09-10 22:01 | B6: — | C6: D13 applied to FlowCast: 100% automation coverage gate on all code; ST-085 amended | D6: ST-085 | E6: jest.config.js coverageThreshold=100 | F6: D13
A7: 2026-09-10 22:01 | B7: S1 | C7: Foundation built: OAuth install/uninstall/reinstall, token rotation, source attribution, role matrix + audit log. Xero OAuth client mocked | D7: ST-051..ST-056 | E7: src/installFlow.ts, src/permissions.ts + tests | F7: —
A8: 2026-09-10 22:01 | B8: S2-S3 | C8: 13-week forecast engine: bucketing, traffic lights, validation errors, pause-without-loss; scenario sliders: levers, validation, preview | D8: ST-001..ST-004, ST-007..ST-009, ST-011..ST-014, ST-017, ST-019 | E8: src/forecastEngine.ts, src/scenarioSliders.ts + tests | F8: —
A9: 2026-09-10 22:01 | B9: S5 | C9: Invoice chase nudges: rule ladder, planning, test mode, retry-on-failure, per-type mute | D9: ST-021..ST-024, ST-027..ST-030 | E9: src/invoiceNudges.ts + tests | F9: —
A10: 2026-09-10 22:01 | B10: S6 | C10: Accountant portal + shared CSV importer; billing: trial, proration, rail selection, dunning, limits, GST/VAT invoices, cancellation | D10: ST-031/032/034/037/039, ST-057..ST-063 | E10: src/accountantPortal.ts, src/billing.ts + tests | F10: —
A11: 2026-09-10 22:01 | B11: S8 | C11: Bank-feed anomaly alerts; compliance: scope audit, retention, export/delete, backoff + circuit breaker; full telemetry suite; onboarding surfaces | D11: ST-041..ST-049, ST-064..ST-077 (code subset), ST-078/079/082/084 | E11: src/anomalyAlerts.ts, src/compliance.ts, src/telemetry.ts, src/onboarding.ts + tests | F11: —
A12: 2026-09-10 22:01 | B12: — | C12: TEST RUN: 11 suites, 120 tests, 100% statements/branches/functions/lines; gate enforced at 100 — build fails below | D12: All Done stories | E12: npx jest --coverage output; coverage/coverage-summary.json | F12: D13
A13: 2026-09-10 22:01 | B13: — | C13: Statuses written to Full_Backlog; Sprint_Board Done counts recalc from formulas. 58 Done, 4 code-complete-pending-live, 2 in progress, 36 backlog | D13: All | E13: Full_Backlog col G | F13: —
A14: 2026-09-10 22:01 | B14: — | C14: PORTFOLIO NOTE: FlowCast (rank 12) is a third open build while RevRescue rank-1 gate unmet; sequencing decision D15 remains open with Senthil | D14: — | E14: marketplace portfolio record | F14: D15 (open)
... A90: 2026-09-13 18:48 | B90: — | C90: REVIEW PLAYBOOK (gates/REVIEW_PLAYBOOK.md): the eight passes in the order that worked, the rules learned the hard way, and how to run them elsewhere. 36 suites / 500 tests at 100% zero pragmas; six gates in CI, five provable ones PROVED; live boot ready:true | D90: — | E90: gates/REVIEW_PLAYBOOK.md | F90: D13

Sheet Traceability_Matrix
A1: TRACEABILITY MATRIX — story → code → automated test → coverage (v008 build, 10 Sep 2026)
A2: Coverage source: jest --coverage, gate = 100% statements/branches/functions/lines (D13). All Xero platform calls mocked in tests; "pending live" = logic complete, live platform verification outstanding.
A4: ID | B4: Epic | C4: Status (v008) | D4: Code file(s) | E4: Automated test file(s) | F4: Coverage | G4: Evidence / notes
A5: ST-001 | B5: F1 | C5: Done | D5: src/forecastEngine.ts | E5: tests/forecastEngine.test.ts | F5: 100% | G5: defaultInput one-screen setup
A6: ST-002 | B6: F1 | C6: Done | D6: src/forecastEngine.ts | E6: tests/forecastEngine.test.ts | F6: 100% | G6: computeForecast happy path, 13-week bucketing
A7: ST-003 | B7: F1 | C7: Done | D7: src/forecastRules.ts | E7: tests/rulesNotificationsMetrics.test.ts | F7: 100% | G7: Rule builder complete: min_balance / amber_floor / week_drop_pct over week ranges; supersedes amber-floor-only v008 state
A8: ST-004 | B8: F1 | C8: Done | D8: src/forecastEngine.ts; src/compliance.ts | E8: tests/forecastEngine.test.ts; tests/compliance.test.ts | F8: 100% | G8: validate() named errors; callWithProtection retry
A9: ST-005 | B9: F1 | C9: Done | D9: src/ui/ForecastScreens.tsx | E9: tests/ui/screens.test.tsx | F9: 100% | G9: ForecastScreen: 13-week table, rule violations, Xero receivables deep link, empty state
A10: ST-006 | B10: F1 | C10: Done | D10: src/featureMetrics.ts; src/ui/MetricsPanel.tsx | E10: tests/rulesNotificationsMetrics.test.ts; tests/ui/screens.test.tsx | F10: 100% | G10: weeklySeries + trend + MetricsPanel surface
A11: ST-007 | B11: F1 | C11: Done | D11: src/permissions.ts | E11: tests/permissions.test.ts | F11: 100% | G11: authorize + AuditLog on forecast actions
A12: ST-008 | B12: F1 | C12: Done | D12: src/forecastEngine.ts | E12: tests/forecastEngine.test.ts | F12: 100% | G12: setEnabled preserves lastInput
A13: ST-009 | B13: F1 | C13: Done | D13: src/accountantPortal.ts | E13: tests/accountantPortal.test.ts | F13: 100% | G13: importCsv shared migration importer
A14: ST-010 | B14: F1 | C14: Done | D14: src/notifications.ts | E14: tests/rulesNotificationsMetrics.test.ts | F14: 100% | G14: dispatch in-app+email, per-type mute, daily digest (forecast event types)
A15: ST-011 | B15: F2 | C15: Done | D15: src/scenarioSliders.ts | E15: tests/scenarioSliders.test.ts | F15: 100% | G15: baselineScenario defaults
... A104: ST-100 | B104: EL | C104: Code-complete — pending live | D104: v016 | E104: src/launchOps.ts (PartnerTracker) | F104: — | G104: 10 slots, 7-day stale-nudge, exit math separating reviews from G-02 paying strangers; outreach = Senthil
A106: Summary (v010): 77 Done · 8 Code-complete — pending live · 7 Drafted — pending publish/review · 2 In progress · 6 Backlog (live-infra: ST-066/068/088/092; post-launch: ST-099/100). Test evidence: 14 suites / 155 tests / 100-100-100-100 incl. jest-axe WCAG pass; tsc clean.
A108: WBH-001 | B108: EQ+ | C108: Code-complete — pending live | D108: src/webhooks.ts | E108: tests/webhooks.test.ts | F108: 100% | G108: Dry-run gap #4 closed in code: HMAC-SHA256 signature verify (constant-time, intent-to-receive), fast-ack + idempotent queue with retry/dead-letter/redelivery-heal, invoice/contact/subscription action mapping (payment cancels nudges), bank-txn polling behind shared circuit breaker (no platform webhook exists — 15-min poll documented). Live wiring pending dev org. Unnumbered: added post-baseline from dry-run, outside ST-001..100 board counts by design
A109: WBH-002 | B109: EQ+ | C109: Done (code) | D109: src/rateLimiter.ts | E109: tests/rateLimitQaHttp.test.ts | F109: 100% | G109: Checklist #3 hardening: proactive per-tenant 60/min sliding-window limiter + paced execution (complements reactive backoff/breaker); live verification pending
A110: WBH-003 | B110: EQ+ | C110: Done (code) | D110: src/server.ts | E110: tests/rateLimitQaHttp.test.ts | F110: 100% | G110: HTTP wiring layer: routed fast-ack webhook endpoint (raw-body signature contract) + /health with release + queue depth; net binding is 5 lines at deploy
A111: QA-007 | B111: EQ+ | C111: Done (logic drill) | D111: src/qaDatasets.ts (twentyClientBook) | E111: tests/rateLimitQaHttp.test.ts | F111: 100% | G111: Checklist #7: 20-client book drill — risk-first sort + portal rules at scale verified
A112: QA-008 | B112: EQ+ | C112: Done (logic drill) | D112: src/qaDatasets.ts (twelveMonthFeed); src/anomalyAlerts.ts (detectWithHistory) | E112: tests/rateLimitQaHttp.test.ts | F112: 100% | G112: Checklist #8: 12-month drill caught a REAL defect — isolated small-batch scans hide lone outliers (self-inflated sigma). Fixed: production scans batch against trailing history; all 3 planted faults caught, false positives <= 2
A113: CFG-001 | B113: EQ+ | C113: Done (code) | D113: src/config.ts; .env.example | E113: tests/config.test.ts | F113: 100% | G113: Typed config loader: all live credentials named + validated at boot (missing keys listed at once; https redirect enforced; Stripe key required only outside UK/AU/NZ). Live-sweep readiness
