Workbook

Sheet Version_Control
A1: VERSION CONTROL — DocMerge Pro
A3: Version | B3: Date | C3: Author | D3: Change | E3: Status
A4: v001-v004 | B4: 2026-09-05 | C4: Claude for Senthil/KP | D4: Lineage: marketplace master (868 entries) -> portfolio plan (12 products) -> wave-1 (RetainKit/ShiftDesk/EngageOS, v005) -> this product selected for wave-3 | E4: Released
A5: v007 | B5: 2026-09-05 19:50 | C5: Claude for Senthil/KP | D5: Full product workbook for DocMerge Pro on Google Workspace Marketplace: spec, screen inventory, 100+ story backlog, live sprint board, 18-month financial model (editable assumptions), GTM execution tasks, platform launch checklist, metric targets, risk register | E5: Released
A6: v008 | B6: 2026-09-10 22:17 | C6: Claude for Senthil/KP | D6: Sprint_Tracker_Log + Traceability_Matrix sheets added. S1 Foundation executed under D13 (100% automation coverage gate; S0 discovery interviews parked): ST-051/052/055/056 built in TypeScript (docmerge-pro-s1), 37 automated tests, 100% stmt/branch/func/line coverage, tsc strict clean. Backlog statuses updated; Sprint_Board live counts reflect S1 Done=4. | E6: Released
A7: v009 | B7: 2026-09-10 22:23 | C7: Claude for Senthil/KP | D7: S2 executed under D13: ST-001/002/003/004 (Template designer part 1 — defaults, happy-path render, rules/conditions, platform-error mapping + retry/backoff) + ST-053 (re-install restore within retention window) + ST-054 (owner/admin/member permission matrix enforced). Suite now 9 test files / 101 tests, 100% stmt/branch/func/line, tsc strict clean. Sprint_Board S2 Done=6. | E7: Released
A8: v010 | B8: 2026-09-10 22:29 | C8: Claude for Senthil/KP | D8: S3 executed under D13: Template designer part 2 (ST-005 sidebar surface end-to-end, ST-006 metrics/trends, ST-007 audit logging incl. denied attempts, ST-008 pause without data loss, ST-009 CSV + competitor importer, ST-010 notifications with per-type mute) + Batch generate skeleton (ST-011..014: defaults, per-row happy path, row rules, error/retry paths) + ST-085 closed as superseded by D13 at 100%. Defect found by the gate and fixed: withRetry was masking validation errors behind a generic platform message. Suite 13 files / 150 tests, 100% all metrics. | E8: Released
A9: v011 | B9: 2026-09-10 22:52 | C9: Claude for Senthil/KP | D9: S4 executed under D13: Batch part 2 (ST-015 batch sidebar end-to-end, ST-016 batch metrics/trends, ST-017 governed runner with allow/deny audit, ST-018 job pause without data loss, ST-019 row-data CSV + competitor import, ST-020 batch notifications with mute) + ST-071 activation funnel dashboard (install->setup->aha->habit with conversions) + ST-072 error tracking with release tagging and spike alerts (re-armable) + ST-086 E2E smoke suite gating the deploy job in .github/workflows/ci.yml. Suite 16 files / 180 tests, 100% all metrics, tsc strict clean. Sprint_Board S4 Done=9. | E9: Released
A10: v012 | B10: 2026-09-10 23:03 | C10: Claude for Senthil/KP | D10: S5 executed under D13: E-sign requests full module (ST-021 defaults, ST-022 sequential/parallel lifecycle draft->sent->partially_signed->completed/declined/expired, ST-023 validated rules incl. domain allow-lists, ST-024 delivery retry with mapped errors and no half-sent state, ST-025 sidebar create->send->track, ST-026 metrics, ST-027 allow/deny audit, ST-028 pause preserving signatures, ST-029 signer CSV + competitor import, ST-030 mute-aware notifications) + ST-078 first-run checklist with <1-day aha budget + ST-079 empty states for all 9 screens. Suite 18 files / 217 tests, 100% all metrics. Companion tracker file v001 opened (claude_v001_docmerge_pro_sprint_tracker_traceability_20260910_2303.xlsx). | E10: Released
A11: v013 | B11: 2026-09-11 08:20 | C11: Claude for Senthil/KP | D11: S6 executed under D13: Auto-file to Drive full module (ST-031 one-screen defaults, ST-032 pattern-driven filing with built-in {{template}}/{{row}}/{{yyyy}}/{{mm}} tokens and named missing-token errors, ST-033 first-match routing rules, ST-034 retry/backoff with mapped errors, ST-035 sidebar file-last-batch flow, ST-036 filing metrics, ST-037 allow/deny audit, ST-038 pause, ST-039 routing-rule CSV + competitor import, ST-040 filing notifications; conflict policies rename/overwrite/skip with first-free-number rename) + Billing (ST-057 no-card 14-day trial with honest banner, ST-058 mid-cycle proration charge/credit verified to the cent, ST-059 marketplace-vs-Stripe provider routing + 1/3/7-day dunning, grace, downgrade-with-data). Suite 21 files / 264 tests, 100% all metrics. Tracker rolled to v002. | E11: Released
A12: v014 | B12: 2026-09-13 09:55 | C12: Claude for Senthil/KP | D12: S7 executed under D13: ST-060 dunning UX (3 emails on 1/3/7-day schedule, 7-day grace, then READ-ONLY mode — corrects S6 ST-059 which ended in downgrade-to-free; read-only retains plan and data, strictly less destructive), ST-061 plan limits with 80%/100% upgrade prompts across documents/templates/seats, ST-062 invoices with GST/VAT incl. B2B reverse charge and downloadable CSV receipts (closes the tax gap flagged at S6), ST-063 cancellation with reason-matched save-offer (offered once) + exit survey + access to period end, ST-064 machine-audited scope-to-feature least-privilege mapping + generated SCOPE_NARRATIVE.md for the OAuth/CASA pack. Suite 23 files / 305 tests, 100% all metrics. Tracker v003. | E12: Released
A13: v015 | B13: 2026-09-13 10:22 | C13: Claude for Senthil/KP | D13: S8 executed under D13 — largest sprint, 22 stories / 87 pts: Form-triggered generation ST-041..050 (submission pipeline with built-in redelivery dedupe, conditions, failure-as-result so the webhook stays up, sidebar activity feed, metrics, audit, pause, field-map import, notifications); Compliance ST-065 validated data-flow + retention policy (DATA_FLOW_AND_RETENTION.md published), ST-066 deployment posture verifier (encryption at rest, TLS floor, vault-only secrets), ST-067 hash-chained admin audit log detecting edits and deletions, ST-070 circuit breaker with half-open recovery; Analytics ST-073..077 (heatmap with unused-feature list, weekly digest, explained health score, CSV/warehouse export, configurable alert thresholds); QE ST-087 p95 budgets per surface, ST-088 deterministic 5x load test in CI, ST-092 blue/green deploy with pre-cutover health gate and verified rollback. Suite 26 files / 385 tests, 100% all metrics. Tracker v004. | E13: Released
A14: v016 | B14: 2026-09-13 10:35 | C14: Claude for Senthil/KP | D14: S9 executed under D13: ST-069 self-serve export + owner-only deletion with cancellable 7-day grace, ST-089 WCAG AA audit (contrast maths, accessible names, keyboard, focus, target size) with the shipped palette passing, ST-090 restore-drill harness verifying contents as well as RTO/RPO, ST-091 chaos degradation proving every dependency outage leaves the product usable with an explaining message, ST-093 two listing variants on genuinely different angles + a copy reviewer that flags risky claims, ST-094 asset-spec validator + 5-screenshot plan. ST-068 is PARTIAL, not Done: the evidence pack is built and published (SECURITY_EVIDENCE_PACK.md, 6 of 9 controls verified in code) but a penetration test is a third-party activity — readyForSubmission stays false until the external report is attached. Suite 28 files / 432 tests, 100% all metrics. Tracker v005. | E14: Released
... A19: v021 | B19: 2026-09-13 11:16 | C19: Claude for Senthil/KP | D19: S12 growth model FRAME built (ST-095-adjacent; the S12 exit criterion, marked In progress not Done because the exit asks for CAC/LTV ESTIMATES and estimates without a cohort are assumptions): src/growthModel.ts restates the 18-month model as unit economics — lifetime, LTV, fully-loaded CAC that charges free-tier support against each conversion (~17 installs served per paying customer at 6%), payback, and a verdict that distinguishes a healthy ratio with slow payback from a marginal one. Three scenarios, sensitivity ranking, and a measurement plan pointing each assumption at instrumentation that already exists. FINDING: churn outranks conversion as the lever to measure first — intuition usually reaches for conversion. Published as GROWTH_MODEL.md. Suite 34 files / 589 tests, 100% all metrics. | E19: Released
A20: v022 | D20: PLANNED: live-evidence log only. No unblocked work remains. | E20: Planned
A21: v022 | B21: 2026-09-13 11:21 | C21: Claude for Senthil/KP | D21: ST-068 vendor outreach pack written (PENTEST_OUTREACH.md): a ready-to-send email that quotes from the written brief rather than requiring a discovery call, vendor shortlist criteria, and a quote-comparison rubric. External-facing copy is company-agnostic per standing instruction. FINDING carried into the pack: LEAD TIME, not price, is the binding constraint — it sits on the critical path beside CASA and the two waits can run in parallel, so both should be booked in the same week. No code change; suite unchanged at 589 tests / 100%. | E21: Released
A22: v023 | D22: PLANNED: live-evidence log only. All preparable work is complete; every remaining item needs Senthil or a third party. | E22: Planned
A23: v023 | B23: 2026-09-13 11:24 | C23: Claude for Senthil/KP | D23: COLD REVIEW PASS 1 — DocMerge first adversarial review, run because portfolio memory shows every sibling found real defects after declaring code-complete (TeleField L-T1). NINE findings in code already at 100% coverage, five CRITICAL. FIXED with regressions: DM-F02 read-only mode enforced nowhere (published behaviour absent from the product), DM-F03 plan limits enforced nowhere (published limits decorative), DM-F04 OAuth install had no CSRF state, DM-F05 webhooks entirely unauthenticated (a forged POST could revoke tokens and schedule deletion for any account), DM-F06 no production backoff existed at all. OPEN: DM-F01 CRITICAL no HTTP app exists behind any route, DM-F07 caller-declared identity, DM-F08 eleven unbounded ledgers, DM-F09 deletion has no implementation behind it. New Review_Findings sheet. 35 suites / 616 tests at 100%. The previous "code phase complete" claim was premature. | E23: Released
A24: v024 | D24: PLANNED: cold-review pass 2 — build the HTTP app (DM-F01), close DM-F07/F08/F09, then re-sweep. | E24: Planned
A25: v024 | B25: 2026-09-13 11:31 | C25: Claude for Senthil/KP | D25: DM-F01 and DM-F07 CLOSED — the two critical findings left open by cold-review pass 1. A real HTTP application now exists: framework-free router, 7 routes wired to the existing services, src/server.ts with npm start, and a readiness check that refuses to listen on a misconfigured environment. Identity is no longer caller-declared: HMAC-signed sessions carry account and role, so editing a role in a token fails verification and a session for one account is refused against another. Every mutating route is authenticated AND passes the entitlement gate, so read-only mode and plan limits are enforced on the wire rather than in principle; reads stay open in read-only mode. Server BOOTED FOR REAL and exercised over HTTP (healthz 200, unsigned webhook 401, unauthenticated route 401, unknown route 404) — the siblings taught that compiling is not running. 36 suites / 650 tests at 100%. Remaining from pass 1: DM-F08 unbounded ledgers, DM-F09 deletion has no implementation. | E25: Released
A26: v025 | D26: PLANNED: close DM-F08 (bounded ledgers) and DM-F09 (purge registry + schema), then cold-review pass 2 over the new HTTP layer — siblings found new surfaces inherit old blind spots (L-OC4). | E26: Planned
A27: v025 | B27: 2026-09-13 11:37 | C27: Claude for Senthil/KP | D27: PASS 1 CLOSED + PASS 2 COMPLETE. DM-F08 fixed: all 11 unbounded ledgers now FIFO-bounded with eviction counted rather than silent; the hash-chained admin audit needed a post-eviction chain anchor so verifyChain reports truncation instead of breaking. DM-F09 fixed: PurgeRegistry over 16 stores with a build-failing registration check, evidence receipts, incomplete-purge honesty — plus the database schema that never existed (3 migrations, ON DELETE CASCADE on every account-scoped table, npm run migrate). PASS 2 over the new HTTP layer found four more, all fixed: DM-F10 uncapped request body (memory exhaustion on an open port), DM-F11 abandoned OAuth states accumulating because sweep() was never called — the same built-but-never-wired class as F02/F03, DM-F12 no rate limiting anywhere, DM-F13 /healthz leaking the build version anonymously. Server booted and all four verified over real HTTP. 40 suites / 691 tests at 100%. All 13 cold-review findings now closed. | E27: Released
A28: v026 | D28: PLANNED: live-evidence log. Cold review complete across both passes; remaining work is Senthil/third-party. | E28: Planned
A29: v026 | B29: 2026-09-13 11:51 | C29: Claude for Senthil/KP | D29: EXTERNAL VERIFICATION SWEEP against live Google documentation — the step every sibling product ran after its cold review, and the step that found live-blocking defects in all of them. TWO LIVE-BLOCKING findings, both invisible to two clean internal passes because they are facts about the platform rather than the code. VER-DM1: the Workspace Marketplace does NOT push uninstall webhooks and the licenseNotification API is deprecated with no replacement — our uninstall endpoint was a handler for an event that never arrives, so token revocation, the retention clock, re-install restore and the purge chain would never have run. Fixed with a license reconciler that DETECTS uninstall (license state + revoked credential) and refuses to treat an API outage as one. VER-DM2: Google Forms cannot POST to an arbitrary URL — form submit needs an installable Apps Script trigger that calls UrlFetch itself, so the entire F5 feature (10 stories / 42 pts) rested on a capability that does not exist. Fixed by shipping the Apps Script forwarder that signs with the scheme our endpoint already verifies. 41 suites / 707 tests at 100%. CONSEQUENCE FOR SENTHIL: the form-trigger setup flow changes — ST-041 "one screen" and the help-centre article need rewording. | E29: Released
A30: v027 | D30: PLANNED: verification sweep part 2 (add-on surface, scopes, asset spec, CASA requirements) — the sweep found two blockers in its first two checks, so the remaining assumptions deserve the same treatment. | E30: Planned
A31: v027 | B31: 2026-09-13 11:56 | C31: Claude for Senthil/KP | D31: VERIFICATION SWEEP PART 2 — VER-DM3, the third live-blocking finding and the first that is a DECISION rather than a defect. Google has two add-on types with incompatible UI models and our features sit across both: the Workspace type is card-only (HTML forbidden), cannot read the open document, has no Apps Script triggers and is absent from Forms, but reaches mobile and every host app; the Editor type has HTML sidebars, document context and triggers, but is desktop-only and Editors-only. Twelve shipped stories cannot run on the Workspace surface as built, and the form feature cannot run there at all. Encoded as a test-pinned constraint matrix (src/addonSurface.ts) and presented as ADDON_SURFACE_DECISION.md; logged as D-DM1 for Senthil rather than decided unilaterally. 42 suites / 721 tests at 100%. Three live-blocking findings in four verification checks — the sweep is finding roughly one blocker per check, which says something about how far internal review can reach. | E31: Released
A32: v028 | D32: PLANNED: sweep part 3 (listing asset spec — TestPulse found theirs wrong; scope behaviour; CASA requirements) once D-DM1 is decided, since the surface choice changes the scope narrative. | E32: Planned
A33: v028 | B33: 2026-09-13 12:01 | C33: Claude for Senthil/KP | D33: VERIFICATION SWEEP PART 3 — VER-DM4: the listing asset and copy spec was invented and wrong in eight ways, including TWO REQUIRED ASSET FAMILIES that were absent entirely (application icons at 32/128 plus 48/96 because we now have a web app, and the 220x140 card banner), a forbidden-Google-name rule on the app name we had no check for, and the terms-of-service link missing from the submission checklist. Every copy limit was wrong in the strict direction, so the drafted variants were being held to tighter constraints than the platform applies. The promo video is an optional YouTube link, not the captioned upload we had specified. src/listing.ts rewritten against the live spec, LISTING_PACK.md regenerated, 13 tests pin the corrections. 42 suites / 729 tests at 100%. Four live findings in five verification checks. | E33: Released
A34: v029 | D34: PLANNED: sweep part 4 (OAuth verification + CASA requirements, scope behaviour) — the last unchecked assumptions; then D-DM1 gates the rest. | E34: Planned
A35: v029 | B35: 2026-09-13 12:06 | C35: Claude for Senthil/KP | D35: VERIFICATION SWEEP PART 4 — VER-DM5, the first finding that REMOVES work. Google routes app review by scope classification, and CASA is triggered only by RESTRICTED scopes. DocMerge requests none: drive.file is the recommended non-sensitive alternative to the restricted Drive scopes, userinfo.email is non-sensitive, and only spreadsheets.readonly and documents are sensitive — requiring Google app verification but not an assessment. CASA has been carried as a blocking multi-week paid item since S6 (R-D1, R-D10, LC-3) on an assumption nobody had checked. LC-3 downgraded to "likely not required, confirm in console" rather than deleted, because classification is per-project and Google may still ask. Found in the same pass: verification requires an unlisted YouTube DEMONSTRATION video (OAuth grant flow, consent screen showing the app name, detailed use of each sensitive scope) — a requirement we did not have, and separate from the optional marketing promo video. scopes.ts derives the review path from classifications with 7 pinning tests; SCOPE_NARRATIVE.md regenerated. 42 suites / 736 tests at 100%. | E35: Released
A36: v030 | D36: PLANNED: verification sweep COMPLETE across the five checkable assumption areas. Next work is D-DM1 (Senthil) and then live execution. | E36: Planned
A37: v030 | B37: 2026-09-13 16:25 | C37: Claude for Senthil/KP | D37: R-D4 CLOSED — Postgres adapter shipped. Every store had been an in-memory Map behind a typed interface, which was correct while no schema existed but left the interfaces never once implemented against a real database; the DM-F09 migrations were decorative until now. src/postgres.ts implements TokenStore, AccountRepo and TemplateRepo against the schema, plus purge targets for all 18 tables ordered children-before-parents so the row counts are real evidence rather than zero-because-already-cascaded. The SQL client is injected, so there is no pg dependency and the adapter is fully testable without a database. Details that would have bitten in production: BIGINT expiries are converted explicitly because the driver returns them as strings, template and rules write inside one transaction with rollback (a half-replaced rule set renders wrong output rather than failing), an absent rule value is stored as NULL not the string "undefined", and indirect tables are reached through their parent rather than a column they do not have. A test purges with a SQL-injection string and asserts it never reaches the statement text. 43 suites / 753 tests at 100%. | E37: Released
A38: v031 | D38: PLANNED: remaining in-memory stores (subscriptions, invoices, audit, telemetry, support) onto the adapter pattern; D-DM1 still gates the surface work. | E38: Planned
A39: v031 | B39: 2026-09-13 16:29 | C39: Claude for Senthil/KP | D39: DM-F14 — the remaining in-memory stores are a DURABILITY GAP, not merely unconverted. A restart resets every plan limit (each deploy silently grants every customer a fresh monthly allowance — a revenue leak invisible to tests, which start from zero anyway), resets billing state so paying customers look like trials, and evaporates the tamper-evident audit chain while restarting its numbering at genesis so the gap is not even visible. Usage counters fixed end to end: PlanLimitEnforcer now takes a UsageBackend; WriteThroughUsageBackend serves reads from a primed cache so the limit check stays synchronous, writes through with an atomic single-statement upsert (read-then-write loses increments exactly when a customer is near the limit), and counts write failures rather than failing the request. Subscription and admin-audit stores are built and tested — append-only with no update path, and lastSequence so the chain continues across restarts — but their services are NOT yet wired, which is stated rather than glossed because this codebase has already produced two built-but-never-called defects. 43 suites / 770 tests at 100%. | E39: Released
A40: v032 | D40: PLANNED: wire BillingService and AdminAuditLog to their stores (closing DM-F14), then telemetry/support persistence. D-DM1 still open. | E40: Planned
A41: v032 | B41: 2026-09-13 16:34 | C41: Claude for Senthil/KP | D41: DM-F14 CLOSED and DM-F15 found and fixed. BillingService now persists after every mutation through a SubscriptionBackend, and AdminAuditLog through an AdminAuditBackend with resume(), so a restart no longer resets a paying customer to trial or forks a second audit chain at genesis. Write-through Postgres backends keep reads synchronous and count write failures rather than failing the customer request. DM-F15 surfaced DURING that wiring: the admin audit log had no accountId at all — every customer shared one chain and one sequence counter, and exportCsv would have handed one customer every other customer admin history. The schema had keyed the table on (account_id, sequence) since DM-F09; the code never matched it, and nothing caught the mismatch because the table had no implementation behind it until today. Now scoped per account, with the accountId inside the digest so an entry cannot be replayed into another tenant chain. 43 suites / 781 tests at 100%. | E41: Released
A42: v033 | D42: PLANNED: telemetry/support persistence, then a tenant-isolation sweep across the remaining services — DM-F15 suggests the audit log may not be the only thing lacking a tenant boundary. | E42: Planned
A43: v033 | B43: 2026-09-13 16:39 | C43: Claude for Senthil/KP | D43: TENANT-ISOLATION SWEEP — run deliberately because DM-F15 was found by accident, and it found five more. DM-F16 (CRITICAL): template lookups took a templateId and nothing else, and POST /accounts/:id/documents takes that id from the request body — so an authenticated user of one account could read another account template and generate documents from it. The session check added for DM-F07 proved WHO was asking; nothing checked WHAT they asked for. DM-F17: the same shape on signature requests, exposing signer names and emails. DM-F18: the feature audit log had no accountId either, the same defect as DM-F15 in a second log. All three fixed with ownership enforced centrally, cross-tenant access reported as "not found" so the id space cannot be probed, and regression tests asserting the cross-tenant failure is indistinguishable from a missing record. DM-F19 and DM-F20 (metrics summaries and the support inbox aggregate across tenants) are logged OPEN rather than fixed blind, because whether they are defects depends on whether they are surfaced per-customer or internally — a decision, not a bug. 43 suites / 786 tests at 100%, smoke green. | E43: Released
A44: v034 | D44: PLANNED: decide DM-F19/F20 surfacing, then telemetry/support persistence. D-DM1 still open. | E44: Planned
A45: v034 | B45: 2026-09-13 17:23 | C45: Claude for Senthil/KP | D45: PORTABLE TENANT-ISOLATION GATE built and wired into CI, then it immediately found DM-F21. A sweep finds this class of defect once; the gate finds it every commit, and it is written to be copied into the sibling products — the tenant parameter names and entity-id suffixes are configuration, not hard-coded. It flagged 28 methods on first run. Triage: five clusters genuine (DM-F21) — pause and resume on signature requests, form triggers and batch jobs took only an entity id, so one tenant could pause another tenant work with nothing but a guessed id; renderCsv would render any account invoice with its billing contact and tax identifiers; openTemplate read another account template metadata. The manual sweep had checked READS and missed writes-that-are-not-reads. The other 23 are exempted with written reasons rather than silenced, and a test asserts every exemption carries one. 44 suites / 797 tests at 100%, smoke green. | E45: Released
...

Sheet ReadMe_Scope
A1: DocMerge Pro — Template-based document generation from Sheets/Forms with e-sign and Drive filing
A3: PLATFORM: Google Workspace Marketplace | CATEGORY: Document Automation
A4: PROBLEM: Mail-merge add-ons are dated; SMBs want doc-gen + sign without Zapier chains [20 Sep: 'doc-gen + sign without Zapier chains' is NO LONGER ACCURATE and must not be reused in copy — P-DM-007 established the product produces no signature. The feature is Approval requests, and a repository gate now fails the build on any signature claim in user-facing copy.]
A5: DIFFERENTIATION (REWRITTEN 20 Sep 2026, external review §5): Governed document operations — a tamper-evident audit chain a customer can verify themselves, enforced tenant isolation, honest quota-aware batch timing, and deletion with per-store receipts. THE PREVIOUS THREE ARE DEAD AND ARE RECORDED AS SUCH: a native Sheets sidebar is what all ten competitors already are (table stakes, not differentiation); the CASA badge is NOT AVAILABLE TO US because we request no restricted scopes — our own SCOPE_NARRATIVE.md established that, so the differentiator was deleted by our own verification work and never replaced; and per-doc pricing is a pricing model, not a reason to switch.
A6: ICP (UNDER REVIEW — D-DM5): as written, SMBs/schools/agencies of 5-200 staff at $19/mo. The external review's §5 finding is that this ICP and the product that was actually built are two different things, and that the arithmetic does not close for the former at any reachable volume. The recommended ICP is an operations or compliance owner running regulated document flows, buying a 3-10 seat team plan. NOT YET CHANGED IN THE BACKLOG: changing the ICP changes the listing copy and five story descriptions, so it waits on D-DM5 rather than being applied unilaterally.
A8: HOW TO USE: Full_Backlog is the single source of truth (edit Status column during execution). Sprint_Board recalculates points per sprint automatically. Financial_Model assumptions (yellow) are editable — the 18-month build recalculates. Launch_Checklist is the platform-specific gate before submission. All costs/timelines are market-standard estimates; verify platform terms (fees/review rules) during S0.
A10: STACK ASSUMPTION (market standard): TypeScript/Node or platform-mandated runtime, React frontends, Postgres, hosted on AWS/GCP/platform FaaS as required, GitHub Actions CI, PostHog + Sentry telemetry, Intercom-class support.

Sheet Product_Spec
A1: PRODUCT SPEC
A3: Module (feature) | B3: Scope in MVP | C3: Out of scope (v1) | D3: Non-functional requirements
A4: Template designer | B4: Template designer: end-to-end happy path + edge cases + permissions | C4: Advanced automation, AI beyond listed, multi-language beyond launch set | D4: p95 <500ms API / <2s UI loads
A5: Batch generate from Sheets | B5: Batch generate from Sheets: end-to-end happy path + edge cases + permissions | C5: Advanced automation, AI beyond listed, multi-language beyond launch set | D5: 99.5% monthly uptime
A6: E-sign requests | B6: E-sign requests: end-to-end happy path + edge cases + permissions | C6: Advanced automation, AI beyond listed, multi-language beyond launch set | D6: WCAG AA
A7: Auto-file to Drive | B7: Auto-file to Drive: end-to-end happy path + edge cases + permissions | C7: Advanced automation, AI beyond listed, multi-language beyond launch set | D7: SOC2-track controls
A8: Form-triggered generation | B8: Form-triggered generation: end-to-end happy path + edge cases + permissions | C8: Advanced automation, AI beyond listed, multi-language beyond launch set | D8: Rate-limit safe (backoff+queue)
A10: Persona | B10: Jobs-to-be-done
A11: Office manager | B11: Buys from marketplace search; needs zero-code setup
A12: Workspace admin | B12: Approves domain install; CASA tier + data policy decide
A13: Ops freelancer | B13: Recommends across clients

Sheet Screens_Wireframes
A1: SCREEN INVENTORY (attach Figma links in col E during S0)
A3: # | B3: Screen | C3: Purpose | D3: Key elements | E3: Wireframe link
A4: 1 | B4: Onboarding / first-run | C4: Reach aha in <1 day | D4: Checklist, sample data toggle, connect steps
A5: 2 | B5: Home dashboard | C5: Daily habit surface | D5: KPI cards, activity feed, alerts
A6: 3 | B6: Template designer workspace | C6: Core value surface | D6: List+detail, bulk actions, status chips
A7: 4 | B7: Batch generate from Sheets builder | C7: Configure second pillar | D7: Rule builder, preview, test mode
A8: 5 | B8: E-sign requests view | C8: Differentiator surface | D8: Timeline/visual, export
A9: 6 | B9: Settings & team | C9: Roles, notifications, data | D9: Role matrix, API keys, danger zone
A10: 7 | B10: Billing | C10: Plan/trial/invoices | D10: Plan cards, usage meter, invoices
A11: 8 | B11: Analytics | C11: Prove ROI | D11: Funnel, cohort, export
A12: 9 | B12: Help & support | C12: Deflect + assist | D12: Search, chat, status

Sheet Full_Backlog
A1: FULL BACKLOG
A3: ID | B3: Epic | C3: Story | D3: Points | E3: Priority | F3: Sprint | G3: Status
A4: ST-001 | B4: F1 | C4: As a Office manager, I can set up Template designer with sensible defaults in one screen | D4: 5 | E4: P0 | F4: S2 | G4: Done
A5: ST-002 | B5: F1 | C5: As a Office manager, the Template designer happy path completes without documentation | D5: 8 | E5: P0 | F5: S2 | G5: Done
A6: ST-003 | B6: F1 | C6: As a Workspace admin, I can customise Template designer rules/conditions for my workflow | D6: 5 | E6: P1 | F6: S2 | G6: Done
A7: ST-004 | B7: F1 | C7: As a user, Template designer shows clear errors and retry paths on platform API failures | D7: 3 | E7: P0 | F7: S2 | G7: Done
A8: ST-005 | B8: F1 | C8: As a Ops freelancer, Template designer works on the Workspace add-on sidebar in Sheets/Docs surface end-to-end | D8: 5 | E8: P0 | F8: S3 | G8: Done
A9: ST-006 | B9: F1 | C9: As a Workspace admin, I can see Template designer performance metrics and trends | D9: 3 | E9: P1 | F9: S3 | G9: Done
A10: ST-007 | B10: F1 | C10: As a user, Template designer respects role permissions and audit logging | D10: 3 | E10: P1 | F10: S3 | G10: Done
A11: ST-008 | B11: F1 | C11: As a Office manager, I can pause/disable Template designer without data loss | D11: 2 | E11: P2 | F11: S3 | G11: Done
A12: ST-009 | B12: F1 | C12: As a Workspace admin, I can import/migrate existing data into Template designer (CSV + competitor importer) | D12: 5 | E12: P1 | F12: S3 | G12: Done
A13: ST-010 | B13: F1 | C13: As a user, I get notifications (in-app + email) for key Template designer events with per-type mute | D13: 3 | E13: P2 | F13: S3 | G13: Done
A14: ST-011 | B14: F2 | C14: As a Office manager, I can set up Batch generate from Sheets with sensible defaults in one screen | D14: 5 | E14: P0 | F14: S3 | G14: Done
A15: ST-012 | B15: F2 | C15: As a Office manager, the Batch generate from Sheets happy path completes without documentation | D15: 8 | E15: P0 | F15: S3 | G15: Done
... A103: ST-100 | B103: EL | C103: First 10 design-partner reviews scheduled | D103: 2 | E103: P1 | F103: S11 | G103: Done
A105: Total stories: 100. Epics: F1-F5 = product features; E1 install, E5 billing, E6 compliance, E7 telemetry, E8 onboarding/docs/support, EQ quality. Edit Status (Backlog/In progress/Done) during execution.

Sheet Review_Response_Backlog
A1: REVIEW RESPONSE BACKLOG — work arising from external review CGPT V001
A2: Kept separate from Full_Backlog on purpose. Full_Backlog is the 100-story baseline and Sprint_Board counts it over a fixed range; adding rows there would both break those counts and quietly restate a settled scope. Points are estimates and are deliberately absent where the work cannot be scoped before a decision.
A4: ID | B4: Source finding | C4: Work item | D4: Points | E4: Priority | F4: Status | G4: Blocked by
A5: RR-01 | B5: CGPT-DM-004 | C5: Commit package-lock.json; add `npm run verify` as the one-command clean gate; publish coverage as a CI artifact | D5: 2 | E5: P0 | F5: DONE 13 Sep 22:53 — reproduced twice from wiped node_modules: 280 packages, tsc clean, 836/836 across 45 suites, 100/100/100/100 | G5: —
A6: RR-02 | B6: CGPT-DM-012 | C6: Supply-chain CI job: npm audit at --audit-level=high, repo-local secret scanner, CycloneDX SBOM as a retained artifact | D6: 3 | E6: P0 | F6: DONE 13 Sep 22:53 — audit 0 vulnerabilities, secret-scan clean (8 rules, 3 reviewed allowlist entries), SBOM 280 components | G6: —
A7: RR-03 | B7: CGPT-DM-012 | C7: CodeQL static analysis on push, PR and weekly schedule | D7: 1 | E7: P1 | F7: CONFIGURED, UNVERIFIED — runs only on GitHub infrastructure. First green run there is the evidence, not the file (R-D17) | G7: GitHub run
A8: RR-04 | B8: CGPT-DM-002 | C8: Remove the placeholder deploy job; fail closed naming the blocker; specify the real deployment work | D8: 2 | E8: P0 | F8: DONE 13 Sep 22:53 — DEPLOY_PLAN.md written. Tradeoff (main now red) logged as D-DM4 | G8: —
A9: RR-05 | B9: CGPT-DM-002 | C9: Real staging: IaC, separate staging/prod projects, Secret Manager, migrations, probes, revision rollback. Exit criterion is destroy/recreate/deploy/migrate/smoke/rollback/redeploy run twice | D9: — | E9: P0 | F9: NOT STARTED — cannot be built against a project that does not exist | G9: LC-1
A10: RR-06 | B10: CGPT-DM-008 | C10: Distributed quota governor: shared budget across processes, fair queueing, jitter/backoff, DLQ, resumable jobs, cancellation | D10: — | E10: P1 | F10: NOT STARTED — today's governor paces a single process, which is honest for a single process | G10: D-DM2
A11: RR-07 | B11: CGPT-DM-005 | C11: Enterprise identity plane: OIDC/SAML federation, SCIM lifecycle, domain policy, break-glass, privileged audit | D11: — | E11: P1 | F11: NOT STARTED — deferred as a bet on a buyer the product has never met | G11: D-DM2
A12: RR-08 | B12: CGPT-DM-009 | C12: Enterprise data lifecycle: configurable retention, legal hold, export evidence, admin APIs | D12: — | E12: P1 | F12: NOT STARTED — purge foundation exists (DM-F09); legal hold is a feature for an unvalidated customer type | G12: D-DM2
A13: RR-09 | B13: CGPT-DM-007 | C13: DR: PITR, restore automation, measured RTO/RPO, dependency-outage and chaos drills | D13: — | E13: P1 | F13: NOT STARTED — drill harness exists; a measured drill needs real backups | G13: LC-1
A14: RR-10 | B14: CGPT-DM-010 | C14: Production SLO evidence: golden signals, traces, synthetics, burn alerts, 7-30 day history | D14: — | E14: P1 | F14: NOT STARTED — history cannot be manufactured | G14: LC-1
A16: Four of these ten (RR-06..RR-09) are deferred behind D-DM2 rather than scheduled. If D-DM2 resolves toward the enterprise bar they become four unscoped sprints — recorded as R-D19 in the tracker RAID so the cost of that decision is visible before it is taken rather than after.
A17: RR-11 | B17: CGPT-DM-002/004/012 | C17: Release-integrity gate: convert the three accepted findings from fixed incidents into a standing CI check (RG-01 install cannot run, RG-02 action job reports false success, RG-03 no supply-chain step, RG-04 coverage never published) | D17: 3 | E17: P0 | F17: DONE 13 Sep 23:04 — src/releaseGate.ts, 26 tests, 100% on the module, wired as its own CI step; the pre-review workflow kept as a regression fixture. Ported to the portfolio guard kit as its fifth module. | G17: —
A18: RR-12 | B18: VER-DM4 | C18: Produce the required listing assets: icons 32/48/96/128 and the 220x140 card banner the corrected spec revealed were required and missing | D18: 3 | E18: P0 | F18: DONE 13 Sep 23:13 — generated as real PNGs; tests read the dimensions from the file headers and run them through the product's own validateAssets, leaving screenshots as the only outstanding asset finding | G18: —
A19: RR-13 | B19: R-D15 | C19: Generate the pages that must be hosted before the OAuth consent screen: privacy (from the enforcing code), terms of service, status, support, index | D19: 5 | E19: P0 | F19: DONE 13 Sep 23:13 — five static files in site/, no runtime. Legal review of terms and of the privacy framing is owed (R-D22); six config values are owed (R-D23) | G19: —
A20: RR-14 | B20: R-D22 | C20: Legal review of the terms of service and the privacy policy framing before publication | D20: — | E20: P0 | F20: NOT STARTED — needs a lawyer. The warranty and liability clauses are an explicit placeholder. | G20: Senthil
A21: RR-15 | B21: R-D24 | C21: Rebuild the submission dry run against the corrected listing spec (VER-DM4) — add the omitted icon/banner and terms-of-service items, correct the screenshot count, split the optional promo video from the required OAuth verification video, and downgrade CASA to an applicability check | D21: 2 | E21: P0 | F21: DONE 14 Sep 13:59 — 22 items, 11 satisfied, 10 blocking, 1 to verify | G21: —
A22: RR-16 | B22: D-DM1..D-DM4, R-D13, R-D22 | C22: Decision pack: give each open item a recommendation with its reasoning, so the blocking set can be closed in one sitting | D22: 2 | E22: P0 | F22: DONE 14 Sep 13:59 — DECISION_PACK.md. Recommendations only; all seven remain OPEN until Senthil decides | G22: Senthil
A23: RR-17 | B23: Portfolio class C-14 | C23: Prove the Postgres adapter against a real engine rather than a FakeClient | D23: 3 | E23: P0 | F23: DONE 15 Sep 09:09 — 10 contract tests on PGlite, CI job added, deploy depends on it. Result clean. | G23: —
A24: RR-18 | B24: R-D26 | C24: Merge the three portable gate packages (at-review-gates, TeleField REVIEW_GATES, portfolio-guard-kit) into one, adding reachability and published-claims | D24: — | E24: P1 | F24: NOT STARTED — needs the other two packages. Highest-value portfolio task and it needs no live environment, decision or budget. | G24: Senthil
A26: PPLX V001 RESPONSE — 20 September 2026. Unlike RR-01..RR-18 above, almost all of this was executable without Senthil, which was the review's central practical point.
A27: PR-01 | B27: P-DM-002 | C27: Process bootstrap, /healthz, /readyz, graceful drain; point npm start at something that starts | D27: 13 | E27: P0 | F27: DONE 20 Sep — proved by spawning the built artefact (EV-1) | G27: —
A28: PR-02 | B28: P-DM-003 | C28: Declare pg; real pooled client with TLS; run the migration against a real Postgres | D28: 8 | E28: P0 | F28: DONE 20 Sep — six migrations applied, re-run a clean no-op (EV-3) | G28: —
A29: PR-03 | B29: P-DM-010 | C29: Remove the ungoverned coverage exemption; add RG-06 so every exemption of any gate names a test that exists | D29: 6 | E29: P0 | F29: DONE 20 Sep | G29: —
A30: PR-04 | B30: P-DM-006 | C30: Real Google Docs rendering: copy, batchUpdate, images, repeating tables, PDF/DOCX export | D30: 26 | E30: P0 | F30: DONE-IN-CODE 20 Sep — against recorded contracts; live render owed | G30: LC-1 for the live half
A31: PR-05 | B31: P-DM-005 | C31: The Editor add-on: generated manifest, Code.gs, sidebar, the SidebarHost shim | D31: 21 | E31: P0 | F31: DONE-IN-CODE 20 Sep — never pushed with clasp | G31: LC-1; D-DM1 ratification
A32: PR-06 | B32: P-DM-001 | C32: Drive, Sheets and OAuth adapters behind the existing interfaces | D32: 21 | E32: P0 | F32: DONE-IN-CODE 20 Sep | G32: LC-1 for the live half
A33: PR-07 | B33: P-DM-004 | C33: Re-baseline the SBOM on a runtime tree and assert the runtime count is non-zero | D33: 3 | E33: P0 | F33: DONE 20 Sep — 13 runtime components of 296 | G33: —
A34: PR-08 | B34: P-DM-009 | C34: Seven RAM-only stores to Postgres, in the review's order; crash-restart invariant per store | D34: 34 | E34: P0 | F34: DONE 20 Sep | G34: —
A35: PR-09 | B35: P-DM-007 | C35: Rename e-sign to Approval requests everywhere; gate it; add the provider boundary | D35: 13 | E35: P0 | F35: DONE 20 Sep — the exposure is closed independently of any vendor decision | G35: D-DM6 for the provider
A36: PR-10 | B36: P-DM-008 | C36: Rebuild the financial model with the free tier's cost and an explicit breakeven row | D36: 5 | E36: P0 | F36: DONE 20 Sep — Financial_Model_v2; breakeven M12 under stated assumptions | G36: D-DM5 for the decision
A37: PR-11 | B37: §5 | C37: Turn the governance assets into buyer-facing artefacts: verifiable audit export, isolation statement, honest batch-SLO page | D37: 13 | E37: P0 | F37: DONE 20 Sep — each generated from the enforcing code, each with a drift validator | G37: —
A38: PR-12 | B38: P-DM-012 | C38: Replace the unverified autoCrat figure with the two confirmed install counts | D38: 1 | E38: P1 | F38: DONE 20 Sep — retraction recorded in code so it cannot come back | G38: —
... A44: PR-18 | B44: §5 / D-DM5 | C44: Make the pricing and positioning call; then align listing copy before submission | D44: 3 | E44: P0 | F44: NOT STARTED — the one genuine new decision | G44: Senthil
A46: Fourteen of these eighteen were executable with no decision, no budget and no external party — which is the measure of how wrong 'everything I can do alone on this product is done' was on 13 September.

Sheet Sprint_Board
A1: SPRINT BOARD — live counts from Full_Backlog
A3: Sprint | B3: Focus | C3: Stories | D3: Points | E3: Done | F3: Exit criteria
A4: S0 | B4: Discovery & Design (2 wks) | C4: =COUNTIF(Full_Backlog!F4:F103,"S0") | D4: =SUMIF(Full_Backlog!F4:F103,"S0",Full_Backlog!D4:D103) | E4: =COUNTIFS(Full_Backlog!F4:F103,"S0",Full_Backlog!G4:G103,"Done") | F4: PRD signed off; prototype tested with 5 target users
A5: S1 | B5: Foundation (2 wks) | C5: =COUNTIF(Full_Backlog!F4:F103,"S1") | D5: =SUMIF(Full_Backlog!F4:F103,"S1",Full_Backlog!D4:D103) | E5: =COUNTIFS(Full_Backlog!F4:F103,"S1",Full_Backlog!G4:G103,"Done") | F5: App installs cleanly in dev store/org; telemetry firing
A6: S2 | B6: Core feature Template designer - part 1 | C6: =COUNTIF(Full_Backlog!F4:F103,"S2") | D6: =SUMIF(Full_Backlog!F4:F103,"S2",Full_Backlog!D4:D103) | E6: =COUNTIFS(Full_Backlog!F4:F103,"S2",Full_Backlog!G4:G103,"Done") | F6: Template designer happy path demoable
A7: S3 | B7: Core feature Template designer - part 2 + Batch generate from Sheets start | C7: =COUNTIF(Full_Backlog!F4:F103,"S3") | D7: =SUMIF(Full_Backlog!F4:F103,"S3",Full_Backlog!D4:D103) | E7: =COUNTIFS(Full_Backlog!F4:F103,"S3",Full_Backlog!G4:G103,"Done") | F7: Template designer complete with tests; Batch generate from Sheets skeleton
A8: S4 | B8: Core feature Batch generate from Sheets | C8: =COUNTIF(Full_Backlog!F4:F103,"S4") | D8: =SUMIF(Full_Backlog!F4:F103,"S4",Full_Backlog!D4:D103) | E8: =COUNTIFS(Full_Backlog!F4:F103,"S4",Full_Backlog!G4:G103,"Done") | F8: MVP loop usable end-to-end internally
A9: S5 | B9: Feature E-sign requests + alpha hardening | C9: =COUNTIF(Full_Backlog!F4:F103,"S5") | D9: =SUMIF(Full_Backlog!F4:F103,"S5",Full_Backlog!D4:D103) | E9: =COUNTIFS(Full_Backlog!F4:F103,"S5",Full_Backlog!G4:G103,"Done") | F9: Internal alpha: team dogfoods daily
A10: S6 | B10: Billing + Auto-file to Drive | C10: =COUNTIF(Full_Backlog!F4:F103,"S6") | D10: =SUMIF(Full_Backlog!F4:F103,"S6",Full_Backlog!D4:D103) | E10: =COUNTIFS(Full_Backlog!F4:F103,"S6",Full_Backlog!G4:G103,"Done") | F10: Can charge a test customer; upgrade/downgrade paths work
A11: S7 | B11: Private beta (design partners) | C11: =COUNTIF(Full_Backlog!F4:F103,"S7") | D11: =SUMIF(Full_Backlog!F4:F103,"S7",Full_Backlog!D4:D103) | E11: =COUNTIFS(Full_Backlog!F4:F103,"S7",Full_Backlog!G4:G103,"Done") | F11: 3+ partners active weekly; NPS pulse >30
A12: S8 | B12: Beta iteration + Form-triggered generation | C12: =COUNTIF(Full_Backlog!F4:F103,"S8") | D12: =SUMIF(Full_Backlog!F4:F103,"S8",Full_Backlog!D4:D103) | E12: =COUNTIFS(Full_Backlog!F4:F103,"S8",Full_Backlog!G4:G103,"Done") | F12: Retention of beta cohort week-over-week >60%
A13: S9 | B13: Marketplace review prep | C13: =COUNTIF(Full_Backlog!F4:F103,"S9") | D13: =SUMIF(Full_Backlog!F4:F103,"S9",Full_Backlog!D4:D103) | E13: =COUNTIFS(Full_Backlog!F4:F103,"S9",Full_Backlog!G4:G103,"Done") | F13: Review submission accepted into queue
A14: S10 | B14: Review remediation + docs | C14: =COUNTIF(Full_Backlog!F4:F103,"S10") | D14: =SUMIF(Full_Backlog!F4:F103,"S10",Full_Backlog!D4:D103) | E14: =COUNTIFS(Full_Backlog!F4:F103,"S10",Full_Backlog!G4:G103,"Done") | F14: Marketplace approval obtained (or final remediation cycle)
A15: S11 | B15: Launch | C15: =COUNTIF(Full_Backlog!F4:F103,"S11") | D15: =SUMIF(Full_Backlog!F4:F103,"S11",Full_Backlog!D4:D103) | E15: =COUNTIFS(Full_Backlog!F4:F103,"S11",Full_Backlog!G4:G103,"Done") | F15: First 10 installs; first 3 reviews; activation >40%
A16: S12 | B16: Iterate & scale decision | C16: =COUNTIF(Full_Backlog!F4:F103,"S12") | D16: =SUMIF(Full_Backlog!F4:F103,"S12",Full_Backlog!D4:D103) | E16: =COUNTIFS(Full_Backlog!F4:F103,"S12",Full_Backlog!G4:G103,"Done") | F16: Growth model doc with CAC/LTV first estimates
B17: TOTAL | C17: =SUM(C4:C16) | D17: =SUM(D4:D16)
B18: Velocity check: points/sprint S2-S8 should sit within 30-45 for a 4-6 person team; rebalance Sprint column in backlog if a sprint exceeds capacity.

Sheet Sprint_Tracker_Log
A1: SPRINT TRACKER LOG — session-by-session execution record
A3: Entry | B3: Date/Time | C3: Sprint | D3: Stories | E3: Action | F3: Outcome | G3: Decision/Ref
A4: L-001 | B4: 2026-09-05 19:50 | C4: — | D4: — | E4: v007 full product workbook released (spec, 100-story backlog, sprint board, financial model, GTM, launch checklist) | F4: Baseline established; all 100 stories Backlog | G4: v007 Version_Control
A5: L-002 | B5: 2026-09-10 22:17 | C5: S0 | D5: — | E5: S0 discovery interviews parked; development proceeds directly | F5: S0 closed as parked (0 stories carried); PRD baseline = Product_Spec sheet | G5: D13 (portfolio decision, 10 Sep 2026)
A6: L-003 | B6: 2026-09-10 22:17 | C6: S1 | D6: ST-051, ST-052, ST-055, ST-056 | E6: S1 Foundation opened and executed: docmerge-pro-s1 TypeScript package — OAuth install flow, uninstall webhook with token revocation + 30-day retention deletion scheduling, rotation-surviving token refresh, install telemetry with listing/search/referral attribution | F6: All 4 stories (13 pts) code-complete: 37 automated tests, 100% statements/branches/functions/lines, coverage gate pinned at 100% in CI config, tsc strict clean | G6: D13 100% coverage gate (supersedes ST-085 ≥70%)
A7: L-004 | B7: 2026-09-10 22:17 | C7: S1 | D7: — | E7: S1 exit criteria review: "App installs cleanly in dev store/org; telemetry firing" | F7: Code-complete; LIVE dev-org install PENDING — requires GCP project + OAuth consent screen (Launch_Checklist #1), not yet created. Same gate pattern as RevRescue S1. | G7: Carry-over to v009
A8: L-005 | B8: 2026-09-10 22:23 | C8: S2 | D8: ST-001, ST-002, ST-003, ST-004 | E8: S2 opened and executed (Template designer part 1): createWithDefaults one-screen setup; happy-path placeholder/section render with actionable missing-field messages; validated rules/conditions (not_empty/equals/greater_than section toggles); platform API failure mapping (429/5xx/403/404/unknown) with exponential-backoff retry paths | F8: 4 stories code-complete at 100% coverage; PlatformApiError messages carry explicit user retry guidance | G8: D13 100% gate
A9: L-006 | B9: 2026-09-10 22:23 | C9: S2 | D9: ST-053, ST-054 | E9: Re-install restore: pending_deletion accounts re-installing before the 30-day purge get deletion cancelled, data retained, tokens re-issued, app_reinstalled attributed. Permission matrix owner/admin/member pinned cell-by-cell and enforced at every privileged TemplateDesigner entry point | F9: S2 complete: 6/6 stories (29 pts). Suite 101 tests / 100% all metrics / tsc strict clean | G9: Matrix doc feeds ST-064 least-privilege narrative (S7)
A10: L-007 | B10: 2026-09-10 22:29 | C10: S3 | D10: ST-005, ST-006, ST-007, ST-008, ST-009, ST-010 | E10: Template designer part 2: SidebarController (Sheets/Docs host injected — list->designer->preview-from-active-row end-to-end, Docs sample-data fallback); TemplateMetrics (p95, success rate, period trend); AuditLog + AuditedTemplateDesigner (allowed AND denied attempts recorded); PauseManager (flag-only, zero data loss); CSV importer with partial success + row-numbered errors and <<legacy>> competitor conversion; NotificationCenter (in-app+email fan-out, per-type per-account mute) | F10: 6 stories code-complete at 100% coverage | G10: D13
A11: L-008 | B11: 2026-09-10 22:29 | C11: S3 | D11: ST-011, ST-012, ST-013, ST-014 | E11: Batch generate skeleton: one-screen job defaults; per-row generation with named outputs; row rules reusing the designer rule evaluator (skip on fail); per-row platform error mapping with retry/backoff, retryableRows list, continueOnError stop, paused-template gate | F11: 4 stories code-complete at 100% coverage | G11: D13
A12: L-009 | B12: 2026-09-10 22:29 | C12: S3 | D12: ST-085 | E12: DEFECT (caught by the 100% branch gate + failing test before merge): withRetry mapped ALL errors to a generic "unknown Google" message, burying actionable validation messages (e.g. missing Sheet column). Fixed: non-platform errors now pass through unmapped, no retry. ST-085 (≥70% coverage gate) closed as SUPERSEDED — D13 pins the gate at 100%, enforced in package.json thresholds (build fails below 100). | F12: S3 complete: 11/11 stories (47 pts). Suite 150 tests / 100% all metrics / tsc strict clean | G12: D13 supersedes ST-085
A13: L-010 | B13: 2026-09-10 22:52 | C13: S4 | D13: ST-015, ST-016, ST-017, ST-018, ST-019, ST-020 | E13: Batch part 2: BatchSidebarController (configure with defaults -> rows from bound sheet -> governed run -> results, with guidance on unconfigured/empty-sheet paths); BatchMetrics (runs, row counts, failure rate, avg duration, trend); GovernedBatchRunner (permission asserted+audited up front incl. denials, job-level pause, run metrics, batch_completed/batch_failed notifications with retryable count, per-type mute honoured); row-data CSV importer with header validation, partial success, and <<legacy>> competitor conversion | F13: 6 stories code-complete at 100% coverage | G13: D13
A14: L-011 | B14: 2026-09-10 22:52 | C14: S4 | D14: ST-071, ST-072 | E14: Observability: ActivationFunnel (install->setup->aha->habit, idempotent, earlier stages implied, one dashboard with counts + stage conversions); ErrorTracker (release-tagged capture, per-release counts, spike alert when current window > factor x previous with a minimum floor, one alert per release until acknowledged) | F14: 2 stories code-complete at 100% coverage | G14: D13
... A27: L-024 | B27: 2026-09-13 10:22 | C27: S8 | D27: ST-073..ST-077, ST-087, ST-088, ST-092 | E27: Analytics + QE: usage heatmap whose unused-feature list is the roadmap-relevant half; weekly digest with alert counts in the subject; health score that always explains its reasons (a score with no explanation cannot be acted on); CSV/warehouse export; configurable thresholds. p95 budgets defined per surface and monitored with headroom; 5x load test written deterministically so it runs on EVERY commit rather than once before launch; blue/green deploy that health-checks the idle colour BEFORE any traffic moves and verifies rollback — droppedRequests is measured, not claimed. | F27: S8 complete: 22/22 stories (87 pts). Suite 385 tests / 100% all metrics / smoke green. Total 82/100 (335/399 pts) | G27: D13; tracker v004
A28: L-025 | B28: 2026-09-13 10:35 | C28: S9 | D28: ST-068 (PARTIAL) | E28: Security evidence pack built and published as SECURITY_EVIDENCE_PACK.md: 9 controls, 6 verified in code (auth, authorisation, least privilege, data handling, auditability, resilience), 3 outstanding (SC-07 encryption posture needs a real deployment, SC-08 third-party pen test NOT STARTED, SC-09 backup/restore needs real backups). NOT MARKED DONE. A penetration test is performed by a third party against running infrastructure; this pack is what the tester and reviewer are handed, not a substitute for the test. readyForSubmission is false by construction until the external report is attached. | F28: ST-068; LC-3 | G28: ST-068 In progress (NOT Done) | H28: Pen test must be booked and paid for — Senthil action; needs deployed infra (LC-1) | I28: L-026
A29: L-026 | B29: 2026-09-13 10:35 | C29: S9 | D29: ST-069, ST-090, ST-091 | E29: Data rights + resilience: self-serve export (owner/admin) that STATES its exclusions rather than silently omitting them, and owner-only deletion with a cancellable 7-day grace window after which it is irreversible; restore-drill harness that verifies restored row counts against the backup manifest as part of the pass condition (a restore that "succeeds" without checking contents evidences nothing) plus RTO/RPO targets; chaos simulation proving every dependency outage leaves the product usable and every lost capability carries a message saying what is safe — the guards are injectable so they can actually fire, since a check that can never fail is not a check. | F29: ST-069, ST-090, ST-091 | G29: 3 stories code-complete at 100% coverage | I29: L-027
A30: L-027 | B30: 2026-09-13 10:35 | C30: S9 | D30: ST-089, ST-093, ST-094 | E30: Listing + accessibility: WCAG AA audit with real contrast maths (shipped 6-pair palette passes; large-text threshold applied correctly), accessible-name/keyboard/focus failures and target-size warnings; two listing variants on genuinely different angles (problem-led vs outcome-led) with a reviewer that fails same-angle A/Bs and flags claims that invite rejection (implied Google endorsement, absolute security, guarantees, superlatives, "free forever"); asset validator for the 5x1280x800 screenshots and 30-120s captioned video, plus the screenshot plan. Published as LISTING_PACK.md. | F30: ST-089, ST-093, ST-094 | G30: S9: 6/7 Done, 1 In progress. Suite 432 tests / 100% all metrics / smoke green. Total 88/100 (357/399 pts) | H30: D13; tracker v005
A31: L-028 | B31: 2026-09-13 10:43 | C31: S10 | D31: ST-080, ST-081 | E31: Support surfaces: 15 launch articles, each documenting shipped behaviour and naming the stories it covers so docs cannot silently drift from code; weighted search (exact keyword > partial > title > summary > body) so "vat" returns invoicing rather than every article containing the word; documentation-coverage report over launch-critical journeys. In-app chat measures first response in BUSINESS hours — a Friday 17:00 message is 2 business hours from a Monday 09:00 reply, not 64 — with a tighter 1-hour SLA for urgent, a breach queue worst-first, and a waiting message that sets expectations instead of going silent. | F31: ST-080, ST-081 | G31: 2 stories code-complete at 100% coverage | H31: Support must actually be STAFFED during the stated hours before the SLA is published | I31: L-029
A32: L-029 | B32: 2026-09-13 10:43 | C32: S10 | D32: ST-083 (PARTIAL), ST-084 | E32: ST-083 sandbox/demo-data mode: a no-account, no-OAuth, platform-read-only session with realistic sample data that exercises real template features including a conditional section, 60-minute TTL, and conversion-to-signup carrying the template across. The 2-minute demo VIDEO half is NOT done — it is a recording of a running app. ST-084 status page: worst-component-wins overall (never rounds up to green), incident templates that state data is unaffected, and an overdue-update check that chases incidents gone quiet past the 30-minute cadence. | F32: ST-083, ST-084 | G32: ST-084 Done; ST-083 In progress (sandbox done, video pending) | H32: Demo video needs a running app (LC-1) | I32: L-030
A33: L-030 | B33: 2026-09-13 10:43 | C33: S10 | D33: ST-095, ST-096, ST-097 | E33: Public pages built FROM the code rather than alongside it: the plan matrix reads prices from the billing module and limits from the enforcer, with a validator that fails if the published page drifts; the trust page is generated from the scope manifest, subprocessor list, and retention policy. ST-097 submission dry-run run for real and published as SUBMISSION_DRY_RUN.md — VERDICT: 10 of 20 items satisfied, 10 blocking (8 Senthil, 2 third-party), NOT READY TO SUBMIT. The dry-run deliberately counts unmet items rather than explaining them away, and records an owner for each so the output is a work list. | F33: ST-095, ST-096, ST-097 | G33: S10: 6 Done + 1 In progress. Suite 484 tests / 100% all metrics / smoke green. Total 94/100 (376/399 pts) | H33: D13; tracker v006
A34: L-031 | B34: 2026-09-13 10:58 | C34: S11 | D34: ST-082, ST-100 | E34: ST-082 review ask: every rule exists to prevent an ill-timed prompt — not before the aha-moment, not before 10 documents, not within 3 days of a failure, not inside a 30-day cooldown, and never again after two dismissals. A prompt at the wrong moment costs a rating rather than earning one. ST-100 partner-review pipeline REFUSES to invite an at-risk account (fix their experience first), refuses to reschedule a decline, excludes declines from the pipeline count, and warns on invitations unanswered for over a week. | F34: ST-082, ST-100 | G34: 2 stories code-complete at 100% coverage | H34: Real partners and a listed app needed to run it | I34: L-032
A35: L-032 | B35: 2026-09-13 10:58 | C35: S11 | D35: ST-098 | E35: Launch runbook built and RUN against the real current state: go/no-go over 13 checks returns NO-GO with 8 blocking failures (not listed, not deployed, rollback unverified against real infra, status/privacy pages unhosted, billing not live, support unstaffed, monitoring sinks unwired). Watchlist items each carry an action rather than just a threshold; the rollback plan budgets 35 minutes with a verification step for each of its 5 steps; the comms tree names an owner and a deadline per audience. Published as LAUNCH_RUNBOOK.md — written now so launch day is execution, not authoring. | F35: ST-098 | G35: 1 story code-complete; runbook verdict NO-GO | H35: All 8 blocking items are Senthil or third-party | I35: L-033
A36: L-033 | B36: 2026-09-13 10:58 | C36: S12 | D36: ST-099 | E36: ST-099 SEO iteration classifies search terms into untargeted, ranking-just-off-page, and high-impressions-low-CTR, ignores anything under 100 impressions rather than chasing noise, sorts by impressions so the biggest lever is first, and recommends EXACTLY ONE change per iteration so the effect is attributable. CODE BACKLOG COMPLETE: 98 of 100 stories Done, 2 In progress (ST-068 needs a third-party pen test, ST-083 needs a running app to record the demo video). Suite 31 files / 516 tests / 100% all metrics / 33 modules / smoke green. Three test-side errors fixed this sprint, none in source. | F36: ST-099; D13 | G36: S11 3/3 and S12 1/1 code-complete. Total 98/100 Done, 2 In progress (391/399 pts) | H36: No further code sprints — remaining work is entirely live/third-party
A37: L-034 | B37: 2026-09-13 11:05 | C37: — | D37: Deployment preparation: src/deployment.ts specifies all 16 environment values with their source (vault / config / platform), validates them (required, https URLs, numeric/boolean kinds, the conditional Stripe key, unknown-variable warnings), and refuses vault-sourced secrets arriving as plain env in production. checkDeploymentReadiness combines that with the S8 posture verifier into one fail-closed gate: a misconfigured instance does not take traffic, which is better than discovering the problem on a customer request. .env.example is generated from the spec so it cannot drift. | E37: LC-1 prep; D13 | F37: 15 new tests; suite 531 at 100% | H37: L-035
