Workbook

Sheet Version_Control
A1: VERSION CONTROL — DocMerge Pro
A3: Version | B3: Date | C3: Author | D3: Change | E3: Status
A4: v001-v004 | B4: 2026-09-05 | C4: Claude for Senthil/KP | D4: Lineage: marketplace master (868 entries) -> portfolio plan (12 products) -> wave-1 (RetainKit/ShiftDesk/EngageOS, v005) -> this product selected for wave-3 | E4: Released
A5: v007 | B5: 2026-09-05 19:50 | C5: Claude for Senthil/KP | D5: Full product workbook for DocMerge Pro on Google Workspace Marketplace: spec, screen inventory, 100+ story backlog, live sprint board, 18-month financial model (editable assumptions), GTM execution tasks, platform launch checklist, metric targets, risk register | E5: Released
A6: v008 | B6: 2026-09-10 22:17 | C6: Claude for Senthil/KP | D6: Sprint_Tracker_Log + Traceability_Matrix sheets added. S1 Foundation executed under D13 (100% automation coverage gate; S0 discovery interviews parked): ST-051/052/055/056 built in TypeScript (docmerge-pro-s1), 37 automated tests, 100% stmt/branch/func/line coverage, tsc strict clean. Backlog statuses updated; Sprint_Board live counts reflect S1 Done=4. | E6: Released
A7: v009 | B7: 2026-09-10 22:23 | C7: Claude for Senthil/KP | D7: S2 executed under D13: ST-001/002/003/004 (Template designer part 1 — defaults, happy-path render, rules/conditions, platform-error mapping + retry/backoff) + ST-053 (re-install restore within retention window) + ST-054 (owner/admin/member permission matrix enforced). Suite now 9 test files / 101 tests, 100% stmt/branch/func/line, tsc strict clean. Sprint_Board S2 Done=6. | E7: Released
A8: v010 | B8: 2026-09-10 22:29 | C8: Claude for Senthil/KP | D8: S3 executed under D13: Template designer part 2 (ST-005 sidebar surface end-to-end, ST-006 metrics/trends, ST-007 audit logging incl. denied attempts, ST-008 pause without data loss, ST-009 CSV + competitor importer, ST-010 notifications with per-type mute) + Batch generate skeleton (ST-011..014: defaults, per-row happy path, row rules, error/retry paths) + ST-085 closed as superseded by D13 at 100%. Defect found by the gate and fixed: withRetry was masking validation errors behind a generic platform message. Suite 13 files / 150 tests, 100% all metrics. | E8: Released
A9: v011 | B9: 2026-09-10 22:52 | C9: Claude for Senthil/KP | D9: S4 executed under D13: Batch part 2 (ST-015 batch sidebar end-to-end, ST-016 batch metrics/trends, ST-017 governed runner with allow/deny audit, ST-018 job pause without data loss, ST-019 row-data CSV + competitor import, ST-020 batch notifications with mute) + ST-071 activation funnel dashboard (install->setup->aha->habit with conversions) + ST-072 error tracking with release tagging and spike alerts (re-armable) + ST-086 E2E smoke suite gating the deploy job in .github/workflows/ci.yml. Suite 16 files / 180 tests, 100% all metrics, tsc strict clean. Sprint_Board S4 Done=9. | E9: Released
A10: v012 | B10: 2026-09-10 23:03 | C10: Claude for Senthil/KP | D10: S5 executed under D13: E-sign requests full module (ST-021 defaults, ST-022 sequential/parallel lifecycle draft->sent->partially_signed->completed/declined/expired, ST-023 validated rules incl. domain allow-lists, ST-024 delivery retry with mapped errors and no half-sent state, ST-025 sidebar create->send->track, ST-026 metrics, ST-027 allow/deny audit, ST-028 pause preserving signatures, ST-029 signer CSV + competitor import, ST-030 mute-aware notifications) + ST-078 first-run checklist with <1-day aha budget + ST-079 empty states for all 9 screens. Suite 18 files / 217 tests, 100% all metrics. Companion tracker file v001 opened (claude_v001_docmerge_pro_sprint_tracker_traceability_20260910_2303.xlsx). | E10: Released
A11: v013 | B11: 2026-09-11 08:20 | C11: Claude for Senthil/KP | D11: S6 executed under D13: Auto-file to Drive full module (ST-031 one-screen defaults, ST-032 pattern-driven filing with built-in {{template}}/{{row}}/{{yyyy}}/{{mm}} tokens and named missing-token errors, ST-033 first-match routing rules, ST-034 retry/backoff with mapped errors, ST-035 sidebar file-last-batch flow, ST-036 filing metrics, ST-037 allow/deny audit, ST-038 pause, ST-039 routing-rule CSV + competitor import, ST-040 filing notifications; conflict policies rename/overwrite/skip with first-free-number rename) + Billing (ST-057 no-card 14-day trial with honest banner, ST-058 mid-cycle proration charge/credit verified to the cent, ST-059 marketplace-vs-Stripe provider routing + 1/3/7-day dunning, grace, downgrade-with-data). Suite 21 files / 264 tests, 100% all metrics. Tracker rolled to v002. | E11: Released
A12: v014 | B12: 2026-09-13 09:55 | C12: Claude for Senthil/KP | D12: S7 executed under D13: ST-060 dunning UX (3 emails on 1/3/7-day schedule, 7-day grace, then READ-ONLY mode — corrects S6 ST-059 which ended in downgrade-to-free; read-only retains plan and data, strictly less destructive), ST-061 plan limits with 80%/100% upgrade prompts across documents/templates/seats, ST-062 invoices with GST/VAT incl. B2B reverse charge and downloadable CSV receipts (closes the tax gap flagged at S6), ST-063 cancellation with reason-matched save-offer (offered once) + exit survey + access to period end, ST-064 machine-audited scope-to-feature least-privilege mapping + generated SCOPE_NARRATIVE.md for the OAuth/CASA pack. Suite 23 files / 305 tests, 100% all metrics. Tracker v003. | E12: Released
A13: v015 | B13: 2026-09-13 10:22 | C13: Claude for Senthil/KP | D13: S8 executed under D13 — largest sprint, 22 stories / 87 pts: Form-triggered generation ST-041..050 (submission pipeline with built-in redelivery dedupe, conditions, failure-as-result so the webhook stays up, sidebar activity feed, metrics, audit, pause, field-map import, notifications); Compliance ST-065 validated data-flow + retention policy (DATA_FLOW_AND_RETENTION.md published), ST-066 deployment posture verifier (encryption at rest, TLS floor, vault-only secrets), ST-067 hash-chained admin audit log detecting edits and deletions, ST-070 circuit breaker with half-open recovery; Analytics ST-073..077 (heatmap with unused-feature list, weekly digest, explained health score, CSV/warehouse export, configurable alert thresholds); QE ST-087 p95 budgets per surface, ST-088 deterministic 5x load test in CI, ST-092 blue/green deploy with pre-cutover health gate and verified rollback. Suite 26 files / 385 tests, 100% all metrics. Tracker v004. | E13: Released
A14: v016 | B14: 2026-09-13 10:35 | C14: Claude for Senthil/KP | D14: S9 executed under D13: ST-069 self-serve export + owner-only deletion with cancellable 7-day grace, ST-089 WCAG AA audit (contrast maths, accessible names, keyboard, focus, target size) with the shipped palette passing, ST-090 restore-drill harness verifying contents as well as RTO/RPO, ST-091 chaos degradation proving every dependency outage leaves the product usable with an explaining message, ST-093 two listing variants on genuinely different angles + a copy reviewer that flags risky claims, ST-094 asset-spec validator + 5-screenshot plan. ST-068 is PARTIAL, not Done: the evidence pack is built and published (SECURITY_EVIDENCE_PACK.md, 6 of 9 controls verified in code) but a penetration test is a third-party activity — readyForSubmission stays false until the external report is attached. Suite 28 files / 432 tests, 100% all metrics. Tracker v005. | E14: Released
... A19: v021 | B19: 2026-09-13 11:16 | C19: Claude for Senthil/KP | D19: S12 growth model FRAME built (ST-095-adjacent; the S12 exit criterion, marked In progress not Done because the exit asks for CAC/LTV ESTIMATES and estimates without a cohort are assumptions): src/growthModel.ts restates the 18-month model as unit economics — lifetime, LTV, fully-loaded CAC that charges free-tier support against each conversion (~17 installs served per paying customer at 6%), payback, and a verdict that distinguishes a healthy ratio with slow payback from a marginal one. Three scenarios, sensitivity ranking, and a measurement plan pointing each assumption at instrumentation that already exists. FINDING: churn outranks conversion as the lever to measure first — intuition usually reaches for conversion. Published as GROWTH_MODEL.md. Suite 34 files / 589 tests, 100% all metrics. | E19: Released
A20: v022 | D20: PLANNED: live-evidence log only. No unblocked work remains. | E20: Planned
A21: v022 | B21: 2026-09-13 11:21 | C21: Claude for Senthil/KP | D21: ST-068 vendor outreach pack written (PENTEST_OUTREACH.md): a ready-to-send email that quotes from the written brief rather than requiring a discovery call, vendor shortlist criteria, and a quote-comparison rubric. External-facing copy is company-agnostic per standing instruction. FINDING carried into the pack: LEAD TIME, not price, is the binding constraint — it sits on the critical path beside CASA and the two waits can run in parallel, so both should be booked in the same week. No code change; suite unchanged at 589 tests / 100%. | E21: Released
A22: v023 | D22: PLANNED: live-evidence log only. All preparable work is complete; every remaining item needs Senthil or a third party. | E22: Planned
A23: v023 | B23: 2026-09-13 11:24 | C23: Claude for Senthil/KP | D23: COLD REVIEW PASS 1 — DocMerge first adversarial review, run because portfolio memory shows every sibling found real defects after declaring code-complete (TeleField L-T1). NINE findings in code already at 100% coverage, five CRITICAL. FIXED with regressions: DM-F02 read-only mode enforced nowhere (published behaviour absent from the product), DM-F03 plan limits enforced nowhere (published limits decorative), DM-F04 OAuth install had no CSRF state, DM-F05 webhooks entirely unauthenticated (a forged POST could revoke tokens and schedule deletion for any account), DM-F06 no production backoff existed at all. OPEN: DM-F01 CRITICAL no HTTP app exists behind any route, DM-F07 caller-declared identity, DM-F08 eleven unbounded ledgers, DM-F09 deletion has no implementation behind it. New Review_Findings sheet. 35 suites / 616 tests at 100%. The previous "code phase complete" claim was premature. | E23: Released
A24: v024 | D24: PLANNED: cold-review pass 2 — build the HTTP app (DM-F01), close DM-F07/F08/F09, then re-sweep. | E24: Planned
A25: v024 | B25: 2026-09-13 11:31 | C25: Claude for Senthil/KP | D25: DM-F01 and DM-F07 CLOSED — the two critical findings left open by cold-review pass 1. A real HTTP application now exists: framework-free router, 7 routes wired to the existing services, src/server.ts with npm start, and a readiness check that refuses to listen on a misconfigured environment. Identity is no longer caller-declared: HMAC-signed sessions carry account and role, so editing a role in a token fails verification and a session for one account is refused against another. Every mutating route is authenticated AND passes the entitlement gate, so read-only mode and plan limits are enforced on the wire rather than in principle; reads stay open in read-only mode. Server BOOTED FOR REAL and exercised over HTTP (healthz 200, unsigned webhook 401, unauthenticated route 401, unknown route 404) — the siblings taught that compiling is not running. 36 suites / 650 tests at 100%. Remaining from pass 1: DM-F08 unbounded ledgers, DM-F09 deletion has no implementation. | E25: Released
A26: v025 | D26: PLANNED: close DM-F08 (bounded ledgers) and DM-F09 (purge registry + schema), then cold-review pass 2 over the new HTTP layer — siblings found new surfaces inherit old blind spots (L-OC4). | E26: Planned
A27: v025 | B27: 2026-09-13 11:37 | C27: Claude for Senthil/KP | D27: PASS 1 CLOSED + PASS 2 COMPLETE. DM-F08 fixed: all 11 unbounded ledgers now FIFO-bounded with eviction counted rather than silent; the hash-chained admin audit needed a post-eviction chain anchor so verifyChain reports truncation instead of breaking. DM-F09 fixed: PurgeRegistry over 16 stores with a build-failing registration check, evidence receipts, incomplete-purge honesty — plus the database schema that never existed (3 migrations, ON DELETE CASCADE on every account-scoped table, npm run migrate). PASS 2 over the new HTTP layer found four more, all fixed: DM-F10 uncapped request body (memory exhaustion on an open port), DM-F11 abandoned OAuth states accumulating because sweep() was never called — the same built-but-never-wired class as F02/F03, DM-F12 no rate limiting anywhere, DM-F13 /healthz leaking the build version anonymously. Server booted and all four verified over real HTTP. 40 suites / 691 tests at 100%. All 13 cold-review findings now closed. | E27: Released
A28: v026 | D28: PLANNED: live-evidence log. Cold review complete across both passes; remaining work is Senthil/third-party. | E28: Planned
A29: v026 | B29: 2026-09-13 11:51 | C29: Claude for Senthil/KP | D29: EXTERNAL VERIFICATION SWEEP against live Google documentation — the step every sibling product ran after its cold review, and the step that found live-blocking defects in all of them. TWO LIVE-BLOCKING findings, both invisible to two clean internal passes because they are facts about the platform rather than the code. VER-DM1: the Workspace Marketplace does NOT push uninstall webhooks and the licenseNotification API is deprecated with no replacement — our uninstall endpoint was a handler for an event that never arrives, so token revocation, the retention clock, re-install restore and the purge chain would never have run. Fixed with a license reconciler that DETECTS uninstall (license state + revoked credential) and refuses to treat an API outage as one. VER-DM2: Google Forms cannot POST to an arbitrary URL — form submit needs an installable Apps Script trigger that calls UrlFetch itself, so the entire F5 feature (10 stories / 42 pts) rested on a capability that does not exist. Fixed by shipping the Apps Script forwarder that signs with the scheme our endpoint already verifies. 41 suites / 707 tests at 100%. CONSEQUENCE FOR SENTHIL: the form-trigger setup flow changes — ST-041 "one screen" and the help-centre article need rewording. | E29: Released
A30: v027 | D30: PLANNED: verification sweep part 2 (add-on surface, scopes, asset spec, CASA requirements) — the sweep found two blockers in its first two checks, so the remaining assumptions deserve the same treatment. | E30: Planned
A31: v027 | B31: 2026-09-13 11:56 | C31: Claude for Senthil/KP | D31: VERIFICATION SWEEP PART 2 — VER-DM3, the third live-blocking finding and the first that is a DECISION rather than a defect. Google has two add-on types with incompatible UI models and our features sit across both: the Workspace type is card-only (HTML forbidden), cannot read the open document, has no Apps Script triggers and is absent from Forms, but reaches mobile and every host app; the Editor type has HTML sidebars, document context and triggers, but is desktop-only and Editors-only. Twelve shipped stories cannot run on the Workspace surface as built, and the form feature cannot run there at all. Encoded as a test-pinned constraint matrix (src/addonSurface.ts) and presented as ADDON_SURFACE_DECISION.md; logged as D-DM1 for Senthil rather than decided unilaterally. 42 suites / 721 tests at 100%. Three live-blocking findings in four verification checks — the sweep is finding roughly one blocker per check, which says something about how far internal review can reach. | E31: Released
A32: v028 | D32: PLANNED: sweep part 3 (listing asset spec — TestPulse found theirs wrong; scope behaviour; CASA requirements) once D-DM1 is decided, since the surface choice changes the scope narrative. | E32: Planned
A33: v028 | B33: 2026-09-13 12:01 | C33: Claude for Senthil/KP | D33: VERIFICATION SWEEP PART 3 — VER-DM4: the listing asset and copy spec was invented and wrong in eight ways, including TWO REQUIRED ASSET FAMILIES that were absent entirely (application icons at 32/128 plus 48/96 because we now have a web app, and the 220x140 card banner), a forbidden-Google-name rule on the app name we had no check for, and the terms-of-service link missing from the submission checklist. Every copy limit was wrong in the strict direction, so the drafted variants were being held to tighter constraints than the platform applies. The promo video is an optional YouTube link, not the captioned upload we had specified. src/listing.ts rewritten against the live spec, LISTING_PACK.md regenerated, 13 tests pin the corrections. 42 suites / 729 tests at 100%. Four live findings in five verification checks. | E33: Released
A34: v029 | D34: PLANNED: sweep part 4 (OAuth verification + CASA requirements, scope behaviour) — the last unchecked assumptions; then D-DM1 gates the rest. | E34: Planned
A35: v029 | B35: 2026-09-13 12:06 | C35: Claude for Senthil/KP | D35: VERIFICATION SWEEP PART 4 — VER-DM5, the first finding that REMOVES work. Google routes app review by scope classification, and CASA is triggered only by RESTRICTED scopes. DocMerge requests none: drive.file is the recommended non-sensitive alternative to the restricted Drive scopes, userinfo.email is non-sensitive, and only spreadsheets.readonly and documents are sensitive — requiring Google app verification but not an assessment. CASA has been carried as a blocking multi-week paid item since S6 (R-D1, R-D10, LC-3) on an assumption nobody had checked. LC-3 downgraded to "likely not required, confirm in console" rather than deleted, because classification is per-project and Google may still ask. Found in the same pass: verification requires an unlisted YouTube DEMONSTRATION video (OAuth grant flow, consent screen showing the app name, detailed use of each sensitive scope) — a requirement we did not have, and separate from the optional marketing promo video. scopes.ts derives the review path from classifications with 7 pinning tests; SCOPE_NARRATIVE.md regenerated. 42 suites / 736 tests at 100%. | E35: Released
A36: v030 | D36: PLANNED: verification sweep COMPLETE across the five checkable assumption areas. Next work is D-DM1 (Senthil) and then live execution. | E36: Planned
A37: v030 | B37: 2026-09-13 16:25 | C37: Claude for Senthil/KP | D37: R-D4 CLOSED — Postgres adapter shipped. Every store had been an in-memory Map behind a typed interface, which was correct while no schema existed but left the interfaces never once implemented against a real database; the DM-F09 migrations were decorative until now. src/postgres.ts implements TokenStore, AccountRepo and TemplateRepo against the schema, plus purge targets for all 18 tables ordered children-before-parents so the row counts are real evidence rather than zero-because-already-cascaded. The SQL client is injected, so there is no pg dependency and the adapter is fully testable without a database. Details that would have bitten in production: BIGINT expiries are converted explicitly because the driver returns them as strings, template and rules write inside one transaction with rollback (a half-replaced rule set renders wrong output rather than failing), an absent rule value is stored as NULL not the string "undefined", and indirect tables are reached through their parent rather than a column they do not have. A test purges with a SQL-injection string and asserts it never reaches the statement text. 43 suites / 753 tests at 100%. | E37: Released
A38: v031 | D38: PLANNED: remaining in-memory stores (subscriptions, invoices, audit, telemetry, support) onto the adapter pattern; D-DM1 still gates the surface work. | E38: Planned
A39: v031 | B39: 2026-09-13 16:29 | C39: Claude for Senthil/KP | D39: DM-F14 — the remaining in-memory stores are a DURABILITY GAP, not merely unconverted. A restart resets every plan limit (each deploy silently grants every customer a fresh monthly allowance — a revenue leak invisible to tests, which start from zero anyway), resets billing state so paying customers look like trials, and evaporates the tamper-evident audit chain while restarting its numbering at genesis so the gap is not even visible. Usage counters fixed end to end: PlanLimitEnforcer now takes a UsageBackend; WriteThroughUsageBackend serves reads from a primed cache so the limit check stays synchronous, writes through with an atomic single-statement upsert (read-then-write loses increments exactly when a customer is near the limit), and counts write failures rather than failing the request. Subscription and admin-audit stores are built and tested — append-only with no update path, and lastSequence so the chain continues across restarts — but their services are NOT yet wired, which is stated rather than glossed because this codebase has already produced two built-but-never-called defects. 43 suites / 770 tests at 100%. | E39: Released
A40: v032 | D40: PLANNED: wire BillingService and AdminAuditLog to their stores (closing DM-F14), then telemetry/support persistence. D-DM1 still open. | E40: Planned
A41: v032 | B41: 2026-09-13 16:34 | C41: Claude for Senthil/KP | D41: DM-F14 CLOSED and DM-F15 found and fixed. BillingService now persists after every mutation through a SubscriptionBackend, and AdminAuditLog through an AdminAuditBackend with resume(), so a restart no longer resets a paying customer to trial or forks a second audit chain at genesis. Write-through Postgres backends keep reads synchronous and count write failures rather than failing the customer request. DM-F15 surfaced DURING that wiring: the admin audit log had no accountId at all — every customer shared one chain and one sequence counter, and exportCsv would have handed one customer every other customer admin history. The schema had keyed the table on (account_id, sequence) since DM-F09; the code never matched it, and nothing caught the mismatch because the table had no implementation behind it until today. Now scoped per account, with the accountId inside the digest so an entry cannot be replayed into another tenant chain. 43 suites / 781 tests at 100%. | E41: Released
A42: v033 | D42: PLANNED: telemetry/support persistence, then a tenant-isolation sweep across the remaining services — DM-F15 suggests the audit log may not be the only thing lacking a tenant boundary. | E42: Planned
A43: v033 | B43: 2026-09-13 16:39 | C43: Claude for Senthil/KP | D43: TENANT-ISOLATION SWEEP — run deliberately because DM-F15 was found by accident, and it found five more. DM-F16 (CRITICAL): template lookups took a templateId and nothing else, and POST /accounts/:id/documents takes that id from the request body — so an authenticated user of one account could read another account template and generate documents from it. The session check added for DM-F07 proved WHO was asking; nothing checked WHAT they asked for. DM-F17: the same shape on signature requests, exposing signer names and emails. DM-F18: the feature audit log had no accountId either, the same defect as DM-F15 in a second log. All three fixed with ownership enforced centrally, cross-tenant access reported as "not found" so the id space cannot be probed, and regression tests asserting the cross-tenant failure is indistinguishable from a missing record. DM-F19 and DM-F20 (metrics summaries and the support inbox aggregate across tenants) are logged OPEN rather than fixed blind, because whether they are defects depends on whether they are surfaced per-customer or internally — a decision, not a bug. 43 suites / 786 tests at 100%, smoke green. | E43: Released
A44: v034 | D44: PLANNED: decide DM-F19/F20 surfacing, then telemetry/support persistence. D-DM1 still open. | E44: Planned
A45: v034 | B45: 2026-09-13 17:23 | C45: Claude for Senthil/KP | D45: PORTABLE TENANT-ISOLATION GATE built and wired into CI, then it immediately found DM-F21. A sweep finds this class of defect once; the gate finds it every commit, and it is written to be copied into the sibling products — the tenant parameter names and entity-id suffixes are configuration, not hard-coded. It flagged 28 methods on first run. Triage: five clusters genuine (DM-F21) — pause and resume on signature requests, form triggers and batch jobs took only an entity id, so one tenant could pause another tenant work with nothing but a guessed id; renderCsv would render any account invoice with its billing contact and tax identifiers; openTemplate read another account template metadata. The manual sweep had checked READS and missed writes-that-are-not-reads. The other 23 are exempted with written reasons rather than silenced, and a test asserts every exemption carries one. 44 suites / 797 tests at 100%, smoke green. | E45: Released
...

Sheet ReadMe_Scope
A1: DocMerge Pro — Template-based document generation from Sheets/Forms with e-sign and Drive filing
A3: PLATFORM: Google Workspace Marketplace | CATEGORY: Document Automation
A4: PROBLEM: Mail-merge add-ons are dated; SMBs want doc-gen + sign without Zapier chains
A5: DIFFERENTIATION: Native Sheets sidebar, per-doc pricing, DPA + CASA badge for admin trust
A6: ICP: SMBs, schools, agencies 5-200 staff generating contracts/certificates/invoices from Sheets data
A8: HOW TO USE: Full_Backlog is the single source of truth (edit Status column during execution). Sprint_Board recalculates points per sprint automatically. Financial_Model assumptions (yellow) are editable — the 18-month build recalculates. Launch_Checklist is the platform-specific gate before submission. All costs/timelines are market-standard estimates; verify platform terms (fees/review rules) during S0.
A10: STACK ASSUMPTION (market standard): TypeScript/Node or platform-mandated runtime, React frontends, Postgres, hosted on AWS/GCP/platform FaaS as required, GitHub Actions CI, PostHog + Sentry telemetry, Intercom-class support.

Sheet Product_Spec
A1: PRODUCT SPEC
A3: Module (feature) | B3: Scope in MVP | C3: Out of scope (v1) | D3: Non-functional requirements
A4: Template designer | B4: Template designer: end-to-end happy path + edge cases + permissions | C4: Advanced automation, AI beyond listed, multi-language beyond launch set | D4: p95 <500ms API / <2s UI loads
A5: Batch generate from Sheets | B5: Batch generate from Sheets: end-to-end happy path + edge cases + permissions | C5: Advanced automation, AI beyond listed, multi-language beyond launch set | D5: 99.5% monthly uptime
A6: E-sign requests | B6: E-sign requests: end-to-end happy path + edge cases + permissions | C6: Advanced automation, AI beyond listed, multi-language beyond launch set | D6: WCAG AA
A7: Auto-file to Drive | B7: Auto-file to Drive: end-to-end happy path + edge cases + permissions | C7: Advanced automation, AI beyond listed, multi-language beyond launch set | D7: SOC2-track controls
A8: Form-triggered generation | B8: Form-triggered generation: end-to-end happy path + edge cases + permissions | C8: Advanced automation, AI beyond listed, multi-language beyond launch set | D8: Rate-limit safe (backoff+queue)
A10: Persona | B10: Jobs-to-be-done
A11: Office manager | B11: Buys from marketplace search; needs zero-code setup
A12: Workspace admin | B12: Approves domain install; CASA tier + data policy decide
A13: Ops freelancer | B13: Recommends across clients

Sheet Screens_Wireframes
A1: SCREEN INVENTORY (attach Figma links in col E during S0)
A3: # | B3: Screen | C3: Purpose | D3: Key elements | E3: Wireframe link
A4: 1 | B4: Onboarding / first-run | C4: Reach aha in <1 day | D4: Checklist, sample data toggle, connect steps
A5: 2 | B5: Home dashboard | C5: Daily habit surface | D5: KPI cards, activity feed, alerts
A6: 3 | B6: Template designer workspace | C6: Core value surface | D6: List+detail, bulk actions, status chips
A7: 4 | B7: Batch generate from Sheets builder | C7: Configure second pillar | D7: Rule builder, preview, test mode
A8: 5 | B8: E-sign requests view | C8: Differentiator surface | D8: Timeline/visual, export
A9: 6 | B9: Settings & team | C9: Roles, notifications, data | D9: Role matrix, API keys, danger zone
A10: 7 | B10: Billing | C10: Plan/trial/invoices | D10: Plan cards, usage meter, invoices
A11: 8 | B11: Analytics | C11: Prove ROI | D11: Funnel, cohort, export
A12: 9 | B12: Help & support | C12: Deflect + assist | D12: Search, chat, status

Sheet Full_Backlog
A1: FULL BACKLOG
A3: ID | B3: Epic | C3: Story | D3: Points | E3: Priority | F3: Sprint | G3: Status
A4: ST-001 | B4: F1 | C4: As a Office manager, I can set up Template designer with sensible defaults in one screen | D4: 5 | E4: P0 | F4: S2 | G4: Done
A5: ST-002 | B5: F1 | C5: As a Office manager, the Template designer happy path completes without documentation | D5: 8 | E5: P0 | F5: S2 | G5: Done
A6: ST-003 | B6: F1 | C6: As a Workspace admin, I can customise Template designer rules/conditions for my workflow | D6: 5 | E6: P1 | F6: S2 | G6: Done
A7: ST-004 | B7: F1 | C7: As a user, Template designer shows clear errors and retry paths on platform API failures | D7: 3 | E7: P0 | F7: S2 | G7: Done
A8: ST-005 | B8: F1 | C8: As a Ops freelancer, Template designer works on the Workspace add-on sidebar in Sheets/Docs surface end-to-end | D8: 5 | E8: P0 | F8: S3 | G8: Done
A9: ST-006 | B9: F1 | C9: As a Workspace admin, I can see Template designer performance metrics and trends | D9: 3 | E9: P1 | F9: S3 | G9: Done
A10: ST-007 | B10: F1 | C10: As a user, Template designer respects role permissions and audit logging | D10: 3 | E10: P1 | F10: S3 | G10: Done
A11: ST-008 | B11: F1 | C11: As a Office manager, I can pause/disable Template designer without data loss | D11: 2 | E11: P2 | F11: S3 | G11: Done
A12: ST-009 | B12: F1 | C12: As a Workspace admin, I can import/migrate existing data into Template designer (CSV + competitor importer) | D12: 5 | E12: P1 | F12: S3 | G12: Done
A13: ST-010 | B13: F1 | C13: As a user, I get notifications (in-app + email) for key Template designer events with per-type mute | D13: 3 | E13: P2 | F13: S3 | G13: Done
A14: ST-011 | B14: F2 | C14: As a Office manager, I can set up Batch generate from Sheets with sensible defaults in one screen | D14: 5 | E14: P0 | F14: S3 | G14: Done
A15: ST-012 | B15: F2 | C15: As a Office manager, the Batch generate from Sheets happy path completes without documentation | D15: 8 | E15: P0 | F15: S3 | G15: Done
... A103: ST-100 | B103: EL | C103: First 10 design-partner reviews scheduled | D103: 2 | E103: P1 | F103: S11 | G103: Done
A105: Total stories: 100. Epics: F1-F5 = product features; E1 install, E5 billing, E6 compliance, E7 telemetry, E8 onboarding/docs/support, EQ quality. Edit Status (Backlog/In progress/Done) during execution.

Sheet Sprint_Board
A1: SPRINT BOARD — live counts from Full_Backlog
A3: Sprint | B3: Focus | C3: Stories | D3: Points | E3: Done | F3: Exit criteria
A4: S0 | B4: Discovery & Design (2 wks) | C4: =COUNTIF(Full_Backlog!F4:F103,"S0") -> 0 | D4: =SUMIF(Full_Backlog!F4:F103,"S0",Full_Backlog!D4:D103) -> 0 | E4: =COUNTIFS(Full_Backlog!F4:F103,"S0",Full_Backlog!G4:G103,"Done") -> 0 | F4: PRD signed off; prototype tested with 5 target users
A5: S1 | B5: Foundation (2 wks) | C5: =COUNTIF(Full_Backlog!F4:F103,"S1") -> 4 | D5: =SUMIF(Full_Backlog!F4:F103,"S1",Full_Backlog!D4:D103) -> 13 | E5: =COUNTIFS(Full_Backlog!F4:F103,"S1",Full_Backlog!G4:G103,"Done") -> 4 | F5: App installs cleanly in dev store/org; telemetry firing
A6: S2 | B6: Core feature Template designer - part 1 | C6: =COUNTIF(Full_Backlog!F4:F103,"S2") -> 6 | D6: =SUMIF(Full_Backlog!F4:F103,"S2",Full_Backlog!D4:D103) -> 29 | E6: =COUNTIFS(Full_Backlog!F4:F103,"S2",Full_Backlog!G4:G103,"Done") -> 6 | F6: Template designer happy path demoable
A7: S3 | B7: Core feature Template designer - part 2 + Batch generate from Sheets start | C7: =COUNTIF(Full_Backlog!F4:F103,"S3") -> 11 | D7: =SUMIF(Full_Backlog!F4:F103,"S3",Full_Backlog!D4:D103) -> 47 | E7: =COUNTIFS(Full_Backlog!F4:F103,"S3",Full_Backlog!G4:G103,"Done") -> 11 | F7: Template designer complete with tests; Batch generate from Sheets skeleton
A8: S4 | B8: Core feature Batch generate from Sheets | C8: =COUNTIF(Full_Backlog!F4:F103,"S4") -> 9 | D8: =SUMIF(Full_Backlog!F4:F103,"S4",Full_Backlog!D4:D103) -> 34 | E8: =COUNTIFS(Full_Backlog!F4:F103,"S4",Full_Backlog!G4:G103,"Done") -> 9 | F8: MVP loop usable end-to-end internally
A9: S5 | B9: Feature E-sign requests + alpha hardening | C9: =COUNTIF(Full_Backlog!F4:F103,"S5") -> 12 | D9: =SUMIF(Full_Backlog!F4:F103,"S5",Full_Backlog!D4:D103) -> 50 | E9: =COUNTIFS(Full_Backlog!F4:F103,"S5",Full_Backlog!G4:G103,"Done") -> 12 | F9: Internal alpha: team dogfoods daily
A10: S6 | B10: Billing + Auto-file to Drive | C10: =COUNTIF(Full_Backlog!F4:F103,"S6") -> 13 | D10: =SUMIF(Full_Backlog!F4:F103,"S6",Full_Backlog!D4:D103) -> 60 | E10: =COUNTIFS(Full_Backlog!F4:F103,"S6",Full_Backlog!G4:G103,"Done") -> 13 | F10: Can charge a test customer; upgrade/downgrade paths work
A11: S7 | B11: Private beta (design partners) | C11: =COUNTIF(Full_Backlog!F4:F103,"S7") -> 5 | D11: =SUMIF(Full_Backlog!F4:F103,"S7",Full_Backlog!D4:D103) -> 15 | E11: =COUNTIFS(Full_Backlog!F4:F103,"S7",Full_Backlog!G4:G103,"Done") -> 5 | F11: 3+ partners active weekly; NPS pulse >30
A12: S8 | B12: Beta iteration + Form-triggered generation | C12: =COUNTIF(Full_Backlog!F4:F103,"S8") -> 22 | D12: =SUMIF(Full_Backlog!F4:F103,"S8",Full_Backlog!D4:D103) -> 87 | E12: =COUNTIFS(Full_Backlog!F4:F103,"S8",Full_Backlog!G4:G103,"Done") -> 22 | F12: Retention of beta cohort week-over-week >60%
A13: S9 | B13: Marketplace review prep | C13: =COUNTIF(Full_Backlog!F4:F103,"S9") -> 7 | D13: =SUMIF(Full_Backlog!F4:F103,"S9",Full_Backlog!D4:D103) -> 30 | E13: =COUNTIFS(Full_Backlog!F4:F103,"S9",Full_Backlog!G4:G103,"Done") -> 6 | F13: Review submission accepted into queue
A14: S10 | B14: Review remediation + docs | C14: =COUNTIF(Full_Backlog!F4:F103,"S10") -> 7 | D14: =SUMIF(Full_Backlog!F4:F103,"S10",Full_Backlog!D4:D103) -> 24 | E14: =COUNTIFS(Full_Backlog!F4:F103,"S10",Full_Backlog!G4:G103,"Done") -> 6 | F14: Marketplace approval obtained (or final remediation cycle)
A15: S11 | B15: Launch | C15: =COUNTIF(Full_Backlog!F4:F103,"S11") -> 3 | D15: =SUMIF(Full_Backlog!F4:F103,"S11",Full_Backlog!D4:D103) -> 8 | E15: =COUNTIFS(Full_Backlog!F4:F103,"S11",Full_Backlog!G4:G103,"Done") -> 3 | F15: First 10 installs; first 3 reviews; activation >40%
A16: S12 | B16: Iterate & scale decision | C16: =COUNTIF(Full_Backlog!F4:F103,"S12") -> 1 | D16: =SUMIF(Full_Backlog!F4:F103,"S12",Full_Backlog!D4:D103) -> 2 | E16: =COUNTIFS(Full_Backlog!F4:F103,"S12",Full_Backlog!G4:G103,"Done") -> 1 | F16: Growth model doc with CAC/LTV first estimates
B17: TOTAL | C17: =SUM(C4:C16) -> 100 | D17: =SUM(D4:D16) -> 399
B18: Velocity check: points/sprint S2-S8 should sit within 30-45 for a 4-6 person team; rebalance Sprint column in backlog if a sprint exceeds capacity.

Sheet Sprint_Tracker_Log
A1: SPRINT TRACKER LOG — session-by-session execution record
A3: Entry | B3: Date/Time | C3: Sprint | D3: Stories | E3: Action | F3: Outcome | G3: Decision/Ref
A4: L-001 | B4: 2026-09-05 19:50 | C4: — | D4: — | E4: v007 full product workbook released (spec, 100-story backlog, sprint board, financial model, GTM, launch checklist) | F4: Baseline established; all 100 stories Backlog | G4: v007 Version_Control
A5: L-002 | B5: 2026-09-10 22:17 | C5: S0 | D5: — | E5: S0 discovery interviews parked; development proceeds directly | F5: S0 closed as parked (0 stories carried); PRD baseline = Product_Spec sheet | G5: D13 (portfolio decision, 10 Sep 2026)
A6: L-003 | B6: 2026-09-10 22:17 | C6: S1 | D6: ST-051, ST-052, ST-055, ST-056 | E6: S1 Foundation opened and executed: docmerge-pro-s1 TypeScript package — OAuth install flow, uninstall webhook with token revocation + 30-day retention deletion scheduling, rotation-surviving token refresh, install telemetry with listing/search/referral attribution | F6: All 4 stories (13 pts) code-complete: 37 automated tests, 100% statements/branches/functions/lines, coverage gate pinned at 100% in CI config, tsc strict clean | G6: D13 100% coverage gate (supersedes ST-085 ≥70%)
A7: L-004 | B7: 2026-09-10 22:17 | C7: S1 | D7: — | E7: S1 exit criteria review: "App installs cleanly in dev store/org; telemetry firing" | F7: Code-complete; LIVE dev-org install PENDING — requires GCP project + OAuth consent screen (Launch_Checklist #1), not yet created. Same gate pattern as RevRescue S1. | G7: Carry-over to v009
A8: L-005 | B8: 2026-09-10 22:23 | C8: S2 | D8: ST-001, ST-002, ST-003, ST-004 | E8: S2 opened and executed (Template designer part 1): createWithDefaults one-screen setup; happy-path placeholder/section render with actionable missing-field messages; validated rules/conditions (not_empty/equals/greater_than section toggles); platform API failure mapping (429/5xx/403/404/unknown) with exponential-backoff retry paths | F8: 4 stories code-complete at 100% coverage; PlatformApiError messages carry explicit user retry guidance | G8: D13 100% gate
A9: L-006 | B9: 2026-09-10 22:23 | C9: S2 | D9: ST-053, ST-054 | E9: Re-install restore: pending_deletion accounts re-installing before the 30-day purge get deletion cancelled, data retained, tokens re-issued, app_reinstalled attributed. Permission matrix owner/admin/member pinned cell-by-cell and enforced at every privileged TemplateDesigner entry point | F9: S2 complete: 6/6 stories (29 pts). Suite 101 tests / 100% all metrics / tsc strict clean | G9: Matrix doc feeds ST-064 least-privilege narrative (S7)
A10: L-007 | B10: 2026-09-10 22:29 | C10: S3 | D10: ST-005, ST-006, ST-007, ST-008, ST-009, ST-010 | E10: Template designer part 2: SidebarController (Sheets/Docs host injected — list->designer->preview-from-active-row end-to-end, Docs sample-data fallback); TemplateMetrics (p95, success rate, period trend); AuditLog + AuditedTemplateDesigner (allowed AND denied attempts recorded); PauseManager (flag-only, zero data loss); CSV importer with partial success + row-numbered errors and <<legacy>> competitor conversion; NotificationCenter (in-app+email fan-out, per-type per-account mute) | F10: 6 stories code-complete at 100% coverage | G10: D13
A11: L-008 | B11: 2026-09-10 22:29 | C11: S3 | D11: ST-011, ST-012, ST-013, ST-014 | E11: Batch generate skeleton: one-screen job defaults; per-row generation with named outputs; row rules reusing the designer rule evaluator (skip on fail); per-row platform error mapping with retry/backoff, retryableRows list, continueOnError stop, paused-template gate | F11: 4 stories code-complete at 100% coverage | G11: D13
A12: L-009 | B12: 2026-09-10 22:29 | C12: S3 | D12: ST-085 | E12: DEFECT (caught by the 100% branch gate + failing test before merge): withRetry mapped ALL errors to a generic "unknown Google" message, burying actionable validation messages (e.g. missing Sheet column). Fixed: non-platform errors now pass through unmapped, no retry. ST-085 (≥70% coverage gate) closed as SUPERSEDED — D13 pins the gate at 100%, enforced in package.json thresholds (build fails below 100). | F12: S3 complete: 11/11 stories (47 pts). Suite 150 tests / 100% all metrics / tsc strict clean | G12: D13 supersedes ST-085
A13: L-010 | B13: 2026-09-10 22:52 | C13: S4 | D13: ST-015, ST-016, ST-017, ST-018, ST-019, ST-020 | E13: Batch part 2: BatchSidebarController (configure with defaults -> rows from bound sheet -> governed run -> results, with guidance on unconfigured/empty-sheet paths); BatchMetrics (runs, row counts, failure rate, avg duration, trend); GovernedBatchRunner (permission asserted+audited up front incl. denials, job-level pause, run metrics, batch_completed/batch_failed notifications with retryable count, per-type mute honoured); row-data CSV importer with header validation, partial success, and <<legacy>> competitor conversion | F13: 6 stories code-complete at 100% coverage | G13: D13
A14: L-011 | B14: 2026-09-10 22:52 | C14: S4 | D14: ST-071, ST-072 | E14: Observability: ActivationFunnel (install->setup->aha->habit, idempotent, earlier stages implied, one dashboard with counts + stage conversions); ErrorTracker (release-tagged capture, per-release counts, spike alert when current window > factor x previous with a minimum floor, one alert per release until acknowledged) | F14: 2 stories code-complete at 100% coverage | G14: D13
... A27: L-024 | B27: 2026-09-13 10:22 | C27: S8 | D27: ST-073..ST-077, ST-087, ST-088, ST-092 | E27: Analytics + QE: usage heatmap whose unused-feature list is the roadmap-relevant half; weekly digest with alert counts in the subject; health score that always explains its reasons (a score with no explanation cannot be acted on); CSV/warehouse export; configurable thresholds. p95 budgets defined per surface and monitored with headroom; 5x load test written deterministically so it runs on EVERY commit rather than once before launch; blue/green deploy that health-checks the idle colour BEFORE any traffic moves and verifies rollback — droppedRequests is measured, not claimed. | F27: S8 complete: 22/22 stories (87 pts). Suite 385 tests / 100% all metrics / smoke green. Total 82/100 (335/399 pts) | G27: D13; tracker v004
A28: L-025 | B28: 2026-09-13 10:35 | C28: S9 | D28: ST-068 (PARTIAL) | E28: Security evidence pack built and published as SECURITY_EVIDENCE_PACK.md: 9 controls, 6 verified in code (auth, authorisation, least privilege, data handling, auditability, resilience), 3 outstanding (SC-07 encryption posture needs a real deployment, SC-08 third-party pen test NOT STARTED, SC-09 backup/restore needs real backups). NOT MARKED DONE. A penetration test is performed by a third party against running infrastructure; this pack is what the tester and reviewer are handed, not a substitute for the test. readyForSubmission is false by construction until the external report is attached. | F28: ST-068; LC-3 | G28: ST-068 In progress (NOT Done) | H28: Pen test must be booked and paid for — Senthil action; needs deployed infra (LC-1) | I28: L-026
A29: L-026 | B29: 2026-09-13 10:35 | C29: S9 | D29: ST-069, ST-090, ST-091 | E29: Data rights + resilience: self-serve export (owner/admin) that STATES its exclusions rather than silently omitting them, and owner-only deletion with a cancellable 7-day grace window after which it is irreversible; restore-drill harness that verifies restored row counts against the backup manifest as part of the pass condition (a restore that "succeeds" without checking contents evidences nothing) plus RTO/RPO targets; chaos simulation proving every dependency outage leaves the product usable and every lost capability carries a message saying what is safe — the guards are injectable so they can actually fire, since a check that can never fail is not a check. | F29: ST-069, ST-090, ST-091 | G29: 3 stories code-complete at 100% coverage | I29: L-027
A30: L-027 | B30: 2026-09-13 10:35 | C30: S9 | D30: ST-089, ST-093, ST-094 | E30: Listing + accessibility: WCAG AA audit with real contrast maths (shipped 6-pair palette passes; large-text threshold applied correctly), accessible-name/keyboard/focus failures and target-size warnings; two listing variants on genuinely different angles (problem-led vs outcome-led) with a reviewer that fails same-angle A/Bs and flags claims that invite rejection (implied Google endorsement, absolute security, guarantees, superlatives, "free forever"); asset validator for the 5x1280x800 screenshots and 30-120s captioned video, plus the screenshot plan. Published as LISTING_PACK.md. | F30: ST-089, ST-093, ST-094 | G30: S9: 6/7 Done, 1 In progress. Suite 432 tests / 100% all metrics / smoke green. Total 88/100 (357/399 pts) | H30: D13; tracker v005
A31: L-028 | B31: 2026-09-13 10:43 | C31: S10 | D31: ST-080, ST-081 | E31: Support surfaces: 15 launch articles, each documenting shipped behaviour and naming the stories it covers so docs cannot silently drift from code; weighted search (exact keyword > partial > title > summary > body) so "vat" returns invoicing rather than every article containing the word; documentation-coverage report over launch-critical journeys. In-app chat measures first response in BUSINESS hours — a Friday 17:00 message is 2 business hours from a Monday 09:00 reply, not 64 — with a tighter 1-hour SLA for urgent, a breach queue worst-first, and a waiting message that sets expectations instead of going silent. | F31: ST-080, ST-081 | G31: 2 stories code-complete at 100% coverage | H31: Support must actually be STAFFED during the stated hours before the SLA is published | I31: L-029
A32: L-029 | B32: 2026-09-13 10:43 | C32: S10 | D32: ST-083 (PARTIAL), ST-084 | E32: ST-083 sandbox/demo-data mode: a no-account, no-OAuth, platform-read-only session with realistic sample data that exercises real template features including a conditional section, 60-minute TTL, and conversion-to-signup carrying the template across. The 2-minute demo VIDEO half is NOT done — it is a recording of a running app. ST-084 status page: worst-component-wins overall (never rounds up to green), incident templates that state data is unaffected, and an overdue-update check that chases incidents gone quiet past the 30-minute cadence. | F32: ST-083, ST-084 | G32: ST-084 Done; ST-083 In progress (sandbox done, video pending) | H32: Demo video needs a running app (LC-1) | I32: L-030
A33: L-030 | B33: 2026-09-13 10:43 | C33: S10 | D33: ST-095, ST-096, ST-097 | E33: Public pages built FROM the code rather than alongside it: the plan matrix reads prices from the billing module and limits from the enforcer, with a validator that fails if the published page drifts; the trust page is generated from the scope manifest, subprocessor list, and retention policy. ST-097 submission dry-run run for real and published as SUBMISSION_DRY_RUN.md — VERDICT: 10 of 20 items satisfied, 10 blocking (8 Senthil, 2 third-party), NOT READY TO SUBMIT. The dry-run deliberately counts unmet items rather than explaining them away, and records an owner for each so the output is a work list. | F33: ST-095, ST-096, ST-097 | G33: S10: 6 Done + 1 In progress. Suite 484 tests / 100% all metrics / smoke green. Total 94/100 (376/399 pts) | H33: D13; tracker v006
A34: L-031 | B34: 2026-09-13 10:58 | C34: S11 | D34: ST-082, ST-100 | E34: ST-082 review ask: every rule exists to prevent an ill-timed prompt — not before the aha-moment, not before 10 documents, not within 3 days of a failure, not inside a 30-day cooldown, and never again after two dismissals. A prompt at the wrong moment costs a rating rather than earning one. ST-100 partner-review pipeline REFUSES to invite an at-risk account (fix their experience first), refuses to reschedule a decline, excludes declines from the pipeline count, and warns on invitations unanswered for over a week. | F34: ST-082, ST-100 | G34: 2 stories code-complete at 100% coverage | H34: Real partners and a listed app needed to run it | I34: L-032
A35: L-032 | B35: 2026-09-13 10:58 | C35: S11 | D35: ST-098 | E35: Launch runbook built and RUN against the real current state: go/no-go over 13 checks returns NO-GO with 8 blocking failures (not listed, not deployed, rollback unverified against real infra, status/privacy pages unhosted, billing not live, support unstaffed, monitoring sinks unwired). Watchlist items each carry an action rather than just a threshold; the rollback plan budgets 35 minutes with a verification step for each of its 5 steps; the comms tree names an owner and a deadline per audience. Published as LAUNCH_RUNBOOK.md — written now so launch day is execution, not authoring. | F35: ST-098 | G35: 1 story code-complete; runbook verdict NO-GO | H35: All 8 blocking items are Senthil or third-party | I35: L-033
A36: L-033 | B36: 2026-09-13 10:58 | C36: S12 | D36: ST-099 | E36: ST-099 SEO iteration classifies search terms into untargeted, ranking-just-off-page, and high-impressions-low-CTR, ignores anything under 100 impressions rather than chasing noise, sorts by impressions so the biggest lever is first, and recommends EXACTLY ONE change per iteration so the effect is attributable. CODE BACKLOG COMPLETE: 98 of 100 stories Done, 2 In progress (ST-068 needs a third-party pen test, ST-083 needs a running app to record the demo video). Suite 31 files / 516 tests / 100% all metrics / 33 modules / smoke green. Three test-side errors fixed this sprint, none in source. | F36: ST-099; D13 | G36: S11 3/3 and S12 1/1 code-complete. Total 98/100 Done, 2 In progress (391/399 pts) | H36: No further code sprints — remaining work is entirely live/third-party
A37: L-034 | B37: 2026-09-13 11:05 | C37: — | D37: Deployment preparation: src/deployment.ts specifies all 16 environment values with their source (vault / config / platform), validates them (required, https URLs, numeric/boolean kinds, the conditional Stripe key, unknown-variable warnings), and refuses vault-sourced secrets arriving as plain env in production. checkDeploymentReadiness combines that with the S8 posture verifier into one fail-closed gate: a misconfigured instance does not take traffic, which is better than discovering the problem on a customer request. .env.example is generated from the spec so it cannot drift. | E37: LC-1 prep; D13 | F37: 15 new tests; suite 531 at 100% | H37: L-035
A38: L-035 | B38: 2026-09-13 11:05 | C38: — | D38: Three blocker documents written so each external task starts warm: GCP_SETUP_GUIDE.md sequences LC-1 (project, five APIs, consent screen, OAuth client, brand verification, Marketplace SDK) with the prerequisites that must exist first — notably that the privacy policy and status page must be HOSTED before the consent screen will accept the authorised domains, which reorders the work. PENTEST_SCOPING_BRIEF.md scopes the test from the shipped code, names what is out of scope, and lists four design decisions a tester should probe rather than accept. CASA_PREFILL.md answers the assessment from existing evidence and marks three controls NOT YET — encryption-at-rest verification, the restore drill against real backups, and the pen test — rather than answering aspirationally. | E38: LC-1, LC-3, ST-068 prep | F38: Three artefacts published; no story status changed | G38: All three still require Senthil/third-party action | H38: Live execution
A39: L-036 | B39: 2026-09-13 11:10 | C39: — | D39: LC-9 template gallery built: 20 templates across 6 categories (invoice, receipt, quote, payment reminder; offer letter, employment contract, performance review, reference; NDA, service agreement, consent form; certificate, report card, enrolment; purchase order, delivery note, work order; meeting summary, onboarding pack, event invitation). Each uses at least one conditional section — the feature the gallery is there to teach — carries required and optional columns so a user knows what they need before committing, and targets named search terms (61 total) because the gallery is the listing's organic-search surface in the GTM plan. | E39: LC-9; GTM | F39: LC-9 moves to Done | H39: L-037
A40: L-037 | B40: 2026-09-13 11:10 | C40: — | D40: Gallery proved rather than asserted: a structural validator catches duplicate slugs, rules referencing placeholders or sections that do not exist, sections with no rule (which would always render), and sample rows that cannot fill their own body; then every template is rendered through the REAL TemplateDesigner with its sample row and asserted to leave no unresolved markers. TWO DEFECTS caught by doing this: (1) I had written 22 templates against a target of 20 — trimmed to exactly 20; (2) the purchase-order and event-invitation rules tested control fields that never appear in the body, which the real engine rejects — restructured so both conditions are driven by rendered fields. Neither would have been visible from reading the templates. | E40: LC-9; D13 | F40: Suite 567 tests / 100% x4 / 35 modules / smoke green | H40: Live execution
A41: L-038 | B41: 2026-09-13 11:16 | C41: S12 | D41: Growth model frame: restates the workbook assumptions as unit economics rather than a cash projection. Fully-loaded CAC charges free-tier support against each conversion — at 6% conversion roughly 17 installs are served per paying customer, so a high-volume free tier is an acquisition cost even with zero marketing spend. The verdict logic separates four cases that a single LTV:CAC number blurs: workable, healthy-ratio-but-slow-payback (needs funding to bridge, not patience), marginal, and loss-making. Three scenarios rather than one forecast, because a plan that only works in the optimistic column is not a plan. | E41: S12 exit; Financial_Model | F41: S12 exit In progress (frame built, estimates unmeasured) | G41: No cohort exists — every input is an assumption | H41: L-039
A42: L-039 | B42: 2026-09-13 11:16 | C42: S12 | D42: SENSITIVITY FINDING: ranking each input by how much it moves the fully-loaded ratio puts CHURN first, ahead of free-to-paid conversion. Intuition (and my own first test expectation, which the model corrected) reaches for conversion; but lifetime scales LTV directly while conversion mostly moves the free-support cost carried per customer. Halving churn beats doubling conversion. Measurement plan attaches each assumption to instrumentation that already exists (ActivationFunnel, subscription transitions, health scores, install source attribution) so first-cohort data lands without new analysis. One source defect found: display rounding to 2dp turned a 0.45% churn rate into 0, which reads as "no churn" — fixed to keep more places for small magnitudes. | E42: S12; D13 | F42: Suite 589 tests / 100% x4 / 36 modules / smoke green | G42: Replace with measured figures after the first cohort | H42: Live execution
A43: L-040 | B43: 2026-09-13 11:21 | C43: — | D43: ST-068 vendor outreach pack: a send-ready email that lets a vendor quote from the attached scoping brief instead of a discovery call, plus shortlist filters (credentials on the testers not just the firm; reports previously accepted for marketplace/CASA submissions; fixed price from a written brief; retest included) and a quote-comparison rubric. External copy kept company-agnostic per standing instruction. Advice included that a clean first report on a multi-tenant app usually means a shallow test, not a perfect app. | E43: ST-068; R-D10 | F43: Outreach ready to send; ST-068 still In progress | G43: Needs a staging target, or send now stating a target date purely to hold a diary slot | H43: Live execution
A44: L-041 | B44: 2026-09-13 11:24 | C44: — | D44: COLD REVIEW PASS 1. Portfolio memory shows every sibling product that declared code-complete then found real defects in code already at 100% coverage; TeleField logged it as L-T1 (review before declaring complete) and the portfolio lesson is F-V14 (coverage proves execution, not correctness). DocMerge had never been reviewed — so the "code phase complete" declaration two turns ago was premature, and this pass proves it. Nine findings, five CRITICAL. Five fixed with pinned regressions: read-only mode and plan limits were both fully built, fully tested, and CALLED FROM NOWHERE, so two behaviours the help centre promises customers were simply absent from the product; OAuth install accepted any code with no state (CSRF); webhooks verified nothing, so an unauthenticated POST could revoke a live account tokens and schedule its data for deletion; and no production backoff existed anywhere because every retry policy came from a test injecting its own no-op sleep. Four left open and logged rather than quietly fixed: DM-F01 (no HTTP app exists behind any route — the setup guide is unrunnable), DM-F07 (caller-declared identity), DM-F08 (eleven unbounded ledgers), DM-F09 (deletion has no implementation behind it, the class that breached published policy in five sibling products). | E44: L-T1; F-V14; DM-F01..F09 | F44: 35 suites / 616 tests at 100%; new Review_Findings sheet | G44: DM-F01 is the next real work; DM-F07 needs his decision | H44: Cold-review pass 2
A45: L-042 | B45: 2026-09-13 11:31 | C45: — | D45: DM-F01 + DM-F07 closed. The product now HAS an application: a framework-free router (literal and :param segments), 7 routes bound to the services that already existed, a server entrypoint with npm start, and a readiness check that refuses to listen on a misconfigured environment rather than failing on the first customer request. Identity comes from HMAC-signed sessions instead of a caller-supplied role parameter — a token whose role field is edited now fails signature verification, and a session issued for one account is refused against another. Every mutating route is authenticated and passes the entitlement gate, so the read-only mode and plan limits fixed earlier are enforced on the wire; reads deliberately stay open so an unpaid customer can still retrieve their work. Unexpected handler failures map to 500 without leaking internals, rather than hanging the request open (sibling M-F21 class). THEN BOOTED IT: healthz returned 200, the install URL carried its CSRF state, an unsigned webhook got 401, an unauthenticated route got 401, an unknown route got 404 — because the sibling lesson is that compiling is not running. | E45: DM-F01; DM-F07; L-OC4 | F45: 36 suites / 650 tests at 100%; server verified over real HTTP | G45: DM-F08 and DM-F09 still open from pass 1 | H45: Close F08/F09, then pass 2 over the new HTTP layer
A46: L-043 | B46: 2026-09-13 11:37 | C46: — | D46: DM-F08 and DM-F09 closed, then cold-review PASS 2 over the HTTP layer built an hour earlier — because the sibling lesson (L-OC4) is that new surfaces inherit old blind spots, and OnCall found two criticals in its equivalent layer immediately after building it. F08: 11 ledgers bounded, with eviction COUNTED rather than silent; the hash-chained admin audit was the interesting one — bounding it breaks verification from genesis, so the last evicted digest becomes the chain anchor and verifyChain now reports truncation instead of failing, with sequence numbers still counting so gaps are visible rather than disguised. F09: a PurgeRegistry over 16 stores whose registration check FAILS THE BUILD when a store has no purge target, receipts carrying per-store row counts as evidence, and an incomplete purge reported as incomplete rather than claimed done — plus the database schema that never existed behind the backup drill or the policy, with ON DELETE CASCADE on every account-scoped table so completeness is a property of the schema rather than of code someone must remember to update. PASS 2 found four more, all fixed and all verified by booting the server: uncapped request body (413 on a 2MB POST), abandoned OAuth states accumulating because sweep() was never called — the SAME built-but-never-wired class as F02/F03, which is worth noting because I introduced it while fixing that class — no rate limiting anywhere (429 after 20 install calls, a different caller unaffected), and /healthz handing the build version to anyone. | E46: DM-F08..F13; L-OC4 | F46: 40 suites / 691 tests at 100%; all 13 findings closed; server verified live | G46: Cold review complete across both passes | H46: Live execution — Senthil
