Workbook

Sheet Cover
A1: ShiftDesk for Microsoft Teams — Version Detail and Manual Test Specification
A3: Document title | B3: Version Detail and Manual Test Specification
A4: Product | B4: ShiftDesk for Microsoft Teams (shift handovers, approvals, digital checklists, kudos, manager dashboard)
A5: Product code | B5: 002-MoPr09-shiftdesk_teams
A6: Document id | B6: claude_V001_MoPr09-shiftdesk_teams_versiondetail_manualtest_20260920_1715
A7: Document version | B7: V001
A8: Document status | B8: Released for review
A9: Issued | B9: 20 September 2026, 17:15
A10: Prepared by | B10: Claude (Opus 5), for Senthil / KP
A11: Reviewed by | B11: (open — Senthil)
A12: Approved by | B12: (open — Senthil; see Signoff sheet)
A13: Covers releases | B13: v001 (10 Sep 2026) to v040 (20 Sep 2026), plus the pending release v041
A14: Codebase at issue | B14: v0.14.0 — 68 unit suites / 555 tests at 100% statements, branches, functions and lines; 9/9 real-Postgres integration tests; backup/restore drill PASS
... A18: Retention | B18: Keep for the life of the product plus 7 years, as the build evidence behind any store submission or audit question.
A20: READ THIS FIRST
A21: What this document is for | B21: Two questions, answered release by release: what was done and why, and how a human can verify it by hand. The automated suite proves the code executes; these cases are what a person walks through when the automated suite is exactly the thing they do not trust.
A22: The honesty rule it follows | B22: Status vocabulary per tracker decision D-SD2, extended by D-SD8: "Done" means verified, "Code-complete pending live" means the code is finished and the proof needs a real tenant, and "To do — Senthil" means no amount of code closes it. Nothing here is marked Done because it compiles.
A23: Where the numbers come from | B23: Every count on the Test_Summary sheet is a live formula over Test_Cases. Nothing is typed in twice.

Sheet Context
A1: CONTEXT — the product, the programme and the two documents this one sits beside
A2: HOW TO USE THIS SHEET — Read top to bottom once. It explains what ShiftDesk is, who it is for, how the release numbering works, and which document answers which question. If you only need to run tests, go straight to How_To_Use and then Test_Cases.
A4: Topic | B4: Detail
A5: What the product does | B5: ShiftDesk runs inside Microsoft Teams and gives a frontline team five things: shift handover threads that produce a retained, queryable record; approval workflows with thresholds and blocked categories; digital checklists; kudos and recognition; and a manager dashboard over the lot. It installs as a Teams app with tabs and a bot, uses Entra ID single sign-on, and stores tenant data in PostgreSQL.
A6: Who it is for | B6: Ops directors, IT admins and frontline supervisors in regulated frontline sectors — the shifts where an inspector can ask "show me the handover record for the night of the 14th" and somebody has to produce it.
A7: The commercial wedge | B7: Two of the three original pillars overlap Microsoft apps the customer already has free (Approvals, Planner task publishing). The independent review was blunt about this. The product is therefore positioned on the one thing those tools do not produce: auditable handover evidence. That repositioning is release v040, story SD245.
A8: How releases are numbered | B8: Two separate ladders, deliberately. This document uses the TRACKER release ladder v001-v041: one entry per working session, each with its own evidence. The codebase has its own semantic version (v0.1.0 to v0.14.0) and the product workbook has its own (v005 to v046). The Version_Detail sheet maps them.
A9: What a release contains | B9: Almost never only features. The dominant pattern across 41 releases is: build, then audit what was built, then find that something built earlier was never wired in, then fix that and pin it with a test. Twenty-four of the forty released versions are audits, reviews or verification sweeps rather than feature work. That is not inefficiency; it is what the evidence says the code needed.
A10: Current state in one line | B10: The product is code-complete and three-tier test-verified in a sandbox. It has never run in a real Microsoft tenant. Nothing has been sold.
A11: Why that distinction matters | B11: The gate for this product (D7/R2) is not "code complete". It is: listed on the Teams store, and ten paying installs from strangers. Both are open. Every claim in this document is scoped to the evidence behind it so that distinction never blurs.
A12: The three companion documents | B12: Sprint tracker v040 — the execution record: 147 stories, per-sprint boards, RAID, gates. Product workbook v046 — the commercial record: backlog, financial model, risks, launch checklist. Source zip v046 — the code, with REVIEW_PACK.md as the findings register. This document — release-by-release reasoning plus the manual test specification.
A13: Independent review V001 | B13: On 16 September an external reviewer verified the build (it passed) and then rated identity, durability, scale and compliance as Absent in the shipped entry point: three CRITICAL defects meant the production configuration had no working authentication and no durable store. Release v040 actioned all 20 findings. That review is the reason this document exists in this shape.
A14: Defect numbering | B14: F-nnn are defects found by our own review passes and audits (F-001 to F-074). P-nnn are the independent reviewer's findings (P-001 to P-020). VER-SDnn came from vendor-documentation sweeps, GAP-SDnn from artefact-gap audits, OBS-SDnn are accepted observations. D-SDn are decisions.
A15: Who owns what | B15: Claude: code, tests, documents, evidence preparation. Senthil: every decision, every purchase, every live-tenant action, and the go/no-go. Eleven of the forty-seven review stories are Senthil-owned and are listed as such rather than absorbed.

Sheet How_To_Use
A1: HOW TO USE THIS DOCUMENT — what each sheet is for, who uses it, and in what order
A2: HOW TO USE THIS SHEET — This is the index. Work down the "Read in this order" column the first time. Every other sheet repeats its own instructions in row 2, so you never have to come back here.
A4: # | B4: Sheet | C4: What it answers | D4: Who uses it | E4: How to use it | F4: Read in this order
A5: 1 | B5: Cover | C5: What this document is, which versions it covers, who prepared and approved it | D5: Anyone | E5: Check the document version and issue date match what you were sent. Note the companion documents — this one does not repeat their content. | F5: 1
A6: 2 | B6: Context | C6: What the product is, how releases are numbered, what state the product is actually in | D6: New reader, reviewer, auditor | E6: Read once, start to finish. It is the shortest honest briefing on the product in the whole document set. | F6: 2
A7: 3 | B7: How_To_Use | C7: Which sheet answers which question | D7: Anyone | E7: You are here. Use the last column as a reading order. | F7: 3
A8: 4 | B8: Version_Control | C8: The change history of THIS document | D8: Reviewer, auditor | E8: Every reissue adds a row. Never edit a released row — supersede it. | F8: 4
A9: 5 | B9: Version_Detail | C9: For each release: what was done, why it was done, what came out of it, and its status | D9: Senthil, reviewer, auditor | E9: One row per release, oldest first. The "Why it was done" column is the point of the sheet: it is the reason the work happened, not a restatement of the work. | F9: 5
A10: 6 | B10: Pending_Versions | C10: What is NOT done, why, who owns it and what would unblock it | D10: Senthil | E10: Read every row. Each names the single thing that has to exist before the work can start. Nothing here can be closed by writing code. | F10: 6
A11: 7 | B11: Version_Steps | C11: The step-by-step of each release, in the order it happened | D11: Reviewer, auditor | E11: Use it to reconstruct a release, or to see the working method: audits and reviews run to a repeated shape and this sheet shows it. | F11: 7
A12: 8 | B12: Test_Cases | C12: How a human verifies each release by hand, positively and negatively | D12: Tester | E12: Filter by Version to test one release, or by Executable to find what you can run today. Fill Actual result, Status, Tester and Date as you go. Do not edit the Expected result column. | F12: 8
A13: 9 | B13: Test_Execution_Log | C13: Which test run happened when, against what build, with what outcome | D13: Test lead | E13: One row per execution cycle. Copy the case ids that failed into the Failed cases column and raise them in Defect_Log. | F13: 9
A14: 10 | B14: RTM | C14: Which test covers which release, story and finding — and which findings have no test | D14: Auditor, reviewer | E14: The reverse map of Test_Cases. Use it to answer "what proves finding F-029 is fixed?" in one lookup. | F14: 10
A15: 11 | B15: Defect_Log | C15: Every defect found, where it came from and how it was closed | D15: Reviewer, auditor | E15: Read the Origin column: the pattern in this product is that defects came from audits of already-"done" work, not from feature development. | F15: 11
A16: 12 | B16: Test_Summary | C16: Counts and coverage, computed live from Test_Cases | D16: Senthil, test lead | E16: Do not type in this sheet. Every number is a formula. If a count looks wrong, the data on Test_Cases is wrong. | F16: 12
... A19: 15 | B19: Signoff | C19: Who accepted this document and on what basis | D19: Senthil | E19: Sign only the rows you have actually checked. An unsigned row is more useful than a signed one that was not read. | F19: Last

Sheet Version_Control
A1: VERSION CONTROL — change history of this document
A2: HOW TO USE THIS SHEET — Add a row for every reissue: never overwrite a released row. Version ids are V001, V002 ... and the file name carries the same id plus the issue timestamp, so a file on disk can always be matched to a row here.
A4: Document version | B4: Date / time | C4: Author | D4: Change description | E4: Sections affected | F4: Status
A5: V001 | B5: 2026-09-20 17:15 | C5: Claude for Senthil/KP | D5: First issue. Created at Senthil's request on 20 Sep 17:15 alongside the pictorial product explainer. Covers releases v001-v040 with the reason for each, the pending release v041 with the reason it is pending, a step-by-step reconstruction of every release, and 199 manual test cases (positive and negative) mapped to releases, stories and findings. Front matter, glossary, requirements traceability matrix, defect log, execution log, live summary, assumptions and sign-off included to market convention. | E5: All — first issue | F5: Released
A6: V002 | D6: PLANNED: reissue when release v041 closes — the cold review of the S13-S20 code, or the first real dev-tenant sweep, whichever lands first. v041 moves from Pending_Versions to Version_Detail, its four blocked cases become executable, and their results are recorded. | F6: Planned

Sheet Version_Detail
A1: VERSION DETAIL — every released version: what was done, why it was done, what came of it
A2: HOW TO USE THIS SHEET — One row per release, oldest first. Columns E and F are the substance: E is what happened, F is why it happened at all. Column H gives the verification status using the D-SD2 vocabulary explained on the Cover sheet. Use column J to jump to the step-by-step on Version_Steps and the cases on Test_Cases.
A4: Release | B4: Date / time | C4: Session | D4: Category | E4: What was done | F4: Why it was done | G4: Outcome / evidence | H4: Verification status | I4: Codebase | J4: Test cases
A5: v001 | B5: 2026-09-10 23:03 | C5: S1-S2 | D5: BUILD | E5: Foundation through S8 consolidated into one tracker | F5: Senthil instruction 10 Sep 22:26: continue per the v005 sprint plan with a sprint tracker, traceability and 100% automation coverage (D13). The product had eight sprints of code and no execution record. | G5: 75 stories Done, 8 code-complete pending live, 15 Jest suites / 67 tests at 100% | H5: Released — verified in sandbox | I5: v0.6.0 | J5: 5 cases
A6: v002 | B6: 2026-09-10 23:10 | C6: S3 | D6: BUILD | E6: Live-sweep readiness pack: manifest v1.17, icons, typed config loader, 12-step sweep, dev-tenant guide | F6: Nothing could be installed in a real tenant: no manifest package existed, so no story could ever leave "pending live". Sideloading needs no Partner Center, so this unblocked same-day verification. | G6: Gate LC-2 advanced to manifest-ready | H6: Released — verified in sandbox | I6: v0.6.1 | J6: 3 cases
A7: v003 | B7: 2026-09-11 08:20 | C7: S4 | D7: BUILD | E7: Ops parity pack: k6 5x load harness, blue/green deploy workflow, scripted backup/restore drill | F7: Three launch-checklist items (load, deploy, backup) were prose. A checklist item with no executable behind it cannot be evidence. | G7: ST-088/090/092 moved Backlog to Drafted; Gate LC-8 harness-scripted | H7: Released — verified in sandbox | I7: v0.6.2 | J7: 3 cases
A8: v004 | B8: 2026-09-11 12:51 | C8: S5 | D8: REVIEW | E8: Adversarial cold-review pass 1 over the S1-S8 code | F8: 100% coverage had never been tested against an adversary. Coverage proves execution, not correctness, and the product had never been read by anyone looking for defects. | G8: 6 defects fixed with regressions (F-001..F-006); F-007/F-008 raised for disposition; F-009 evidence-discipline finding closed | H8: Released — verified in sandbox | I8: v0.7.0 | J8: 5 cases
A9: v005 | B9: 2026-09-11 20:30 | C9: S6 | D9: REVIEW | E9: Cold-review pass 2 plus the completion wave taking the last backlog stories to sandbox ceiling | F9: Pass 1 found six defects in code that was already "done", so a second pass was warranted before declaring the code phase complete. | G9: F-010..F-013 fixed; backlog zero; 22 suites / 109 tests at 100% | H9: Released — verified in sandbox | I9: v0.11.0 | J9: 4 cases
A10: v006 | B10: 2026-09-13 09:52 | C10: S7 | D10: VERIFY | E10: External verification sweep against live Microsoft documentation, plus artifact-gap audit round 1 | F10: Every Teams-platform behaviour had been written from assumption. A store-blocking mistake is cheapest to find against the vendor documentation, not in a review queue. | G10: VER-SD01/02 store-blocking and VER-SD08 live-blocking raised; LC-5 reopened on an overstated permission model | H10: Released — verified in sandbox | I10: v0.11.1 | J10: 3 cases
A11: v007 | B11: 2026-09-13 10:01 | C11: S8 | D11: GAP | E11: Artifact-gap audit round 2: the web tab layer and the bot command router | F11: The manifest declared three static tabs and advertised bot commands with nothing behind either. A manifest promise with no implementation is a store rejection and a broken install. | G11: GAP-SD1 and GAP-SD2 closed; 26 suites / 145 tests | H11: Released — verified in sandbox | I11: v0.11.2 | J11: 4 cases
A12: v008 | B12: 2026-09-13 10:24 | C12: S9 | D12: REVIEW | E12: Cold-review pass 3 over the sessions 5-8 code that had never been reviewed | F12: New code is the least-reviewed code. Twelve modules had shipped at 100% coverage since the last review pass. | G12: F-014..F-019 fixed; headline F-016: the tab API validated the SSO token then never sent it | H12: Released — verified in sandbox | I12: v0.11.3 | J12: 4 cases
A13: v009 | B13: 2026-09-13 10:37 | C13: S10 | D13: GAP | E13: Artifact-gap audit round 3: the HTTP server and bootstrap | F13: Three of five tab paths and the bot messaging endpoint had no server behind them. The client called a server that did not exist. | G13: GAP-SD5 closed with src/server.ts + src/bootstrap.ts and a client-vs-server parity test | H13: Released — verified in sandbox | I13: v0.11.4 | J13: 4 cases
A14: v010 | B14: 2026-09-13 10:42 | C14: S11 | D14: VERIFY | E14: Verification sweep 2 over the bot transport seam | F14: The bot endpoint built one session earlier was written from assumption: authentication, payload shape and reply mechanism were all guesses, and its own tests passed. | G14: VER-SD09/SD10 live-blockers closed (Connector JWT, ack-then-send); VER-SD11/SD12 closed | H14: Released — verified in sandbox | I14: v0.11.5 | J14: 4 cases
A15: v011 | B15: 2026-09-13 10:57 | C15: S12 | D15: VERIFY | E15: Verification sweep 3 over the tab SSO seam | F15: Same class as the bot seam one session earlier: the tab was sending a hardcoded placeholder token while the manifest declared SSO. | G15: VER-SD13 live-blocker closed with real acquisition and validation; VER-SD14 documented | H15: Released — verified in sandbox | I15: v0.11.6 | J15: 4 cases
... A44: v040 | B44: 2026-09-20 16:40 | C44: S41 | D44: REVIEW | E44: Independent review V001 actioned in full: 47-story S13-S20 remediation programme | F44: An external reviewer rated identity, durability, scale and compliance as Absent while the tracker showed a code-complete product at 100% coverage. Three CRITICAL defects meant the shipped entry point had no working authentication and no durable store. | G44: 36 of 47 stories built; 3 CRITICALs closed; real-Postgres tier and backup drill run for real; 68 suites / 555 tests at 100%; F-071..F-074 recorded | H44: Released — verified in sandbox + real Postgres | I44: v0.14.0 | J44: 35 cases
A46: READING THE CATEGORY COLUMN: BUILD = new capability. REVIEW = adversarial cold review of code already called done. AUDIT = a single named property examined across the whole product (tenancy, deletion, authorization, billing, multi-instance, dependency failure, wiring, deliverability). VERIFY = a sweep against vendor documentation or a live artefact. GAP = a promise made in the manifest or a document with nothing implementing it. Twenty-four of the forty released versions are REVIEW, AUDIT, VERIFY or GAP. The lesson the tracker records (R-S10, R-S14, R-S21) is that in this codebase the defect was almost never a wrong algorithm — it was a correct module that nothing called.

Sheet Pending_Versions
A1: PENDING — what is not done, why it is not done, and the one thing that would unblock it
A2: HOW TO USE THIS SHEET — Every row names a blocker in column D and the single unblocking action in column E. Read column D before asking why something is not finished: in every case it is access, money, a person or a customer, not effort. Nothing on this sheet can be closed by writing code.
A4: Item | B4: Type | C4: What it is | D4: Why it is pending | E4: What unblocks it | F4: Owner | G4: Cost / lead time | H4: Blocks
A5: v041 | B5: Release | C5: The next release of the tracker and this document | D5: It opens on whichever comes first: the cold review of the S13-S20 code written in v040, or the first real sweep report from a dev tenant. Neither has happened. Opening it now would mean writing a release note about work that has not been done. | E5: Either Claude runs the v040 cold review (no external dependency — this can start immediately), or Senthil sideloads the app in a dev tenant and runs the sweep. | F5: Claude / Senthil | G5: Review: one session. Sweep: half a day once a tenant exists. | H5: Nothing — but R-S21 says the v040 code is the least-reviewed code in the product
A6: SD226 | B6: Story — live | C6: Mobile pass on live iOS and Android Teams clients, including the store-required mobile screenshot | D6: Requires the app sideloaded on a physical phone signed into a Microsoft 365 tenant. A sandbox cannot render a Teams mobile client, and the store submission is blocked without the screenshot (VER-SD01). | E6: Senthil sideloads the package on a phone and walks the five flows in ASSET_PLAN.md. | F6: Senthil | G6: ~2 hours once a tenant exists | H6: Store submission (G-01)
A7: SD228 | B7: Story — live | C7: Admin consent and tenant-wide rollout verified in two tenants | D7: Needs two live Microsoft 365 tenants with an administrator willing to grant consent. The consent screen cannot be observed any other way, and it must match the least-privilege document exactly. | E7: Senthil provides two tenants and performs the install-consent-rollout walkthrough. | F7: Senthil | G7: ~half a day | H7: LC-4, LC-5
A8: SD219 / SD220 | B8: Story — infra | C8: The k6 5x load sweep and its latency/conflict evidence, run on staging | D8: There is no staging environment. The harness and the pass bar are scripted and the instrumentation is real, but a performance number that has not been measured is not a number. | E8: Provision staging (App Service + Postgres) and run npm run sweep plus the k6 profile. | F8: Senthil + Claude | G8: Azure staging: hours to provision, then ~1 hour to run | H8: LC-8
A9: SD231 / SD232 | B9: Story — infra | C9: Data rights over HTTP against a real store, and KMS-backed key custody against a real vault | D9: Both halves are built and unit-tested, and production already refuses a plain-environment key. Neither has spoken to a real Azure Key Vault or run against a hosted database, because neither exists yet. | E9: Same staging environment as above, plus a Key Vault and a managed identity. | F9: Senthil + Claude | G9: Hours, alongside staging | H9: Trust page publication (D-07)
A10: SD233 | B10: Story — human | C10: Incident-response tabletop exercise | D10: The runbook is written and bound to the alert rules by test. A tabletop is a rehearsal with people in it; writing a transcript of one nobody attended would be a lie in an audit file. | E10: Senthil schedules 90 minutes with whoever would actually be on call. | F10: Senthil | G10: 90 minutes | H10: M365 certification evidence quality
A11: SD234 | B11: Story — procurement | C11: Third-party penetration test with all High and Critical findings closed and retested | D11: Needs a staging environment to test against and a vendor engagement with a budget. The scope pack and surface inventory are prepared so the engagement starts without a discovery phase. | E11: Senthil engages a vendor once staging exists. | F11: Senthil | G11: Typically £4k-£15k, 2-4 weeks including retest | H11: LC-3, store review confidence
A12: SD235 | B12: Story — procurement | C12: Microsoft 365 Publisher Attestation submitted and accepted | D12: Requires a Partner Center account with publisher verification. Every answer the attestation asks for is drafted in ops/m365-certification-pack.md; none of it can be submitted without the account. | E12: Senthil completes Partner Center enrollment (LC-1) and submits. | F12: Senthil | G12: Enrollment fee plus ~1 week of review | H12: LC-3, LC-1
A13: SD237 | B13: Story — procurement | C13: SOC 2 Type I readiness with an audit firm engaged | D13: The control mapping and the compliance automation are in code. Engaging a firm is a purchase decision with a real budget, and Type II additionally needs an observation window that cannot be shortened. | E13: Senthil engages an audit firm. | F13: Senthil | G13: $15k-$50k audit fee; ~6 months observation for Type II | H13: Enterprise procurement above ~500 seats
A14: SD238 | B14: Story — human | C14: Manual WCAG AA and screen-reader audit on the live tabs | D14: jest-axe passes on all nine screens and cannot hear a screen reader. Keyboard-only and NVDA/VoiceOver passes have to be performed by a person in a live client. Closes R-S6, open since the first session. | E14: Senthil (or a tester) works through ops/accessibility-audit-script.md in a live tenant. | F14: Senthil | G14: ~half a day | H14: LC-7, store accessibility expectations
A15: SD240 | B15: Story — procurement | C15: Transactable AppSource offer live, with the private-offer path tested on a pilot | D15: Partner Center work. The fulfillment integration is built and the plan identifiers are bound to the entitlement table by test, so the offer and the code cannot disagree once it exists — but there is no offer. | E15: Senthil configures the transactable offer in Partner Center. | F15: Senthil | G15: Days of Partner Center review; 3% marketplace fee thereafter | H15: LC-6, LC-11, G-02
... A19: Trust page publication | B19: Content | C19: content/security-trust-page.md going live | D19: Held deliberately per review finding D-07. Its claims were true only of a configuration nobody was running. It now describes what the code does, and it publishes when a deployment actually runs durably with KMS custody — not before. | E19: Publish once staging runs with a real store and vault (SD231/SD232). | F19: Senthil | G19: Minutes, once the conditions hold | H19: Nothing — it is a gate on us, not on anyone else
A21: THE ONE-LINE VERSION: eleven of the forty-seven review stories, and the whole product gate, are waiting on four things that money and access buy — a Microsoft tenant, a staging environment, a Partner Center account and a budget — plus two things only customers can give: fifteen conversations and five signatures.

Sheet Version_Steps
A1: VERSION STEPS — how each release was actually executed, in order
A2: HOW TO USE THIS SHEET — One block per release, in order, oldest first. Steps are numbered within the release. Use this to reconstruct what happened, to repeat the method on a new release, or to audit whether a release did what its note claims. The step shapes repeat by category because the working method is deliberate, not improvised.
A4: Release | B4: Step | C4: Action | D4: Why this step | E4: Output of the step
A5: v001 | B5: 1 | C5: Confirm the instruction and the scope for the session, and record it as an event in the tracker log. | D5: A release with no recorded instruction cannot be audited later, and scope creep inside a session is invisible without it. | E5: A tracker log event (E-nnn) naming the instruction and the scope.
B6: 2 | C6: Read the current state: the backlog rows in scope, the code they claim, and the tests that pin them. | D6: The product's recurring defect is a module that exists and is never called, so the starting question is always what is really wired. | E6: A written list of what exists versus what is claimed.
B7: 3 | C7: Build the capability, smallest honest slice first, with the test written against the behaviour rather than the implementation. | D7: A test coupled to implementation detail passes through a refactor that breaks the product. | E7: New or changed modules under src/ or web/.
B8: 4 | C8: Wire it at the boundary — a real request must drive it, not only a unit test. | D8: Findings F-036, F-039, F-062 and F-063 were all correct modules nothing constructed. Wiring is part of building, not a later step. | E8: Construction in the entry point plus a boundary test that proves a request reaches it.
B9: 5 | C9: Run the full gate: typecheck, unit suite at 100%, and from v040 the integration and seam tiers too. | D9: The gate is the only thing standing between a green feeling and a green build. | E9: A clean gate run, or a defect to fix before the release closes.
B10: 6 | C10: Update the tracker, traceability and companion workbook, then release and deliver the artefacts. | D10: Evidence that is not written down where the reader will look for it is not evidence (finding F-009). | E10: Tracker version row, traceability rows, source zip, workbook.
B11: 7 | C11: RELEASE-SPECIFIC: Foundation through S8 consolidated into one tracker. | D11: Senthil instruction 10 Sep 22:26: continue per the v005 sprint plan with a sprint tracker, traceability and 100% automation coverage (D13). The product had eight sprints of code and no execution record. | E11: 75 stories Done, 8 code-complete pending live, 15 Jest suites / 67 tests at 100%
A12: v002 | B12: 1 | C12: Confirm the instruction and the scope for the session, and record it as an event in the tracker log. | D12: A release with no recorded instruction cannot be audited later, and scope creep inside a session is invisible without it. | E12: A tracker log event (E-nnn) naming the instruction and the scope.
B13: 2 | C13: Read the current state: the backlog rows in scope, the code they claim, and the tests that pin them. | D13: The product's recurring defect is a module that exists and is never called, so the starting question is always what is really wired. | E13: A written list of what exists versus what is claimed.
B14: 3 | C14: Build the capability, smallest honest slice first, with the test written against the behaviour rather than the implementation. | D14: A test coupled to implementation detail passes through a refactor that breaks the product. | E14: New or changed modules under src/ or web/.
B15: 4 | C15: Wire it at the boundary — a real request must drive it, not only a unit test. | D15: Findings F-036, F-039, F-062 and F-063 were all correct modules nothing constructed. Wiring is part of building, not a later step. | E15: Construction in the entry point plus a boundary test that proves a request reaches it.
B16: 5 | C16: Run the full gate: typecheck, unit suite at 100%, and from v040 the integration and seam tiers too. | D16: The gate is the only thing standing between a green feeling and a green build. | E16: A clean gate run, or a defect to fix before the release closes.
B17: 6 | C17: Update the tracker, traceability and companion workbook, then release and deliver the artefacts. | D17: Evidence that is not written down where the reader will look for it is not evidence (finding F-009). | E17: Tracker version row, traceability rows, source zip, workbook.
B18: 7 | C18: RELEASE-SPECIFIC: Live-sweep readiness pack: manifest v1.17, icons, typed config loader, 12-step sweep, dev-tenant guide. | D18: Nothing could be installed in a real tenant: no manifest package existed, so no story could ever leave "pending live". Sideloading needs no Partner Center, so this unblocked same-day verification. | E18: Gate LC-2 advanced to manifest-ready
A19: v003 | B19: 1 | C19: Confirm the instruction and the scope for the session, and record it as an event in the tracker log. | D19: A release with no recorded instruction cannot be audited later, and scope creep inside a session is invisible without it. | E19: A tracker log event (E-nnn) naming the instruction and the scope.
B20: 2 | C20: Read the current state: the backlog rows in scope, the code they claim, and the tests that pin them. | D20: The product's recurring defect is a module that exists and is never called, so the starting question is always what is really wired. | E20: A written list of what exists versus what is claimed.
B21: 3 | C21: Build the capability, smallest honest slice first, with the test written against the behaviour rather than the implementation. | D21: A test coupled to implementation detail passes through a refactor that breaks the product. | E21: New or changed modules under src/ or web/.
B22: 4 | C22: Wire it at the boundary — a real request must drive it, not only a unit test. | D22: Findings F-036, F-039, F-062 and F-063 were all correct modules nothing constructed. Wiring is part of building, not a later step. | E22: Construction in the entry point plus a boundary test that proves a request reaches it.
B23: 5 | C23: Run the full gate: typecheck, unit suite at 100%, and from v040 the integration and seam tiers too. | D23: The gate is the only thing standing between a green feeling and a green build. | E23: A clean gate run, or a defect to fix before the release closes.
B24: 6 | C24: Update the tracker, traceability and companion workbook, then release and deliver the artefacts. | D24: Evidence that is not written down where the reader will look for it is not evidence (finding F-009). | E24: Tracker version row, traceability rows, source zip, workbook.
B25: 7 | C25: RELEASE-SPECIFIC: Ops parity pack: k6 5x load harness, blue/green deploy workflow, scripted backup/restore drill. | D25: Three launch-checklist items (load, deploy, backup) were prose. A checklist item with no executable behind it cannot be evidence. | E25: ST-088/090/092 moved Backlog to Drafted; Gate LC-8 harness-scripted
A26: v004 | B26: 1 | C26: Freeze the scope: name the sessions whose code has never been reviewed, and read nothing else. | D26: A review with unbounded scope becomes a skim. New code is the least-reviewed code (R-S10). | E26: A named module list for the pass.
B27: 2 | C27: Read each module adversarially, asking what input would make it do the wrong thing, not whether it looks correct. | D27: Every defect found this way had a passing test over it already. | E27: A candidate defect list.
B28: 3 | C28: Reproduce each candidate as a failing test before touching the code. | D28: A defect without a failing test is an opinion, and a fix without one regresses silently. | E28: Failing tests, one per confirmed defect.
B29: 4 | C29: Fix, and keep the regression test pinned in a pass-specific suite so its origin stays visible. | D29: The suite name is the audit trail: tests/reviewPass4.test.ts says when and why the assertion exists. | E29: F-nnn entries fixed with named regressions.
B30: 5 | C30: Record anything not fixed as an explicit open finding with a disposition owner, rather than fixing it quietly or dropping it. | D30: F-007 and F-008 stayed open for weeks under their own ids. That is honest; silence would not have been. | E30: Open findings with owners.
B31: 6 | C31: Rerun the full gate and release, with the defect count in the release note. | D31: The count belongs in the note because a release that fixed six defects is not the same artefact as one that fixed none. | E31: Released version with the findings recorded.
B32: 7 | C32: RELEASE-SPECIFIC: Adversarial cold-review pass 1 over the S1-S8 code. | D32: 100% coverage had never been tested against an adversary. Coverage proves execution, not correctness, and the product had never been read by anyone looking for defects. | E32: 6 defects fixed with regressions (F-001..F-006); F-007/F-008 raised for disposition; F-009 evidence-discipline finding closed
A33: v005 | B33: 1 | C33: Freeze the scope: name the sessions whose code has never been reviewed, and read nothing else. | D33: A review with unbounded scope becomes a skim. New code is the least-reviewed code (R-S10). | E33: A named module list for the pass.
B34: 2 | C34: Read each module adversarially, asking what input would make it do the wrong thing, not whether it looks correct. | D34: Every defect found this way had a passing test over it already. | E34: A candidate defect list.
B35: 3 | C35: Reproduce each candidate as a failing test before touching the code. | D35: A defect without a failing test is an opinion, and a fix without one regresses silently. | E35: Failing tests, one per confirmed defect.
B36: 4 | C36: Fix, and keep the regression test pinned in a pass-specific suite so its origin stays visible. | D36: The suite name is the audit trail: tests/reviewPass4.test.ts says when and why the assertion exists. | E36: F-nnn entries fixed with named regressions.
B37: 5 | C37: Record anything not fixed as an explicit open finding with a disposition owner, rather than fixing it quietly or dropping it. | D37: F-007 and F-008 stayed open for weeks under their own ids. That is honest; silence would not have been. | E37: Open findings with owners.
B38: 6 | C38: Rerun the full gate and release, with the defect count in the release note. | D38: The count belongs in the note because a release that fixed six defects is not the same artefact as one that fixed none. | E38: Released version with the findings recorded.
B39: 7 | C39: RELEASE-SPECIFIC: Cold-review pass 2 plus the completion wave taking the last backlog stories to sandbox ceiling. | D39: Pass 1 found six defects in code that was already "done", so a second pass was warranted before declaring the code phase complete. | E39: F-010..F-013 fixed; backlog zero; 22 suites / 109 tests at 100%
A40: v006 | B40: 1 | C40: Choose the seam that was most recently written from assumption rather than from vendor documentation. | D40: The bot transport and the tab SSO seam were each wrong in three ways and their own tests passed (R-S12). | E40: The seam under verification.
B41: 2 | C41: Read the vendor documentation for that seam properly, and write down what it actually requires. | D41: Guessing an authentication or payload contract produces code that is confidently wrong. | E41: A requirement list quoted from the documentation.
...

Sheet Test_Cases
A1: MANUAL TEST CASES — 199 cases across 41 releases, positive and negative
A2: HOW TO USE THIS SHEET — Filter column B to test one release, or column J to find what is executable today. Work the steps in column G in order and compare with column H. Fill columns L-O as you go; leave H alone. A case whose Executable column says "No" cannot be run from a sandbox and the reason is stated — record it as Blocked rather than Pass.
A4: Case id | B4: Release | C4: Covers (story / finding) | D4: Test case name | E4: Type | F4: Priority | G4: Preconditions | H4: Test steps (in order) | I4: Expected result | J4: Automated evidence | K4: Executable now | L4: Status | M4: Actual result | N4: Tester | O4: Date run
A5: TC-001-01 | B5: v001 | C5: ST-051..056 | D5: Install creates a tenant in the welcome state | E5: Positive | F5: High | G5: App not installed for tenant T1 | H5: 1. POST the Teams install webhook for tenant T1. 2. Read the tenant record. 3. Read the telemetry stream. | I5: Tenant T1 exists, state = welcome, install event recorded once with its source attribution. | J5: tests/install.test.ts | K5: Yes — sandbox | L5: Not run
A6: TC-001-02 | B6: v001 | C6: ST-051..056 | D6: A repeated install webhook does not wipe the tenant | E6: Negative | F6: Critical | G6: Tenant T1 installed with 3 handovers | H6: 1. POST the identical install webhook for T1 a second time. 2. List handovers for T1. | I6: The existing account is returned untouched, all 3 handovers remain, and one install_duplicate_ignored telemetry row is written. No data loss (F-002). | J6: tests/install.test.ts | K6: Yes — sandbox | L6: Not run
A7: TC-001-03 | B7: v001 | C7: ST-051..056 | D7: Uninstall schedules deletion 30 days out rather than deleting immediately | E7: Positive | F7: High | G7: Tenant T1 installed | H7: 1. POST the uninstall webhook for T1. 2. Read the deletion schedule. 3. Attempt to read T1 data. | I7: A purge is scheduled 30 days ahead, tokens are wiped, and the data is still restorable inside the window. | J7: tests/install.test.ts | K7: Yes — sandbox | L7: Not run
A8: TC-001-04 | B8: v001 | C8: ST-051..056 | D8: Re-install inside the retention window restores the account | E8: Positive | F8: High | G8: T1 uninstalled 5 days ago | H8: 1. POST the install webhook for T1. 2. List handovers for T1. | I8: The scheduled purge is cancelled and the prior data is visible again. | J8: tests/tenantLifecycle.test.ts | K8: Yes — sandbox | L8: Not run
A9: TC-001-05 | B9: v001 | C9: ST-051..056 | D9: A rotated platform token is refreshed rather than failing the call | E9: Positive | F9: Medium | G9: Token store holds a stale token | H9: 1. Force the gateway to make a call with a stale token. 2. Observe the retry. | I9: The token is refreshed once and the call succeeds; no user-visible error. | J9: tests/platformGateway.test.ts | K9: Yes — sandbox | L9: Not run
A10: TC-002-01 | B10: v002 | C10: ST-093, LC-2 | D10: The app package validates against the store manifest rules | E10: Positive | F10: High | G10: Repo built | H10: 1. Run npm run package with all substitution values supplied. 2. Unzip the produced archive. | I10: manifest.json, both icons and the localisation file sit at the archive root; schema and size rules pass. | J10: tests/packageApp.test.ts | K10: Yes — sandbox | L10: Not run
A11: TC-002-02 | B11: v002 | C11: ST-093, LC-2 | D11: Packaging refuses to produce a package with a placeholder left in | E11: Negative | F11: High | G11: BASE_DOMAIN unset | H11: 1. Run npm run package without BASE_DOMAIN. | I11: The command fails and names the missing value: "missing value for BASE_DOMAIN". No archive is produced. | J11: tests/packageApp.test.ts | K11: Yes — sandbox | L11: Not run
A12: TC-002-03 | B12: v002 | C12: ST-093, LC-2 | D12: Typed config loader rejects a malformed environment | E12: Negative | F12: Medium | G12: None | H12: 1. Set SHIFTDESK_BODY_LIMIT to "abc". 2. Start the process. | I12: Boot fails with CONFIG_INVALID naming the variable, rather than silently using a default. | J12: tests/config.test.ts | K12: Yes — sandbox | L12: Not run
A13: TC-003-01 | B13: v003 | C13: ST-088/090/092, LC-8 | D13: The k6 harness runs the 5x profile and applies its thresholds | E13: Positive | F13: Medium | G13: k6 installed, target URL reachable | H13: 1. Run the k6 sweep against a target. 2. Read the summary. | I13: The run reports api p95, bot p95 and failure rate against the declared thresholds and exits non-zero on breach. | J13: load/k6-load-sweep.js | K13: No — needs staging (SD219) | L13: Blocked
A14: TC-003-02 | B14: v003 | C14: ST-088/090/092, LC-8 | D14: The backup drill fails when the restore target is not empty | E14: Negative | F14: High | G14: Restore database contains rows | H14: 1. Point RESTORE_URL at a non-empty database. 2. Run npm run backup:drill. | I14: The drill refuses rather than restoring over existing data, and the report is not overwritten with a pass. | J14: ops/backup-restore-drill.sh | K14: Yes — sandbox | L14: Not run
A15: TC-003-03 | B15: v003 | C15: ST-088/090/092, LC-8 | D15: The deploy workflow requires an approval before switching traffic | E15: Positive | F15: Medium | G15: Workflow file present | H15: 1. Inspect the deploy workflow job graph. | I15: The traffic switch is gated on an approval environment and runs after migrations. | J15: .github/workflows/deploy.yml | K15: Yes — sandbox | L15: Not run
A16: TC-004-01 | B16: v004 | C16: F-001..F-006 | D16: A recovered payment returns a read-only account to active | E16: Positive | F16: Critical | G16: Tenant in read_only after 3 dunning notices | H16: 1. Call paymentRecovered() for the tenant. 2. Attempt a write. 3. Read the dunning counter. | I16: State returns to active, the write succeeds, and the dunning counter and grace start are reset (F-001). | J16: tests/billing.test.ts | K16: Yes — sandbox | L16: Not run
... A203: TC-041-04 | B203: v041 | C203: SD219/220/226/228/240 | D203: A test customer transacts through the marketplace end to end | E203: Positive | F203: Critical | G203: Transactable offer live | H203: 1. Purchase through the offer. 2. Resolve and activate. 3. Verify entitlement enforcement. | I203: The subscription activates and the entitlement gates writes correctly (SD240, LC-6/LC-11). | J203: tests/commercial.test.ts | K203: No — needs a Partner Center offer | L203: Blocked

Sheet Test_Execution_Log
A1: TEST EXECUTION LOG — one row per execution cycle
A2: HOW TO USE THIS SHEET — Add a row each time someone works through a set of cases. Record the build under test, the environment, which cases were in scope and what happened. The first row is the automated evidence run that backs this issue of the document; manual cycles follow it.
A4: Run id | B4: Date | C4: Executed by | D4: Build / version under test | E4: Environment | F4: Cases in scope | G4: Pass | H4: Fail | I4: Blocked | J4: Outcome / notes
A5: RUN-001 | B5: 2026-09-20 | C5: Claude (automated tiers) | D5: v0.14.0 / release v040 | E5: Sandbox + real PostgreSQL 16 (local, port 55432) | F5: Automated equivalents of the sandbox-executable cases | G5: 555 | H5: 0 | I5: 0 | J5: Tier 1: 68 unit suites / 555 tests green at 100% statements, branches, functions and lines with zero pragmas. Tier 2: 9/9 real-Postgres integration tests. Tier 3: production-seam wiring assertion green. Backup/restore drill PASS with RPO 0s and RTO 0s against a 15 min / 60 min bar. This run is the automated backing for the manual cases marked "Yes — sandbox"; it is not a substitute for walking them.
A6: RUN-002 | C6: (open) | E6: Manual, sandbox | F6: All cases where Executable = Yes | J6: PLANNED — the first human pass over this specification. Expect it to find at least one case where the expected result is written wrongly; that is a finding about this document and belongs in Defect_Log too.
A7: RUN-003 | C7: (open — Senthil) | E7: Live Microsoft 365 dev tenant | F7: The four v041 cases plus every case marked Partial | J7: BLOCKED — needs a dev tenant with the app sideloaded. This is the run that turns eleven pending-live stories into evidence.

Sheet RTM
A1: REQUIREMENTS TRACEABILITY MATRIX — release to coverage, and the cases that prove it
A2: HOW TO USE THIS SHEET — The reverse of Test_Cases: start from a release or a finding and see what proves it. Column E counts the cases with a live formula, so a release that loses its cases shows a zero here rather than quietly disappearing.
A4: Release | B4: Category | C4: What it delivered | D4: Covers (story / finding ids) | E4: Manual cases | F4: Positive | G4: Negative | H4: Automated evidence | I4: Status
A5: v001 | B5: BUILD | C5: Foundation through S8 consolidated into one tracker | D5: ST-051..056 | E5: =COUNTIF(Test_Cases!$B$5:$B$203,"v001") | F5: =COUNTIFS(Test_Cases!$B$5:$B$203,"v001",Test_Cases!$E$5:$E$203,"Positive") | G5: =COUNTIFS(Test_Cases!$B$5:$B$203,"v001",Test_Cases!$E$5:$E$203,"Negative") | H5: Unit suite at 100% | I5: Released — verified in sandbox
A6: v002 | B6: BUILD | C6: Live-sweep readiness pack: manifest v1.17, icons, typed config loader, 12-step sweep, dev-tenant guide | D6: ST-093, LC-2 | E6: =COUNTIF(Test_Cases!$B$5:$B$203,"v002") | F6: =COUNTIFS(Test_Cases!$B$5:$B$203,"v002",Test_Cases!$E$5:$E$203,"Positive") | G6: =COUNTIFS(Test_Cases!$B$5:$B$203,"v002",Test_Cases!$E$5:$E$203,"Negative") | H6: Unit suite at 100% | I6: Released — verified in sandbox
A7: v003 | B7: BUILD | C7: Ops parity pack: k6 5x load harness, blue/green deploy workflow, scripted backup/restore drill | D7: ST-088/090/092, LC-8 | E7: =COUNTIF(Test_Cases!$B$5:$B$203,"v003") | F7: =COUNTIFS(Test_Cases!$B$5:$B$203,"v003",Test_Cases!$E$5:$E$203,"Positive") | G7: =COUNTIFS(Test_Cases!$B$5:$B$203,"v003",Test_Cases!$E$5:$E$203,"Negative") | H7: Unit suite at 100% | I7: Released — verified in sandbox
A8: v004 | B8: REVIEW | C8: Adversarial cold-review pass 1 over the S1-S8 code | D8: F-001..F-006 | E8: =COUNTIF(Test_Cases!$B$5:$B$203,"v004") | F8: =COUNTIFS(Test_Cases!$B$5:$B$203,"v004",Test_Cases!$E$5:$E$203,"Positive") | G8: =COUNTIFS(Test_Cases!$B$5:$B$203,"v004",Test_Cases!$E$5:$E$203,"Negative") | H8: Unit suite at 100% | I8: Released — verified in sandbox
A9: v005 | B9: REVIEW | C9: Cold-review pass 2 plus the completion wave taking the last backlog stories to sandbox ceiling | D9: F-010..F-013 | E9: =COUNTIF(Test_Cases!$B$5:$B$203,"v005") | F9: =COUNTIFS(Test_Cases!$B$5:$B$203,"v005",Test_Cases!$E$5:$E$203,"Positive") | G9: =COUNTIFS(Test_Cases!$B$5:$B$203,"v005",Test_Cases!$E$5:$E$203,"Negative") | H9: Unit suite at 100% | I9: Released — verified in sandbox
A10: v006 | B10: VERIFY | C10: External verification sweep against live Microsoft documentation, plus artifact-gap audit round 1 | D10: VER-SD01..08 | E10: =COUNTIF(Test_Cases!$B$5:$B$203,"v006") | F10: =COUNTIFS(Test_Cases!$B$5:$B$203,"v006",Test_Cases!$E$5:$E$203,"Positive") | G10: =COUNTIFS(Test_Cases!$B$5:$B$203,"v006",Test_Cases!$E$5:$E$203,"Negative") | H10: Unit suite at 100% | I10: Released — verified in sandbox
A11: v007 | B11: GAP | C11: Artifact-gap audit round 2: the web tab layer and the bot command router | D11: GAP-SD1/2/3 | E11: =COUNTIF(Test_Cases!$B$5:$B$203,"v007") | F11: =COUNTIFS(Test_Cases!$B$5:$B$203,"v007",Test_Cases!$E$5:$E$203,"Positive") | G11: =COUNTIFS(Test_Cases!$B$5:$B$203,"v007",Test_Cases!$E$5:$E$203,"Negative") | H11: Unit suite at 100% | I11: Released — verified in sandbox
A12: v008 | B12: REVIEW | C12: Cold-review pass 3 over the sessions 5-8 code that had never been reviewed | D12: F-014..F-019 | E12: =COUNTIF(Test_Cases!$B$5:$B$203,"v008") | F12: =COUNTIFS(Test_Cases!$B$5:$B$203,"v008",Test_Cases!$E$5:$E$203,"Positive") | G12: =COUNTIFS(Test_Cases!$B$5:$B$203,"v008",Test_Cases!$E$5:$E$203,"Negative") | H12: Unit suite at 100% | I12: Released — verified in sandbox
A13: v009 | B13: GAP | C13: Artifact-gap audit round 3: the HTTP server and bootstrap | D13: GAP-SD5 | E13: =COUNTIF(Test_Cases!$B$5:$B$203,"v009") | F13: =COUNTIFS(Test_Cases!$B$5:$B$203,"v009",Test_Cases!$E$5:$E$203,"Positive") | G13: =COUNTIFS(Test_Cases!$B$5:$B$203,"v009",Test_Cases!$E$5:$E$203,"Negative") | H13: Unit suite at 100% | I13: Released — verified in sandbox
A14: v010 | B14: VERIFY | C14: Verification sweep 2 over the bot transport seam | D14: VER-SD09..12 | E14: =COUNTIF(Test_Cases!$B$5:$B$203,"v010") | F14: =COUNTIFS(Test_Cases!$B$5:$B$203,"v010",Test_Cases!$E$5:$E$203,"Positive") | G14: =COUNTIFS(Test_Cases!$B$5:$B$203,"v010",Test_Cases!$E$5:$E$203,"Negative") | H14: Unit suite at 100% | I14: Released — verified in sandbox
A15: v011 | B15: VERIFY | C15: Verification sweep 3 over the tab SSO seam | D15: VER-SD13/14 | E15: =COUNTIF(Test_Cases!$B$5:$B$203,"v011") | F15: =COUNTIFS(Test_Cases!$B$5:$B$203,"v011",Test_Cases!$E$5:$E$203,"Positive") | G15: =COUNTIFS(Test_Cases!$B$5:$B$203,"v011",Test_Cases!$E$5:$E$203,"Negative") | H15: Unit suite at 100% | I15: Released — verified in sandbox
A16: v012 | B16: GAP | C16: Artifact-gap audit round 4: Graph membership consumed, unused scope dropped | D16: GAP-SD6/7, D-SD5 | E16: =COUNTIF(Test_Cases!$B$5:$B$203,"v012") | F16: =COUNTIFS(Test_Cases!$B$5:$B$203,"v012",Test_Cases!$E$5:$E$203,"Positive") | G16: =COUNTIFS(Test_Cases!$B$5:$B$203,"v012",Test_Cases!$E$5:$E$203,"Negative") | H16: Unit suite at 100% | I16: Released — verified in sandbox
A17: v013 | B17: REVIEW | C17: Cold-review pass 4 over the sessions 10-13 integration code | D17: F-020..F-024 | E17: =COUNTIF(Test_Cases!$B$5:$B$203,"v013") | F17: =COUNTIFS(Test_Cases!$B$5:$B$203,"v013",Test_Cases!$E$5:$E$203,"Positive") | G17: =COUNTIFS(Test_Cases!$B$5:$B$203,"v013",Test_Cases!$E$5:$E$203,"Negative") | H17: Unit suite at 100% | I17: Released — verified in sandbox
A18: v014 | B18: GAP | C18: Artifact-gap audit round 5: the repository seam actually built | D18: GAP-SD8 | E18: =COUNTIF(Test_Cases!$B$5:$B$203,"v014") | F18: =COUNTIFS(Test_Cases!$B$5:$B$203,"v014",Test_Cases!$E$5:$E$203,"Positive") | G18: =COUNTIFS(Test_Cases!$B$5:$B$203,"v014",Test_Cases!$E$5:$E$203,"Negative") | H18: Unit suite at 100% | I18: Released — verified in sandbox
A19: v015 | B19: GAP | C19: Persistence slice 1: snapshot/restore on the service core wired through HTTP | D19: GAP-SD8b | E19: =COUNTIF(Test_Cases!$B$5:$B$203,"v015") | F19: =COUNTIFS(Test_Cases!$B$5:$B$203,"v015",Test_Cases!$E$5:$E$203,"Positive") | G19: =COUNTIFS(Test_Cases!$B$5:$B$203,"v015",Test_Cases!$E$5:$E$203,"Negative") | H19: Unit suite at 100% | I19: Released — verified in sandbox
A20: v016 | B20: BUILD | C20: Persistence slice 2: billing, install and support chat survive a restart | D20: OBS-SD5a, F-025 | E20: =COUNTIF(Test_Cases!$B$5:$B$203,"v016") | F20: =COUNTIFS(Test_Cases!$B$5:$B$203,"v016",Test_Cases!$E$5:$E$203,"Positive") | G20: =COUNTIFS(Test_Cases!$B$5:$B$203,"v016",Test_Cases!$E$5:$E$203,"Negative") | H20: Unit suite at 100% | I20: Released — verified in sandbox
A21: v017 | B21: AUDIT | C21: Multi-tenancy audit | D21: F-026..F-028 | E21: =COUNTIF(Test_Cases!$B$5:$B$203,"v017") | F21: =COUNTIFS(Test_Cases!$B$5:$B$203,"v017",Test_Cases!$E$5:$E$203,"Positive") | G21: =COUNTIFS(Test_Cases!$B$5:$B$203,"v017",Test_Cases!$E$5:$E$203,"Negative") | H21: Unit suite at 100% | I21: Released — verified in sandbox
A22: v018 | B22: AUDIT | C22: Data-deletion audit | D22: F-029 | E22: =COUNTIF(Test_Cases!$B$5:$B$203,"v018") | F22: =COUNTIFS(Test_Cases!$B$5:$B$203,"v018",Test_Cases!$E$5:$E$203,"Positive") | G22: =COUNTIFS(Test_Cases!$B$5:$B$203,"v018",Test_Cases!$E$5:$E$203,"Negative") | H22: Unit suite at 100% | I22: Released — verified in sandbox
A23: v019 | B23: AUDIT | C23: Authorization audit | D23: F-030, D-SD6 | E23: =COUNTIF(Test_Cases!$B$5:$B$203,"v019") | F23: =COUNTIFS(Test_Cases!$B$5:$B$203,"v019",Test_Cases!$E$5:$E$203,"Positive") | G23: =COUNTIFS(Test_Cases!$B$5:$B$203,"v019",Test_Cases!$E$5:$E$203,"Negative") | H23: Unit suite at 100% | I23: Released — verified in sandbox
A24: v020 | B24: AUDIT | C24: Billing-integrity audit | D24: F-031..F-033 | E24: =COUNTIF(Test_Cases!$B$5:$B$203,"v020") | F24: =COUNTIFS(Test_Cases!$B$5:$B$203,"v020",Test_Cases!$E$5:$E$203,"Positive") | G24: =COUNTIFS(Test_Cases!$B$5:$B$203,"v020",Test_Cases!$E$5:$E$203,"Negative") | H24: Unit suite at 100% | I24: Released — verified in sandbox
A25: v021 | B25: AUDIT | C25: Notification delivery and latency instrumentation | D25: F-034/F-035 | E25: =COUNTIF(Test_Cases!$B$5:$B$203,"v021") | F25: =COUNTIFS(Test_Cases!$B$5:$B$203,"v021",Test_Cases!$E$5:$E$203,"Positive") | G25: =COUNTIFS(Test_Cases!$B$5:$B$203,"v021",Test_Cases!$E$5:$E$203,"Negative") | H25: Unit suite at 100% | I25: Released — verified in sandbox
A26: v022 | B26: AUDIT | C26: Telemetry and audit wiring | D26: F-036/F-037 | E26: =COUNTIF(Test_Cases!$B$5:$B$203,"v022") | F26: =COUNTIFS(Test_Cases!$B$5:$B$203,"v022",Test_Cases!$E$5:$E$203,"Positive") | G26: =COUNTIFS(Test_Cases!$B$5:$B$203,"v022",Test_Cases!$E$5:$E$203,"Negative") | H26: Unit suite at 100% | I26: Released — verified in sandbox
A27: v023 | B27: AUDIT | C27: Systematic wiring audit of all 112 exports | D27: F-038..F-040 | E27: =COUNTIF(Test_Cases!$B$5:$B$203,"v023") | F27: =COUNTIFS(Test_Cases!$B$5:$B$203,"v023",Test_Cases!$E$5:$E$203,"Positive") | G27: =COUNTIFS(Test_Cases!$B$5:$B$203,"v023",Test_Cases!$E$5:$E$203,"Negative") | H27: Unit suite at 100% | I27: Released — verified in sandbox
A28: v024 | B28: BUILD | C28: Encryption at rest resolved both ways, trust page rewritten | D28: F-040, OBS-SD8 | E28: =COUNTIF(Test_Cases!$B$5:$B$203,"v024") | F28: =COUNTIFS(Test_Cases!$B$5:$B$203,"v024",Test_Cases!$E$5:$E$203,"Positive") | G28: =COUNTIFS(Test_Cases!$B$5:$B$203,"v024",Test_Cases!$E$5:$E$203,"Negative") | H28: Unit suite at 100% | I28: Released — verified in sandbox
A29: v025 | B29: REVIEW | C29: Cold-review pass 5 over the sessions 18-25 modules | D29: F-041..F-045 | E29: =COUNTIF(Test_Cases!$B$5:$B$203,"v025") | F29: =COUNTIFS(Test_Cases!$B$5:$B$203,"v025",Test_Cases!$E$5:$E$203,"Positive") | G29: =COUNTIFS(Test_Cases!$B$5:$B$203,"v025",Test_Cases!$E$5:$E$203,"Negative") | H29: Unit suite at 100% | I29: Released — verified in sandbox
A30: v026 | B30: AUDIT | C30: Multi-instance audit | D30: F-046 | E30: =COUNTIF(Test_Cases!$B$5:$B$203,"v026") | F30: =COUNTIFS(Test_Cases!$B$5:$B$203,"v026",Test_Cases!$E$5:$E$203,"Positive") | G30: =COUNTIFS(Test_Cases!$B$5:$B$203,"v026",Test_Cases!$E$5:$E$203,"Negative") | H30: Unit suite at 100% | I30: Released — verified in sandbox
A31: v027 | B31: AUDIT | C31: Dependency-failure audit | D31: F-047/F-048 | E31: =COUNTIF(Test_Cases!$B$5:$B$203,"v027") | F31: =COUNTIFS(Test_Cases!$B$5:$B$203,"v027",Test_Cases!$E$5:$E$203,"Positive") | G31: =COUNTIFS(Test_Cases!$B$5:$B$203,"v027",Test_Cases!$E$5:$E$203,"Negative") | H31: Unit suite at 100% | I31: Released — verified in sandbox
A32: v028 | B32: REVIEW | C32: Cold-review pass 6 over sessions 26-28 | D32: F-049..F-051 | E32: =COUNTIF(Test_Cases!$B$5:$B$203,"v028") | F32: =COUNTIFS(Test_Cases!$B$5:$B$203,"v028",Test_Cases!$E$5:$E$203,"Positive") | G32: =COUNTIFS(Test_Cases!$B$5:$B$203,"v028",Test_Cases!$E$5:$E$203,"Negative") | H32: Unit suite at 100% | I32: Released — verified in sandbox
A33: v029 | B33: BUILD | C33: Live-day preparation: the automated half of the sweep made executable | D33: ST-096 | E33: =COUNTIF(Test_Cases!$B$5:$B$203,"v029") | F33: =COUNTIFS(Test_Cases!$B$5:$B$203,"v029",Test_Cases!$E$5:$E$203,"Positive") | G33: =COUNTIFS(Test_Cases!$B$5:$B$203,"v029",Test_Cases!$E$5:$E$203,"Negative") | H33: Unit suite at 100% | I33: Released — verified in sandbox
A34: v030 | B34: BUILD | C34: Six more sweep steps automated behind capability gates | D34: F-052 | E34: =COUNTIF(Test_Cases!$B$5:$B$203,"v030") | F34: =COUNTIFS(Test_Cases!$B$5:$B$203,"v030",Test_Cases!$E$5:$E$203,"Positive") | G34: =COUNTIFS(Test_Cases!$B$5:$B$203,"v030",Test_Cases!$E$5:$E$203,"Negative") | H34: Unit suite at 100% | I34: Released — verified in sandbox
A35: v031 | B35: BUILD | C35: Packaging automated with manifest validation | D35: GAP-SD3 | E35: =COUNTIF(Test_Cases!$B$5:$B$203,"v031") | F35: =COUNTIFS(Test_Cases!$B$5:$B$203,"v031",Test_Cases!$E$5:$E$203,"Positive") | G35: =COUNTIFS(Test_Cases!$B$5:$B$203,"v031",Test_Cases!$E$5:$E$203,"Negative") | H35: Unit suite at 100% | I35: Released — verified in sandbox
A36: v032 | B36: AUDIT | C36: Deliverability audit from a clean install | D36: F-053/054/056 | E36: =COUNTIF(Test_Cases!$B$5:$B$203,"v032") | F36: =COUNTIFS(Test_Cases!$B$5:$B$203,"v032",Test_Cases!$E$5:$E$203,"Positive") | G36: =COUNTIFS(Test_Cases!$B$5:$B$203,"v032",Test_Cases!$E$5:$E$203,"Negative") | H36: Unit suite at 100% | I36: Released — verified in sandbox
A37: v033 | B37: AUDIT | C37: Clean-checkout rehearsal of the full delivery | D37: F-057 | E37: =COUNTIF(Test_Cases!$B$5:$B$203,"v033") | F37: =COUNTIFS(Test_Cases!$B$5:$B$203,"v033",Test_Cases!$E$5:$E$203,"Positive") | G37: =COUNTIFS(Test_Cases!$B$5:$B$203,"v033",Test_Cases!$E$5:$E$203,"Negative") | H37: Unit suite at 100% | I37: Released — verified in sandbox
A38: v034 | B38: AUDIT | C38: The tab URLs actually served | D38: F-058 | E38: =COUNTIF(Test_Cases!$B$5:$B$203,"v034") | F38: =COUNTIFS(Test_Cases!$B$5:$B$203,"v034",Test_Cases!$E$5:$E$203,"Positive") | G38: =COUNTIFS(Test_Cases!$B$5:$B$203,"v034",Test_Cases!$E$5:$E$203,"Negative") | H38: Unit suite at 100% | I38: Released — verified in sandbox
A39: v035 | B39: AUDIT | C39: The bot endpoint actually wired | D39: F-059 | E39: =COUNTIF(Test_Cases!$B$5:$B$203,"v035") | F39: =COUNTIFS(Test_Cases!$B$5:$B$203,"v035",Test_Cases!$E$5:$E$203,"Positive") | G39: =COUNTIFS(Test_Cases!$B$5:$B$203,"v035",Test_Cases!$E$5:$E$203,"Negative") | H39: Unit suite at 100% | I39: Released — verified in sandbox
A40: v036 | B40: AUDIT | C40: Lifecycle hooks and the retention scheduler wired | D40: F-060/F-061 | E40: =COUNTIF(Test_Cases!$B$5:$B$203,"v036") | F40: =COUNTIFS(Test_Cases!$B$5:$B$203,"v036",Test_Cases!$E$5:$E$203,"Positive") | G40: =COUNTIFS(Test_Cases!$B$5:$B$203,"v036",Test_Cases!$E$5:$E$203,"Negative") | H40: Unit suite at 100% | I40: Released — verified in sandbox
A41: v037 | B41: AUDIT | C41: Runtime wiring audit of the shipped entry point | D41: F-062..F-064 | E41: =COUNTIF(Test_Cases!$B$5:$B$203,"v037") | F41: =COUNTIFS(Test_Cases!$B$5:$B$203,"v037",Test_Cases!$E$5:$E$203,"Positive") | G41: =COUNTIFS(Test_Cases!$B$5:$B$203,"v037",Test_Cases!$E$5:$E$203,"Negative") | H41: Unit suite at 100% | I41: Released — verified in sandbox
...

Sheet Defect_Log
A1: DEFECT LOG — every defect of consequence, where it came from and how it closed
A2: HOW TO USE THIS SHEET — Read the Origin column first. The pattern matters more than any single row: in this product the defect was almost never a wrong algorithm, it was a correct module that nothing called, and it was found by an audit of work already called done. Severity is as assessed at the time.
A4: Defect id | B4: Release found | C4: Severity | D4: Origin | E4: What was wrong | F4: Why the tests did not catch it | G4: How it was closed | H4: Status
A5: F-002 | B5: v004 | C5: High | D5: Cold review pass 1 | E5: A duplicate Teams install webhook overwrote the existing tenant — full data loss on a repeated platform event. | F5: Nobody had written a test for the second install. Coverage was 100% of the paths that existed, and that path existed only in production. | G5: install() made idempotent; the duplicate is returned untouched and counted. | H5: Closed
