Workbook

Sheet 01_Cover
A1: QUOTEFLOW — MANUAL TEST PACK
A2: The human-executable counterpart to the automated suite. Every case below can be run by a person with a terminal and a browser, against a build of the delivered zip — including the cases that cannot be run yet, which say so and name what is missing.
A4: Document | B4: QuoteFlow manual test pack
A5: Document ID | B5: claude_V001_MoPr04-quoteflow_hubspot_manualtest_20260920_1813
A6: Product | B6: QuoteFlow — CPQ for the HubSpot App Marketplace (portfolio ref 003-MoPr04)
A7: Version | B7: V001
A8: Date / time | B8: 2026-09-20 18:13
A9: Author | B9: Claude for Senthil/KP
A10: Status | B10: Released
A11: Code baseline under test | B11: quoteflow_extreview2_codebase_20260920_1020.zip · tree 43de1cac3aa5a9aa · 70 source files · 17 migrations
A12: Automated suite at this baseline | B12: 793 tests across 45 suites, 100% statements/branches/functions/lines (a REGRESSION FLOOR, not a quality claim)
A13: Scope of this pack | B13: 26 versions (17 completed, 9 pending) · 72 test cases · 331 numbered steps
A14: Test types | B14: 33 positive, 39 negative
A15: Companion documents | B15: claude_V001 architecture & completion status (PDF + SVG/PNG figures) · claude_v028 sprint tracker · claude_v036 product workbook
A16: Classification | B16: Internal. Records what is NOT built and why; not for external distribution.
A19: Why a manual pack exists beside a 100% automated suite
A20: Because they answer different questions. The automated suite asks "did the behaviour change since last release?" — that is a regression floor, and it is why the coverage gate exists. This pack asks "does the behaviour do what a person expects, including when that person is hostile?" Three cold reviews and two external reviews found twenty-five defects in code that was already at 100% coverage, which is the empirical case for the distinction.
A21: It also does something the suite cannot: it writes down the tests that CANNOT be run yet. Cases TC-056 to TC-060 are fully specified and blocked on an account, an environment or a purchase. They are in the pack so that the day a HubSpot developer account exists, the test is already written and nobody has to remember what LIVE evidence was supposed to mean.
A22: How to use this workbook in one line
A23: Read 03_How_To_Use, set up from 11_Environments, work down 07_Test_Cases picking up the steps from 08_Test_Steps, record results in the Actual/Status columns, raise anything that fails in 10_Defect_Log, and check 09_Traceability to confirm nothing was skipped.

Sheet 02_Version_Control
A1: VERSION CONTROL — manual test pack
A2: One row per issued version of THIS DOCUMENT. Rows are never edited after release; a PLANNED row is recorded before work starts so an abandoned attempt still leaves a trace. (The versions of the PRODUCT are a different thing and live on sheet 05.)
A3: Version | B3: Date / time | C3: Author | D3: Change description | E3: Baseline tested | F3: Status
A4: V001 | B4: 2026-09-20 18:13 | C4: Claude for Senthil/KP | D4: First issue. Covers the full product lineage from S1 through external review V002: 26 versions (17 completed, 9 pending), 72 test cases (33 positive, 39 negative) and 331 numbered steps. Includes the five blocked cases (TC-056..TC-060) written in full so they can be run the day their blocker clears. | E4: tree 43de1cac3aa5 | F4: Released
A5: V002 | B5: — (planned) | C5: — | D5: Will be issued when the first blocked case becomes runnable — most likely TC-056 once a HubSpot developer account exists (R-Q15). That run would produce the first LIVE evidence in the product’s history. | E5: — | F5: Planned
A7: Document control rules
A8: 1. A released row is never edited. Corrections are issued as a new version with a note saying what was wrong.
A9: 2. The baseline column must name the exact tree hash the pack was written against. A pack executed against a different build is evidence about that build, not this one.
A10: 3. A test case may be added or amended only with a version bump. Changing an expected result silently is how a test pack stops being evidence.
A11: 4. Results are NOT recorded in this file. Take a dated copy per execution cycle (see 12_Entry_Exit_Criteria) so the master stays clean.

Sheet 03_How_To_Use
A1: HOW TO USE THIS WORKBOOK
A2: Every sheet, what it is for, who uses it, and when. Read this once before the first execution cycle.
A3: Sheet | B3: What it contains | C3: Who uses it | D3: When | E3: How to use it
A4: 01_Cover | B4: Identity of this pack, the baseline it was written against, and its size. | C4: Everyone | D4: First | E4: Check the baseline hash matches the build you are about to test. If it does not, stop — your results will describe a different product.
A5: 02_Version_Control | B5: Lineage of this document and the rules that govern changing it. | C5: Test lead | D5: First, then on every amendment | E5: Add a row; never edit one. Bump the version before changing any expected result.
A6: 03_How_To_Use | B6: This sheet. | C6: Everyone | D6: First | E6: Read once. It is the map.
A7: 04_Context | B7: What the product is, what shape it is in, and the evidence-class vocabulary used throughout. | C7: New tester, reviewer, auditor | D7: Before writing or judging a result | E7: Read before deciding whether a case "passed". PASS means the expected result occurred — it does not mean the feature is production-ready; the evidence class says that.
A8: 05_Version_Status | B8: Every delivered version of the PRODUCT: what it contained and why it was built. | C8: Test lead, product owner, auditor | D8: Planning a cycle | E8: Use it to scope a regression run: pick the versions touched by a change and run their cases.
A9: 06_Pending_Versions | B9: Every version NOT delivered, with the reason and the owner. | C9: Product owner, Senthil | D9: Planning, and every status conversation | E9: This is the decision list. Nothing on it is unblocked by writing more code.
A10: 07_Test_Cases | B10: One row per test case: name, description, type, priority, precondition, expected outcome, evidence class, automated counterpart. | C10: Tester | D10: Every cycle | E10: Work top to bottom or filter by Version / Module / Priority. Record Actual result and Status here.
A11: 08_Test_Steps | B11: One row per numbered step, linked to its case by Test ID. | C11: Tester | D11: Every cycle | E11: Execute the Action column exactly; compare against Expected. Record per-step Pass/Fail so a failure is pinned to a step, not a whole case.
A12: 09_Traceability | B12: Test case → product version → finding/story → evidence class. | C12: Test lead, auditor | D12: End of cycle | E12: Confirm coverage: every completed version should have at least one positive and one negative case.
A13: 10_Defect_Log | B13: Defects raised from this pack. | C13: Tester, developer | D13: On any failure | E13: Raise one row per defect, referencing the Test ID and the failing Step No. Do not edit the test case to make it pass.
A14: 11_Environments | B14: Environments, required accounts, configuration and how to mint a session for testing. | C14: Tester | D14: Setup, every cycle | E14: Follow it before the first case. TC-010 exists to prove the session mint works; everything after it depends on that.
... A18: 15_Glossary | B18: Every term, code and abbreviation used in this pack. | C18: Anyone | D18: As needed | E18: If a column says PXR-004 or CL-11 and you do not know what that means, it is here.

Sheet 04_Context
A1: CONTEXT — what you are testing, and how to judge a result
A2: Read this before your first cycle. It defines the vocabulary the rest of the pack uses.
A4: What QuoteFlow is
A5: A CPQ (Configure–Price–Quote) product for the HubSpot App Marketplace. A sales rep works on a HubSpot deal record; QuoteFlow adds a card to that record where they configure a product from a rule-driven model, price it through a deep pricing engine, route it through a deal desk for approval, send it for signature, and push the result back onto the deal as line items.
A6: The reason it can exist beside HubSpot’s own native quoting is depth: compatibility rules with an explanation for every decision, a pricing engine with nested bundles, multi-entity price books, pinned FX, ramps, usage tiers and margin floors, and an approval DAG rather than a chain. Everything shallow is already free inside the CRM the customer pays for.
A7: What state it is in — read this before judging any result
A8: The codebase is complete and heavily tested: 793 automated tests across 45 suites at a 100% coverage floor. It has never run inside HubSpot. There is no developer account, no listing, no customer and no deployed environment. That is not a defect to be raised — it is the stated position of the product, and sheet 06 lists every consequence of it.
A9: So "PASS" on a case here means the expected result occurred on the build you ran. It does not mean the feature is proven in production. The Evidence Class column on each case says how strong the claim actually is, and that vocabulary is the next section.
A10: Evidence classes — the vocabulary
A11: CODE — the code does what the code says, against our own doubles. The cheapest class, and the only one a coverage gate speaks to.
A12: CONTRACT — a third party’s API shape is honoured and its real error shapes handled. Recorded real fixtures count; invented ones do not.
A13: LIVE — exercised end to end against the real system, in an account that exists, watched by a human. Currently EMPTY for this product.
... A25: Never edit an expected result to make a case pass. If an expected result is wrong, that is a document defect: raise it, and fix it in a version bump on sheet 02.

Sheet 05_Version_Status
A1: VERSION STATUS — what was delivered, and why
A2: Every delivered version of the product, in order. "Why it was done" is the part that matters in a review: a change with no reason behind it is a change nobody can defend. Test cases on sheet 07 reference these IDs.
A3: Version ID | B3: Release | C3: Date | D3: Artefact | E3: What was delivered | F3: Why it was done | G3: Status | H3: Evidence reached | I3: Refs
A4: VER-01 | B4: S1 — Foundation | C4: 2026-09-10 | D4: workbook v007 / tracker v001 | E4: OAuth install with attribution in a signed state, uninstall webhook with retention-scheduled deletion, token refresh that survives rotation, install-source telemetry. | F4: A marketplace app that cannot install, refresh or uninstall cleanly fails review before a single feature is looked at. This is the floor everything else stands on. | G4: COMPLETED | H4: CODE | I4: ST-051/052/055/056
A5: VER-02 | B5: S2 — Price book part 1 | C5: 2026-09-10 | D5: workbook v008 / tracker v001 | E5: One-call sensible defaults, catalogue to priced quote, customisable pricing rules with best-discount-wins, typed retryable platform errors, re-install restore, owner/admin/member RBAC on every route. | F5: The core loop had to be demonstrable end to end before depth was worth adding. RBAC went in at the same time because retrofitting authorisation is how authorisation gets holes. | G5: COMPLETED | H5: CODE | I5: ST-001..004, ST-053/054
A6: VER-03 | B6: S3 — Price book part 2 + card | C6: 2026-09-11 | D6: workbook v009 / tracker v001 | E6: Bundles, metrics, audit trail, pause/resume without data loss, CSV import, notifications, and the first deal-card surface. | F6: A rep never leaves the deal record, so the product had to appear there. (The card built here was a legacy CRM card, and was deleted in VER-13 — see that row.) | G6: COMPLETED | H6: CODE | I6: ST-005..010
A7: VER-04 | B7: S4 — Approval chains | C7: 2026-09-11 | D7: workbook v010 / tracker v002 | E7: Approval chains with snapshotting, reminders, decisions, metrics, and the approvals shell. | F7: Discounting without approval is the single most common reason a CPQ purchase is refused by finance. | G7: COMPLETED | H7: CODE | I7: ST-011..015
A8: VER-05 | B8: S5 — E-signature + alpha hardening | C8: 2026-09-11 | D8: workbook v011 / tracker v003 | E8: Envelopes, signer tokens, signing and declining, reminders, import, and the signer shell. | F8: A quote that cannot be accepted is a document, not a quote. | G8: COMPLETED | H8: CODE | I8: ST-021..025
A9: VER-06 | B9: S6–S8 — Analytics, billing, deal sync, trust | C9: 2026-09-11 to 09-12 | D9: workbooks v012–v016 | E9: Quote analytics with import, trial and subscription billing with dunning and invoices, deal sync with idempotency and stage skipping, the trust posture and data-flow map, ops surfaces and the public status page. | F9: These are the sheets a buyer opens after the demo: what does it cost, what does it touch, and what happens when it breaks. | G9: COMPLETED | H9: CODE | I9: ST-031..070
A10: VER-07 | B10: S9–S12 — Marketplace, launch, iterate | C10: 2026-09-12 to 09-13 | D10: workbooks v017–v018 | E10: Listing copy and assets, launch runbook and preflight, partner and review-ask flows, SEO iteration, and the programme close-out. | F10: The listing is the product for everyone who has not installed it yet. | G10: COMPLETED | H10: CODE | I10: ST-081..100
A11: VER-08 | B11: RP1 — First cold review | C11: 2026-09-13 11:51 | D11: workbook v019 / tracker v011 | E11: Eight defects found in code already at 100% coverage, four critical: delete-my-data left records behind, no runnable entrypoint existed, identity was unsigned caller-declared headers, an expired trial granted perpetual free use. | F11: A coverage number proves the tests execute the lines; it proves nothing about whether the lines are right. This pass existed to find out how much difference that makes. The answer was eight defects. | G11: COMPLETED | H11: CODE | I11: F-Q01..F-Q08
A12: VER-09 | B12: RP2 + RP3 — Second and third cold reviews | C12: 2026-09-13 12:03–16:53 | D12: workbooks v020–v024 | E12: Nine further defects: retention policy never enforced, a redaction control with zero call sites, a breaker on writes only, no deploy workflow, no database schema, replayable future-dated signatures; then status page and launch preflight wired to constants, and nine vendor-only surfaces reachable with tenant RBAC. | F12: Pass 1 found defects inside features. Passes 2 and 3 looked for the opposite failure: published claims with no code behind them. Both classes existed. | G12: COMPLETED | H12: CODE | I12: F-Q09..F-Q17
A13: VER-10 | B13: Postgres persistence | C13: 2026-09-13 13:00–17:30 | D13: workbooks v020–v026 | E13: Five migrations, Postgres adapters for every store, a store-contract suite run against both in-memory and real SQL, and boot wiring behind DATABASE_URL. | F13: Everything above this line was, until now, lost on restart. A product whose data does not survive a deploy is a demo. | G13: COMPLETED | H13: CODE | I13: R-Q4, R-Q14
A14: VER-11 | B14: Async store cascade (R-Q13) | C14: 2026-09-13 18:48 to 09-20 11:05 | D14: workbooks v027–v034; completed in v036 | E14: Every store made async and cache-free; four latent defects fixed on the way (feature settings, envelope mutations, notification mutes, billing fields all published but never persisted); the writer lease retired. | F14: The write-through caches meant two instances silently diverged. Retiring the lease is what makes a second instance — and therefore a zero-downtime deploy — possible at all. | G14: COMPLETED | H14: CODE | I14: R-Q13, PXR-005
... A20: VER-17 | B20: EXT-V002 part E — Billing, operations, quality system (PS29–PS31) | C20: 2026-09-20 16:35 | D20: code zip 20260920_1020 | E20: Form-encoded authenticated provider charges; inbound webhooks verified, deduplicated and ordered by event time; plan-based entitlements; proration on real calendar months; migration rollback; chaos degradation; residency and subprocessor posture; and the evidence-class quality system with a claims register enforced by CI. | F20: A billing system that only ever talks and never listens keeps a cancelled card on an active plan. And the deepest finding of both reviews was not a defect: it was 100% coverage being presented as proof of readiness. PS31 makes that structurally impossible. | G20: COMPLETED | H20: CODE + OPS | I20: PXR-011, PXR-012, PXR-015, DQ48..DQ50
A22: 17 completed versions. Every one is covered by at least one case on sheet 07 — see 09_Traceability.

Sheet 06_Pending_Versions
A1: PENDING VERSIONS — what is not delivered, and exactly why
A2: The decision list. Read the "Why it is pending" column carefully: in every case the blocker is an account, an environment, a purchase or a customer — not an unwritten module. No amount of further engineering closes any of these.
A3: Version ID | B3: Release | C3: Planned scope | D3: Why it matters | E3: Status | F3: Evidence class blocked | G3: WHY IT IS PENDING | H3: Owner / what unblocks it | I3: Refs
A4: VER-18 | B4: PENDING — Live install inside HubSpot (PS14/PS15 LIVE) | C4: Upload the Projects app to a real developer account, install it into a test portal, render the app card on a real deal, and mint a session from the real extension context. | D4: This is the only way the LIVE evidence class can ever be reached, and it gates every other live claim. | E4: PENDING | F4: LIVE (absent) | G4: A HubSpot developer account does not exist. Nothing in the app surface has been uploaded, installed, rendered or accepted. Every green box in the engines band is a statement about our own tests until this happens. | H4: Senthil — create a HubSpot developer account and supply client id/secret | I4: R-Q15, CL-01
A5: VER-19 | B5: PENDING — Billing against a real provider (PS29 CONTRACT) | C5: Run subscribe → upgrade → fail → recover → cancel in Stripe test mode, and replay real provider webhooks including out-of-order delivery. | D5: CODE evidence cannot catch a field name the provider rejects, and a billing defect is a revenue defect. | E5: PENDING | F5: CONTRACT (absent) | G5: No Stripe test-mode keys and no HubSpot marketplace monetisation access. No payload has ever been accepted by a provider; no webhook has ever arrived. | H5: Senthil — Stripe test keys; apply for marketplace monetisation | I5: R-Q10, CL-09
A6: VER-20 | B6: PENDING — p95 under load (PS30-01) | C6: Run scripts/loadtest.js against two instances behind a load balancer at a stated concurrency and record p50/p95/p99. | D6: A performance target that has not been measured is not a target. | E6: PENDING | F6: PERF (absent) | G6: There is no deployed environment. The harness is written and has never been run; running it against localhost would prove localhost is fast, which is not the claim. | H6: Senthil — a hosting target with two instances behind a load balancer | I6: R-Q17, CL-10
A7: VER-21 | B7: PENDING — Measured RPO and RTO (PS30-03) | C7: Run scripts/restore-drill.sh: seed a marker, back up, write more, restore, prove the restored database serves tenant-scoped reads, and print both figures. | D7: "We have backups" is a hope with a cron job attached. RPO and RTO are numbers or they are nothing. | E7: PENDING | F7: OPS (absent) | G7: No managed Postgres with point-in-time recovery exists to run the drill against. | H7: Senthil — managed Postgres with PITR | I7: R-Q18, CL-11
A8: VER-22 | B8: PENDING — Zero-dropped-request deploy (PS30-02) | C8: Perform a blue/green deploy under continuous traffic and record zero dropped requests. | D8: The workflow was fiction while the writer lease existed. The lease is gone; the proof is still missing. | E8: PENDING | F8: OPS (absent) | G8: The blocker was removed and the workflow is executable, but no deploy has ever been run because there is nowhere to deploy to. | H8: Follows the hosting decision | I8: CL-12
A9: VER-23 | B9: PENDING — External penetration test (PS30-06) | C9: An independent firm tests against ABUSE_CASES as the scope document; target is zero critical or high findings. | D9: Our own adversarial tests are SECURITY evidence. They are not an independent assessment, and a buyer knows the difference. | E9: PENDING | F9: SECURITY (independent, absent) | G9: A penetration test is a purchase, not a sprint. | H9: Senthil — engage a testing firm | I9: R-Q12, CL-13
A10: VER-24 | B10: PENDING — SOC 2 Type I readiness (PS30-08) | C10: A readiness assessment consuming the posture declarations, audit trail and data-flow map. | D10: Enterprise procurement asks for it; nothing below enterprise does. | E10: PENDING | F10: OPS (absent) | G10: An assessment, not an engineering task, and premature before a first customer asks. | H10: Senthil — commission when a customer requires it | I10: —
A11: VER-25 | B11: PENDING — Invoice tax depth (R-Q20) | C11: A jurisdiction table and per-line tax codes so invoicing matches the multi-currency depth quoting now has. | D11: PXR-010 is half-closed: quoting is fully multi-currency, invoicing still applies one flat rate per portal. | E11: PENDING | F11: CODE (not started) | G11: Deliberately not faked in the last release. Sized for the next sprint and recorded as half-closed rather than counted as done. | H11: Next build sprint | I11: PXR-010, R-Q20
A12: VER-26 | B12: PENDING — Positioning decision and PMF (PS13, PS32) | C12: PS13: a written wedge decision with an ADR on field ownership. PS32: five weekly-active design partners, three verbally committed to pay, one signed pilot, ten paying strangers, churn observed over 90 days. | D12: The configuration scenarios come from limitations HubSpot documents, not from a prospect who asked. The depth may be real and still be depth in the wrong direction. | E12: PENDING | F12: COMMERCIAL (absent) | G12: Not an engineering sprint. No listing, no design partner, no revenue, no churn data — and no amount of further code produces any of them. | H12: Senthil — PS13 decision, then PS32 validation | I12: R-Q1, R-Q19, CL-14
A15: Read this before treating the list above as a backlog
A16: It is not a backlog. A backlog is work that can be started. Every row here is waiting on a decision or a purchase by the owner named in column H, and putting engineers on them would produce more untested code, which is the condition both external reviews criticised.
A17: The ordering that matters: VER-18 (a HubSpot developer account) unblocks more than everything else combined, because it is the only route to the LIVE evidence class and it gates whether any of the completed work is reachable by a customer at all. VER-26 (positioning and PMF) decides whether the rest is worth doing.

Sheet 07_Test_Cases
A1: TEST CASES — positive and negative
A2: One row per case. Execute the numbered steps from 08_Test_Steps, then record Actual result and Status here. Filter by Version ID for a targeted regression run, or by Priority for a smoke pass. Cases marked BLOCKED in Status cannot be run yet — see sheet 06.
A3: Test ID | B3: Version ID | C3: Module | D3: Test case name | E3: Type | F3: Priority | G3: Test description (what this proves) | H3: Pre-conditions | I3: Steps | J3: Expected overall result | K3: Evidence class | L3: Automated counterpart | M3: Actual result | N3: Status | O3: Tested by | P3: Date | Q3: Defect ref
A4: TC-001 | B4: VER-01 | C4: Install & OAuth | D4: Install redirects to HubSpot with a signed state carrying the source | E4: Positive | F4: P0 | G4: The install entry point must send the admin to HubSpot’s authorize screen and carry the attribution source inside a signed state, so a tampered source cannot be attributed. | H4: App running at BASE_URL with HUBSPOT_CLIENT_ID, HUBSPOT_CLIENT_SECRET and OAUTH_REDIRECT_URI set. | I4: 4 | J4: The admin reaches HubSpot’s consent screen and the install source travels tamper-evident. | K4: CODE | L4: tests/s3api.test.ts signedState | N4: Not Run
A5: TC-002 | B5: VER-01 | C5: Install & OAuth | D5: Callback with a forged state is refused | E5: Negative | F5: P0 | G5: An attacker who can craft a callback must not be able to attach an install to a portal of their choosing. | H5: As TC-001. | I5: 4 | J5: Only a state this server minted is accepted. | K5: CODE + SECURITY | L5: tests/review1.test.ts F-Q05 | N5: Not Run
A6: TC-003 | B6: VER-01 | C6: Install & OAuth | D6: Uninstall webhook removes tokens and schedules deletion | E6: Positive | F6: P0 | G6: When a customer uninstalls, their tokens must go immediately and their data must be queued for deletion at the retention boundary. | H6: A portal installed; the webhook signing secret known. | I6: 4 | J6: Tokens are gone at once; data deletion is scheduled, so a re-install inside the retention window can still restore. | K6: CODE | L6: tests/s7api.test.ts, smoke.test.ts | N6: Not Run
A7: TC-004 | B7: VER-01 | C7: Install & OAuth | D7: Unsigned or stale webhook is rejected | E7: Negative | F7: P0 | G7: A webhook endpoint that trusts its caller is an unauthenticated way to delete a customer’s account. | H7: As TC-003. | I7: 4 | J7: Every unverifiable webhook is refused and nothing is mutated. | K7: CODE + SECURITY | L7: tests/review2.test.ts signature block | N7: Not Run
A8: TC-005 | B8: VER-02 | C8: Price book | D8: One call produces a usable price book | E8: Positive | F8: P0 | G8: A new admin must reach a working catalogue in one action, not twelve. | H8: A minted admin session (see Environments sheet). | I8: 4 | J8: Setup is one call and is idempotent. | K8: CODE | L8: tests/s2api.test.ts ST-001 | N8: Not Run
A9: TC-006 | B9: VER-02 | C9: Price book | D9: A quote prices with the best matching discount | E9: Positive | F9: P0 | G9: Where several rules match, the largest discount must win, and the result must be deterministic. | H9: TC-005 completed. | I9: 4 | J9: Pricing is deterministic and attributable. | K9: CODE | L9: tests/s2.test.ts ST-003 | N9: Not Run
A10: TC-007 | B10: VER-02 | C10: RBAC | D10: A member cannot perform admin actions | E10: Negative | F10: P0 | G10: Role enforcement must be on every route, not on the ones someone remembered. | H10: Sessions for an owner, an admin and a member on the same portal. | I10: 5 | J10: The role matrix is enforced uniformly and the member keeps the rights they should have. | K10: CODE + SECURITY | L10: tests/s3api.test.ts RBAC | N10: Not Run
A11: TC-008 | B11: VER-13 | C11: App card | D11: The deal app card returns the data the extension renders | E11: Positive | F11: P0 | G11: The card payload must be data, not presentation, and must reflect the portal’s real state. | H11: A member session; the default price book set up. | I11: 4 | J11: The card payload is data the React extension can render, and reflects pause state. | K11: CODE | L11: tests/s3.test.ts buildDealCard | N11: Not Run
A12: TC-009 | B12: VER-13 | C12: App card | D12: The legacy CRM card route no longer exists | E12: Negative | F12: P0 | G12: PS14-05 required the legacy surface to be removed from the tree, not deprecated — a route that cannot be listed should not be reachable. | H12: App running. | I12: 3 | J12: The legacy card is gone from the product, not merely hidden. | K12: CODE | L12: tests/s3api.test.ts route-removal | N12: Not Run
A13: TC-010 | B13: VER-13 | C13: Identity | D13: A HubSpot-signed context mints a working session | E13: Positive | F13: P0 | G13: The serverless function inside the Projects app is the only thing that may mint a session, and it proves itself with a signature. | H13: clientSecret known; app running. | I13: 5 | J13: A session can only originate from a signed HubSpot context, and it works. | K13: CODE | L13: tests/s3api.test.ts PS16 | N13: Not Run
A14: TC-011 | B14: VER-13 | C14: Identity | D14: A browser cannot mint a session | E14: Negative | F14: P0 | G14: If an unsigned caller can mint, the whole identity design is decorative. | H14: As TC-010. | I14: 5 | J14: Only a signed, well-formed context mints, and the failure reason is specific enough to debug without leaking. | K14: CODE + SECURITY | L14: tests/s3api.test.ts PS16 | N14: Not Run
A15: TC-012 | B15: VER-13 | C15: Identity | D15: The unsigned header identity path is gone | E15: Negative | F15: P0 | G15: PS16-02 required deletion, not a NODE_ENV gate: a development-only path that exists in the binary is a production path. | H15: App running. | I15: 3 | J15: There is no environment in which unsigned headers authenticate. | K15: CODE + SECURITY | L15: tests/review1.test.ts PS16 | N15: Not Run
... A75: TC-072 | B75: VER-09 | C75: Regression (cold reviews 2 and 3) | D75: Published controls still have code behind them | E75: Negative | F75: P0 | G75: Passes 2 and 3 looked for the opposite failure to pass 1: claims with nothing implementing them. Nine existed. | H75: Ops token; an admin session; a portal with data past its retention age. | I75: 5 | J75: Every control the documentation claims is wired, reachable and effective. | K75: CODE + SECURITY | L75: tests/review2.test.ts | N75: Not Run

Sheet 08_Test_Steps
A1: TEST STEPS — step by step, with the expected result at each step
A2: Execute the Action column exactly as written and compare against Expected. Record Pass/Fail per STEP: a failure pinned to a step is a defect report; a failure pinned to a whole case is a conversation.
A3: Test ID | B3: Version ID | C3: Test case name | D3: Type | E3: Step No | F3: Action (do exactly this) | G3: Expected result | H3: Actual result | I3: Pass / Fail | J3: Notes
A4: TC-001 | B4: VER-01 | C4: Install redirects to HubSpot with a signed state carrying the source | D4: Positive | E4: 1 | F4: Open BASE_URL/install?source=listing in a browser (or curl -i). | G4: HTTP 302.
A5: TC-001 | B5: VER-01 | C5: Install redirects to HubSpot with a signed state carrying the source | D5: Positive | E5: 2 | F5: Read the Location header. | G5: It points at HubSpot’s authorize URL and carries client_id, redirect_uri, scope and a state parameter.
A6: TC-001 | B6: VER-01 | C6: Install redirects to HubSpot with a signed state carrying the source | D6: Positive | E6: 3 | F6: Inspect the state parameter. | G6: It is not the bare word "listing" — it is signed, so the source cannot be edited by hand.
A7: TC-001 | B7: VER-01 | C7: Install redirects to HubSpot with a signed state carrying the source | D7: Positive | E7: 4 | F7: Repeat with ?source=search and compare. | G7: A different state value; both are accepted.
A8: TC-002 | B8: VER-01 | C8: Callback with a forged state is refused | D8: Negative | E8: 1 | F8: Call BASE_URL/oauth/callback?code=abc&state=listing (an unsigned state). | G8: The request is refused; no account is created.
A9: TC-002 | B9: VER-01 | C9: Callback with a forged state is refused | D9: Negative | E9: 2 | F9: Call the same URL with state omitted entirely. | G9: Refused.
A10: TC-002 | B10: VER-01 | C10: Callback with a forged state is refused | D10: Negative | E10: 3 | F10: Take a valid state from TC-001, change one character, and call back with it. | G10: Refused — the signature no longer verifies.
A11: TC-002 | B11: VER-01 | C11: Callback with a forged state is refused | D11: Negative | E11: 4 | F11: Check the portal list afterwards. | G11: No portal was created by any of the three attempts.
A12: TC-003 | B12: VER-01 | C12: Uninstall webhook removes tokens and schedules deletion | D12: Positive | E12: 1 | F12: Build the body [{"subscriptionType":"app.uninstalled","portalId":1}]. | G12: Body prepared.
A13: TC-003 | B13: VER-01 | C13: Uninstall webhook removes tokens and schedules deletion | D13: Positive | E13: 2 | F13: Sign it with the HubSpot v3 scheme over method+uri+body+timestamp and POST to /webhooks/hubspot. | G13: HTTP 200.
A14: TC-003 | B14: VER-01 | C14: Uninstall webhook removes tokens and schedules deletion | D14: Positive | E14: 3 | F14: Attempt any authenticated API call for portal 1. | G14: The portal no longer has a usable token.
A15: TC-003 | B15: VER-01 | C15: Uninstall webhook removes tokens and schedules deletion | D15: Positive | E15: 4 | F15: Inspect the deletion queue (ops surface). | G15: A deletion is scheduled at the retention boundary, not executed immediately.
... A334: TC-072 | B334: VER-09 | C334: Published controls still have code behind them | D334: Negative | E334: 5 | F334: Vendor surfaces: call each /api/ops/* route with a tenant owner session and no ops token. | G334: All refused.

Sheet 09_Traceability
A1: TRACEABILITY — case → version → finding → evidence
A2: Use at the end of a cycle to prove nothing was skipped. Every COMPLETED version carries at least one case, and every version with cases carries at least one negative one. Four pending versions carry no case, for a stated reason — see the note below the table.
A3: Version ID | B3: Release | C3: Status | D3: Cases | E3: Positive | F3: Negative | G3: P0 cases | H3: Test IDs | I3: Findings / stories covered | J3: Evidence class reached
A4: VER-01 | B4: S1 — Foundation | C4: COMPLETED | D4: 4 | E4: 2 | F4: 2 | G4: 4 | H4: TC-001, TC-002, TC-003, TC-004 | I4: ST-051/052/055/056 | J4: CODE
A5: VER-02 | B5: S2 — Price book part 1 | C5: COMPLETED | D5: 3 | E5: 2 | F5: 1 | G5: 3 | H5: TC-005, TC-006, TC-007 | I5: ST-001..004, ST-053/054 | J5: CODE
A6: VER-03 | B6: S3 — Price book part 2 + card | C6: COMPLETED | D6: 2 | E6: 1 | F6: 1 | G6: 0 | H6: TC-061, TC-062 | I6: ST-005..010 | J6: CODE
A7: VER-04 | B7: S4 — Approval chains | C7: COMPLETED | D7: 2 | E7: 1 | F7: 1 | G7: 1 | H7: TC-063, TC-064 | I7: ST-011..015 | J7: CODE
A8: VER-05 | B8: S5 — E-signature + alpha hardening | C8: COMPLETED | D8: 2 | E8: 1 | F8: 1 | G8: 0 | H8: TC-065, TC-066 | I8: ST-021..025 | J8: CODE
A9: VER-06 | B9: S6–S8 — Analytics, billing, deal sync, trust | C9: COMPLETED | D9: 2 | E9: 0 | F9: 2 | G9: 2 | H9: TC-067, TC-068 | I9: ST-031..070 | J9: CODE
A10: VER-07 | B10: S9–S12 — Marketplace, launch, iterate | C10: COMPLETED | D10: 1 | E10: 0 | F10: 1 | G10: 0 | H10: TC-069 | I10: ST-081..100 | J10: CODE
A11: VER-08 | B11: RP1 — First cold review | C11: COMPLETED | D11: 1 | E11: 0 | F11: 1 | G11: 1 | H11: TC-071 | I11: F-Q01..F-Q08 | J11: CODE
A12: VER-09 | B12: RP2 + RP3 — Second and third cold reviews | C12: COMPLETED | D12: 1 | E12: 0 | F12: 1 | G12: 1 | H12: TC-072 | I12: F-Q09..F-Q17 | J12: CODE
A13: VER-10 | B13: Postgres persistence | C13: COMPLETED | D13: 1 | E13: 1 | F13: 0 | G13: 1 | H13: TC-070 | I13: R-Q4, R-Q14 | J13: CODE
A14: VER-11 | B14: Async store cascade (R-Q13) | C14: COMPLETED | D14: 2 | E14: 2 | F14: 0 | G14: 1 | H14: TC-048, TC-049 | I14: R-Q13, PXR-005 | J14: CODE
A15: VER-12 | B15: EXT-V001 — First external review | C15: COMPLETED | D15: 1 | E15: 0 | F15: 1 | G15: 1 | H15: TC-051 | I15: QF-001..QF-014 | J15: CODE
... A29: VER-26 | B29: PENDING — Positioning decision and PMF (PS13, PS32) | C29: PENDING | D29: 0 | E29: 0 | F29: 0 | G29: 0 | H29: — none (covered indirectly) | I29: R-Q1, R-Q19, CL-14 | J29: COMMERCIAL (absent)
A31: COVERAGE NOTE
A32: Every COMPLETED version has at least one case, and every version that has cases has at least one NEGATIVE case — a pack of only happy paths proves the product works when nothing goes wrong, which is not the interesting question. Four PENDING versions carry no case on purpose: VER-23 (an external penetration test) and VER-24 (a SOC 2 readiness assessment) are performed by a third party against their own methodology, not by this pack; VER-25 (invoice tax depth) has no code to test yet; and VER-26 (positioning and PMF) is a commercial outcome, not a behaviour. Writing manual test cases for any of the four would be theatre. The other five pending versions DO carry their case — TC-056 to TC-060 — written in full so the day the blocker clears the test is already there.

Sheet 10_Defect_Log
A1: DEFECT LOG
A2: One row per defect found by executing this pack. Reference the Test ID and the failing Step No so a developer can reproduce it in one read. Do NOT amend a test case to make it pass — that is how a test pack stops being evidence.
A3: Defect ID | B3: Raised | C3: Test ID | D3: Step No | E3: Version ID | F3: Severity | G3: Summary | H3: Steps to reproduce | I3: Expected | J3: Actual | K3: Environment | L3: Severity rationale | M3: Assigned to | N3: Status | O3: Resolution | P3: Closed
A4: DEF-000 | B4: (example) | C4: TC-000 | D4: 0 | E4: VER-00 | F4: EXAMPLE | G4: This row is an example of the level of detail required — delete it before use. | H4: 1. Mint an admin session. 2. PUT /api/config/models/pm-1 with the model from the Environments sheet. 3. Observe the response. | I4: HTTP 200 and the model echoed back. | J4: HTTP 500 with an unhandled TypeError. | K4: Local, in-memory backend, build <tree hash> | L4: Critical if it blocks a P0 path with no workaround; High if a workaround exists; Medium if cosmetic but wrong; Low if presentational. | M4: — | N4: Example | O4: n/a
A8: SEVERITY DEFINITIONS
A9: Critical | B9: Customer data loss, cross-tenant exposure, an approval bypass, a money error, or a P0 path with no workaround. Stops the release.
A10: High | B10: A P0 path with a workaround, or any defect in billing, identity or tenancy that is not itself Critical.
A11: Medium | B11: Wrong behaviour in a P1 path, or a correct behaviour reported misleadingly.
A12: Low | B12: Presentational, or a documentation defect in this pack itself.

Sheet 11_Environments
A1: ENVIRONMENTS, ACCOUNTS AND TEST DATA
A2: Set this up before the first case. Everything here is required by TC-001 onwards; the blocked cases (TC-056..TC-060) additionally need the accounts in the second table, which do not exist.
A3: Item | B3: Value / how to obtain it | C3: Needed for | D3: Available today?
A4: Runtime | B4: Node 22. From the delivered zip: npm ci, then npm run build. | C4: All cases | D4: YES
A5: Local run (in-memory) | B5: HUBSPOT_CLIENT_ID=cid HUBSPOT_CLIENT_SECRET=csecret OAUTH_REDIRECT_URI=http://localhost:3000/oauth/callback npm start | C5: Most functional cases | D5: YES
A6: Local run (Postgres) | B6: As above plus DATABASE_URL pointing at a Postgres 15+ instance, connected as a NON-superuser role without BYPASSRLS (create one: CREATE ROLE quoteflow_app LOGIN PASSWORD ...). | C6: TC-014, TC-015, TC-016, TC-043, TC-044, TC-052 | D6: YES — any local Postgres
A7: Operator token | B7: QF_OPS_TOKEN=<any value>. Sent as X-QF-Ops-Token on vendor-only surfaces. | C7: TC-050 | D7: YES
A8: Mail provider stub | B8: QF_EMAIL_URL / QF_EMAIL_TOKEN / QF_EMAIL_FROM pointed at a local stub you can make fail on demand. | C8: TC-017, TC-045 | D8: YES
A9: Minting a session | B9: Sessions are HMAC-signed and mint only from a HubSpot-SIGNED body. For testing, POST /session/mint with the v3 signature computed over POST + the full URI + the raw body + the timestamp, using HUBSPOT_CLIENT_SECRET. The repository’s tests/support/session.ts shows the exact construction; copy it into a small script. | C9: Every authenticated case | D9: YES
A10: Sample product model | B10: Use the model in tests/cpqApi.test.ts (gateway/cellular/data-plan with an implies rule and an excludes rule) — it exercises implication, exclusion and conditional visibility in four options. | C10: TC-019..TC-022 | D10: YES
A11: Sample pricing catalogue | B11: Use the catalogue in tests/pricingDepth.test.ts: a USD parent book, a EUR subsidiary book that overrides one SKU, two nested bundles, four rules, a channel matrix and two floor policies. | C11: TC-023..TC-026 | D11: YES
A12: Sample approval DAG | B12: Use the DAG in tests/dealDesk.test.ts: legal and finance in parallel feeding a conditional CFO node, plus an entity-gated VP node and a 2-of-3 quorum security node. | C12: TC-027..TC-031 | D12: YES
A13: Recorded HubSpot fixtures | B13: The fixture harness in tests/extreview2.test.ts returns a deal carrying one QuoteFlow line, one rep-added line and one native-quote line. | C13: TC-036 | D13: YES
A15: ACCOUNTS AND ENVIRONMENTS THAT DO NOT EXIST
A16: Item | B16: Why it is needed | C16: Blocks | D16: Owner
A17: HubSpot developer account + test portal | B17: The only way to upload the Projects app, install it, render the app card and obtain LIVE evidence. | C17: TC-056 — and the LIVE class for every other feature | D17: Senthil (R-Q15)
A18: Stripe test-mode keys | B18: To prove the charge payload is accepted by the real API and that real webhooks are handled. | C18: TC-057 | D18: Senthil (R-Q10)
A19: HubSpot marketplace monetisation access | B19: To exercise the marketplace billing rail that HubSpot mandates for marketplace-acquired portals. | C19: TC-057 | D19: Senthil (R-Q10)
A20: Hosted environment (2 instances + load balancer) | B20: To measure p95 under load against something that is not localhost. | C20: TC-058, TC-060 | D20: Senthil (R-Q17)
A21: Managed Postgres with PITR + empty restore target | B21: To run the restore drill and produce a real RPO and RTO. | C21: TC-059 | D21: Senthil (R-Q18)
A22: Signature provider account | B22: To exercise the provider adapter instead of the homegrown signer. | C22: Part of TC-034 (provider path) | D22: Senthil

Sheet 12_Entry_Exit_Criteria
A1: ENTRY AND EXIT CRITERIA
A2: A cycle started without its entry criteria produces results nobody can trust, and a cycle closed without its exit criteria produces a number nobody can defend.
A3: # | B3: Criterion | C3: Type | D3: Why it is there | E3: Met? (fill in)
A4: E1 | B4: The build under test is a clean extraction of the delivered zip, and npm ci + npm run build both succeed. | C4: Entry | D4: A modified working tree makes every result ambiguous.
A5: E2 | B5: The tree hash on 01_Cover matches the build. | C5: Entry | D5: Otherwise the pack describes a different product.
A6: E3 | B6: The automated suite passes at 100% on that build before manual execution starts. | C6: Entry | D6: Manual time is expensive; do not spend it finding what the suite would have found for free.
A7: E4 | B7: The environment on 11_Environments is set up, including a Postgres instance connected as a non-superuser role. | C7: Entry | D7: Six cases are meaningless without a real engine, and two exist specifically to check the superuser refusal.
A8: E5 | B8: A session can be minted (TC-010 passes). | C8: Entry | D8: Every authenticated case depends on it.
A9: X1 | B9: Every P0 case has a Status of Pass or Blocked, with Blocked only for TC-056..TC-060. | C9: Exit | D9: A P0 left Not Run is a P0 nobody looked at.
A10: X2 | B10: Every Fail has a corresponding row in 10_Defect_Log with a step number. | C10: Exit | D10: A failure with no defect is a failure that will be forgotten.
A11: X3 | B11: No Critical or High defect is open, or each open one has a written, dated waiver on 14_Sign_Off. | C11: Exit | D11: Shipping over a known Critical should require a signature.
A12: X4 | B12: Every negative case in the run has been executed — not skipped in favour of the happy path. | C12: Exit | D12: Three cold reviews found 17 defects; almost all were found by negative reasoning.
A13: X5 | B13: 13_Test_Summary has been refreshed and 14_Sign_Off is complete and dated. | C13: Exit | D13: A cycle with no sign-off is a rehearsal.

Sheet 13_Test_Summary
A1: TEST SUMMARY — live counts
A2: Every figure here is a formula over 07_Test_Cases. Fill in the Status column there and these update by themselves; nothing on this sheet is typed, for the same reason the release manifest is generated rather than written.
A3: Metric | B3: Value | C3: Note
A4: Total test cases | B4: =COUNTA('07_Test_Cases'!A4:A75) | C4: All cases in the pack.
A5: Positive cases | B5: =COUNTIF('07_Test_Cases'!E4:E75,"Positive") | C5: Does it do what it should?
A6: Negative cases | B6: =COUNTIF('07_Test_Cases'!E4:E75,"Negative") | C6: Does it refuse what it should? Historically where the defects are.
A7: P0 cases | B7: =COUNTIF('07_Test_Cases'!F4:F75,"P0") | C7: Must pass or be explicitly waived.
A8: Total steps | B8: =SUM('07_Test_Cases'!I4:I75) | C8: Numbered, individually recordable steps.
A9: Passed | B9: =COUNTIF('07_Test_Cases'!N4:N75,"Pass")
A10: Failed | B10: =COUNTIF('07_Test_Cases'!N4:N75,"Fail") | C10: Each must appear in 10_Defect_Log.
A11: Blocked | B11: =COUNTIF('07_Test_Cases'!N4:N75,"Blocked") | C11: Expected to be 5 until an account or environment exists (TC-056..TC-060).
A12: Not run | B12: =COUNTIF('07_Test_Cases'!N4:N75,"Not Run") | C12: Must be zero at exit for P0 cases.
A13: Executed % | B13: =IFERROR(ROUND((COUNTIF('07_Test_Cases'!N4:N75,"Pass")+COUNTIF('07_Test_Cases'!N4:N75,"Fail"))/COUNTA('07_Test_Cases'!A4:A75)*100,1),0) | C13: Of all cases, including the ones that cannot be run.
A14: Pass rate of executed % | B14: =IFERROR(ROUND(COUNTIF('07_Test_Cases'!N4:N75,"Pass")/(COUNTIF('07_Test_Cases'!N4:N75,"Pass")+COUNTIF('07_Test_Cases'!N4:N75,"Fail"))*100,1),0) | C14: The honest headline: excludes blocked and not-run.
A17: BY MODULE
A18: Module | B18: Cases | C18: Passed
A19: Abuse controls | B19: =COUNTIF('07_Test_Cases'!C4:C75,"Abuse controls") | C19: =COUNTIFS('07_Test_Cases'!C4:C75,"Abuse controls",'07_Test_Cases'!N4:N75,"Pass")
A20: App card | B20: =COUNTIF('07_Test_Cases'!C4:C75,"App card") | C20: =COUNTIFS('07_Test_Cases'!C4:C75,"App card",'07_Test_Cases'!N4:N75,"Pass")
A21: Approvals (chain) | B21: =COUNTIF('07_Test_Cases'!C4:C75,"Approvals (chain)") | C21: =COUNTIFS('07_Test_Cases'!C4:C75,"Approvals (chain)",'07_Test_Cases'!N4:N75,"Pass")
A22: Billing | B22: =COUNTIF('07_Test_Cases'!C4:C75,"Billing") | C22: =COUNTIFS('07_Test_Cases'!C4:C75,"Billing",'07_Test_Cases'!N4:N75,"Pass")
A23: Billing (trial) | B23: =COUNTIF('07_Test_Cases'!C4:C75,"Billing (trial)") | C23: =COUNTIFS('07_Test_Cases'!C4:C75,"Billing (trial)",'07_Test_Cases'!N4:N75,"Pass")
A24: Boot safety | B24: =COUNTIF('07_Test_Cases'!C4:C75,"Boot safety") | C24: =COUNTIFS('07_Test_Cases'!C4:C75,"Boot safety",'07_Test_Cases'!N4:N75,"Pass")
A25: CPQ persistence | B25: =COUNTIF('07_Test_Cases'!C4:C75,"CPQ persistence") | C25: =COUNTIFS('07_Test_Cases'!C4:C75,"CPQ persistence",'07_Test_Cases'!N4:N75,"Pass")
A26: Configuration | B26: =COUNTIF('07_Test_Cases'!C4:C75,"Configuration") | C26: =COUNTIFS('07_Test_Cases'!C4:C75,"Configuration",'07_Test_Cases'!N4:N75,"Pass")
A27: Data lifecycle | B27: =COUNTIF('07_Test_Cases'!C4:C75,"Data lifecycle") | C27: =COUNTIFS('07_Test_Cases'!C4:C75,"Data lifecycle",'07_Test_Cases'!N4:N75,"Pass")
A28: Deal desk | B28: =COUNTIF('07_Test_Cases'!C4:C75,"Deal desk") | C28: =COUNTIFS('07_Test_Cases'!C4:C75,"Deal desk",'07_Test_Cases'!N4:N75,"Pass")
A29: Deal sync | B29: =COUNTIF('07_Test_Cases'!C4:C75,"Deal sync") | C29: =COUNTIFS('07_Test_Cases'!C4:C75,"Deal sync",'07_Test_Cases'!N4:N75,"Pass")
A30: Deploy (PENDING) | B30: =COUNTIF('07_Test_Cases'!C4:C75,"Deploy (PENDING)") | C30: =COUNTIFS('07_Test_Cases'!C4:C75,"Deploy (PENDING)",'07_Test_Cases'!N4:N75,"Pass")
A31: Durability | B31: =COUNTIF('07_Test_Cases'!C4:C75,"Durability") | C31: =COUNTIFS('07_Test_Cases'!C4:C75,"Durability",'07_Test_Cases'!N4:N75,"Pass")
A32: E-signature | B32: =COUNTIF('07_Test_Cases'!C4:C75,"E-signature") | C32: =COUNTIFS('07_Test_Cases'!C4:C75,"E-signature",'07_Test_Cases'!N4:N75,"Pass")
A33: Entitlements | B33: =COUNTIF('07_Test_Cases'!C4:C75,"Entitlements") | C33: =COUNTIFS('07_Test_Cases'!C4:C75,"Entitlements",'07_Test_Cases'!N4:N75,"Pass")
A34: HubSpot sync | B34: =COUNTIF('07_Test_Cases'!C4:C75,"HubSpot sync") | C34: =COUNTIFS('07_Test_Cases'!C4:C75,"HubSpot sync",'07_Test_Cases'!N4:N75,"Pass")
A35: Identity | B35: =COUNTIF('07_Test_Cases'!C4:C75,"Identity") | C35: =COUNTIFS('07_Test_Cases'!C4:C75,"Identity",'07_Test_Cases'!N4:N75,"Pass")
A36: Import | B36: =COUNTIF('07_Test_Cases'!C4:C75,"Import") | C36: =COUNTIFS('07_Test_Cases'!C4:C75,"Import",'07_Test_Cases'!N4:N75,"Pass")
A37: Install & OAuth | B37: =COUNTIF('07_Test_Cases'!C4:C75,"Install & OAuth") | C37: =COUNTIFS('07_Test_Cases'!C4:C75,"Install & OAuth",'07_Test_Cases'!N4:N75,"Pass")
A38: Launch readiness | B38: =COUNTIF('07_Test_Cases'!C4:C75,"Launch readiness") | C38: =COUNTIFS('07_Test_Cases'!C4:C75,"Launch readiness",'07_Test_Cases'!N4:N75,"Pass")
A39: Live billing (PENDING) | B39: =COUNTIF('07_Test_Cases'!C4:C75,"Live billing (PENDING)") | C39: =COUNTIFS('07_Test_Cases'!C4:C75,"Live billing (PENDING)",'07_Test_Cases'!N4:N75,"Pass")
A40: Live install (PENDING) | B40: =COUNTIF('07_Test_Cases'!C4:C75,"Live install (PENDING)") | C40: =COUNTIFS('07_Test_Cases'!C4:C75,"Live install (PENDING)",'07_Test_Cases'!N4:N75,"Pass")
A41: Load (PENDING) | B41: =COUNTIF('07_Test_Cases'!C4:C75,"Load (PENDING)") | C41: =COUNTIFS('07_Test_Cases'!C4:C75,"Load (PENDING)",'07_Test_Cases'!N4:N75,"Pass")
A42: Operations | B42: =COUNTIF('07_Test_Cases'!C4:C75,"Operations") | C42: =COUNTIFS('07_Test_Cases'!C4:C75,"Operations",'07_Test_Cases'!N4:N75,"Pass")
...

Sheet 14_Sign_Off
A1: EXECUTION RECORD AND SIGN-OFF
A2: One block per execution cycle. Copy the block for each new cycle; a cycle is not complete until it is signed and dated.
A3: Field | B3: Value | C3: Guidance
A4: Cycle reference | C4: e.g. CYC-001. Reference it in 10_Defect_Log entries.
A5: Build / tree hash tested | C5: Must match 01_Cover, or state why it differs.
A6: Environment | C6: Local in-memory, local Postgres, or a deployed target if one ever exists.
A7: Cycle start
A8: Cycle end
A9: Cases executed | C9: Take from 13_Test_Summary.
A10: Pass / Fail / Blocked | C10: Take from 13_Test_Summary.
A11: Critical or High defects open at exit | C11: If non-zero, a written waiver is required below.
A12: Waiver (if any) | C12: State the defect, the risk accepted, who accepted it and until when. A waiver with no expiry is a decision nobody will revisit.
A14: Tested by | C14: Name, role, date.
A15: Reviewed by | C15: Someone who did not execute the cases.
A16: Accepted by | C16: Product owner — Senthil/KP.
A18: Statement of scope | B18: This cycle tested a build of QuoteFlow outside HubSpot. It does not and cannot constitute evidence that the product works inside a HubSpot portal. | C18: Leave this statement in place until TC-056 passes. It is the single most important caveat on any result this pack produces.

Sheet 15_Glossary
A1: GLOSSARY
A2: Every term, code and abbreviation used in this pack, in one place.
A3: Term | B3: Meaning
A4: CPQ | B4: Configure, Price, Quote — the product category QuoteFlow sits in.
A5: Portal | B5: A HubSpot customer account. The tenant boundary for everything in this product.
A6: App card | B6: The React UI extension rendered on a HubSpot deal record. Replaces the legacy CRM card, which was deleted.
A7: Projects app | B7: The HubSpot developer-platform packaging format (platformVersion 2026.03) that an app card must ship inside to be listable.
A8: Session (X-QF-Session) | B8: A short-lived HMAC-signed token, the only identity the API accepts. Minted at POST /session/mint from a HubSpot-signed context.
A9: RLS | B9: Row-level security: Postgres enforcing tenant isolation at the database, so a query that forgets its portal filter returns nothing.
A10: GUC | B10: A Postgres runtime setting. Here, a transaction-local setting carrying the current portal id that RLS policies read.
A11: Outbox | B11: The durable job table through which side effects (mail, deletions) are issued, with retry, backoff, dead-letter and replay.
A12: Envelope encryption | B12: Encrypting each record with its own key, which is itself wrapped by a master key — so rotation re-wraps keys rather than re-encrypting data.
A13: Waterfall | B13: The per-line price audit: list → book → bundle → rule → discount → channel → floor → fx, each step attributed.
A14: DAG | B14: Directed acyclic graph — the approval shape that allows parallel branches, as opposed to a linear chain.
... A29: Blocked (status) | B29: In this pack: the case could not be executed because an account, environment or purchase does not exist. Distinct from Fail.
