Workbook

Sheet Version_Control
A1: VERSION CONTROL — VoiceBridge Sprint Tracker & Traceability
A2: File naming: claude_v<NNN>_<proper file name>_YYYYMMDD_HHMI.
A3: Version | B3: Date/Time | C3: Author | D3: Change Description | E3: Status
A4: v001 | B4: 2026-09-10 23:00 | C4: Claude for Senthil/KP | D4: THIS FILE — Live execution tracker for VoiceBridge CTI (portfolio P02, Salesforce AppExchange). S1-S8 executed done-in-code under D13 from v006 workbook: 79 Done + 5 code-complete-pending-live of 100 stories; TypeScript codebase 20 Jest suites / 85 tests at 100% statements/branches/functions/lines; released with v007 product workbook. | E4: Released
A5: v002 | B5: 2026-09-11 08:46 | C5: Claude for Senthil/KP | D5: S9 REVIEW PREP executed done-in-code: WCAG AA automated audit (jest-axe) on new softphone+settings widget shells (ST-089 Done), backup/restore drill w/ sha256 integrity verify (ST-090 Done), chaos outage degradation + /status user comms (ST-091 Done), security evidence pack sandbox half (ST-068 In progress — pen-test vendor his), listing copy A/B + asset plan Drafted (ST-093/094). Plus portfolio live-sweep pack (12-step sweep: 8 auto + 4 operator, 30-min dev-org guide) and D18 packaging recommendation doc (hybrid-minimal 2GP shim). Codebase 24 suites / 101 tests at 100% coverage. 82 Done / 5 code-complete / 1 in progress / 2 drafted / 10 backlog = 352/399 pts engaged. | E5: Released
A6: v003 | B6: 2026-09-11 12:48 | C6: Claude for Senthil/KP | D6: S10 REVIEW REMEDIATION executed done-in-code: help center 15 articles + search, built-in chat SLA engine (<4 business hrs, vendor deferred), status page + incident template, pricing + trust pages from single sources — all Done; demo-data mode Code-complete (video needs live capture); dry-run engine READY 11/11 automated + REVIEW_PACK.md, ST-097 In progress pending external reviewer sign-off (DR-12). Codebase 30 suites / 131 tests at 100% zero pragmas. 87 Done / 6 code-complete / 2 in progress / 2 drafted / 3 backlog (373/399 pts engaged). | E6: Released
A7: v004 | B7: 2026-09-11 13:32 | C7: Claude for Senthil/KP | D7: CODE PHASE COMPLETE. S11+S12 codeable scope executed: executable launch-day runbook with rollback triggers wired to real p95 budgets (ST-098 Done); 10-slot design-partner tracker with stale-nudge + honest exit math (ST-100 CC — outreach his); listing SEO iteration engine with thin-data guards (ST-099 CC — needs post-listing data). Backlog ZERO. Codebase 33 suites / 150 tests at 100% zero pragmas. Final position: 88 Done / 8 code-complete / 2 in progress / 2 drafted — 380/399 pts; remaining 19 pts all Senthil-side. | E7: Released
A8: v005 | B8: 2026-09-11 15:26 | C8: Claude for Senthil/KP | D8: POST-CODE-PHASE GAP CLOSED: D18 shim package source built — sfdx project with CallCenter Open CTI definition, 3 permission sets generated from the enforced role matrix (drift-tested), esbuild softphone static resource from a new functional dependency-injected Open CTI adapter (click-to-dial, screen pop, activity logging with degraded fallback, status polling) tested in jsdom against mocked sforce.opencti. Dev-org guide O2 now turnkey (deploy + assign, zero authoring). 35 suites / 162 tests at 100% zero pragmas. Story position unchanged (88/8/2/2 — honest: infrastructure, not story flips). | E8: Released
A9: v006 | B9: 2026-09-11 22:09 | C9: Claude for Senthil/KP | D9: COLD-REVIEW PASS 1 (sibling pattern): 7 defects fixed with pinned regressions — retention-sweep PII leak, missing payment-recovery path, unenforced trial expiry, unguarded invoice mutation, unbounded ledgers → FIFO 10k, NO-OP production backoff sleep, and read-only status enforced nowhere → new billing write-gate across all mutating feature ops. 2 observations (CSV quoting, half-open probes) logged for disposition in the new Review_Findings sheet. 36 suites / 176 tests at 100% zero pragmas. Story position unchanged (88/8/2/2, 380/399) — defects lived inside Done stories; fixes keep them Done with corrected behaviour. | E9: Released
A10: v007 | B10: 2026-09-11 22:34 | C10: Claude for Senthil/KP | D10: COLD REVIEW COMPLETE + EXTERNAL VERIFICATION SWEEP. Pass 2 over the ~28 modules pass 1 never opened: 13 defects fixed with pinned regressions (F-V08..F-V20) + 2 observations logged. Verification sweep vs live Open CTI Lightning docs found 2 LIVE-BLOCKING defects (VER-V01 opencti_min.js never loaded — softphone dead in-org with no error; VER-V02 enableClickToDial never called) plus VER-V03/V04; artifact-gap audit clean apart from the missing /log route (F-V10). 39 suites / 217 tests at 100% zero pragmas. Story position unchanged (88/8/2/2, 380/399) — correctness release, no new stories. | E10: Released
A11: v008 | B11: 2026-09-13 10:39 | C11: Claude for Senthil/KP | D11: SCREEN SURFACE + OAUTH COMPLIANCE RELEASE (code v0.14.0). (1) GAP-V2 closed: Screens_Wireframes specifies 9 screens and only 2 existed while 5 P0 stories claimed an end-to-end LWC surface — the 7 missing screens built as typed view-models + accessible renderer (src/views.ts), wired to the real modules via src/screenData.ts and served at /ui/:orgId[/:screenId?format=html]; WCAG audit widened from 2 screens to all 9 in populated AND empty states. (2) EXTERNAL VERIFICATION SWEEP #2 vs live Salesforce ISV docs found VER-V06 (new Connected Apps cannot be created from Spring 26 — the 30-min guide step 2 was unrunnable; ECA everywhere now) and VER-V07/V08/V09 (four OAuth controls mandatory since 11 May 2026, enforceable by interoperability suspension since 25 Jun 2026: PKCE + state, rotation anomaly telemetry, 30-day idle timeout, refresh IP allowlist). (3) VER-V10 verified: AppExchange Checkout is NOT mandatory — ISVforce+COA alternative, 15%/25% rev share, $999 review fee, ~$150 listing — raised as D-V3. (4) F-V21 logged UNFIXED for disposition: identity is caller-declared. 41 suites / 274 tests at 100% zero pragmas. | E11: Released
A12: v009 | B12: 2026-09-13 10:57 | C12: Claude for Senthil/KP | D12: ARTIFACT-GAP AUDIT (code v0.15.0) — sibling OnCall/EngageOS pattern applied to VoiceBridge. 5 gaps, 2 CRITICAL. GAP-V3: NO PROCESS and NO PRODUCTION OAUTH GATEWAY existed — createApp() had never been called by anything, and the only OAuthGateway implementations were test doubles, so the ECA callback, the sweep /health probe, the k6 harness and the softphone's /dial and /log posts all addressed a server that could not be started; the 30-minute dev-org guide was unrunnable past step 3. GAP-V4: NO SCHEMA behind a published 30-day retention policy, the ST-090 backup/restore drill and sweep check A5 — all against an in-memory Map. GAP-V5: CI pinned Node 20, end-of-life since April 2026. All fixed: server.ts + main.ts + npm start, SfOAuthGateway against the real token endpoint, 5 ordered migrations + npm run migrate with order/re-run/checksum-drift guards, Node 22. R-V11 logged honestly — the migrations describe the store but the runtime is STILL in-memory. 42 suites / 296 tests at 100% zero pragmas. | E12: Released
A13: v010 | B13: 2026-09-13 11:14 | C13: Claude for Senthil/KP | D13: COLD-REVIEW PASS 3 + IDENTITY BOUNDARY (code v0.16.0). Pass 3 targeted the surfaces v0.14.0 and v0.15.0 added, on the sibling principle that new surfaces inherit old blind spots — and it found one I introduced: F-V23, the /ui routes shipped last release taking the org straight from the URL with no identity check, so anyone who knew or guessed an org id could read that org's billing, invoices, analytics and support queue. Fixing it required the boundary F-V21 has been waiting for, so both are closed here: HMAC-signed sessions minted only at the install callback, identity never read from body or URL, a claim that disagrees with the session refused as forgery, and 401/403 separated from the blanket 400 every failure used to return. Also F-V24 (public /oauth/start could grow the PKCE map without bound — OBS-V5 escalated, now TTL-swept and FIFO-capped), F-V25 (no timeout on the token endpoint), F-V26 (drain waited forever on open connections) and F-V26b (the listening log printed the requested port, not the bound one). 43 suites / 318 tests at 100% zero pragmas. | E13: Released
A14: v011 | B14: 2026-09-13 11:36 | C14: Claude for Senthil/KP | D14: R-V11 STAGE 1 — ASYNC REPOSITORY CONTRACT (code v0.17.0). Measured first: 91 store call sites across 20 modules and 277 store/await lines in the tests, so a single-pass conversion is a broken build for hours and a coverage gate that cannot run. Staged instead, green at every step. Stage 1 ships the Repository interface, InMemoryRepository, PgRepository against the v0.15.0 migrations plus a new 006_sequences.sql, and — the load-bearing part — a conformance suite that runs the SAME behavioural tests against BOTH implementations, which is what makes stages 2..N a swap rather than a leap. Postgres earns two things the in-memory version got free: the F-V05 FIFO cap enforced in SQL with drops counted so a cap survives restart, and F-V19 nextSeq as one atomic INSERT..ON CONFLICT..RETURNING because read-then-write would give two instances the same id. docs/r-v11-plan.md fixes the conversion order (leaf modules first, permissions its own stage, app.ts last). NOT WIRED: createApp() still constructs the sync Store, so R-V11 stays OPEN — stage 1 is not persistence, exactly as db/migrations/ was not. New operator step O6: run the conformance suite against live Postgres, because a double proves we send the right statements, not that Postgres does the right thing with them. 44 suites / 340 tests at 100% zero pragmas. | E14: Released
... A27: v024 | B27: 2026-09-20 10:45 | C27: Claude for Senthil/KP | D27: PERPLEXITY REVIEW V001 INCORPORATED + EXECUTED (code v0.28.0, voicebridge-cti-codebase-20260920_1045.zip). Independent second review (Perplexity, 16 Sep 13:53 BST; verdict HOLD then RE-PLATFORM OR PIVOT; enterprise readiness ~35-40%) found six defects nobody had recorded (F-P01..F-P06) and one strategic fact: Salesforce Open CTI — the entire in-org surface — is in maintenance mode, EoL 28 Feb 2028, closed to new Agentforce Service orgs (verified 20 Sep against help.salesforce.com 005306437; R-V21 CRITICAL; D18 OVERTAKEN, D-V2 DISSOLVED). Direction from Senthil (20 Sep 10:45): enterprise grade, do not shrink scope, keep everything in the tracker. Executed: ALL of S14 (VB-E-010..017 — widget served + VB_CONFIG injected + adapter moved from static resource to host; AES-256-GCM token encryption with key ring + rotation sweep; CSP/HSTS/nosniff/body cap/inbound timeout/request ids; per-ip + per-org rate limits on a shared store proven across two instances; symmetric evidence manifest with testFiles[] and CI/deploy calling evidence:check; claim-to-test registry gate over 34 published claims; Express 5 + qs>=6.16 → 0 advisories, Node 22), the codeable halves of S19-S20 (updateWhere + detached copies on both stores; leader-elected outbox worker with backoff/dead-letter/metrics; transactional counted caps closing R-V15; structured JSON logs, RED metrics, /metrics, error sink, 500-not-400 for internal faults; SLO error budget + burn-rate alert rules; real blue/green deploy.yml + script with migration/health gates and auto-rollback; DR drill script), S25-S26 (Postgres RLS with per-transaction tenant context + superuser refusal + CI smoke as an app role; hash-chained append-only audit with /audit/verify; session jti/revocation/epoch, logout, revoke-all, role assignment revoking sessions, TTL 7→1 day; contacts from config, DPA template), and the provider-independent parts of S15-S16 (E.164 + per-country rules + blocklist + DNC seam before any dial; SOSL phone-index matching with ambiguity never resolved by guessing). FOUR MORE DEFECTS FOUND BY THE WORK ITSELF: F-V31 (dialer/cadence/supportChat/designPartners mutated detached copies — on Postgres no call ever ended), F-V32 (coaching.snapshot stored a Promise — '{}' in production), F-V33 (the CI scripts type-check step could never have passed), F-V34 (evidence gate false positive on build output). WhatsApp claim WITHDRAWN from HC-05 pending D-V6; listing copy D-V6-gated. NOT built: provider adapter (D-V5), WhatsApp (D-V6), Partner Telephony package (D-V8 + dev org), AI layer (needs recordings), pen test/SOC 2/DPA execution (vendor/legal). 58 suites / 613 tests at 100% ×4, zero pragmas, 0 advisories, evidence bound to package hash f0f4eb4ab67d, zip verified from a clean extraction (build → typecheck:scripts → evidence:check → suite). New sheet Enhancement_Plan carries S13-S29 (VB-E-001..105) with live status. Story position held at 96/100 pending D-V4 (reviewer and this release both recommend (a) reclassify → 76/100). G-06 still REJECT; new G-07 (Perplexity) HOLD. | E27: Released
A28: v025 | D28: PLANNED: opens on the S13 decision gate — D-V8 strategy ruling (A/B/C), D-V9 Open CTI confirmation (partner case), D-V5 provider, D-V6 WhatsApp, D-V7 model rebuild (Financial_Model_v2), D-V4 reclassification — or on operator steps O6/O7/O7b/O9/O10 producing live evidence. | E28: Planned

Sheet Sprint_Tracker_Log
A1: SPRINT TRACKER LOG — every execution event, newest last
A2: ID | B2: Date/Time | C2: Sprint | D2: What happened | E2: Refs | F2: State changes | G2: Blockers | H2: Next
A3: E001 | B3: 2026-09-10 23:00 | C3: — | D3: D17 RECORDED — Senthil instruction 23:00: 'continue work as per sprint... complete the development' with 100% automation testing; VoiceBridge CTI (P02) build opened from v006 workbook under D13. Ninth concurrent build; D15 (sequencing mode) still open. | E3: D13,D15,D17 | F3: VoiceBridge S1 opened | G3: None | H3: S1 build
A4: E002 | B4: 2026-09-10 23:00 | C4: S1 | D4: S1 FOUNDATION BUILT (TypeScript/Node/Express per v006 stack assumption, D18): config w/ secrets fail-fast + Hyperforce region, typed Store repository (R-V4), Connected-App OAuth install→welcome, uninstall token-wipe + retention-scheduled deletion sweep, rotation-safe token refresh, install source attribution. | E4: ST-051,ST-052,ST-055,ST-056 | F4: 4 S1 stories Done-in-code (13 pts) | G4: Live dev-org install = Senthil (ISV agreement + Connected App) | H4: E003
A5: E003 | B5: 2026-09-10 23:00 | C5: S2 | D5: S2 CORE PT-1 — click-to-dial dial state machine (dialing→connected→ended/failed, outcome capture, E.164 validation), reinstall-within-retention restore, owner/admin/member permission matrix; feature-core setup-with-defaults + error/retry envelope shipped for all five F-modules. | E5: ST-001..004,ST-053,ST-054 | F5: 6 S2 stories Done (29 pts) | G5: None | H5: E004
A6: E004 | B6: 2026-09-10 23:00 | C6: S3 | D6: S3 CORE PT-2 + F2 START — F1 completed (utility-bar surface, metrics, permissions+audit, pause-no-data-loss, import, notifications); auto call/WhatsApp logging built: provider-event ingestion deduped by externalId → activity records, contact threads; D13 coverage gate story closed (100% supersedes >=70%). | E6: ST-005..014,ST-085 | F6: 11 S3 stories Done (47 pts) | G6: None | H6: E005
A7: E005 | B7: 2026-09-10 23:00 | C7: S4 | D7: S4 MVP LOOP — F2 completed; activation funnel (install→setup→aha→habit), release-tagged error tracking + spike alert, E2E smoke suite wired as CI deploy gate. MVP loop (install→setup→dial→auto-log) usable end-to-end in E2E harness. | E7: ST-015..020,ST-071,ST-072,ST-086 | F7: 9 S4 stories Done (34 pts) | G7: None | H7: E006
A8: E006 | B8: 2026-09-10 23:00 | C8: S5 | D8: S5 CADENCE + ALPHA HARDENING — cadence/sequence lite: step sequences w/ cumulative delays, enrollment, due-step engine, advance-to-complete; first-run checklist reaching aha at 3/4 steps; teaching empty states on all surfaces. | E8: ST-021..030,ST-078,ST-079 | F8: 12 S5 stories Done (50 pts) | G8: Internal dogfood needs live org | H8: E007
A9: E007 | B9: 2026-09-10 23:00 | C9: S6 | D9: S6 BILLING + COACHING — coaching scorecards (connect rate, avg duration, leaderboard, zero-guards); 14-day no-card trial + banner; mid-cycle proration. ST-059 provider abstraction (AppExchange Checkout | Stripe fallback) CODE-COMPLETE — live Checkout wiring needs ISV agreement. | E9: ST-031..040,ST-057..059 | F9: 12 Done + 1 code-complete (60 pts) | G9: ISV agreement = Senthil | H9: E008
A10: E008 | B10: 2026-09-10 23:00 | C10: S7 | D10: S7 BILLING EDGE + TRUST — dunning (7d grace, 3 emails, read-only), plan limits w/ 80%/100% prompts, GST/VAT invoices, cancellation save-offer + exit survey; least-privilege scope map doc (scopes 1:1 features). | E10: ST-060..064 | F10: 5 S7 stories Done (15 pts) | G10: None | H10: E009
A11: E009 | B11: 2026-09-10 23:00 | C11: S8 | D11: S8 FLOW PACK + SCALE — Flow actions pack (StartCall / EnrollInCadence / SendNotification invocables, validated inputs, run ledger incl. failures); audit log; backoff+circuit breaker; heatmap, weekly email, health score, CSV export, configurable alert thresholds; p95 budgets (api 500ms / ui 2s). ST-082 review-ask + ST-069 export/delete-my-data pulled early. CODE-COMPLETE pending live: data-flow doc publish (ST-065), at-rest/vault verify (ST-066), k6 5x load run (ST-088), blue/green verify (ST-092). | E11: ST-041..050,ST-065..067,ST-069,ST-070,ST-073..077,ST-082,ST-087,ST-088,ST-092 | F11: 18 Done + 4 code-complete (87 pts) + 2 pulled-early stories | G11: Live infra = Senthil | H11: E010
A12: E010 | B12: 2026-09-10 23:00 | C12: — | D12: D13 TEST GATE MET — 20 Jest suites / 85 tests, coverage 100% statements/branches/functions/lines (jest coverageThreshold 100x4, CI-enforced); tsc --noEmit clean; E2E smoke + blue/green jobs in ci.yml; k6 harness at load/k6-load.js. | E12: D13 | F12: Evidence in Traceability col K | G12: None | H12: E011
A13: E011 | B13: 2026-09-10 23:00 | C13: — | D13: RELEASE — this tracker v001 + product workbook v007 (Full_Backlog statuses updated; Sprint_Board Done counts now live COUNTIFS; tracker sheets embedded). Next sprint S9 (marketplace review prep) blocked on live-org items. | E13: D17 | F13: v001 + v007 released | G13: S1-live items; D15; D18 | H13: v002
... A133: E131 | B133: 2026-09-20 10:45 | C133: S14 | D133: D13 GATE MET + PACKAGED + VERIFIED FROM THE ZIP. 58 suites / 613 tests, 100% statements, branches, functions and lines, zero pragmas, 0 production advisories at any severity. Evidence regenerated and bound: RUN_STAMP 2026-09-20T11:02:23Z, package hash f0f4eb4ab67d. voicebridge-cti-codebase-20260920_1045.zip extracted to a clean directory: npm ci → npm run build → npm run typecheck:scripts → npm run evidence:check → full suite, all green. REVIEW_PACK addendum lists the ten things a second reviewer should try. Story position unchanged at 96/100 on purpose (D-V4). G-06 stays REJECT (VB-CR-005 telephony half, VB-CR-008); G-07 (Perplexity) opens at HOLD. | E133: D13,VB-CR-009,G-06,G-07 | F133: v0.28.0 released and verified | G133: D-V4..D-V9 | H133: v025

Sheet Decisions
A1: DECISIONS (tracker scope)
A2: ID | B2: Decision | C2: Rationale | D2: Decided by | E2: Status
A3: D13 | B3: (Portfolio-wide) Discovery interviews parked; development proceeds with 100% automation test coverage on all code (supersedes >=70% gate). | C3: Senthil 10 Sep 20:45; applied to VoiceBridge per 23:00 instruction. | D3: Senthil | E3: LOCKED
A4: D15 | B4: Sequencing mode — parallel builds vs WIN-order swap — while rank-1 (RevRescue) completion gate unmet. | C4: Nine products now built done-in-code same evening; R1 serial rule formally intact until ratified. | D4: Senthil (mode ratification pending) | E4: OPEN — pick (a) or (b)
A5: D17 | B5: VoiceBridge (P02) build opened 10 Sep 23:00 from v006 workbook while rank-1 gate unmet. | C5: Senthil instruction 'continue work as per sprint... complete the development'; ninth concurrent build. | D5: Senthil | E5: LOCKED
A6: D18 | B6: Stack = TypeScript/Node/Express per v006 ReadMe stack assumption. FLAG: AppExchange packaging decision needed — Open CTI softphone adapter is JS in-org, but security review scope depends on managed-package vs connected-app-only architecture (Launch #3/#4). | C6: Follows workbook; provider-agnostic dial core keeps both paths open; decide with ISV onboarding. | D6: Claude — recommendation documented (docs/d18-packaging-decision.md): hybrid-minimal 2GP shim package, zero Apex | E6: OVERTAKEN (20 Sep, R-V21) — Open CTI in maintenance mode, EoL 28 Feb 2028; the packaging question re-opens under D-V8. Kept for the record; shim now = CallCenter + Task field + permsets (adapter served from host, F-P01)
A7: D-V1 | B7: Chat vendor decision deferred: built-in SLA engine (Mon-Fri 9-18 IST, 4-business-hr first response) ships as-is; vendor swap is config-level later. | C7: TeleField S10 precedent; avoids a procurement blocker on the listing path. | D7: Claude — flagged for Senthil | E7: OPEN for ratification
A8: D-V2 | B8: Surface architecture — LWC bundles in the package vs static-resource/web surface only. | C8: Five P0 story texts demand an LWC surface; D18's hybrid-minimal recommendation forbids one to keep security-review scope small. GAP-V2 forced the contradiction into the open. The 7 screens built in v0.14.0 are valid under either ruling. | D8: Senthil | E8: DISSOLVED (20 Sep, R-V21) — neither LWC nor static resource if the Open CTI surface itself retires; the 7 screens built in v0.14.0 are valid under any option
A9: D-V3 | B9: Billing route — AppExchange Checkout vs ISVforce licence + Channel Order Application (COA). | C9: VER-V10 verified Checkout is optional, not mandatory. Checkout automates licensing with the LMA and collects revenue share at purchase; ISVforce+COA means billing on your own paper with every order reported to Salesforce. 15% rev share either way (25% OEM). ST-059's provider abstraction already supports both. | D9: Senthil | E9: OPEN — decides LC-1 urgency and the pricing page copy
A10: D-V4 | B10: Story-status semantics after external review V001: do ST-001..020 stay "Done" or move to "Prototype (code-only)" until a telephony provider and Salesforce write-back exist? | C10: VB-CR-005/008: the modules are built, tested and correct as state machines, but the story text promises click-to-dial and automatic logging, and neither reaches an external system. Keeping "Done" reads as product readiness; moving them is honest and moves the counted position 96/100 → 76/100 (380 → ~310 pts). | 20 Sep: the Perplexity review (VB-E-007) and this release both recommend (a) reclassify to "Code-complete (unproven)"; F-P01 showed the surface those stories promise was not even served. The DoD clause is recorded in Gate_Checklist regardless. | D10: Senthil | E10: OPEN — (a) reclassify now (RECOMMENDED by both reviewers; 96/100 → 76/100), (b) keep Done and rely on the readiness column
A11: D-V5 | B11: Telephony provider for the real dial path (closes VB-CR-005 half 1). | C11: A provider must be named before RM-04 can be built: Twilio (global, strongest docs, dearest), Exotel or Plivo (India-first, fits the mid-market ICP and IPBS experience), or Service Cloud Voice BYOT (no separate provider contract but ties us to the platform we are positioned against, per R-V2). Choice sets credentials, webhook auth, per-minute cost and the pricing floor. | 20 Sep (VB-E-003): decide on landed cost per minute for the target geography, not documentation quality — Plivo ₹0.38/min India vs Twilio ~₹3.50-5.00/min moves gross margin an order of magnitude on a $29 seat. The DNC registry vendor usually comes with the carrier. Not needed at all under option (B). | D11: Senthil | E11: OPEN — blocks RM-04
A12: D-V6 | B12: WhatsApp: build the Meta Cloud API integration now, or withdraw the claim until it exists? | C12: VB-CR-008: help article HC-05, the data-flow doc and the listing copy describe linking a WhatsApp Business number; the code only stores a caller-supplied event with channel=whatsapp. EngageOS already carries a working Cloud API pattern (opt-in ledger, 24h session window, signature verify) that could be ported. Withdrawing the claim is a one-day copy change; building is the larger half of RM-05. | 20 Sep: the reviewer recommends BUILD and lead with it (Salesforce's own path = $165 Service Cloud + $75 Digital Engagement per user/month). The unbacked claim is already WITHDRAWN from HC-05 and the listing copy is gated (VB-E-016), so "publish it unbuilt" is no longer possible either way. | D12: Senthil | E12: OPEN — blocks RM-05
A13: D-V7 | B13: Financial model response to VB-CR-014 (no breakeven inside 18 months, ≈-$750k cumulative). | C13: The model assumes $40k month-1 team cost growing 3%/mo against 4 pilots/mo and $600 ARPU. Either the cost base is wrong for a solo build, or the plan needs a stated funding requirement. Needed before RM-09 can produce base/downside/upside scenarios with a named cash-minimum month. | 20 Sep (F-P06/VB-E-005): the $600 ARPU contradicts the 50-500 seat ICP at $29/seat by 2.5-5x; no per-minute cost line exists; PLAN_SEAT_LIMIT.scale=500 equals the ICP ceiling with no enterprise/annual tier. Financial_Model_v2 = base/downside/upside, per-minute cost, funding requirement, cash-minimum month, solo-build variant, 5-9 month listing lag. | D13: Senthil | E13: OPEN — blocks RM-09
... A16: D-V10 | B16: SSO (SAML/OIDC) + SCIM (VB-E-083): is there a surface outside the Salesforce frame that needs its own identity? Today the only one is /ui/* behind the install session minted by Salesforce OAuth. Options: (a) keep it, no SSO needed — document the smaller attack surface; (b) add SSO/SCIM for a standalone admin console. | C16: The review's own framing: "if there is no such surface, delete the standalone paths so the claim surface shrinks". Recommendation (a) until a customer asks. | D16: Senthil | E16: OPEN — low urgency; document either way before LC-3

Sheet Build_Board
A1: BUILD BOARD S1-S8 — done-in-code under D13; exits pending live org marked
A2: Codebase: voicebridge-cti (TypeScript/Node/Express 5) — 57 src modules, 58 test suites / 613 tests @ 100% coverage ×4, zero pragmas, 0 advisories; CI (test → evidence:check → typecheck:scripts → migration-smoke + RLS/audit checks → security → e2e → workflow-lint) + deploy.yml blue/green
A3: ID | B3: Item | C3: Story refs | D3: Points | E3: Owner | F3: Status | G3: Notes / Evidence
A4: S1-01 | B4: Repo scaffold + CI with 100% coverage gate (D13) | C4: — | D4: 2 | E4: Claude | F4: Done | G4: jest coverageThreshold 100x4; .github/workflows/ci.yml test→e2e-smoke→deploy-blue-green. E010
A5: S1-02 | B5: Env config: secrets fail-fast, retention, Hyperforce region | C5: — | D5: 1 | E5: Claude | F5: Done | G5: src/config.ts — 4 tests; region surfaced at /health for residency statement (Launch #6).
A6: S1-03 | B6: Typed Store repository (Postgres adapter point) | C6: — | D6: 2 | E6: Claude | F6: Done | G6: src/store.ts — R-V4 constraint logged; domain code storage-agnostic.
A7: S1-04 | B7: Connected-App OAuth install → welcome state | C7: ST-051 | D7: 5 | E7: Claude | F7: Done | G7: DONE-IN-CODE — src/sfAuth.ts exchangeCode + src/lifecycle.ts install; E2E covers <2min path.
A8: S1-05 | B8: Uninstall: token wipe + deletion schedule + sweep | C8: ST-052 | D8: 3 | E8: Claude | F8: Done | G8: src/lifecycle.ts handleUninstall + retention sweep — 4 tests incl. skip/due/deleted branches.
A9: S1-06 | B9: Rotation-safe token refresh | C9: ST-055 | D9: 3 | E9: Claude | F9: Done | G9: src/sfAuth.ts refreshTokens persists rotated refresh token; keeps old when not rotated.
A10: S1-07 | B10: Install telemetry source attribution | C10: ST-056 | D10: 2 | E10: Claude | F10: Done | G10: src/lifecycle.ts + analytics install event; listing/search/referral captured.
A11: S2-01 | B11: Click-to-dial state machine + softphone core | C11: ST-001..004 | D11: 21 | E11: Claude | F11: Done | G11: src/dialer.ts — E.164 validation, dialing→connected→ended/failed, outcome defaults, retry envelopes.
A12: S2-02 | B12: Reinstall restore + permission matrix | C12: ST-053,ST-054 | D12: 8 | E12: Claude | F12: Done | G12: src/lifecycle.ts retention-window restore; src/permissions.ts owner/admin/member enforced across ops.
A13: S3-01 | B13: F1 completion: surfaces, metrics, RBAC+audit, pause, import, notify | C13: ST-005..010 | D13: 21 | E13: Claude | F13: Done | G13: featureCore.ts shared machinery + dialer specialisation; utility-bar surface flag.
A14: S3-02 | B14: Auto call/WhatsApp logging start + coverage gate story | C14: ST-011..014,ST-085 | D14: 26 | E14: Claude | F14: Done | G14: src/callLogger.ts dedupe-by-externalId ingestion; D13 100% gate closes ST-085.
... A41: PKG-03 | B41: Functional Open CTI softphone adapter + bundle | C41: R-V5,ST-089 | D41: 0 | E41: Claude | F41: Done | G41: src/softphoneAdapter.ts (DI, jsdom-tested vs mocked sforce.opencti); esbuild static resource; HTML bootstrap; live click-to-dial verify = O2.
A42: RV2-01 | B42: Cold-review pass 2 — 13 defects fixed with pinned regressions | C42: F-V08..F-V20 | D42: 0 | E42: Claude | F42: Done | G42: test/coldReview2.test.ts — 27 regressions; see Review_Findings
A43: RV2-02 | B43: External verification sweep vs live Open CTI Lightning docs | C43: VER-V01..V05 | D43: 0 | E43: Claude | F43: Done | G43: test/verificationSweep.test.ts; 2 live-blocking defects fixed before the dev-org day
A44: RV2-03 | B44: Artifact-gap audit + missing /log route built | C44: GAP-V1,F-V10 | D44: 0 | E44: Claude | F44: Done | G44: test/logRoute.test.ts — 5 supertest regressions; all other referenced artifacts verified present
A45: V14-01 | B45: 7 missing screens as view-models + accessible renderer | C45: GAP-V2,ST-079 | D45: 0 | E45: Claude | F45: Done | G45: src/views.ts — 15 tests; every screen has populated + empty state; output escaped; single h1 + labelled regions
A46: V14-02 | B46: Screen adapter over the live store/modules + /ui routes | C46: GAP-V2 | D46: 0 | E46: Claude | F46: Done | G46: src/screenData.ts + app.ts /ui/:orgId and /ui/:orgId/:screenId?format=html — 9 tests incl. 404 path
A47: V14-03 | B47: WCAG audit widened from 2 screens to all 9 | C47: ST-089 | D47: 0 | E47: Claude | F47: Done | G47: test/a11y.test.ts — 18 assertions across populated + empty states; ST-089 stays In progress pending live-UI audit
A48: V14-04 | B48: ECA migration across code, docs, sweep and guide | C48: VER-V06 | D48: 0 | E48: Claude | F48: Done | G48: config/sfAuth/sweepChecks/dev-org guide/live-sweep/D18/data-flow — 'New Connected App' no longer exists in Setup
A49: V14-05 | B49: PKCE (S256) + single-use state on the install flow | C49: VER-V07 | D49: 0 | E49: Claude | F49: Done | G49: src/sfAuth.ts beginInstall/completeInstall + GET /oauth/start — 6 regressions incl. replay, forged state, expiry
A50: V14-06 | B50: Refresh-token idle timeout + rotation anomaly telemetry | C50: VER-V08 | D50: 0 | E50: Claude | F50: Done | G50: 30-day ceiling enforced in loadConfig; idle token asks for reconnect without calling the platform; NO_ROTATION recorded
A51: V14-07 | B51: Refresh-token IP allowlist config + sweep checks A9/A10 + operator O5 | C51: VER-V09 | D51: 0 | E51: Claude | F51: Done | G51: src/config.ts + src/sweepChecks.ts; sweep is now 10 auto + 5 operator steps
A52: V14-08 | B52: docs/oauth-security-controls.md + dry-run check DR-16 | C52: VER-V06..V09 | D52: 0 | E52: Claude | F52: Done | G52: Compliance artefact, operator sequence, and the warning that Review Controls attestation LOCKS the config
A53: V15-01 | B53: Server entry point: start(), PORT, graceful drain, npm start | C53: GAP-V3 | D53: 0 | E53: Claude | F53: Done | G53: src/server.ts + src/main.ts — listens, logs, drains on SIGTERM/SIGINT; tested against a real bound port
... A109: V28-19 | B109: Evidence regenerated and bound (f0f4eb4ab67d); zip verified from a clean extraction | C109: D13,VB-CR-009 | D109: 0 | E109: Claude | F109: Done | G109: 58 suites / 613 tests, 100% ×4, zero pragmas, 0 advisories

Sheet Traceability_Matrix
A1: TRACEABILITY MATRIX — 100 stories: module → epic → story → sprint → verification → status → evidence
A2: Source: v006 Full_Backlog (single source of truth). Status values: Done | Code-complete (pending live) | Backlog. | L2: Status column J is unchanged pending D-V4 (both reviewers recommend (a)); this column names the findings that bear on each story block. 20 Sep: Perplexity review V001 (F-P01..F-P06) and v0.28.0 remediation added.
A3: Story ID | B3: Epic | C3: Module / feature | D3: Story | E3: Points | F3: Priority | G3: Sprint | H3: Primary screen | I3: Verification | J3: Status | K3: Evidence | L3: External review V001 readiness (13 Sep)
A4: ST-001 | B4: F1 | C4: Click-to-dial + softphone | D4: As a RevOps lead, I can set up Click-to-dial + softphone with sensible defaults in one screen | E4: 5 | F4: P0 | G4: S2 | H4: SCR-3 Call workspace | I4: Automated (Jest, 100% cov) + E2E smoke | J4: Done | K4: src/dialer.ts.setup defaults + featureCore — dialer.test.ts | L4: PROTOTYPE (code-only), NOW LABELLED AS SUCH IN THE PRODUCT — VB-CR-005 telephony half: no adapter places the call (D-V5), so every call is marked simulated:true and the panel says so rather than reading "Ringing". The seam and the adapter contract exist (src/telephony.ts, docs/telephony-provider-decision.md). D-V4 records whether these stay counted as Done. | F-P01 (20 Sep): the softphone page those stories promise was NEVER SERVED — fixed in v0.28.0 (src/widget.ts, boot test); pre-dial E.164/blocklist/DNC refusal added (VB-E-025). Still no adapter (D-V5). R-V21: the Open CTI surface itself retires 28 Feb 2028 (D-V8). Reviewer + v0.28.0 recommend D-V4(a) → Code-complete (unproven).
A5: ST-002 | B5: F1 | C5: Click-to-dial + softphone | D5: As a RevOps lead, the Click-to-dial + softphone happy path completes without documentation | E5: 8 | F5: P0 | G5: S2 | H5: SCR-3 Call workspace | I5: Automated (Jest, 100% cov) + E2E smoke | J5: Done | K5: src/dialer.ts happy-path state machine — dialer.test.ts + app.e2e.test.ts | L5: PROTOTYPE (code-only), NOW LABELLED AS SUCH IN THE PRODUCT — VB-CR-005 telephony half: no adapter places the call (D-V5), so every call is marked simulated:true and the panel says so rather than reading "Ringing". The seam and the adapter contract exist (src/telephony.ts, docs/telephony-provider-decision.md). D-V4 records whether these stay counted as Done. | F-P01 (20 Sep): the softphone page those stories promise was NEVER SERVED — fixed in v0.28.0 (src/widget.ts, boot test); pre-dial E.164/blocklist/DNC refusal added (VB-E-025). Still no adapter (D-V5). R-V21: the Open CTI surface itself retires 28 Feb 2028 (D-V8). Reviewer + v0.28.0 recommend D-V4(a) → Code-complete (unproven).
A6: ST-003 | B6: F1 | C6: Click-to-dial + softphone | D6: As a Sales leader, I can customise Click-to-dial + softphone rules/conditions for my workflow | E6: 5 | F6: P1 | G6: S2 | H6: SCR-3 Call workspace | I6: Automated (Jest, 100% cov) + E2E smoke | J6: Done | K6: featureCore.customise rules merge — featureCore.test.ts | L6: PROTOTYPE (code-only), NOW LABELLED AS SUCH IN THE PRODUCT — VB-CR-005 telephony half: no adapter places the call (D-V5), so every call is marked simulated:true and the panel says so rather than reading "Ringing". The seam and the adapter contract exist (src/telephony.ts, docs/telephony-provider-decision.md). D-V4 records whether these stay counted as Done. | F-P01 (20 Sep): the softphone page those stories promise was NEVER SERVED — fixed in v0.28.0 (src/widget.ts, boot test); pre-dial E.164/blocklist/DNC refusal added (VB-E-025). Still no adapter (D-V5). R-V21: the Open CTI surface itself retires 28 Feb 2028 (D-V8). Reviewer + v0.28.0 recommend D-V4(a) → Code-complete (unproven).
A7: ST-004 | B7: F1 | C7: Click-to-dial + softphone | D7: As a user, Click-to-dial + softphone shows clear errors and retry paths on platform API failures | E7: 3 | F7: P0 | G7: S2 | H7: SCR-3 Call workspace | I7: Automated (Jest, 100% cov) + E2E smoke | J7: Done | K7: errors.ts retry envelope + src/dialer.ts error paths — dialer.test.ts | L7: PROTOTYPE (code-only), NOW LABELLED AS SUCH IN THE PRODUCT — VB-CR-005 telephony half: no adapter places the call (D-V5), so every call is marked simulated:true and the panel says so rather than reading "Ringing". The seam and the adapter contract exist (src/telephony.ts, docs/telephony-provider-decision.md). D-V4 records whether these stay counted as Done. | F-P01 (20 Sep): the softphone page those stories promise was NEVER SERVED — fixed in v0.28.0 (src/widget.ts, boot test); pre-dial E.164/blocklist/DNC refusal added (VB-E-025). Still no adapter (D-V5). R-V21: the Open CTI surface itself retires 28 Feb 2028 (D-V8). Reviewer + v0.28.0 recommend D-V4(a) → Code-complete (unproven).
A8: ST-005 | B8: F1 | C8: Click-to-dial + softphone | D8: As a Salesforce admin, Click-to-dial + softphone works on the Lightning utility-bar softphone + LWC surface end-to-end | E8: 5 | F8: P0 | G8: S3 | H8: SCR-3 Call workspace | I8: Automated (Jest, 100% cov) + E2E smoke | J8: Done | K8: featureCore.availableOn lightning-utility-bar — featureCore.test.ts | GAP-V2: the web screen now exists (src/views.ts, /ui route) but no LWC bundle does — status held pending D-V2 ruling + in-org proof. | L8: PROTOTYPE (code-only), NOW LABELLED AS SUCH IN THE PRODUCT — VB-CR-005 telephony half: no adapter places the call (D-V5), so every call is marked simulated:true and the panel says so rather than reading "Ringing". The seam and the adapter contract exist (src/telephony.ts, docs/telephony-provider-decision.md). D-V4 records whether these stay counted as Done. | F-P01 (20 Sep): the softphone page those stories promise was NEVER SERVED — fixed in v0.28.0 (src/widget.ts, boot test); pre-dial E.164/blocklist/DNC refusal added (VB-E-025). Still no adapter (D-V5). R-V21: the Open CTI surface itself retires 28 Feb 2028 (D-V8). Reviewer + v0.28.0 recommend D-V4(a) → Code-complete (unproven).
A9: ST-006 | B9: F1 | C9: Click-to-dial + softphone | D9: As a Sales leader, I can see Click-to-dial + softphone performance metrics and trends | E9: 3 | F9: P1 | G9: S3 | H9: SCR-3 Call workspace | I9: Automated (Jest, 100% cov) + E2E smoke | J9: Done | K9: featureCore.metrics total/24h — featureCore.test.ts | L9: PROTOTYPE (code-only), NOW LABELLED AS SUCH IN THE PRODUCT — VB-CR-005 telephony half: no adapter places the call (D-V5), so every call is marked simulated:true and the panel says so rather than reading "Ringing". The seam and the adapter contract exist (src/telephony.ts, docs/telephony-provider-decision.md). D-V4 records whether these stay counted as Done. | F-P01 (20 Sep): the softphone page those stories promise was NEVER SERVED — fixed in v0.28.0 (src/widget.ts, boot test); pre-dial E.164/blocklist/DNC refusal added (VB-E-025). Still no adapter (D-V5). R-V21: the Open CTI surface itself retires 28 Feb 2028 (D-V8). Reviewer + v0.28.0 recommend D-V4(a) → Code-complete (unproven).
A10: ST-007 | B10: F1 | C10: Click-to-dial + softphone | D10: As a user, Click-to-dial + softphone respects role permissions and audit logging | E10: 3 | F10: P1 | G10: S3 | H10: SCR-3 Call workspace | I10: Automated (Jest, 100% cov) + E2E smoke | J10: Done | K10: permissions.ts matrix + audit.ts on every admin op — permissions/audit tests | L10: PROTOTYPE (code-only), NOW LABELLED AS SUCH IN THE PRODUCT — VB-CR-005 telephony half: no adapter places the call (D-V5), so every call is marked simulated:true and the panel says so rather than reading "Ringing". The seam and the adapter contract exist (src/telephony.ts, docs/telephony-provider-decision.md). D-V4 records whether these stay counted as Done. | F-P01 (20 Sep): the softphone page those stories promise was NEVER SERVED — fixed in v0.28.0 (src/widget.ts, boot test); pre-dial E.164/blocklist/DNC refusal added (VB-E-025). Still no adapter (D-V5). R-V21: the Open CTI surface itself retires 28 Feb 2028 (D-V8). Reviewer + v0.28.0 recommend D-V4(a) → Code-complete (unproven).
A11: ST-008 | B11: F1 | C11: Click-to-dial + softphone | D11: As a RevOps lead, I can pause/disable Click-to-dial + softphone without data loss | E11: 2 | F11: P2 | G11: S3 | H11: SCR-3 Call workspace | I11: Automated (Jest, 100% cov) + E2E smoke | J11: Done | K11: featureCore.setEnabled pause, data bags untouched — featureCore.test.ts | L11: PROTOTYPE (code-only), NOW LABELLED AS SUCH IN THE PRODUCT — VB-CR-005 telephony half: no adapter places the call (D-V5), so every call is marked simulated:true and the panel says so rather than reading "Ringing". The seam and the adapter contract exist (src/telephony.ts, docs/telephony-provider-decision.md). D-V4 records whether these stay counted as Done. | F-P01 (20 Sep): the softphone page those stories promise was NEVER SERVED — fixed in v0.28.0 (src/widget.ts, boot test); pre-dial E.164/blocklist/DNC refusal added (VB-E-025). Still no adapter (D-V5). R-V21: the Open CTI surface itself retires 28 Feb 2028 (D-V8). Reviewer + v0.28.0 recommend D-V4(a) → Code-complete (unproven).
A12: ST-009 | B12: F1 | C12: Click-to-dial + softphone | D12: As a Sales leader, I can import/migrate existing data into Click-to-dial + softphone (CSV + competitor importer) | E12: 5 | F12: P1 | G12: S3 | H12: SCR-3 Call workspace | I12: Automated (Jest, 100% cov) + E2E smoke | J12: Done | K12: featureCore.importData validation report — featureCore.test.ts | L12: PROTOTYPE (code-only), NOW LABELLED AS SUCH IN THE PRODUCT — VB-CR-005 telephony half: no adapter places the call (D-V5), so every call is marked simulated:true and the panel says so rather than reading "Ringing". The seam and the adapter contract exist (src/telephony.ts, docs/telephony-provider-decision.md). D-V4 records whether these stay counted as Done. | F-P01 (20 Sep): the softphone page those stories promise was NEVER SERVED — fixed in v0.28.0 (src/widget.ts, boot test); pre-dial E.164/blocklist/DNC refusal added (VB-E-025). Still no adapter (D-V5). R-V21: the Open CTI surface itself retires 28 Feb 2028 (D-V8). Reviewer + v0.28.0 recommend D-V4(a) → Code-complete (unproven).
A13: ST-010 | B13: F1 | C13: Click-to-dial + softphone | D13: As a user, I get notifications (in-app + email) for key Click-to-dial + softphone events with per-type mute | E13: 3 | F13: P2 | G13: S3 | H13: SCR-3 Call workspace | I13: Automated (Jest, 100% cov) + E2E smoke | J13: Done | K13: notifications.ts in-app+email — notifications.test.ts | L13: PROTOTYPE (code-only), NOW LABELLED AS SUCH IN THE PRODUCT — VB-CR-005 telephony half: no adapter places the call (D-V5), so every call is marked simulated:true and the panel says so rather than reading "Ringing". The seam and the adapter contract exist (src/telephony.ts, docs/telephony-provider-decision.md). D-V4 records whether these stay counted as Done. | F-P01 (20 Sep): the softphone page those stories promise was NEVER SERVED — fixed in v0.28.0 (src/widget.ts, boot test); pre-dial E.164/blocklist/DNC refusal added (VB-E-025). Still no adapter (D-V5). R-V21: the Open CTI surface itself retires 28 Feb 2028 (D-V8). Reviewer + v0.28.0 recommend D-V4(a) → Code-complete (unproven).
A14: ST-011 | B14: F2 | C14: Auto call/WhatsApp logging | D14: As a RevOps lead, I can set up Auto call/WhatsApp logging with sensible defaults in one screen | E14: 5 | F14: P0 | G14: S3 | H14: SCR-4 Logging builder | I14: Automated (Jest, 100% cov) + E2E smoke | J14: Done | K14: src/callLogger.ts.setup defaults + featureCore — callLogger.test.ts | L14: CODE-COMPLETE PENDING LIVE (was PROTOTYPE) — v0.26.0 writes the activity back to Salesforce as a Task, matched to Contact/Lead, idempotent on an external id. Verified against doubles only: operator step O7 proves it in an org (R-V20). WhatsApp remains VB-CR-008: no provider, no webhook, no send. | v0.28.0: matching moved to the platform phone index with ambiguity written unattached (VB-E-031); outbox now drains itself with backoff + dead-letter (F-P03); F-V31 — on Postgres no call ever ENDED before this release (transition mutated a detached copy). Live proof still O7. D-V4(a) recommended.
A15: ST-012 | B15: F2 | C15: Auto call/WhatsApp logging | D15: As a RevOps lead, the Auto call/WhatsApp logging happy path completes without documentation | E15: 8 | F15: P0 | G15: S3 | H15: SCR-4 Logging builder | I15: Automated (Jest, 100% cov) + E2E smoke | J15: Done | K15: src/callLogger.ts happy-path state machine — callLogger.test.ts + app.e2e.test.ts | L15: CODE-COMPLETE PENDING LIVE (was PROTOTYPE) — v0.26.0 writes the activity back to Salesforce as a Task, matched to Contact/Lead, idempotent on an external id. Verified against doubles only: operator step O7 proves it in an org (R-V20). WhatsApp remains VB-CR-008: no provider, no webhook, no send. | v0.28.0: matching moved to the platform phone index with ambiguity written unattached (VB-E-031); outbox now drains itself with backoff + dead-letter (F-P03); F-V31 — on Postgres no call ever ENDED before this release (transition mutated a detached copy). Live proof still O7. D-V4(a) recommended.
... A73: ST-070 | B73: E6 | C73: Security & compliance | D73: Rate-limit backoff + circuit breaker on platform APIs | E73: 5 | F73: P0 | G73: S8 | H73: SCR-6 Settings | I73: Automated (Jest, 100% cov) + E2E smoke | J73: Done | K73: src/sfClient.ts exp backoff+jitter + circuit breaker — sfClient.test.ts | v006: F-V06 fixed: real backoff sleep by default; F-V05 FIFO ledger caps | L73: PARTLY CLEARED 19:26 — VB-CR-004/009/010 FIXED; VB-CR-013 MITIGATED with a dated acceptance (Express 5 decision open).
A74: ST-071 | B74: E7 | C74: Analytics & telemetry | D74: Activation funnel events (install->setup->aha->habit) in one dashboard | E74: 5 | F74: P0 | G74: S4 | H74: SCR-8 Analytics | I74: Automated (Jest, 100% cov) + E2E smoke | J74: Done | K74: src/analytics.ts funnel install→setup→aha→habit — analytics.test.ts
A75: ST-072 | B75: E7 | C75: Analytics & telemetry | D75: Error tracking with release tagging; alert on error-rate spike | E75: 3 | F75: P0 | G75: S4 | H75: SCR-8 Analytics | I75: Automated (Jest, 100% cov) + E2E smoke | J75: Done | K75: src/analytics.ts trackError release-tagged + errorSpike alert — analytics.test.ts
A76: ST-073 | B76: E7 | C76: Analytics & telemetry | D76: Feature-usage heatmap for roadmap decisions | E76: 3 | F76: P2 | G76: S8 | H76: SCR-8 Analytics | I76: Automated (Jest, 100% cov) + E2E smoke | J76: Done | K76: src/analytics.ts heatmap over feature bags — analytics.test.ts
A77: ST-074 | B77: E7 | C77: Analytics & telemetry | D77: Weekly automated metrics email to team | E77: 2 | F77: P2 | G77: S8 | H77: SCR-8 Analytics | I77: Automated (Jest, 100% cov) + E2E smoke | J77: Done | K77: src/analytics.ts weeklyEmail body — analytics.test.ts
A78: ST-075 | B78: E7 | C78: Analytics & telemetry | D78: Health score computed per account (usage+billing+support) | E78: 5 | F78: P1 | G78: S8 | H78: SCR-8 Analytics | I78: Automated (Jest, 100% cov) + E2E smoke | J78: Done | K78: src/analytics.ts healthScore usage+billing+support — analytics.test.ts
A79: ST-076 | B79: E7 | C79: Analytics & telemetry | D79: Metrics export to CSV/warehouse for founder analysis | E79: 3 | F79: P2 | G79: S8 | H79: SCR-8 Analytics | I79: Automated (Jest, 100% cov) + E2E smoke | J79: Done | K79: src/analytics.ts exportCsv — analytics.test.ts
A80: ST-077 | B80: E7 | C80: Analytics & telemetry | D80: Alert thresholds configurable (activation drop, error spike, churn signal) | E80: 3 | F80: P2 | G80: S8 | H80: SCR-8 Analytics | I80: Automated (Jest, 100% cov) + E2E smoke | J80: Done | K80: src/analytics.ts setThresholds configurable — analytics.test.ts
A81: ST-078 | B81: E8 | C81: Onboarding & support | D81: First-run checklist reaches aha-moment in <1 day | E81: 5 | F81: P0 | G81: S5 | H81: SCR-1/9 | I81: Automated (Jest, 100% cov) + E2E smoke | J81: Done | K81: src/onboarding.ts checklist aha at 3/4 steps — onboarding.test.ts
A82: ST-079 | B82: E8 | C82: Onboarding & support | D82: Empty states teach next action on every screen | E82: 3 | F82: P1 | G82: S5 | H82: SCR-1/9 | I82: Automated (Jest, 100% cov) + E2E smoke | J82: Done | K82: src/views.ts — all 7 web screens carry an empty state naming the next action (test/views.test.ts asserts it per screen); widget shells unchanged. GAP-V2 closed the 2-of-9 gap.
A83: ST-080 | B83: E8 | C83: Onboarding & support | D83: Help center with 15 launch articles + search | E83: 5 | F83: P1 | G83: S10 | H83: SCR-1/9 | I83: Automated (Jest, 100% cov) + E2E smoke | J83: Done | K83: src/helpCenter.ts + test — 15 launch articles (getting-started→troubleshooting) + title-weighted token search, /help routes; e2e verified
A84: ST-081 | B84: E8 | C84: Onboarding & support | D84: In-app chat with <4 business-hr first response | E84: 3 | F84: P0 | G84: S10 | H84: SCR-1/9 | I84: Automated (Jest, 100% cov) + E2E smoke | J84: Done | K84: src/supportChat.ts + test — built-in chat with <4-business-hr SLA engine (Mon-Fri 9-18 IST, weekend/night rollover math tested), breach flags, operator queue; vendor decision deferred — engine works as-is (TeleField precedent) | L84: F-V31 (20 Sep): supportChat.respond mutated a detached copy — on Postgres no ticket was ever marked responded; fixed.
A85: ST-082 | B85: E8 | C85: Onboarding & support | D85: In-app review ask after aha-moment (marketplace rating engine) | E85: 3 | F85: P1 | G85: S11 | H85: SCR-1/9 | I85: Automated (Jest, 100% cov) + E2E smoke | J85: Done | K85: src/onboarding.ts shouldAskReview once-after-aha — onboarding.test.ts (built early with E8)
A86: ST-083 | B86: E8 | C86: Onboarding & support | D86: Demo video (2 min) + interactive sandbox/demo data mode | E86: 5 | F86: P1 | G86: S10 | H86: SCR-1/9 | I86: Integration test + manual QA | J86: Code-complete (pending live) | K86: src/demoMode.ts + test — isolated demo- namespace seeding (5 calls, 3 WA threads, live cadence, 2 enrollments), idempotent re-seed, real-org write guard; VIDEO half needs live-org capture (launch/asset-plan.md script ready)
A87: ST-084 | B87: E8 | C87: Onboarding & support | D87: Status page + incident comms template | E87: 2 | F87: P2 | G87: S10 | H87: SCR-1/9 | I87: Automated (Jest, 100% cov) + E2E smoke | J87: Done | K87: src/statusPage.ts + test — public status from breaker state (platform-bound components degrade, dial/billing stay up) + investigating/identified/resolved incident template | L87: v0.28.0: /status/slo publishes the error budget and importable burn-rate alert rules behind the 99.5% (VB-E-055).
A88: ST-085 | B88: EQ | C88: Quality engineering | D88: Unit+integration test coverage gate ≥70% on core modules | E88: 5 | F88: P0 | G88: S3 | H88: — | I88: Automated (Jest, 100% cov) + E2E smoke | J88: Done | K88: jest coverageThreshold 100x4 (D13 supersedes >=70) — CI fails below 100% | L88: CLEARED 19:26 — VB-CR-006/009/010 FIXED; migration smoke and evidence integrity now run in CI. | v0.28.0: CI gained evidence:check, typecheck:scripts (F-V33 — the old step could never pass), RLS + audit DB checks, actionlint; the echo deploy job is gone.
A89: ST-086 | B89: EQ | C89: Quality engineering | D89: E2E smoke suite runs on every deploy | E89: 5 | F89: P0 | G89: S4 | H89: — | I89: Automated (Jest, 100% cov) + E2E smoke | J89: Done | K89: test/app.e2e.test.ts smoke + ci.yml e2e-smoke job gating deploy | L89: CLEARED 19:26 — VB-CR-006/009/010 FIXED; migration smoke and evidence integrity now run in CI. | v0.28.0: CI gained evidence:check, typecheck:scripts (F-V33 — the old step could never pass), RLS + audit DB checks, actionlint; the echo deploy job is gone.
A90: ST-087 | B90: EQ | C90: Quality engineering | D90: p95 latency budgets defined and monitored per surface | E90: 3 | F90: P0 | G90: S8 | H90: — | I90: Automated (Jest, 100% cov) + E2E smoke | J90: Done | K90: src/analytics.ts p95WithinBudget api 500ms / ui 2000ms — analytics.test.ts | L90: CLEARED 19:26 — VB-CR-006/009/010 FIXED; migration smoke and evidence integrity now run in CI.
A91: ST-088 | B91: EQ | C91: Quality engineering | D91: Load test at 5x expected launch traffic | E91: 5 | F91: P1 | G91: S8 | H91: — | I91: Automated (Jest, 100% cov) + E2E smoke | J91: Code-complete (pending live) | K91: load/k6-load.js 5x-launch harness (100 rps, p95<500) — LIVE run pending infra | L91: CLEARED 19:26 — VB-CR-006/009/010 FIXED; migration smoke and evidence integrity now run in CI.
A92: ST-089 | B92: EQ | C92: Quality engineering | D92: Accessibility WCAG AA pass on primary flows | E92: 3 | F92: P1 | G92: S9 | H92: — | I92: Automated (Jest, 100% cov) + E2E smoke | J92: Done | K92: test/a11y.test.ts — jest-axe over ALL 9 screens x populated+empty (18 assertions), was 2 screens. Stays In progress: live-UI/screen-reader pass is Senthil's half. | L92: CLEARED 19:26 — VB-CR-006/009/010 FIXED; migration smoke and evidence integrity now run in CI.
A93: ST-090 | B93: EQ | C93: Quality engineering | D93: Backup + restore drill executed | E93: 3 | F93: P1 | G93: S9 | H93: — | I93: Automated (Jest, 100% cov) + E2E smoke | J93: Done | K93: src/backup.ts + test/backup.test.ts — snapshot→wipe→restore drill, sha256 integrity verify, divergence blocks ship; live pg variant scripted (live-sweep step 9) | L93: CLEARED 19:26 — VB-CR-006/009/010 FIXED; migration smoke and evidence integrity now run in CI. | v0.28.0 VB-E-057: scripts/dr-drill.sh — live pg_dump/pg_restore with checksum diff and measured RTO; execution = O9.
A94: ST-091 | B94: EQ | C94: Quality engineering | D94: Chaos test: platform API outage degrades gracefully with user comms | E94: 3 | F94: P2 | G94: S9 | H94: — | I94: Automated (Jest, 100% cov) + E2E smoke | J94: Done | K94: src/resilience.ts + /status route + chaos e2e — breaker-driven degraded mode, user banner, queued-writes comms, auto-recovery | L94: CLEARED 19:26 — VB-CR-006/009/010 FIXED; migration smoke and evidence integrity now run in CI.
A95: ST-092 | B95: EQ | C95: Quality engineering | D95: Zero-downtime deploy verified (blue/green or rolling) | E95: 3 | F95: P2 | G95: S8 | H95: — | I95: Automated (Jest, 100% cov) + E2E smoke | J95: Code-complete (pending live) | K95: ci.yml deploy-blue-green job — LIVE slot-swap verification pending infra | L95: CLEARED 19:26 — VB-CR-006/009/010 FIXED; migration smoke and evidence integrity now run in CI. | v0.28.0 VB-E-056: real blue/green pipeline (deploy.yml + script) with migration gate, health gates incl. the widget route, automatic rollback; R-V15 caps half closed so two instances are safe.
A96: ST-093 | B96: EL | C96: Launch & listing | D96: Marketplace listing copy A + B variants drafted and reviewed | E96: 3 | F96: P0 | G96: S9 | H96: — | I96: E2E test + demo | J96: Drafted | K96: launch/listing-copy-ab.md — variants A (outcome-led) + B (pain-led) awaiting pick | L96: D-V6 gate (20 Sep): both listing variants lead with WhatsApp logging, which does not exist; gated in launch/listing-copy-ab.md. R-V21 applies to any Open CTI wording.
A97: ST-094 | B97: EL | C97: Launch & listing | D97: 5 screenshots + 2-min demo video meet platform asset specs | E97: 5 | F97: P0 | G97: S9 | H97: — | I97: E2E test + demo | J97: Drafted | K97: launch/asset-plan.md — 5-shot list + 2-min video script per AppExchange specs; capture needs live org | L97: D-V6 gate (20 Sep): both listing variants lead with WhatsApp logging, which does not exist; gated in launch/listing-copy-ab.md. R-V21 applies to any Open CTI wording.
...

Sheet Sprint_Status_Rollup
A1: SPRINT STATUS ROLLUP — live formulas over Traceability_Matrix
A2: Do not edit computed cells. 'Done' counts Done + Code-complete (pending live). EXTERNAL REVIEW V001 (13 Sep): these are CODE STATUS counts, NOT product readiness — the AppExchange listing, security review, packaging, residency statement, managed upgrade path and independent dry-run are all still open, and VB-CR-005 means the core dial/log stories do not yet reach an external system. Read this table with Traceability_Matrix column L.
A3: Sprint | B3: Focus | C3: Stories | D3: Points | E3: Done | F3: Done points | G3: % points done | H3: RAG (manual) | I3: Exit criteria
A4: S0 | B4: Discovery & Design (2 wks) | C4: =COUNTIF(Traceability_Matrix!$G$4:$G$103,$A4) -> 0 | D4: =SUMIF(Traceability_Matrix!$G$4:$G$103,$A4,Traceability_Matrix!$E$4:$E$103) -> 0 | E4: =COUNTIFS(Traceability_Matrix!$G$4:$G$103,$A4,Traceability_Matrix!$J$4:$J$103,"Done")+COUNTIFS(Traceability_Matrix!$G$4:$G$103,$A4,Traceability_Matrix!$J$4:$J$103,"Code-complete (pending live)") -> 0 | F4: =SUMIFS(Traceability_Matrix!$E$4:$E$103,Traceability_Matrix!$G$4:$G$103,$A4,Traceability_Matrix!$J$4:$J$103,"Done")+SUMIFS(Traceability_Matrix!$E$4:$E$103,Traceability_Matrix!$G$4:$G$103,$A4,Traceability_Matrix!$J$4:$J$103,"Code-complete (pending live)") -> 0 | G4: =IF(D4=0,0,F4/D4) -> 0 | I4: PRD signed off; prototype tested with 5 target users
A5: S1 | B5: Foundation (2 wks) | C5: =COUNTIF(Traceability_Matrix!$G$4:$G$103,$A5) -> 4 | D5: =SUMIF(Traceability_Matrix!$G$4:$G$103,$A5,Traceability_Matrix!$E$4:$E$103) -> 13 | E5: =COUNTIFS(Traceability_Matrix!$G$4:$G$103,$A5,Traceability_Matrix!$J$4:$J$103,"Done")+COUNTIFS(Traceability_Matrix!$G$4:$G$103,$A5,Traceability_Matrix!$J$4:$J$103,"Code-complete (pending live)") -> 4 | F5: =SUMIFS(Traceability_Matrix!$E$4:$E$103,Traceability_Matrix!$G$4:$G$103,$A5,Traceability_Matrix!$J$4:$J$103,"Done")+SUMIFS(Traceability_Matrix!$E$4:$E$103,Traceability_Matrix!$G$4:$G$103,$A5,Traceability_Matrix!$J$4:$J$103,"Code-complete (pending live)") -> 13 | G5: =IF(D5=0,0,F5/D5) -> 1 | H5: GREEN — done-in-code; live dev-org install pending (S1-live) | I5: App installs cleanly in dev store/org; telemetry firing
A6: S2 | B6: Core feature Click-to-dial + softphone - part 1 | C6: =COUNTIF(Traceability_Matrix!$G$4:$G$103,$A6) -> 6 | D6: =SUMIF(Traceability_Matrix!$G$4:$G$103,$A6,Traceability_Matrix!$E$4:$E$103) -> 29 | E6: =COUNTIFS(Traceability_Matrix!$G$4:$G$103,$A6,Traceability_Matrix!$J$4:$J$103,"Done")+COUNTIFS(Traceability_Matrix!$G$4:$G$103,$A6,Traceability_Matrix!$J$4:$J$103,"Code-complete (pending live)") -> 6 | F6: =SUMIFS(Traceability_Matrix!$E$4:$E$103,Traceability_Matrix!$G$4:$G$103,$A6,Traceability_Matrix!$J$4:$J$103,"Done")+SUMIFS(Traceability_Matrix!$E$4:$E$103,Traceability_Matrix!$G$4:$G$103,$A6,Traceability_Matrix!$J$4:$J$103,"Code-complete (pending live)") -> 29 | G6: =IF(D6=0,0,F6/D6) -> 1 | H6: GREEN | I6: Click-to-dial + softphone happy path demoable
A7: S3 | B7: Core feature Click-to-dial + softphone - part 2 + Auto call/WhatsApp logging start | C7: =COUNTIF(Traceability_Matrix!$G$4:$G$103,$A7) -> 11 | D7: =SUMIF(Traceability_Matrix!$G$4:$G$103,$A7,Traceability_Matrix!$E$4:$E$103) -> 47 | E7: =COUNTIFS(Traceability_Matrix!$G$4:$G$103,$A7,Traceability_Matrix!$J$4:$J$103,"Done")+COUNTIFS(Traceability_Matrix!$G$4:$G$103,$A7,Traceability_Matrix!$J$4:$J$103,"Code-complete (pending live)") -> 11 | F7: =SUMIFS(Traceability_Matrix!$E$4:$E$103,Traceability_Matrix!$G$4:$G$103,$A7,Traceability_Matrix!$J$4:$J$103,"Done")+SUMIFS(Traceability_Matrix!$E$4:$E$103,Traceability_Matrix!$G$4:$G$103,$A7,Traceability_Matrix!$J$4:$J$103,"Code-complete (pending live)") -> 47 | G7: =IF(D7=0,0,F7/D7) -> 1 | H7: GREEN | I7: Click-to-dial + softphone complete with tests; Auto call/WhatsApp logging skeleton
A8: S4 | B8: Core feature Auto call/WhatsApp logging | C8: =COUNTIF(Traceability_Matrix!$G$4:$G$103,$A8) -> 9 | D8: =SUMIF(Traceability_Matrix!$G$4:$G$103,$A8,Traceability_Matrix!$E$4:$E$103) -> 34 | E8: =COUNTIFS(Traceability_Matrix!$G$4:$G$103,$A8,Traceability_Matrix!$J$4:$J$103,"Done")+COUNTIFS(Traceability_Matrix!$G$4:$G$103,$A8,Traceability_Matrix!$J$4:$J$103,"Code-complete (pending live)") -> 9 | F8: =SUMIFS(Traceability_Matrix!$E$4:$E$103,Traceability_Matrix!$G$4:$G$103,$A8,Traceability_Matrix!$J$4:$J$103,"Done")+SUMIFS(Traceability_Matrix!$E$4:$E$103,Traceability_Matrix!$G$4:$G$103,$A8,Traceability_Matrix!$J$4:$J$103,"Code-complete (pending live)") -> 34 | G8: =IF(D8=0,0,F8/D8) -> 1 | H8: GREEN — MVP loop e2e in harness | I8: MVP loop usable end-to-end internally
