Workbook

Sheet Cover_Sheet
A1: OnCall Copilot for Slack — Version Detail & Manual Test Workbook
A2: 002-MoPr08-oncall_copilot_slack
A4: Document id | B4: claude_V001_MoPr08-oncall_copilot_slack_versiondetail_manualtest
A5: Document version | B5: V001 (first issue)
A6: Issued | B6: 20 September 2026, 17:17 BST
A7: Author | B7: Claude (Anthropic) — build and verification agent
A8: Approver | B8: Senthil — product owner
A9: Product | B9: OnCall Copilot for Slack — incident declare, triage, paging, timeline and postmortem inside Slack
A10: Codebase version described | B10: v0.37.0
A11: Product workbook version | B11: v037
A12: Sprint tracker version | B12: v030
A13: Quality gate at time of issue | B13: 60 suites / 624 tests (616 run, 8 gated on a real PostgreSQL) at 100.00% statements, branches, functions and lines over src/ AND scripts/
A14: Purpose | B14: One place that answers three questions without reading the code: what has been released and why each release happened; what has NOT been released and the real reason each item is waiting; and how a person with no access to the codebase can manually verify each claim, positively and negatively.
A15: Audience | B15: Product owner, an incoming engineer, an external reviewer, and any manual tester.
... A21: Standing caveat | B21: The enterprise-ready claim is withdrawn and gate G0 is closed. Nothing in v0.37.0 moves enterprise readiness; it moves the thing under it — whether the core can host a real adapter at all.

Sheet Version_Control
A1: Version Control
A2: HOW TO USE THIS SHEET: Add one row per re-issue. Never edit a previous row. The document version in the Cover_Sheet must equal the newest row here.
A4: Doc version | B4: Date | C4: Author | D4: Change | E4: Sections affected | F4: Product state at issue | G4: Approved by
A5: V001 | B5: 20 September 2026, 17:17 BST | C5: Claude | D5: First issue. Version-by-version what/why for all 32 released versions; 14 pending versions with root-cause reasons; 17-layer completed-vs-pending map; 77 manual test cases with 321 steps, positive and negative; traceability to the PX and F finding registers. | E5: All | F5: codebase v0.37.0 / workbook v037 / tracker v030 | G5: Pending
A6: V002 | B6: (next) | D6: Reserved: re-issue after v038 so the blocked cases move from NO to Yes.

Sheet Context_and_Scope
A1: Context and Scope
A2: HOW TO USE THIS SHEET: Read before drawing any conclusion from the test sheets. In particular read the 'Out of scope' rows — an untested area here is stated, not hidden.
A4: Topic | B4: Detail
A5: The product | B5: A Slack-native incident management app. A responder types /incident, a modal collects severity and summary, the app creates a dedicated channel, posts a structured incident message, pages the on-call rotation through PagerDuty or Opsgenie, captures a timeline from the channel automatically, and drafts a postmortem from that timeline when the incident resolves.
A6: Why it exists | B6: Incident tooling lives outside the place the incident is actually handled. The wedge is that the whole loop stays in Slack, and the second wedge is a migration path off Opsgenie.
A7: Where it is | B7: Pre-revenue, pre-install. 37 codebase versions exist. Not one of them has ever run against a real Slack workspace, because no workspace credential has been issued. Everything that touches a third party is a named, health-probed stub that the production boot gate refuses by name.
A8: What 'done' means here | B8: A version is DONE when its code is merged under a 100% automated-coverage gate over src/ and scripts/, its behaviour is asserted by a test that would fail if the behaviour were removed, and the claim it supports is written down with its evidence. It does NOT mean the behaviour has been observed against a live third party.
A9: The honesty rule | B9: Every capability in this workbook is stated at the level it has actually been proven. 'Built and covered' and 'observed working live' are never merged into one word. Where a claim has not been measured, the sheet says NOT MEASURED rather than estimating.
A10: In scope of this document | B10: The 32 released versions and their reasons; the 14 pending versions and their blockers; a 17-layer view of what is complete and what is not; and a manual test pack that a person can execute by hand against the delivered zip.
A11: Out of scope — stated, not hidden | B11: Live Slack behaviour (no workspace); real payment behaviour (no Stripe keys); real paging delivery (no PagerDuty/Opsgenie account); deploy-topology behaviour such as two replicas behind a load balancer (no staging environment); human accessibility testing with a screen reader; and measured production latency. Each of these has test cases written and marked BLOCKED with the exact blocker.
A12: Known open defects at issue | B12: PX-014 — the DegradationService replay queue is in memory and nothing replays it. PX-015 — the EventReceiver retry queue is not drained at shutdown. Both are recorded in Defect_Log with owners and both are scheduled for S42.
A13: Source of truth | B13: The 'what' column of Version_Detail is taken verbatim from the released product workbook's Version_Control sheet. The 'why' column is written against the directive, review or portfolio rule that caused the release. Test cases are written against the code in oncall-copilot-v037-codebase.zip.
A14: How this relates to the diagram | B14: The status map issued alongside this workbook is the same data drawn. The 17 rows of Completed_vs_Pending are the 17 cards in its layer panel; the pending queue in its third panel is the Pending_Versions sheet.

Sheet How_To_Use_This_Workbook
A1: How To Use This Workbook
A2: HOW TO USE THIS SHEET: Start here if you do not know which sheet answers your question. The 'Read this if' column routes you in one hop.
A4: # | B4: Sheet | C4: Read this if you want to know… | D4: Purpose | E4: How to use it | F4: Maintained by
A5: 1 | B5: Cover_Sheet | C5: …exactly which build this document describes. | D5: Identifies the document, the exact product state it describes and who signed it off. | E5: Read first. Check that the codebase version here matches the zip you were given before running any test. | F5: Author on each re-issue.
A6: 2 | B6: Version_Control | C6: …what changed in this document and when. | D6: Change history of this document (not of the product). | E6: Add one row per re-issue. Never edit a previous row. The document version in the Cover_Sheet must equal the newest row here. | F6: Author
A7: 3 | B7: Context_and_Scope | C7: …what the product is and what this pack deliberately does not cover. | D7: What the product is, where it is in its life, and what this document does and does not cover. | E7: Read before drawing any conclusion from the test sheets. In particular read the 'Out of scope' rows — an untested area here is stated, not hidden. | F7: Author
A8: 4 | B8: How_To_Use_This_Workbook | C8: …which sheet to open. | D8: A map of every sheet: what it is for, how to use it, who keeps it current. | E8: Start here if you do not know which sheet answers your question. The 'Read this if' column routes you in one hop. | F8: Author
A9: 5 | B9: Version_Detail | C9: …what each released version delivered and WHY it was released. | D9: Every released version: what it delivered, why it was released, and the gate it passed. | E9: Read the WHY column first — it is the decision that caused the release. The WHAT column is taken verbatim from the product workbook, so this sheet and the product record cannot drift. Filter Findings closed to trace a defect to the release that fixed it. | F9: Claude on each release
A10: 6 | B10: Pending_Versions | C10: …what has not been built and the real reason it is waiting. | D10: Every version that has NOT happened, with the root cause of the wait — not a restatement of the task. | E10: The WHY PENDING column is the point of this sheet: it separates 'we have not written it' from 'we cannot observe it without a credential or an environment'. Sort by Blocker type to see how much is waiting on one signature. Anything owned by Senthil is an unblock action, not an engineering task. | F10: Claude weekly; owner column reviewed by Senthil
A11: 7 | B11: Completed_vs_Pending | C11: …the whole product in 17 rows, colour-coded. | D11: The whole product in 17 layers, each marked DONE, PARTIAL, BLOCKED or NOT BUILT, with what exists and what is missing and why. | E11: This is the one-screen answer to 'what is finished'. Green means built and covered by an automated test; amber means the code is complete but no third party has ever confirmed it; red means it does not exist. Read the 'what is missing and why' column before treating any amber row as done. | F11: Claude on each release
A12: 8 | B12: Test_Strategy | C12: …how these tests were designed and what they can and cannot prove. | D12: How this manual pack was designed, what it can prove, and what it cannot. | E12: Read before executing. The 'cannot prove' rows matter most: a green manual run here does not mean the product works against Slack, because no test in this pack touches Slack. | F12: Author
A13: 9 | B13: Test_Environment | C13: …what you need on your machine before you start testing. | D13: Everything needed on the machine before the first case is run. | E13: Set this up once, in order. The environment variable block is the exact string the cases assume; copy it as-is or the expected results will not match. | F13: Claude
A14: 10 | B14: Entry_Exit_Criteria | C14: …when testing may begin and when it may be called finished. | D14: The conditions that must hold before testing starts, and the conditions that let it be called finished. | E14: Tick every entry row before running case 1. At the end, every exit row must be met or explicitly waived in writing on Sign_Off — a waiver is recorded, never assumed. | F14: Author + Approver
A15: 11 | B15: Manual_Test_Cases | C15: …the test case register — one row per case. | D15: The test case register: 77 cases, one row each, positive and negative, across 20 versions. | E15: One row per case. The steps are NOT here — they are on Test_Steps, keyed by the same Test case id, because one case has many steps. Filter Type for positive vs negative, Priority for a smoke run (P0 only), and Executable to see what you can actually run today. A case whose Executable column starts with NO is blocked, not failing. | F15: Claude; re-issued with each version
A16: 12 | B16: Test_Steps | C16: …the actual click-by-click steps and the expected result at each step. | D16: The step-by-step detail: 321 numbered steps, each with the result expected at that step. | E16: Execute top to bottom within a Test case id. Stop at the first step whose expected result does not occur, record that step number on Test_Execution_Log, and do not continue the case — later steps assume the earlier ones succeeded. Look the case up on Manual_Test_Cases for its preconditions and data first. | F16: Claude; re-issued with each version
... A23: 19 | B23: Sign_Off | C23: …who accepted it. | D23: The record of who accepted this document and this test run, and on what basis. | E23: Sign only after Entry_Exit_Criteria shows every exit row met or waived. Write any waiver in full on the waiver rows — a waiver that is not written down did not happen. | F23: Approver

Sheet Version_Detail
A1: Version Detail
A2: HOW TO USE THIS SHEET: Read the WHY column first — it is the decision that caused the release. The WHAT column is taken verbatim from the product workbook, so this sheet and the product record cannot drift. Filter Findings closed to trace a defect to the release that fixed it.
A4: # | B4: Version | C4: Codebase | D4: Tracker | E4: Released | F4: Theme | G4: WHAT was done | H4: WHY it was done | I4: Quality gate / evidence | J4: Findings closed | K4: Status
A5: 1 | B5: v001-v004 | C5: — | D5: — | E5: 2026-09-05 | F5: Portfolio selection | G5: Lineage: marketplace master (868 entries) -> portfolio plan (12 products) -> wave-1 (RetainKit/ShiftDesk/EngageOS, v005) -> this product selected for wave-3 | H5: Portfolio process, not product work: 868 marketplace entries were filtered to 12 products, then to waves. OnCall Copilot was selected for wave-3. Nothing was built. | I5: Portfolio master + 12-product plan | J5: — | K5: Released
A6: 2 | B6: v007 | C6: — | D6: — | E6: 2026-09-05 19:50 | F6: Product baseline (pre-code) | G6: Full product workbook for OnCall Copilot on Slack App Directory: spec, screen inventory, 100+ story backlog, live sprint board, 18-month financial model (editable assumptions), GTM execution tasks, platform launch checklist, metric targets, risk register | H6: Portfolio rule R1: no product starts coding without a spec, a costed backlog and a financial model, so that 'done' has something to be measured against. | I6: 100-story backlog, 18-month model, launch checklist | J6: — | K6: Released
A7: 3 | B7: v008 | C7: v0.8.0 | D7: v001 | E7: 2026-09-10 22:22 | F7: First development release | G7: Development release per D13 (discovery parked, 100% automation coverage): TypeScript codebase for F1-F5 + E1/E5/E6/E7/E8/EQ; 16 Jest suites / 105 tests at 100% statements/branches/functions/lines; Sprint_Tracker_Log + Traceability_Matrix sheets added; backlog statuses updated (75 Done / 5 Code-complete / 2 In progress / 18 Backlog) | H7: Directive D13 (Senthil, 10 Sep 20:45): discovery interviews parked portfolio-wide; build instead, under a 100% automated-coverage rule that supersedes the old 70% gate. | I7: 16 suites / 105 tests at 100x4 | J7: — | K7: Released
A8: 4 | B8: v009 | C8: v0.9.0 | D8: v001 | E8: 2026-09-10 22:55 | F8: Sandbox completion | G8: Sandbox completion release: Events API receiver (signature verify, replay guard, dedupe, backoff+dead-letter queue) closing checklist #4; ST-091 graceful degradation + ST-074 scheduler Done; 7 launch-content artifacts Drafted (listing A/B, pricing FAQ, trust page, runbook, comms templates, 15 help articles, k6 script); 19 suites / 122 tests at 100% coverage; statuses now 77 Done / 5 Code-complete / 8 Drafted / 10 Backlog | H8: Close the remaining sandbox-codeable backlog and Slack launch-checklist item #4 (Events API vs Socket Mode) while credentials were still unavailable. | I8: 19 suites / 122 tests at 100x4 | J8: — | K8: Released
A9: 5 | B9: v010 | C9: v0.10.0 | D9: v002 | E9: 2026-09-10 23:10 | F9: Live readiness | G9: Live-readiness release: typed config loader, 12-step scripted live verification sweep (dry-run tested), 30-min Slack dev-workspace guide with least-privilege manifest.json + .env.example; standalone tracker v001 issued 23:03; 21 suites / 133 tests at 100% coverage; LC-1 -> Code-complete; story statuses unchanged (77/5/8/10) | H9: Make the live run turnkey so that the only thing missing is a credential: a typed config loader that fails fast, a 12-step scripted sweep, and a 30-minute setup guide. | I9: 21 suites / 133 tests at 100x4 | J9: — | K9: Released
A10: 6 | B10: v011 | C10: v0.11.0 | D10: v003 | E10: 2026-09-11 08:41 | F10: Cold review pass 1 | G10: Cold-review + ops parity release: 4 defects fixed with regressions (payment recovery, cycle reset, dedupe cap, timeline config knobs), F-005..F-008 logged in new Review_Findings sheet for disposition, REVIEW_PACK.md for external reviewer (ST-097 In progress); blue/green deploy workflow + scripted backup/restore drill (ST-092/090 Drafted); 22 suites/139 tests at 100x4; statuses 77/5/10/1/7 | H10: Adversarial self-review before claiming anything was done. Four defects found in code written days earlier. | I10: 22 suites / 139 tests at 100x4 | J10: F-001..F-004 | K10: Released
A11: 7 | B11: v012 | C11: v0.12.0 | D11: v004 | E11: 2026-09-11 12:51 | F11: Sibling-validated scope | G11: Sibling-validated scope release: ST-066 AES-256-GCM field encryption behind vault boundary (Code-complete, live infra evidence pending); ST-068 sandbox half SECURITY_EVIDENCE.md (In progress); ST-081 built-in chat + 4-business-hr SLA engine (Code-complete, vendor optional); ST-089 automated WCAG AA via jest-axe on 6 screen shells (In progress); 25 suites/156 tests at 100x4; statuses 77/6/10/3/4 — sandbox-codeable backlog exhausted | H11: Apply defect classes already found on sibling products (FlowCast crypto, chat SLA, accessibility) rather than rediscovering them here. | I11: 25 suites / 156 tests at 100x4 | J11: — | K11: Released
A12: 8 | B12: v013 | C12: v0.13.0 | D12: v005 | E12: 2026-09-13 09:54 | F12: Cold review pass 2 + platform doc verification | G12: Correctness release — cold-review pass 2 + external verification sweep. 5 pass-2 defects fixed (F-009 retention sweep never deleted, F-010 unbounded error ledger, F-011 paging partial-failure lost, F-012 foreign-timeline postmortem, F-013 CSV quoted fields) and 3 doc-verified defects fixed incl. VER-OC1 LIVE-BLOCKING 3-second slash-command ack (duplicate incident channels on the day), VER-OC2 channel naming/name_taken, VER-OC3 12h token TTL proactive refresh; VER-OC4 verified correct. Cold review now COMPLETE across all modules. 27 suites/180 tests at 100x4; story counts unchanged 77/6/10/3/4 | H12: Two lenses at once: modules skipped by pass 1, and the platform's own published contracts. The second found a live-blocking defect no test could see — Slack gives a slash command 3 seconds, and a slow declare would have created duplicate incident channels. | I12: 30 suites / ~190 tests at 100x4 | J12: F-009..F-013, VER-OC1..OC3 | K12: Released
A13: 9 | B13: v014 | C13: v0.14.0 | D13: v006 | E13: 2026-09-13 10:01 | F13: Artifact-gap closure | G13: Artifact-gap closure release: 5 gaps found by auditing every artifact the docs/scripts reference, 2 CRITICAL — no HTTP app existed behind the routes the manifest and setup guide promised (setup guide was unrunnable), and no DB schema existed behind the backup drill and retention sweep. Built router+app (5 routes, signature verification, 3s ack contract) with npm start, 5 ordered migrations with cascade deletes + parity test with npm run migrate, signed k6 fixture generator, manifest.json as a real file, pricing matrix generated from billing.ts with a drift gate. ST-088/090 -> Code-complete. 31 suites/201 tests at 100x4; statuses 77/8/8/3/4 | H13: Audit every artifact the docs, scripts and manifest reference. Two CRITICAL gaps: no HTTP app existed behind the routes the setup guide promised, and no database schema existed behind the backup drill. | I13: 5 routes + 5 migrations, parity tests | J13: GAP-OC1..OC5 | K13: Released
A14: 10 | B14: v015 | C14: v0.15.0 | D14: v007 | E14: 2026-09-13 10:22 | F14: Cold review pass 3 (HTTP/tenancy) | G14: Security/tenancy correctness release — cold-review pass 3 over the v014 HTTP surface using sibling-product defect classes. 2 CRITICAL fixed: F-014 no multi-tenancy (one service instance served every workspace; cross-tenant reads and id collisions) and F-015 OAuth CSRF (callback accepted any code, no state); plus F-016 signature-is-not-installation guard and F-017 unauthenticated health leak. VER-OC5 verified non-applicable. 32 suites/213 tests at 100x4; story counts unchanged 77/8/8/3/4 | H14: New layers inherit old blind spots: the HTTP surface was one release old and carried two CRITICAL defects that sibling products had already found elsewhere. | I14: 32 suites / 213 tests at 100x4 | J14: F-014..F-017 | K14: Released
A15: 11 | B15: v016 | C15: v0.16.0 | D15: v008 | E15: 2026-09-13 10:38 | F15: As-built re-baseline | G15: As-built re-baseline + F-018. Product_Spec, Screens_Wireframes and Metrics_Targets rewritten to match the code after nine releases of drift from the 05/09 template, recording where the product does LESS than claimed (6 of 9 screens have shells and none is data-wired; only 1 of 5 non-functional claims is met; 0 of 6 metrics reportable without the Postgres adapter). F-018 fixed: the role matrix had no assignment mechanism, so owner/admin capability was unreachable on the live surface — RoleResolver added and wired. 33 suites/222 tests at 100x4; story counts unchanged 77/8/8/3/4 | H15: The spec sheets had not been revised since 05/09, before any code existed. Nine releases of drift were corrected downward, recording where the product does LESS than claimed. | I15: Spec, screens and metrics rewritten to reality | J15: F-018 | K15: Released
A16: 12 | B16: v017 | C16: v0.17.0 | D16: v009 | E16: 2026-09-13 10:42 | F16: Persistence + dashboard API | G16: Persistence + dashboard API release (V16-06 executed). Repository contracts with in-memory AND Postgres adapters verified by one shared contract suite; funnel_events migration; activation now reportable per tenant. Dashboard read API (5 routes) closes the AB-1 code half — session-scoped tenancy, matrix-gated, member refused billing. 35 suites/243 tests at 100x4; story counts unchanged 77/8/8/3/4 | H16: Decision V16-06: telemetry and metrics could not be reported end to end without storage, so the S12 kill/continue gate would have had no evidence. | I16: 35 suites / 243 tests at 100x4 | J16: — | K16: Released
... A36: 32 | B36: v037 | C36: v0.37.0 | D36: v030 | E36: 2026-09-20 13:05 | F36: Independent review V001 remediation (Perplexity) — Phase 0 | G36: SECOND INDEPENDENT REVIEW RELEASE. Perplexity review V001 (16/09): CONTINUE at 6.1/10, 12 findings (2 BLOCKER: sync platform boundary, plan limits unenforced). Codebase v0.37.0 closes Phase 0 (PX-S0 async boundary, PX-S1 enforcement, PX-S2 gate blind spots) in the review's order: nine async platform contracts with budgets, one write gate, closed provider set with a boot-time healthcheck probe, persisted deferred work, key rotation, session revocation, frequency-safe leases, time-bounded replay window, scripts/ in the gate. 3 further defects found by audit v3 (PX-013 fixed; PX-014/015 open). 60 suites / 624 tests (616 run, 8 gated on a real Postgres) at 100% statements, branches, functions and lines over src/ AND scripts/; clean tsc over src+scripts and tests. New sheet External_Review_PX_V001; Financial_Model COMPUTED for the first time (PX-009) with a summary and sensitivities; pricing moved to workspace-size bands (D-OC8, awaiting ratification); 30 stories ST-101..ST-130 added to Full_Backlog/Traceability with every original retained; Risk_Register +5; Product_Spec, Launch_Checklist, Submission_Readiness, Metrics_Targets updated. | H36: The second independent review found what a green gate over a FIXED core still hides: a synchronous platform boundary that only stubs could satisfy, and plan limits that were enforced nowhere. Its most valuable instruction was a sequence — convert the boundary before wiring any adapter, or S38-S41 become re-work. | I36: 60 suites / 624 tests at 100x4 over src AND scripts; production refusal and development boot both asserted from the built artifact | J36: PX-001..PX-013 (12 fixed, 1 addressed) | K36: Released

Sheet Pending_Versions
A1: Pending Versions
A2: HOW TO USE THIS SHEET: The WHY PENDING column is the point of this sheet: it separates 'we have not written it' from 'we cannot observe it without a credential or an environment'. Sort by Blocker type to see how much is waiting on one signature. Anything owned by Senthil is an unblock action, not an engineering task.
A4: # | B4: Planned version | C4: Sprint | D4: Theme | E4: What it will deliver (with exit criteria) | F4: WHY IT IS PENDING (root cause) | G4: Blocker type | H4: Owner | I4: Unblock action | J4: Can start when | K4: Size
A5: 1 | B5: v038 | C5: S37 | D5: Durable data plane proven under deployment | E5: Rolling-deploy and kill -9 recovery against a real PostgreSQL; two-replica sequence-allocation soak under blue/green specifically; connection-pool exhaustion behaviour; migration rollback drill. Exit: a CI job that deploys two replicas, kills one mid-declare and asserts no lost and no duplicated incident. | F5: The code is done and the adapters are proven against a real PostgreSQL 16 in CI, but a DEPLOY TOPOLOGY does not exist: there is no environment where two replicas of this service run against one database behind a load balancer. The defect class this sprint hunts (F-033 / PX-013) only appears when two instances overlap, so a single-container test cannot produce it. | G5: Infrastructure | H5: Claude | I5: Provision a staging environment with two replicas and a managed Postgres, or run the drill locally with docker compose (2 app containers + 1 postgres) — the cheaper option and enough for the CI job. | J5: Immediately — no third party required | K5: 5-8 points
A6: 2 | B6: v039 | C6: S38 | D6: Real Slack runtime | E6: oauth.v2.access and token refresh, conversations.create, chat.postMessage, views.open, response_url delivery and users.list (for the pricing band), all behind the existing async contracts, with retry/backoff through the circuit breaker and Slack tier rate limits honoured. Exit: npm run live-sweep passes all 12 steps in a real workspace, captured as evidence. | F6: Needs a real Slack workspace, an app registration and a signing secret (SC-06). Everything else is ready: the contracts are asynchronous, budgeted, health-probed and inventoried, and the boot gate already refuses the stubs by name. This is the single highest-value item in the entire plan — it turns three amber boxes green and makes 23 stories reachable. | G6: Credential / access (SC-06) | H6: Senthil to supply, Claude to build | I6: Create a free Slack workspace, follow docs/DEV_WORKSPACE_SETUP.md (about 30 minutes), and hand over SLACK_SIGNING_SECRET, SLACK_CLIENT_ID and SLACK_CLIENT_SECRET. | J6: The day the workspace exists | K6: 13 points
A7: 3 | B7: v040 | C7: S40 | D7: Production billing | E7: Stripe customer, checkout, subscription and webhooks with idempotency keys and signature verification; dunning; grace to read-only transition; invoices and tax; proration on band changes. Exit: one real test charge, one real failed payment driving the account read-only, and one real reactivation, all asserted end to end. | F7: Needs Stripe test-mode keys (SC-07). The billing state machine, the entitlement gate, the dunning clock and the read-only enforcement are all built and tested; only the payment provider itself is a fake that approves everything — and the boot gate refuses that fake in production. | G7: Credential / access (SC-07) | H7: Senthil to supply, Claude to build | I7: Create a Stripe account in test mode and hand over STRIPE_SECRET_KEY and STRIPE_WEBHOOK_SECRET. | J7: After v039 (a paid install needs a working install) | K7: 8 points
A8: 4 | B8: v041 | C8: PX-S3 | D8: Opsgenie migration wedge | E8: Opsgenie importer (schedules, escalation policies, teams, integrations), a mapping report showing the customer exactly what will and will not transfer, a dry-run mode, and a migration landing page. Exit: a real Opsgenie export imported into a real workspace with a diff report. | F8: Two things: decision D-OC7 has not been ratified, and there is no representative Opsgenie export to import. Commercially this is the sharpest asset in the plan and it has an expiry date — Atlassian ends Opsgenie support on 5 April 2027, so the installed base is re-buying now. | G8: Decision (D-OC7) + sample data | H8: Senthil to ratify, Claude to build | I8: Ratify D-OC7 (recommended: yes) and obtain one anonymised Opsgenie export — from a design partner, or from a trial Opsgenie account. | J8: After v039; earlier than S41 by deliberate choice | K8: 8-13 points
A9: 5 | B9: v042 | C9: S41 | D9: Paging ecosystem | E9: PagerDuty Events API v2, Jira Service Management, Compass and a generic webhook behind the widened provider type, with per-responder outcome reporting and retry that never double-pages. | F9: Needs vendor accounts to certify against. The provider union, the config validation, the fan-out logic and the degraded user comms are all built; only the HTTP calls are missing. Deliberately sequenced AFTER the Opsgenie importer, because the importer is the reason a stranger installs. | G9: Vendor accounts | H9: Claude | I9: Create free PagerDuty and JSM developer accounts; Compass and the generic webhook need no account. | J9: After v041 | K9: 8 points
A10: 6 | B10: v043 | C10: S42 | D10: SRE, observability, HA and DR | E10: Structured JSON logs with tenant and incident correlation ids, OpenTelemetry traces across the async boundary (now possible), SLOs with error budgets, canary deploys, an automated restore-from-backup drill, a chaos test that kills Postgres mid-declare, and p95 measured on a real staging URL instead of in-process. Also closes PX-014 (the degradation replay queue is in memory and nothing replays it) and PX-015 (the receiver retry queue is not drained at shutdown). | F10: Needs somewhere to observe: a staging deployment, a log sink and a tracing backend. The two known defects are honest carry-overs found by our own audit tool, not by a reviewer, and both are low-risk today — the replay queue only fills during a platform outage, and the receiver queue never fills because the runtime handler cannot fail. | G10: Infrastructure | H10: Claude | I10: Stand up staging (shared with v038) plus any OTel-compatible backend; the two queue defects can be fixed locally before that. | J10: The queue fixes now; the rest after v038 | K10: 8-13 points
A11: 7 | B11: v044 | C11: S43 | D11: Security and enterprise identity | E11: KMS or secrets manager behind the existing SecretsVault contract; SAML and OIDC; SCIM provisioning; security headers and CSP; audit-log export; SBOM and image signing; and a decision on the UNLICENSED package licence. | F11: Three separate blockers: no cloud account for a KMS, no identity provider to test SAML/OIDC/SCIM against, and no licence decision. The rotation PATH already shipped in v0.37.0 (multi-key vault, POST /ops/rotate-keys, stale-key boot warning), so the KMS is an adapter swap rather than a design. | G11: Infrastructure + decision | H11: Claude + Senthil (licence) | I11: Pick a cloud (AWS KMS / GCP KMS / Vault), provide a test IdP (Okta and Auth0 both have free developer tiers), and decide the licence. | J11: KMS any time; IdP work after v039 | K11: 13 points
A12: 8 | B12: v045 | C12: S44 | D12: Enterprise Grid and organisation model | E12: Organisation-to-workspace hierarchy, Grid install flow, delegated admins, shared integrations and scale quotas. | F12: Needs a Slack Enterprise Grid tenant, which is not available on a free plan. Nothing can be verified without one, and guessing at Grid semantics is how the F-014 tenancy class appeared in the first place. | G12: Platform access (paid tier) | H12: Claude + a Grid tenant | I12: Obtain a Slack Enterprise Grid sandbox (via the Slack partner programme) or defer Grid support out of v1 and say so in the listing. | J12: After v039 | K12: 8-13 points
A13: 9 | B13: v046 | C13: S45 | D13: AI incident intelligence — the differentiator | E13: Evidence-linked postmortems where every assertion cites the timeline event that supports it; similar-incident retrieval across the workspace's own history; prompt-injection controls and PII redaction before anything leaves the tenant; bring-your-own-model and bring-your-own-key; postmortem quality measured by a human-rated sample per release. | F13: Two blockers: an AI provider key, and a compliance question that must be answered first. Salesforce tightened the Slack API terms specifically around LLM ingestion of Slack data, so the data flow has to be designed and recorded before a single message is sent to a model. Commercially this is now the PRIMARY differentiator: the market leader gives away Slack-native declare, timeline and status page for free, so the postmortem and the memory are what is left to sell. | G13: Credential + compliance review | H13: Claude | I13: Provide an AI provider key, and read the current Slack API Terms of Service; the compliance argument is then recorded in docs/DATA_FLOW.md (a placeholder section already names this). | J13: After v039 | K13: 13 points
A14: 10 | B14: v047 | C14: S46 + S47 | D14: Integration ecosystem and Slack UX | E14: Jira/JSM, GitHub/GitLab, Datadog, Sentry, Grafana, status vendors, a webhook SDK and API tokens; plus App Home, guided setup, integration health, an on-call test button, incident templates and shortcuts. | F14: Prioritisation depends on evidence that does not exist yet: which tools the design partners actually run, and where real users drop out of the funnel. Building these on a guess is how the 29 unreachable capabilities happened at v020. | G14: Evidence (design partners) | H14: Claude + user research | I14: Run S49 first; the interview script should capture the integration stack and the activation drop-off. | J14: After v048 (S49) | K14: 13 points
A15: 11 | B15: v048 | C15: S48 | D15: Compliance and procurement pack | E15: Data-processing agreement, subprocessor list, security whitepaper, vulnerability SLA, BCP/DR plan and a SOC 2 control map — with a rule that every claim cites the enforcing code path or the sprint that will build it. | F15: Needs legal and security review, and it is deliberately last of the enterprise band: writing a procurement pack before S42-S44 close would produce exactly the class of unenforced promise that three separate reviews have already found in this product. | G15: Legal / security review | H15: Claude + legal | I15: Engage a legal reviewer once S42-S44 are closed. | J15: After v043-v045 | K15: 8 points
A16: 12 | B16: v049 | C16: S49 | D16: Design-partner and pricing validation | E16: Fifteen interviews, five design partners, Opsgenie-migration interviews specifically, and price tests on the BANDED model rather than the incident-metered one. Proceed only on 8/15 strong pain, 5 pilots, 3 weekly active and 2 willing to pay. | F16: Blocked by a portfolio decision, not by engineering: D13 parked discovery across all products. The computed financial model now says this plan needs 305 paying workspaces and roughly $215,000 of runway to reach a $442 monthly surplus at month 18 — and no customer has yet seen a price. This needs calendar time rather than code, so it can run in parallel with everything above. | G16: Decision (D13 vs S49) | H16: Senthil / GTM | I16: Unpark discovery for this product only, and start booking interviews this week — it is the longest lead-time item in the plan. | J16: Today, in parallel with engineering | K16: Calendar, not points
... A18: 14 | B18: v051 | C18: S51 | D18: Marketplace launch and enterprise pilots | E18: App Directory listing, migration landing page, comparison pages, case studies, two enterprise pilots and a support process. | F18: Needs the running product for screenshots and a demo video, the listing copy variant decision, and Slack's own manual review queue — which cannot be accelerated and re-triggers on any change to the app or its listing. | G18: Platform review queue + assets | H18: Senthil / Growth | I18: Prepare assets during v039-v040 so the listing can be submitted the day the live sweep passes. | J18: After v049 evidence and v050 certification | K18: Calendar

Sheet Completed_vs_Pending
A1: Completed vs Pending
A2: HOW TO USE THIS SHEET: This is the one-screen answer to 'what is finished'. Green means built and covered by an automated test; amber means the code is complete but no third party has ever confirmed it; red means it does not exist. Read the 'what is missing and why' column before treating any amber row as done.
A4: # | B4: Area | C4: Status | D4: What exists today (and is covered) | E4: What is missing, and why | F4: Unblocking sprint | G4: Evidence
A5: 1 | B5: Slack surface (slash command, declare modal, incident message, App Home) | C5: BLOCKED | D5: Every view is built and validated against Slack's published Block Kit limits and audited for accessibility before it can leave the process; the slash-command route honours the 3-second ack contract. | E5: Nothing renders the views: views.open and chat.postMessage are not written. | F5: S38 | G5: tests/blockkit, tests/http, tests/px/bootSmoke
A6: 2 | B6: Incident engine (declare, mitigate, resolve, reopen) | C6: DONE | D6: Explicit transition map refuses illegal moves; first resolution immutable so MTTR cannot drift; reopens counted; every change audited and persisted. | E6: — | F6: — | G6: tests/declare, tests/dispositions
A7: 3 | B7: Automatic timeline capture | C7: DONE | D7: Config-driven bot/reaction filters, ordered per-incident view, markdown export, foreign-incident events refused. | E7: — | F7: — | G7: tests/timeline, tests/review-pass2
A8: 4 | B8: AI postmortem draft | C8: BLOCKED | D8: Generator, blameless template, duration maths, refusal of unresolved incidents and of foreign timelines; the call runs under its own circuit breaker and latency budget so a slow model degrades the draft instead of holding the resolve. | E8: No AI provider is wired, and the Slack API terms for LLM ingestion must be read before one is. | F8: S45 | G8: tests/postmortem, tests/px/identityAndWindows
A9: 5 | B9: Responder paging | C9: BLOCKED | D9: Fan-out never abandons mid-way: every responder attempted, outcomes reported per person, retries target only failures so nobody is paged twice; five provider ids supported. | E9: PagerDuty / JSM / Compass / webhook adapters are not written. | F9: S41 | G9: tests/paging, tests/px/identityAndWindows
A10: 6 | B10: Status page publish | C10: BLOCKED | D10: Component states with worst-of rollup and platform-error surfacing. | E10: No status vendor is wired. | F10: S46 | G10: tests/statuspage
A11: 7 | B11: Multi-tenancy, roles and audit | C11: DONE | D11: One workflow bundle per workspace so no cross-tenant read or id collision is possible; roles resolved from the signed Slack user id; owner/admin/member matrix enforced on every route; audit log on every state change. | E11: — | F11: — | G11: tests/roleResolver, tests/abuse.security
A12: 8 | B12: Billing, plan limits and pricing bands | C12: DONE | D12: The limit the pricing page sells is claimed atomically on the write path, so two replicas cannot jointly exceed it; grace, dunning, read-only and cancellation all enforced; workspace-size bands replace incident metering (D-OC8). | E12: Band enforcement needs users.list to know the engineer count; Stripe itself is S40. | F12: S38 / S40 | G12: tests/px/enforcementWiring, tests/billing
A13: 9 | B13: Privacy — export, delete and retention | C13: DONE | D13: All seven tenant stores derived from one inventory so export, delete and the 30-day sweep cannot drift; the one exempt store declares its reason in the type rather than returning an empty array. | E13: — | F13: — | G13: tests/composition, tests/px/ackDurability
A14: 10 | B14: Encryption and key rotation | C14: PARTIAL | D14: AES-256-GCM per field with a random IV and verified auth tag; ciphertext is key-versioned; POST /ops/rotate-keys re-encrypts under a new current key, idempotently and resumably; boot warns while any record is on an old key. | E14: Keys come from environment variables; a managed KMS behind the same contract is not built. | F14: S43 | G14: tests/crypto, tests/px/identityAndWindows
A15: 11 | B15: Durability — restart, deploy, two replicas | C15: DONE | D15: Nine Postgres stores and 14 ordered migrations; atomic incident ids and usage claims; leases that make a daily job run once per day across five deploys; a deferred queue that survives SIGTERM and kill -9; verified against a real PostgreSQL 16 in CI. | E15: A two-replica DEPLOY has never been performed (the code is proven, the topology is not). | F15: S37 | G15: tests/px/pgStores, tests/multiReplica, tests/pgReal
A16: 12 | B16: Boot gate and composition | C16: DONE | D16: Production refuses a stub, an in-memory store, a non-durable service or an adapter that fails its healthcheck, naming each one — and is proven to permit a healthy composition. The provider set is closed and typed, so omission is a compile error. | E16: — | F16: — | G16: tests/px/providerGate, tests/px/bootSmoke
... A21: 17 | B21: Commercial — pricing validation, listing, partners | C21: PARTIAL | D21: Listing copy (A/B), pricing page, trust page, help centre, launch runbook and comms templates all drafted; the financial model is computed for the first time with sensitivities. | E21: No design partner has seen a price; listing assets need the running product; the Opsgenie importer is not started. | F21: S49, S51, PX-S3 | G21: Workbook Financial_Model, docs/LISTING_COPY.md

Sheet Test_Strategy
A1: Test Strategy
A2: HOW TO USE THIS SHEET: Read before executing. The 'cannot prove' rows matter most: a green manual run here does not mean the product works against Slack, because no test in this pack touches Slack.
A4: Topic | B4: Detail
A5: Objective | B5: Give a person without access to the codebase a way to confirm, by hand, every claim this project makes about v0.37.0 — and to falsify it if the claim is wrong.
A6: Design method | B6: Each case is written against a specific behaviour that a specific commit introduced, and each is paired: a positive case proving the behaviour happens, and where a guard exists, a negative case proving the guard fires. A guard with no negative case is treated as untested.
A7: Positive testing | B7: 34 cases. The intended path: the thing does what it should — the app boots, the command acks within the budget, the incident declares, the limit permits the write, the key rotates.
A8: Negative testing | B8: 43 cases. The refusal path: a tampered signature, a replayed request, a cross-tenant id, a revoked session, a missing key, a stub in production, a limit exceeded, a process killed mid-flight. A product of this kind is defined by what it refuses, so the negative cases outnumber the positive ones deliberately.
A9: Levels covered | B9: System and integration level, exercised through the real composition root (npm start, the built dist/, the HTTP surface, the CLI scripts and the audit tool). Unit behaviour is covered by the automated suite and is not re-tested by hand.
A10: Priorities | B10: P0 — a failure means the build must not ship (boot gate, entitlement enforcement, durability, signature verification). P1 — a failure blocks a sprint. P2 — cosmetic or documentation.
A11: Entry into a case | B11: Every case names its preconditions and test data explicitly so that two testers running it get the same result. Where a case needs a credential that does not exist, it is marked BLOCKED with the blocker id rather than being left out.
A12: What this pack CAN prove | B12: That the delivered artefact compiles from nothing; that it refuses to start in production on stubs and names every one of them; that it boots, serves and drains in development; that queued work survives SIGTERM and kill -9; that plan limits are enforced by the same path the product actually uses; that signatures, replay windows, tenancy and session revocation are enforced; that 100% coverage is real and measured over both src/ and scripts/.
A13: What this pack CANNOT prove | B13: That a message ever appears in Slack; that a card is ever charged; that a pager ever rings; that two replicas behind a load balancer behave; that the latency claim holds under real network conditions; that a screen-reader user can operate the product. Those require SC-06, SC-07, a staging environment and a human tester respectively, and they are written as BLOCKED cases so that the gap is visible rather than absent.
A14: Regression approach | B14: Every case in this pack is re-runnable against a later zip unchanged. When a case starts failing on a version where it used to pass, that is a regression and is logged in Defect_Log with the version that broke it.
A15: Relationship to the automated suite | B15: Each case names its automated equivalent where one exists. Where the automated equivalent is the stronger test (it runs on every commit), the manual case exists so that a reviewer can confirm the automated test is not lying to itself.
A16: Risks to this approach | B16: A manual pack written by the same agent that wrote the code can inherit the same blind spot. That is why the two independent external reviews are traced in Traceability_Matrix: cases derived from a review that the build did not anticipate are marked with their PX id.

Sheet Test_Environment
A1: Test Environment
A2: HOW TO USE THIS SHEET: Set this up once, in order. The environment variable block is the exact string the cases assume; copy it as-is or the expected results will not match.
A4: # | B4: Item | C4: Required value / version | D4: Why it is needed | E4: How to confirm it
A5: 1 | B5: Operating system | C5: macOS, Linux, or Windows with WSL2 | D5: The scripts are POSIX shell; the SIGTERM and kill -9 cases need real signals. | E5: uname -a
A6: 2 | B6: Node.js | C6: 20.x or 22.x | D6: package.json engines; ts-jest and the compiler API tests assume it. | E6: node -v
A7: 3 | B7: npm | C7: 10 or newer | D7: npm ci needs a lockfile-aware client. | E7: npm -v
A8: 4 | B8: The artefact | C8: oncall-copilot-v037-codebase.zip | D8: Every case is written against this exact zip. A different zip invalidates the expected results. | E8: Unpack it; docs/ and audit.mjs must be present.
A9: 5 | B9: Disk | C9: About 500 MB free | D9: node_modules plus a coverage report. | E9: df -h .
A10: 6 | B10: PostgreSQL 16 (optional) | C10: Local server, empty database, superuser or a role that can create tables | D10: 8 of the 624 automated tests and 4 manual cases are gated on a real database; without it they are skipped, not failed. | E10: psql -c 'select version()'
A11: 7 | B11: Environment variables (development) | C11: APP_ENV=development SLACK_SIGNING_SECRET=test-secret SLACK_CLIENT_ID=1.1 SLACK_CLIENT_SECRET=cs SLACK_REDIRECT_URL=https://example.com/cb DATABASE_URL=postgres://u@localhost/db STRIPE_SECRET_KEY=sk STRIPE_WEBHOOK_SECRET=wh AI_API_KEY=ai PAGING_PROVIDER=pagerduty PAGING_API_KEY=pk ENCRYPTION_KEY=local-key OPERATOR_TOKEN=op-token SESSION_SECRET=sess-secret | D11: The exact development block the cases assume. Every value is a placeholder; none is a real credential. | E11: Export it, then run npm start and read the Config line.
A12: 8 | B12: Slack workspace | C12: NOT AVAILABLE — blocker SC-06 | D12: Needed by 6 cases. Those cases are marked BLOCKED and must not be marked Fail. | E12: n/a
A13: 9 | B13: Stripe test keys | C13: NOT AVAILABLE — blocker SC-07 | D13: Needed by 2 cases, same rule. | E13: n/a
A14: 10 | B14: Staging environment | C14: NOT AVAILABLE — no deploy topology | D14: Needed by 3 cases (two-replica, restore drill, real latency). | E14: n/a
A15: 11 | B15: Time and clock | C15: System clock correct to within a minute, UTC preferred | D15: Lease frequency, replay window and monthly reset cases all read the clock. | E15: date -u
A16: 12 | B16: Tooling | C16: unzip, curl, ps, kill | D16: Used directly by the boot, drain and durability cases. | E16: which unzip curl kill

Sheet Entry_Exit_Criteria
A1: Entry Exit Criteria
A2: HOW TO USE THIS SHEET: Tick every entry row before running case 1. At the end, every exit row must be met or explicitly waived in writing on Sign_Off — a waiver is recorded, never assumed.
A4: Type | B4: # | C4: Criterion | D4: Why it matters | E4: Met?
A5: Entry | B5: 1 | C5: The exact zip named on the Cover_Sheet has been unpacked and nothing in it has been edited. | D5: A case that passes against edited source proves nothing.
A6: Entry | B6: 2 | C6: npm ci and npm run build both exit 0 (TC-001). | D6: Nothing later can be trusted if the artefact does not compile.
A7: Entry | B7: 3 | C7: The development environment variable block from Test_Environment is exported verbatim. | D7: Half the expected results are exact strings produced from those values.
A8: Entry | B8: 4 | C8: The tester has read Context_and_Scope and knows which cases are BLOCKED and why. | D8: Prevents a blocked case being recorded as a failure, which would distort the summary.
A9: Entry | B9: 5 | C9: A clean Test_Execution_Log has been copied for this run and stamped with the build under test. | D9: Runs must be attributable to a build.
A10: Exit | B10: 1 | C10: Every case whose Executable column says Yes has a result of Pass, Fail or Blocked — no blanks. | D10: A blank is an untested claim that looks tested.
A11: Exit | B11: 2 | C11: Every P0 case has passed. | D11: A P0 failure means the build must not ship, by definition.
A12: Exit | B12: 3 | C12: Every failure has a Defect_Log row with a severity and an owner. | D12: A failure with no defect row disappears at the next run.
A13: Exit | B13: 4 | C13: Test_Summary shows zero cases in the 'not run' count. | D13: The summary is computed from the sheets, so it cannot be talked past.
A14: Exit | B14: 5 | C14: Any case marked Blocked names the blocker id (SC-06, SC-07, or 'no staging'). | D14: Blocked without a named blocker is indistinguishable from skipped.
A15: Exit | B15: 6 | C15: Sign_Off is signed by the approver, with any waiver written on it. | D15: Acceptance is a decision by a person, not a spreadsheet state.

Sheet Manual_Test_Cases
A1: Manual Test Cases
A2: HOW TO USE THIS SHEET: One row per case. The steps are NOT here — they are on Test_Steps, keyed by the same Test case id, because one case has many steps. Filter Type for positive vs negative, Priority for a smoke run (P0 only), and Executable to see what you can actually run today. A case whose Executable column starts with NO is blocked, not failing.
A4: Test case id | B4: Version | C4: Area | D4: Module / sprint | E4: Type | F4: Priority | G4: Test case name | H4: Test description (what it proves) | I4: Preconditions | J4: Test data | K4: Steps | L4: Expected result (overall) | M4: Executable today? | N4: Automated equivalent
A5: TC-001 | B5: v037 | C5: Build & environment | D5: package.json / tsconfig | E5: Positive | F5: P0 | G5: Clean install and build from the delivered zip | H5: Prove the delivered artefact compiles from nothing, including the composition root that external review V001 found outside the type-check. | I5: Node 20-22 installed; the zip unpacked; no node_modules present. | J5: — | K5: 5 | L5: The product builds cleanly from a clean checkout and the composition root is inside the type-check. | M5: Yes — now | N5: CI build job
A6: TC-002 | B6: v036 | C6: Build & environment | D6: tsconfig.json | E6: Negative | F6: P0 | G6: A type error in the composition root must fail the build | H6: Regression for CF-001: for 28 releases tsconfig included src/** only, so a composition root with four type errors coexisted with 473 green tests. Deliberately break it and prove the gate now catches it. | I6: TC-001 passed. | J6: A deliberate, temporary edit to scripts/serve.ts. | K6: 5 | L6: The build refuses a composition root that cannot compile. CF-001 cannot recur silently. | M6: Yes — now | N6: tests/reviewV001.regressions.test.ts (tsconfig include assertions)
A7: TC-003 | B7: v037 | C7: Quality gate | D7: jest.config.js | E7: Positive | F7: P0 | G7: Full suite and 100% coverage gate over src AND scripts | H7: The headline quality claim. Coverage must cover the composition scripts too — closing audit finding A9. | I7: TC-001 passed. | J7: — | K7: 5 | L7: 616 tests pass and every metric is at 100% across both source and the composition scripts. | M7: Yes — now | N7: CI test job
A8: TC-004 | B8: v037 | C8: Quality gate | D8: jest.config.js | E8: Negative | F8: P1 | G8: Deleting a test must break the coverage gate | H8: Proves the 100% figure is enforced rather than reported. A gate that cannot fail is not a gate. | I8: TC-003 passed. | J8: A deliberate, temporary deletion. | K8: 5 | L8: The coverage gate fails the build when coverage drops, so the 100% claim is enforced. | M8: Yes — now | N8: —
A9: TC-005 | B9: v037 | C9: Supply chain | D9: package.json | E9: Positive | F9: P2 | G9: No known vulnerabilities in the production dependency tree | H9: The runtime surface is deliberately tiny (one dependency). Confirm it and the dev tree are clean. | I9: TC-001 passed. | J9: — | K9: 3 | L9: Neither the production nor the development dependency tree has a known vulnerability. | M9: Yes — now | N9: CI (manual step today)
A10: TC-006 | B10: v037 | C10: Portfolio tooling | D10: audit.mjs v3 | E10: Positive | F10: P1 | G10: The mechanical audit runs and reports suspects, not verdicts | H10: audit.mjs is the portfolio tool. v3 added A10-A13, the four defect classes the second review named. | I10: TC-001 passed. | J10: — | K10: 4 | L10: The audit tool runs clean on the three new checks and still surfaces the two honestly-open queue items. | M10: Yes — now | N10: CI audit step (advisory)
A11: TC-007 | B11: v037 | C11: Portfolio tooling | D11: audit.mjs A10 | E11: Negative | F11: P1 | G11: A10 must catch an enforcement method that production stops calling | H11: A10 is the check that found PX-002 in the review and PX-013 in our own fix. Prove it still fires by removing the production caller. | I11: TC-006 passed. | J11: A deliberate, temporary edit to src/app/workflow.ts. | K11: 5 | L11: The audit tool mechanically detects the 'two enforcement methods, one wired' class that caused the blocker. | M11: Yes — now | N11: —
A12: TC-010 | B12: v036 | C12: Boot gate | D12: scripts/serve.ts | E12: Positive | F12: P0 | G12: Development boot starts, serves and shuts down cleanly | H12: The product must start on honest stubs in development, say what is degraded, and drain its queues on SIGTERM. | I12: TC-001 passed; dist/ built. | J12: Environment string ENV (see Test_Environment sheet). | K12: 5 | L12: The product boots in development, is honest about what is degraded, and loses nothing at shutdown. | M12: Yes — now | N12: tests/px/bootSmoke.test.ts
A13: TC-011 | B13: v037 | C13: Boot gate | D13: src/composition/production.ts | E13: Negative | F13: P0 | G13: Production refuses to start on stubs and names every one | H13: Regression for CF-002/CB-02 plus the PX-003 capability probe: a production boot must be impossible while any adapter is fake, and it must say which. | I13: TC-001 passed; dist/ built. | J13: Same environment as TC-010 but APP_ENV=production. | K13: 6 | L13: Production cannot start on a fake composition, and the operator is told exactly which adapters and why. | M13: Yes — now | N13: tests/px/bootSmoke.test.ts + the CI package job
A14: TC-012 | B14: v037 | C14: Boot gate | D14: src/compliance/crypto.ts | E14: Negative | F14: P1 | G14: Missing encryption key stops the boot with the variable named | H14: Fail-fast configuration: a missing secret must never degrade into a silent insecure default. | I14: TC-001 passed. | J14: ENV with ENCRYPTION_KEY removed. | K14: 4 | L14: Every boot-critical secret is named individually when it is missing. | M14: Yes — now | N14: tests/px/bootSmoke.test.ts
A15: TC-013 | B15: v037 | C15: Boot gate / rotation | D15: src/compliance/crypto.ts | E15: Negative | F15: P1 | G15: Two encryption keys without a nominated current key is refused | H15: PX-005: rotation is only safe if the operator says which key is current. Ambiguity must be an error, not a guess. | I15: TC-001 passed. | J15: ENCRYPTION_KEY=old plus ENCRYPTION_KEY_k2=new, no ENCRYPTION_KEY_CURRENT. | K15: 3 | L15: An ambiguous or wrong key configuration is refused before any data can be written under it. | M15: Yes — now | N15: tests/px/identityAndWindows.test.ts
A16: TC-014 | B16: v036 | C16: Ops surface | D16: /ops/composition | E16: Positive | F16: P1 | G16: An operator can read the live adapter inventory and probe results | H16: CF-014: an operator must be able to see what the runtime is actually wired to without reading the source. | I16: TC-010 running. | J16: Operator token op-token. | K16: 4 | L16: The live composition is inspectable, and the reasons are written for a human. | M16: Yes — now | N16: tests/px/providerGate.test.ts
... A81: TC-160 | B81: v050 (pending) | C81: Accessibility | D81: S50 | E81: Positive | F81: P1 | G81: BLOCKED: screen-reader pass over the rendered Slack surfaces | H81: jest-axe passes on static shells and every view is validated against Slack's limits, but no human has used the product with a screen reader. | I81: The app installed in a real workspace (TC-150). | J81: VoiceOver or NVDA. | K81: 4 | L81: The Slack surfaces are usable without sight. | M81: NO — blocked on SC-06 and a human tester | N81: jest-axe covers the static shells only

Sheet Test_Steps
A1: Test Steps
A2: HOW TO USE THIS SHEET: Execute top to bottom within a Test case id. Stop at the first step whose expected result does not occur, record that step number on Test_Execution_Log, and do not continue the case — later steps assume the earlier ones succeeded. Look the case up on Manual_Test_Cases for its preconditions and data first.
A4: Test case id | B4: Version | C4: Test case name | D4: Type | E4: Step # | F4: Action — exactly what to do | G4: Expected result at this step | H4: Actual (fill in) | I4: Pass/Fail
A5: TC-001 | B5: v037 | C5: Clean install and build from the delivered zip | D5: Positive | E5: 1 | F5: Unpack oncall-copilot-v037-codebase.zip and cd into repo/ | G5: The folder contains package.json, src/, scripts/, tests/, docs/ and audit.mjs.
A6: TC-001 | B6: v037 | C6: Clean install and build from the delivered zip | D6: Positive | E6: 2 | F6: Run: npm ci | G6: Completes with no errors; pg is installed as a runtime dependency, not a dev dependency.
A7: TC-001 | B7: v037 | C7: Clean install and build from the delivered zip | D7: Positive | E7: 3 | F7: Run: npm run build | G7: Exits 0 and prints nothing. dist/scripts/serve.js and dist/src/** now exist.
A8: TC-001 | B8: v037 | C8: Clean install and build from the delivered zip | D8: Positive | E8: 4 | F8: Run: npm run typecheck:all | G8: Exits 0 — tests and the load harness type-check as well as src and scripts.
A9: TC-001 | B9: v037 | C9: Clean install and build from the delivered zip | D9: Positive | E9: 5 | F9: Run: ls dist/scripts | G9: serve.js, migrate.js, live-sweep.js, loadrun.js and submission-check.js are all present.
A10: TC-002 | B10: v036 | C10: A type error in the composition root must fail the build | D10: Negative | E10: 1 | F10: Open scripts/serve.ts and add a line inside main(): const broken: number = 'not a number'; | G10: File saved.
A11: TC-002 | B11: v036 | C11: A type error in the composition root must fail the build | D11: Negative | E11: 2 | F11: Run: npm run build | G11: FAILS with TS2322 naming scripts/serve.ts and the line number.
A12: TC-002 | B12: v036 | C12: A type error in the composition root must fail the build | D12: Negative | E12: 3 | F12: Run: npx tsc -p tsconfig.all.json | G12: Also fails — the error is not hidden by the wider project either.
A13: TC-002 | B13: v036 | C13: A type error in the composition root must fail the build | D13: Negative | E13: 4 | F13: Remove the line and re-run npm run build | G13: Exits 0 again.
A14: TC-002 | B14: v036 | C14: A type error in the composition root must fail the build | D14: Negative | E14: 5 | F14: Run: git diff | G14: Empty — the repository is back to its released state.
A15: TC-003 | B15: v037 | C15: Full suite and 100% coverage gate over src AND scripts | D15: Positive | E15: 1 | F15: Run: npx jest --coverage | G15: Runs 60 suites. One suite (pgReal.integration) is skipped without DATABASE_URL_TEST.
A16: TC-003 | B16: v037 | C16: Full suite and 100% coverage gate over src AND scripts | D16: Positive | E16: 2 | F16: Read the final counts | G16: 616 passed, 8 skipped, 624 total; no failures.
... A325: TC-160 | B325: v050 (pending) | C325: BLOCKED: screen-reader pass over the rendered Slack surfaces | D325: Positive | E325: 4 | F325: Open App Home | G325: Structure and headings are announced in a sensible order.

Sheet Test_Execution_Log
A1: Test Execution Log
